<sdf version='1.9'>
  <model name='pepper_robot'>
    <link name='base_link'>
      <inertial>
        <pose>-0.00247 0 0.195 0 0 0</pose>
        <mass>11.6015</mass>
        <inertia>
          <ixx>0.12922900000000009</ixx>
          <ixy>-0.00040194299999999998</ixy>
          <ixz>0.0004855600000000012</ixz>
          <iyy>0.122839</iyy>
          <iyz>-1.0166599999999999e-08</iyz>
          <izz>0.108168</izz>
        </inertia>
      </inertial>
      <collision name='base_link_fixed_joint_lump__Tibia_collision'>
        <pose>0 0 0.334 0 0 0</pose>
        <geometry>
          <mesh>
            <scale>0.1 0.1 0.1</scale>
            <uri>model://pepper_robot_description/pepper_robot/meshes/KneePitch_0.10.stl</uri>
          </mesh>
        </geometry>
        <surface>
          <contact>
            <ode/>
          </contact>
          <friction>
            <ode>
              <mu>0.5</mu>
              <mu2>0.5</mu2>
            </ode>
          </friction>
        </surface>
      </collision>
      <visual name='base_link_fixed_joint_lump__Tibia_visual'>
        <pose>0 0 0.334 0 0 0</pose>
        <geometry>
          <mesh>
            <scale>0.1 0.1 0.1</scale>
            <uri>model://pepper_robot_description/pepper_robot/meshes/KneePitch.dae</uri>
          </mesh>
        </geometry>
      </visual>
      <gravity>true</gravity>
      <self_collide>false</self_collide>
    </link>
    <joint name='KneePitch' type='revolute'>
      <pose relative_to='base_link'>0 0 0.334 0 0 0</pose>
      <parent>base_link</parent>
      <child>Pelvis</child>
      <axis>
        <xyz>0 -1 0</xyz>
        <limit>
          <lower>-0.514872</lower>
          <upper>0.514872</upper>
          <effort>27.702000000000002</effort>
          <velocity>2.93276</velocity>
        </limit>
        <dynamics>
          <spring_reference>0</spring_reference>
          <spring_stiffness>0</spring_stiffness>
        </dynamics>
      </axis>
    </joint>
    <link name='Pelvis'>
      <pose relative_to='KneePitch'>0 0 0 0 0 0</pose>
      <inertial>
        <pose>0.00247 0 0.1754 0 0 0</pose>
        <mass>2.4591699999999999</mass>
        <inertia>
          <ixx>0.034351</ixx>
          <ixy>0</ixy>
          <ixz>0.00022303399999999999</ixz>
          <iyy>0.030312200000000001</iyy>
          <iyz>-8.3754199999999998e-05</iyz>
          <izz>0.0143771</izz>
        </inertia>
      </inertial>
      <collision name='Pelvis_collision'>
        <pose>0 0 0.268 0 0 0</pose>
        <geometry>
          <mesh>
            <scale>0.1 0.1 0.1</scale>
            <uri>model://pepper_robot_description/pepper_robot/meshes/HipPitch_0.10.stl</uri>
          </mesh>
        </geometry>
        <surface>
          <contact>
            <ode/>
          </contact>
          <friction>
            <ode>
              <mu>0.5</mu>
              <mu2>0.5</mu2>
            </ode>
          </friction>
        </surface>
      </collision>
      <visual name='Pelvis_visual'>
        <pose>0 0 0.268 0 0 0</pose>
        <geometry>
          <mesh>
            <scale>0.1 0.1 0.1</scale>
            <uri>model://pepper_robot_description/pepper_robot/meshes/HipPitch.dae</uri>
          </mesh>
        </geometry>
      </visual>
      <gravity>true</gravity>
      <self_collide>false</self_collide>
    </link>
    <joint name='HipPitch' type='revolute'>
      <pose relative_to='Pelvis'>0 0 0.268 0 0 0</pose>
      <parent>Pelvis</parent>
      <child>Hip</child>
      <axis>
        <xyz>0 -1 0</xyz>
        <limit>
          <lower>-1.03847</lower>
          <upper>1.03847</upper>
          <effort>19.786999999999999</effort>
          <velocity>2.93276</velocity>
        </limit>
        <dynamics>
          <spring_reference>0</spring_reference>
          <spring_stiffness>0</spring_stiffness>
        </dynamics>
      </axis>
    </joint>
    <link name='Hip'>
      <pose relative_to='HipPitch'>0 0 0 0 0 0</pose>
      <inertial>
        <pose>0.00032 0 -0.003416125 0 0 0</pose>
        <mass>1.02338</mass>
        <inertia>
          <ixx>0.0050242200000000002</ixx>
          <ixy>0</ixy>
          <ixz>-2.5491100000000001e-05</ixz>
          <iyy>0.0064097099999999999</iyy>
          <iyz>0.00015944900000000001</iyz>
          <izz>0.0044108200000000002</izz>
        </inertia>
      </inertial>
      <collision name='Hip_collision'>
        <pose>0 0 0.079 0 0 0</pose>
        <geometry>
          <mesh>
            <scale>0.1 0.1 0.1</scale>
            <uri>model://pepper_robot_description/pepper_robot/meshes/HipRoll_0.10.stl</uri>
          </mesh>
        </geometry>
        <surface>
          <contact>
            <ode/>
          </contact>
          <friction>
            <ode>
              <mu>0.5</mu>
              <mu2>0.5</mu2>
            </ode>
          </friction>
        </surface>
      </collision>
      <visual name='Hip_visual'>
        <pose>0 0 0.079 0 0 0</pose>
        <geometry>
          <mesh>
            <scale>0.1 0.1 0.1</scale>
            <uri>model://pepper_robot_description/pepper_robot/meshes/HipRoll.dae</uri>
          </mesh>
        </geometry>
      </visual>
      <gravity>true</gravity>
      <self_collide>false</self_collide>
    </link>
    <joint name='HipRoll' type='revolute'>
      <pose relative_to='Hip'>-2e-05 0 0.079 0 0 0</pose>
      <parent>Hip</parent>
      <child>torso</child>
      <axis>
        <xyz>-1 0 0</xyz>
        <limit>
          <lower>-0.514872</lower>
          <upper>0.514872</upper>
          <effort>10.1884</effort>
          <velocity>2.2703199999999999</velocity>
        </limit>
        <dynamics>
          <spring_reference>0</spring_reference>
          <spring_stiffness>0</spring_stiffness>
        </dynamics>
      </axis>
    </joint>
    <link name='torso'>
      <pose relative_to='HipRoll'>0 0 0 0 0 0</pose>
      <inertial>
        <pose>0.00322 0 0.12871 0 0.1963 0</pose>
        <mass>3.99533</mass>
        <inertia>
          <ixx>0.0452761</ixx>
          <ixy>0</ixy>
          <ixz>0.0049909100000000003</ixz>
          <iyy>0.043270200000000002</iyy>
          <iyz>-0.00026688599999999998</iyz>
          <izz>0.025888100000000001</izz>
        </inertia>
      </inertial>
      <collision name='torso_collision'>
        <pose>0 0 0.139 0 0 0</pose>
        <geometry>
          <mesh>
            <scale>0.1 0.1 0.1</scale>
            <uri>model://pepper_robot_description/pepper_robot/meshes/Torso_0.10.stl</uri>
          </mesh>
        </geometry>
        <surface>
          <contact>
            <ode/>
          </contact>
          <friction>
            <ode>
              <mu>0.5</mu>
              <mu2>0.5</mu2>
            </ode>
          </friction>
        </surface>
      </collision>
      <visual name='torso_visual'>
        <pose>0 0 0.139 0 0 0</pose>
        <geometry>
          <mesh>
            <scale>0.1 0.1 0.1</scale>
            <uri>model://pepper_robot_description/pepper_robot/meshes/Torso.dae</uri>
          </mesh>
        </geometry>
      </visual>
      <gravity>true</gravity>
      <self_collide>false</self_collide>
    </link>
    <joint name='HeadYaw' type='revolute'>
      <pose relative_to='torso'>-0.038 0 0.3089 0 0 0</pose>
      <parent>torso</parent>
      <child>Neck</child>
      <axis>
        <xyz>0 0 1</xyz>
        <limit>
          <lower>-2.0856699999999999</lower>
          <upper>2.0856699999999999</upper>
          <effort>5.4279999999999999</effort>
          <velocity>7.3399799999999997</velocity>
        </limit>
        <dynamics>
          <spring_reference>0</spring_reference>
          <spring_stiffness>0</spring_stiffness>
        </dynamics>
      </axis>
    </joint>
    <link name='Neck'>
      <pose relative_to='HeadYaw'>0 0 0 0 0 0</pose>
      <inertial>
        <pose>-0.00207 0 -0.003295 0 0 0</pose>
        <mass>0.27390999999999999</mass>
        <inertia>
          <ixx>0.00034350100000000002</ixx>
          <ixy>0</ixy>
          <ixz>-1.8856300000000001e-05</ixz>
          <iyy>0.00049389799999999999</iyy>
          <iyz>2.0986300000000001e-06</iyz>
          <izz>0.00021525200000000001</izz>
        </inertia>
      </inertial>
      <collision name='Neck_collision'>
        <pose>0 0 0 0 0 0</pose>
        <geometry>
          <mesh>
            <scale>0.1 0.1 0.1</scale>
            <uri>model://pepper_robot_description/pepper_robot/meshes/HeadYaw_0.10.stl</uri>
          </mesh>
        </geometry>
        <surface>
          <contact>
            <ode/>
          </contact>
          <friction>
            <ode>
              <mu>0.5</mu>
              <mu2>0.5</mu2>
            </ode>
          </friction>
        </surface>
      </collision>
      <visual name='Neck_visual'>
        <pose>0 0 0 0 0 0</pose>
        <geometry>
          <mesh>
            <scale>0.1 0.1 0.1</scale>
            <uri>model://pepper_robot_description/pepper_robot/meshes/HeadYaw.dae</uri>
          </mesh>
        </geometry>
      </visual>
      <gravity>true</gravity>
      <self_collide>false</self_collide>
    </link>
    <joint name='HeadPitch' type='revolute'>
      <pose relative_to='Neck'>0 0 0 0 0 0</pose>
      <parent>Neck</parent>
      <child>Head</child>
      <axis>
        <xyz>0 1 0</xyz>
        <limit>
          <lower>-0.70685799999999999</lower>
          <upper>0.4451</upper>
          <effort>2.6659999999999999</effort>
          <velocity>9.2275600000000004</velocity>
        </limit>
        <dynamics>
          <spring_reference>0</spring_reference>
          <spring_stiffness>0</spring_stiffness>
        </dynamics>
      </axis>
    </joint>
    <link name='Head'>
      <pose relative_to='HeadPitch'>0 0 0 0 0 0</pose>
      <inertial>
        <pose>0.00312 0 0.11152 1.5708 0 0.3926</pose>
        <mass>1.5189299999999999</mass>
        <inertia>
          <ixx>0.0059720900000000002</ixx>
          <ixy>0</ixy>
          <ixz>0.00012513800000000001</ixz>
          <iyy>0.0059053999999999999</iyy>
          <iyz>4.3428e-07</iyz>
          <izz>0.0057037399999999997</izz>
        </inertia>
      </inertial>
      <collision name='Head_collision'>
        <pose>0 0 0 0 0 0</pose>
        <geometry>
          <mesh>
            <scale>0.1 0.1 0.1</scale>
            <uri>model://pepper_robot_description/pepper_robot/meshes/HeadPitch_0.10.stl</uri>
          </mesh>
        </geometry>
        <surface>
          <contact>
            <ode/>
          </contact>
          <friction>
            <ode>
              <mu>0.5</mu>
              <mu2>0.5</mu2>
            </ode>
          </friction>
        </surface>
      </collision>
      <visual name='Head_visual'>
        <pose>0 0 0 0 0 0</pose>
        <geometry>
          <mesh>
            <scale>0.1 0.1 0.1</scale>
            <uri>model://pepper_robot_description/pepper_robot/meshes/HeadPitch.dae</uri>
          </mesh>
        </geometry>
      </visual>
      <gravity>true</gravity>
      <self_collide>false</self_collide>
    </link>
    <joint name='LShoulderPitch' type='revolute'>
      <pose relative_to='torso'>-0.057 0.14974 0.22582 0 0 0</pose>
      <parent>torso</parent>
      <child>LShoulder</child>
      <axis>
        <xyz>0 1 0</xyz>
        <limit>
          <lower>-2.0856699999999999</lower>
          <upper>2.0856699999999999</upper>
          <effort>5.4279999999999999</effort>
          <velocity>7.3399799999999997</velocity>
        </limit>
        <dynamics>
          <spring_reference>0</spring_reference>
          <spring_stiffness>0</spring_stiffness>
        </dynamics>
      </axis>
    </joint>
    <link name='LShoulder'>
      <pose relative_to='LShoulderPitch'>0 0 0 0 0 0</pose>
      <inertial>
        <pose>0.00018 -0.01856 0.00099 0 0 0</pose>
        <mass>0.3125</mass>
        <inertia>
          <ixx>0.00036119800000000002</ixx>
          <ixy>-1.9834700000000002e-06</ixy>
          <ixz>6.35907e-07</ixz>
          <iyy>0.000137229</iyy>
          <iyz>-5.6887799999999999e-06</iyz>
          <izz>0.00039919400000000001</izz>
        </inertia>
      </inertial>
      <collision name='LShoulder_collision'>
        <pose>0 0 0 0 0 0</pose>
        <geometry>
          <mesh>
            <scale>0.1 0.1 0.1</scale>
            <uri>model://pepper_robot_description/pepper_robot/meshes/LShoulderPitch_0.10.stl</uri>
          </mesh>
        </geometry>
        <surface>
          <contact>
            <ode/>
          </contact>
          <friction>
            <ode>
              <mu>0.5</mu>
              <mu2>0.5</mu2>
            </ode>
          </friction>
        </surface>
      </collision>
      <visual name='LShoulder_visual'>
        <pose>0 0 0 0 0 0</pose>
        <geometry>
          <mesh>
            <scale>0.1 0.1 0.1</scale>
            <uri>model://pepper_robot_description/pepper_robot/meshes/LShoulderPitch.dae</uri>
          </mesh>
        </geometry>
      </visual>
      <gravity>true</gravity>
      <self_collide>false</self_collide>
    </link>
    <joint name='LShoulderRoll' type='revolute'>
      <pose relative_to='LShoulder'>0 0 0 0 0 0</pose>
      <parent>LShoulder</parent>
      <child>LBicep</child>
      <axis>
        <xyz>0 0 1</xyz>
        <limit>
          <lower>0.0087266500000000007</lower>
          <upper>1.5620700000000001</upper>
          <effort>2.6659999999999999</effort>
          <velocity>9.2275600000000004</velocity>
        </limit>
        <dynamics>
          <spring_reference>0</spring_reference>
          <spring_stiffness>0</spring_stiffness>
        </dynamics>
      </axis>
    </joint>
    <link name='LBicep'>
      <pose relative_to='LShoulderRoll'>0 0 0 0 0 0</pose>
      <inertial>
        <pose>0.08151 0.01284 -0.01017 0 0 0</pose>
        <mass>0.50527</mass>
        <inertia>
          <ixx>0.00050087199999999997</ixx>
          <ixy>-3.55918e-05</ixy>
          <ixz>8.5126300000000005e-05</ixz>
          <iyy>0.0012628400000000001</iyy>
          <iyz>9.0681299999999992e-06</iyz>
          <izz>0.0011571800000000001</izz>
        </inertia>
      </inertial>
      <collision name='LBicep_collision'>
        <pose>0 0 0 0 0 0</pose>
        <geometry>
          <mesh>
            <scale>0.1 0.1 0.1</scale>
            <uri>model://pepper_robot_description/pepper_robot/meshes/LShoulderRoll_0.10.stl</uri>
          </mesh>
        </geometry>
        <surface>
          <contact>
            <ode/>
          </contact>
          <friction>
            <ode>
              <mu>0.5</mu>
              <mu2>0.5</mu2>
            </ode>
          </friction>
        </surface>
      </collision>
      <visual name='LBicep_visual'>
        <pose>0 0 0 0 0 0</pose>
        <geometry>
          <mesh>
            <scale>0.1 0.1 0.1</scale>
            <uri>model://pepper_robot_description/pepper_robot/meshes/LShoulderRoll.dae</uri>
          </mesh>
        </geometry>
      </visual>
      <gravity>true</gravity>
      <self_collide>false</self_collide>
    </link>
    <joint name='LElbowYaw' type='revolute'>
      <pose relative_to='LBicep'>0.1812 0.015 0.00013 0 -0.1570790000000001 0</pose>
      <parent>LBicep</parent>
      <child>LElbow</child>
      <axis>
        <xyz>1 0 0</xyz>
        <limit>
          <lower>-2.0856699999999999</lower>
          <upper>2.0856699999999999</upper>
          <effort>5.4279999999999999</effort>
          <velocity>7.3399799999999997</velocity>
        </limit>
        <dynamics>
          <spring_reference>0</spring_reference>
          <spring_stiffness>0</spring_stiffness>
        </dynamics>
      </axis>
    </joint>
    <link name='LElbow'>
      <pose relative_to='LElbowYaw'>0 0 0 0 0 0</pose>
      <inertial>
        <pose>-0.02297 -0.00019 0.00119 0 0 0</pose>
        <mass>0.27495000000000003</mass>
        <inertia>
          <ixx>0.00012297100000000001</ixx>
          <ixy>9.8602399999999999e-07</ixy>
          <ixz>-2.5583800000000001e-05</ixz>
          <iyy>0.00033176599999999999</iyy>
          <iyz>-1.9892500000000001e-06</iyz>
          <izz>0.00030304699999999997</izz>
        </inertia>
      </inertial>
      <collision name='LElbow_collision'>
        <pose>0 0 0 0 0 0</pose>
        <geometry>
          <mesh>
            <scale>0.1 0.1 0.1</scale>
            <uri>model://pepper_robot_description/pepper_robot/meshes/LElbowYaw_0.10.stl</uri>
          </mesh>
        </geometry>
        <surface>
          <contact>
            <ode/>
          </contact>
          <friction>
            <ode>
              <mu>0.5</mu>
              <mu2>0.5</mu2>
            </ode>
          </friction>
        </surface>
      </collision>
      <visual name='LElbow_visual'>
        <pose>0 0 0 0 0 0</pose>
        <geometry>
          <mesh>
            <scale>0.1 0.1 0.1</scale>
            <uri>model://pepper_robot_description/pepper_robot/meshes/LElbowYaw.dae</uri>
          </mesh>
        </geometry>
      </visual>
      <gravity>true</gravity>
      <self_collide>false</self_collide>
    </link>
    <joint name='LElbowRoll' type='revolute'>
      <pose relative_to='LElbow'>0 0 0 0 0 0</pose>
      <parent>LElbow</parent>
      <child>LForeArm</child>
      <axis>
        <xyz>0 0 1</xyz>
        <limit>
          <lower>-1.5620700000000001</lower>
          <upper>-0.0087266500000000007</upper>
          <effort>2.6659999999999999</effort>
          <velocity>9.2275600000000004</velocity>
        </limit>
        <dynamics>
          <spring_reference>0</spring_reference>
          <spring_stiffness>0</spring_stiffness>
        </dynamics>
      </axis>
    </joint>
    <link name='LForeArm'>
      <pose relative_to='LElbowRoll'>0 0 0 0 0 0</pose>
      <inertial>
        <pose>0.0593 0.00271 -0.01014 0 0.3927 0</pose>
        <mass>0.16578999999999999</mass>
        <inertia>
          <ixx>0.000156513</ixx>
          <ixy>1.47517e-05</ixy>
          <ixz>-6.0574600000000001e-05</ixz>
          <iyy>0.00037321899999999999</iyy>
          <iyz>-1.7618999999999999e-07</iyz>
          <izz>0.000273081</izz>
        </inertia>
      </inertial>
      <collision name='LForeArm_collision'>
        <pose>0 0 0 0 0 0</pose>
        <geometry>
          <mesh>
            <scale>0.1 0.1 0.1</scale>
            <uri>model://pepper_robot_description/pepper_robot/meshes/LElbowRoll_0.10.stl</uri>
          </mesh>
        </geometry>
        <surface>
          <contact>
            <ode/>
          </contact>
          <friction>
            <ode>
              <mu>0.5</mu>
              <mu2>0.5</mu2>
            </ode>
          </friction>
        </surface>
      </collision>
      <visual name='LForeArm_visual'>
        <pose>0 0 0 0 0 0</pose>
        <geometry>
          <mesh>
            <scale>0.1 0.1 0.1</scale>
            <uri>model://pepper_robot_description/pepper_robot/meshes/LElbowRoll.dae</uri>
          </mesh>
        </geometry>
      </visual>
      <gravity>true</gravity>
      <self_collide>false</self_collide>
    </link>
    <joint name='LWristYaw' type='revolute'>
      <pose relative_to='LForeArm'>0.15 0 0 0 0 0</pose>
      <parent>LForeArm</parent>
      <child>l_wrist</child>
      <axis>
        <xyz>1 0 0</xyz>
        <limit>
          <lower>-1.8238700000000001</lower>
          <upper>1.8238700000000001</upper>
          <effort>0.2014</effort>
          <velocity>17.383500000000002</velocity>
        </limit>
        <dynamics>
          <spring_reference>0</spring_reference>
          <spring_stiffness>0</spring_stiffness>
        </dynamics>
      </axis>
    </joint>
    <link name='l_wrist'>
      <pose relative_to='LWristYaw'>0 0 0 0 0 0</pose>
      <inertial>
        <pose>0.03560961268239957 -0.0007148117456314178 -0.002184957234228067 0 0 0</pose>
        <mass>0.27755000000000002</mass>
        <inertia>
          <ixx>0.00015215047001351179</ixx>
          <ixy>1.061337784226265e-05</ixy>
          <ixz>3.9923627784830811e-06</ixz>
          <iyy>0.00043398800671796143</iyy>
          <iyz>-3.1143429445580879e-06</iyz>
          <izz>0.00045855669536227697</izz>
        </inertia>
      </inertial>
      <collision name='l_wrist_collision'>
        <pose>0 0 0 0 0 0</pose>
        <geometry>
          <mesh>
            <scale>0.1 0.1 0.1</scale>
            <uri>model://pepper_robot_description/pepper_robot/meshes/LWristYaw.dae</uri>
          </mesh>
        </geometry>
        <surface>
          <contact>
            <ode/>
          </contact>
          <friction>
            <ode>
              <mu>0.5</mu>
              <mu2>0.5</mu2>
            </ode>
          </friction>
        </surface>
      </collision>
      <visual name='l_wrist_visual'>
        <pose>0 0 0 0 0 0</pose>
        <geometry>
          <mesh>
            <scale>0.1 0.1 0.1</scale>
            <uri>model://pepper_robot_description/pepper_robot/meshes/LWristYaw.dae</uri>
          </mesh>
        </geometry>
      </visual>
      <gravity>true</gravity>
      <self_collide>false</self_collide>
    </link>
    <joint name='LFinger11' type='revolute'>
      <pose relative_to='l_wrist'>0.08210000000000001 -0.0268 0.004 1.74402 1.04064 -0.03343350000000005</pose>
      <parent>l_wrist</parent>
      <child>LFinger11_link</child>
      <axis>
        <xyz>0 0 1</xyz>
        <limit>
          <lower>0</lower>
          <upper>0.87266500000000002</upper>
          <effort>0.14399999999999999</effort>
          <velocity>1</velocity>
        </limit>
        <dynamics>
          <spring_reference>0</spring_reference>
          <spring_stiffness>0</spring_stiffness>
        </dynamics>
      </axis>
    </joint>
    <link name='LFinger11_link'>
      <pose relative_to='LFinger11'>0 0 0 0 0 0</pose>
      <inertial>
        <pose>0 0 0 -1.57 0 0</pose>
        <mass>0.002</mass>
        <inertia>
          <ixx>1.0999999999999999e-09</ixx>
          <ixy>0</ixy>
          <ixz>0</ixz>
          <iyy>1.0999999999999999e-09</iyy>
          <iyz>0</iyz>
          <izz>1.0999999999999999e-09</izz>
        </inertia>
      </inertial>
      <collision name='LFinger11_link_collision'>
        <pose>0 0 0 -1.57 0 0</pose>
        <geometry>
          <mesh>
            <scale>0.1 0.1 0.1</scale>
            <uri>model://pepper_robot_description/pepper_robot/meshes/LFinger11_0.10.stl</uri>
          </mesh>
        </geometry>
        <surface>
          <contact>
            <ode/>
          </contact>
          <friction>
            <ode>
              <mu>0.5</mu>
              <mu2>0.5</mu2>
            </ode>
          </friction>
        </surface>
      </collision>
      <visual name='LFinger11_link_visual'>
        <pose>0 0 0 -1.57 0 0</pose>
        <geometry>
          <mesh>
            <scale>0.1 0.1 0.1</scale>
            <uri>model://pepper_robot_description/pepper_robot/meshes/LFinger11.dae</uri>
          </mesh>
        </geometry>
      </visual>
      <gravity>true</gravity>
      <self_collide>false</self_collide>
    </link>
    <joint name='LFinger12' type='revolute'>
      <pose relative_to='LFinger11_link'>0.018 0 0 0 0 -1.0472</pose>
      <parent>LFinger11_link</parent>
      <child>LFinger12_link</child>
      <axis>
        <xyz>0 0 1</xyz>
        <limit>
          <lower>0</lower>
          <upper>0.87266500000000002</upper>
          <effort>0.14399999999999999</effort>
          <velocity>1</velocity>
        </limit>
        <dynamics>
          <spring_reference>0</spring_reference>
          <spring_stiffness>0</spring_stiffness>
        </dynamics>
      </axis>
    </joint>
    <link name='LFinger12_link'>
      <pose relative_to='LFinger12'>0 0 0 0 0 0</pose>
      <inertial>
        <pose>0 0 0 -1.57 0 0</pose>
        <mass>0.002</mass>
        <inertia>
          <ixx>1.0999999999999999e-09</ixx>
          <ixy>0</ixy>
          <ixz>0</ixz>
          <iyy>1.0999999999999999e-09</iyy>
          <iyz>0</iyz>
          <izz>1.0999999999999999e-09</izz>
        </inertia>
      </inertial>
      <collision name='LFinger12_link_collision'>
        <pose>0 0 0 -1.57 0 0</pose>
        <geometry>
          <mesh>
            <scale>0.1 0.1 0.1</scale>
            <uri>model://pepper_robot_description/pepper_robot/meshes/LFinger12_0.10.stl</uri>
          </mesh>
        </geometry>
        <surface>
          <contact>
            <ode/>
          </contact>
          <friction>
            <ode>
              <mu>0.5</mu>
              <mu2>0.5</mu2>
            </ode>
          </friction>
        </surface>
      </collision>
      <visual name='LFinger12_link_visual'>
        <pose>0 0 0 -1.57 0 0</pose>
        <geometry>
          <mesh>
            <scale>0.1 0.1 0.1</scale>
            <uri>model://pepper_robot_description/pepper_robot/meshes/LFinger12.dae</uri>
          </mesh>
        </geometry>
      </visual>
      <gravity>true</gravity>
      <self_collide>false</self_collide>
    </link>
    <joint name='LFinger13' type='revolute'>
      <pose relative_to='LFinger12_link'>0.018 0 0 0 0 -1.0472</pose>
      <parent>LFinger12_link</parent>
      <child>LFinger13_link</child>
      <axis>
        <xyz>0 0 1</xyz>
        <limit>
          <lower>0</lower>
          <upper>0.87266500000000002</upper>
          <effort>0.14399999999999999</effort>
          <velocity>1</velocity>
        </limit>
        <dynamics>
          <spring_reference>0</spring_reference>
          <spring_stiffness>0</spring_stiffness>
        </dynamics>
      </axis>
    </joint>
    <link name='LFinger13_link'>
      <pose relative_to='LFinger13'>0 0 0 0 0 0</pose>
      <inertial>
        <pose>0 0 0 -1.57 0 0</pose>
        <mass>0.002</mass>
        <inertia>
          <ixx>1.0999999999999999e-09</ixx>
          <ixy>0</ixy>
          <ixz>0</ixz>
          <iyy>1.0999999999999999e-09</iyy>
          <iyz>0</iyz>
          <izz>1.0999999999999999e-09</izz>
        </inertia>
      </inertial>
      <collision name='LFinger13_link_collision'>
        <pose>0 0 0 -1.57 0 0</pose>
        <geometry>
          <mesh>
            <scale>0.1 0.1 0.1</scale>
            <uri>model://pepper_robot_description/pepper_robot/meshes/LFinger13_0.10.stl</uri>
          </mesh>
        </geometry>
        <surface>
          <contact>
            <ode/>
          </contact>
          <friction>
            <ode>
              <mu>0.5</mu>
              <mu2>0.5</mu2>
            </ode>
          </friction>
        </surface>
      </collision>
      <visual name='LFinger13_link_visual'>
        <pose>0 0 0 -1.57 0 0</pose>
        <geometry>
          <mesh>
            <scale>0.1 0.1 0.1</scale>
            <uri>model://pepper_robot_description/pepper_robot/meshes/LFinger13.dae</uri>
          </mesh>
        </geometry>
      </visual>
      <gravity>true</gravity>
      <self_collide>false</self_collide>
    </link>
    <joint name='LFinger21' type='revolute'>
      <pose relative_to='l_wrist'>0.0873 -0.0073 0.006 1.5708 1.0472 -0.06108599999999988</pose>
      <parent>l_wrist</parent>
      <child>LFinger21_link</child>
      <axis>
        <xyz>0 0 1</xyz>
        <limit>
          <lower>0</lower>
          <upper>0.87266500000000002</upper>
          <effort>0.14399999999999999</effort>
          <velocity>1</velocity>
        </limit>
        <dynamics>
          <spring_reference>0</spring_reference>
          <spring_stiffness>0</spring_stiffness>
        </dynamics>
      </axis>
    </joint>
    <link name='LFinger21_link'>
      <pose relative_to='LFinger21'>0 0 0 0 0 0</pose>
      <inertial>
        <pose>0 0 0 -1.57 0 0</pose>
        <mass>0.002</mass>
        <inertia>
          <ixx>1.0999999999999999e-09</ixx>
          <ixy>0</ixy>
          <ixz>0</ixz>
          <iyy>1.0999999999999999e-09</iyy>
          <iyz>0</iyz>
          <izz>1.0999999999999999e-09</izz>
        </inertia>
      </inertial>
      <collision name='LFinger21_link_collision'>
        <pose>0 0 0 -1.57 0 0</pose>
        <geometry>
          <mesh>
            <scale>0.1 0.1 0.1</scale>
            <uri>model://pepper_robot_description/pepper_robot/meshes/LFinger21_0.10.stl</uri>
          </mesh>
        </geometry>
        <surface>
          <contact>
            <ode/>
          </contact>
          <friction>
            <ode>
              <mu>0.5</mu>
              <mu2>0.5</mu2>
            </ode>
          </friction>
        </surface>
      </collision>
      <visual name='LFinger21_link_visual'>
        <pose>0 0 0 -1.57 0 0</pose>
        <geometry>
          <mesh>
            <scale>0.1 0.1 0.1</scale>
            <uri>model://pepper_robot_description/pepper_robot/meshes/LFinger21.dae</uri>
          </mesh>
        </geometry>
      </visual>
      <gravity>true</gravity>
      <self_collide>false</self_collide>
    </link>
    <joint name='LFinger22' type='revolute'>
      <pose relative_to='LFinger21_link'>0.018 0 0 0 0 -1.0472</pose>
      <parent>LFinger21_link</parent>
      <child>LFinger22_link</child>
      <axis>
        <xyz>0 0 1</xyz>
        <limit>
          <lower>0</lower>
          <upper>0.87266500000000002</upper>
          <effort>0.14399999999999999</effort>
          <velocity>1</velocity>
        </limit>
        <dynamics>
          <spring_reference>0</spring_reference>
          <spring_stiffness>0</spring_stiffness>
        </dynamics>
      </axis>
    </joint>
    <link name='LFinger22_link'>
      <pose relative_to='LFinger22'>0 0 0 0 0 0</pose>
      <inertial>
        <pose>0 0 0 -1.57 0 0</pose>
        <mass>0.002</mass>
        <inertia>
          <ixx>1.0999999999999999e-09</ixx>
          <ixy>0</ixy>
          <ixz>0</ixz>
          <iyy>1.0999999999999999e-09</iyy>
          <iyz>0</iyz>
          <izz>1.0999999999999999e-09</izz>
        </inertia>
      </inertial>
      <collision name='LFinger22_link_collision'>
        <pose>0 0 0 -1.57 0 0</pose>
        <geometry>
          <mesh>
            <scale>0.1 0.1 0.1</scale>
            <uri>model://pepper_robot_description/pepper_robot/meshes/LFinger22_0.10.stl</uri>
          </mesh>
        </geometry>
        <surface>
          <contact>
            <ode/>
          </contact>
          <friction>
            <ode>
              <mu>0.5</mu>
              <mu2>0.5</mu2>
            </ode>
          </friction>
        </surface>
      </collision>
      <visual name='LFinger22_link_visual'>
        <pose>0 0 0 -1.57 0 0</pose>
        <geometry>
          <mesh>
            <scale>0.1 0.1 0.1</scale>
            <uri>model://pepper_robot_description/pepper_robot/meshes/LFinger22.dae</uri>
          </mesh>
        </geometry>
      </visual>
      <gravity>true</gravity>
      <self_collide>false</self_collide>
    </link>
    <joint name='LFinger23' type='revolute'>
      <pose relative_to='LFinger22_link'>0.018 0 0 0 0 -1.0472</pose>
      <parent>LFinger22_link</parent>
      <child>LFinger23_link</child>
      <axis>
        <xyz>0 0 1</xyz>
        <limit>
          <lower>0</lower>
          <upper>0.87266500000000002</upper>
          <effort>0.14399999999999999</effort>
          <velocity>1</velocity>
        </limit>
        <dynamics>
          <spring_reference>0</spring_reference>
          <spring_stiffness>0</spring_stiffness>
        </dynamics>
      </axis>
    </joint>
    <link name='LFinger23_link'>
      <pose relative_to='LFinger23'>0 0 0 0 0 0</pose>
      <inertial>
        <pose>0 0 0 -1.57 0 0</pose>
        <mass>0.002</mass>
        <inertia>
          <ixx>1.0999999999999999e-09</ixx>
          <ixy>0</ixy>
          <ixz>0</ixz>
          <iyy>1.0999999999999999e-09</iyy>
          <iyz>0</iyz>
          <izz>1.0999999999999999e-09</izz>
        </inertia>
      </inertial>
      <collision name='LFinger23_link_collision'>
        <pose>0 0 0 -1.57 0 0</pose>
        <geometry>
          <mesh>
            <scale>0.1 0.1 0.1</scale>
            <uri>model://pepper_robot_description/pepper_robot/meshes/LFinger23_0.10.stl</uri>
          </mesh>
        </geometry>
        <surface>
          <contact>
            <ode/>
          </contact>
          <friction>
            <ode>
              <mu>0.5</mu>
              <mu2>0.5</mu2>
            </ode>
          </friction>
        </surface>
      </collision>
      <visual name='LFinger23_link_visual'>
        <pose>0 0 0 -1.57 0 0</pose>
        <geometry>
          <mesh>
            <scale>0.1 0.1 0.1</scale>
            <uri>model://pepper_robot_description/pepper_robot/meshes/LFinger23.dae</uri>
          </mesh>
        </geometry>
      </visual>
      <gravity>true</gravity>
      <self_collide>false</self_collide>
    </link>
    <joint name='LFinger31' type='revolute'>
      <pose relative_to='l_wrist'>0.0833 0.0123 0.004 1.46636 1.04483 -0.02931400000000012</pose>
      <parent>l_wrist</parent>
      <child>LFinger31_link</child>
      <axis>
        <xyz>0 0 1</xyz>
        <limit>
          <lower>0</lower>
          <upper>0.87266500000000002</upper>
          <effort>0.14399999999999999</effort>
          <velocity>1</velocity>
        </limit>
        <dynamics>
          <spring_reference>0</spring_reference>
          <spring_stiffness>0</spring_stiffness>
        </dynamics>
      </axis>
    </joint>
    <link name='LFinger31_link'>
      <pose relative_to='LFinger31'>0 0 0 0 0 0</pose>
      <inertial>
        <pose>0 0 0 -1.57 0 0</pose>
        <mass>0.002</mass>
        <inertia>
          <ixx>1.0999999999999999e-09</ixx>
          <ixy>0</ixy>
          <ixz>0</ixz>
          <iyy>1.0999999999999999e-09</iyy>
          <iyz>0</iyz>
          <izz>1.0999999999999999e-09</izz>
        </inertia>
      </inertial>
      <collision name='LFinger31_link_collision'>
        <pose>0 0 0 -1.57 0 0</pose>
        <geometry>
          <mesh>
            <scale>0.1 0.1 0.1</scale>
            <uri>model://pepper_robot_description/pepper_robot/meshes/LFinger31_0.10.stl</uri>
          </mesh>
        </geometry>
        <surface>
          <contact>
            <ode/>
          </contact>
          <friction>
            <ode>
              <mu>0.5</mu>
              <mu2>0.5</mu2>
            </ode>
          </friction>
        </surface>
      </collision>
      <visual name='LFinger31_link_visual'>
        <pose>0 0 0 -1.57 0 0</pose>
        <geometry>
          <mesh>
            <scale>0.1 0.1 0.1</scale>
            <uri>model://pepper_robot_description/pepper_robot/meshes/LFinger31.dae</uri>
          </mesh>
        </geometry>
      </visual>
      <gravity>true</gravity>
      <self_collide>false</self_collide>
    </link>
    <joint name='LFinger32' type='revolute'>
      <pose relative_to='LFinger31_link'>0.018 0 0 0 0 -1.0472</pose>
      <parent>LFinger31_link</parent>
      <child>LFinger32_link</child>
      <axis>
        <xyz>0 0 1</xyz>
        <limit>
          <lower>0</lower>
          <upper>0.87266500000000002</upper>
          <effort>0.14399999999999999</effort>
          <velocity>1</velocity>
        </limit>
        <dynamics>
          <spring_reference>0</spring_reference>
          <spring_stiffness>0</spring_stiffness>
        </dynamics>
      </axis>
    </joint>
    <link name='LFinger32_link'>
      <pose relative_to='LFinger32'>0 0 0 0 0 0</pose>
      <inertial>
        <pose>0 0 0 -1.57 0 0</pose>
        <mass>0.002</mass>
        <inertia>
          <ixx>1.0999999999999999e-09</ixx>
          <ixy>0</ixy>
          <ixz>0</ixz>
          <iyy>1.0999999999999999e-09</iyy>
          <iyz>0</iyz>
          <izz>1.0999999999999999e-09</izz>
        </inertia>
      </inertial>
      <collision name='LFinger32_link_collision'>
        <pose>0 0 0 -1.57 0 0</pose>
        <geometry>
          <mesh>
            <scale>0.1 0.1 0.1</scale>
            <uri>model://pepper_robot_description/pepper_robot/meshes/LFinger32_0.10.stl</uri>
          </mesh>
        </geometry>
        <surface>
          <contact>
            <ode/>
          </contact>
          <friction>
            <ode>
              <mu>0.5</mu>
              <mu2>0.5</mu2>
            </ode>
          </friction>
        </surface>
      </collision>
      <visual name='LFinger32_link_visual'>
        <pose>0 0 0 -1.57 0 0</pose>
        <geometry>
          <mesh>
            <scale>0.1 0.1 0.1</scale>
            <uri>model://pepper_robot_description/pepper_robot/meshes/LFinger32.dae</uri>
          </mesh>
        </geometry>
      </visual>
      <gravity>true</gravity>
      <self_collide>false</self_collide>
    </link>
    <joint name='LFinger33' type='revolute'>
      <pose relative_to='LFinger32_link'>0.018 0 0 0 0 -1.0472</pose>
      <parent>LFinger32_link</parent>
      <child>LFinger33_link</child>
      <axis>
        <xyz>0 0 1</xyz>
        <limit>
          <lower>0</lower>
          <upper>0.87266500000000002</upper>
          <effort>0.14399999999999999</effort>
          <velocity>1</velocity>
        </limit>
        <dynamics>
          <spring_reference>0</spring_reference>
          <spring_stiffness>0</spring_stiffness>
        </dynamics>
      </axis>
    </joint>
    <link name='LFinger33_link'>
      <pose relative_to='LFinger33'>0 0 0 0 0 0</pose>
      <inertial>
        <pose>0 0 0 -1.57 0 0</pose>
        <mass>0.002</mass>
        <inertia>
          <ixx>1.0999999999999999e-09</ixx>
          <ixy>0</ixy>
          <ixz>0</ixz>
          <iyy>1.0999999999999999e-09</iyy>
          <iyz>0</iyz>
          <izz>1.0999999999999999e-09</izz>
        </inertia>
      </inertial>
      <collision name='LFinger33_link_collision'>
        <pose>0 0 0 -1.57 0 0</pose>
        <geometry>
          <mesh>
            <scale>0.1 0.1 0.1</scale>
            <uri>model://pepper_robot_description/pepper_robot/meshes/LFinger33_0.10.stl</uri>
          </mesh>
        </geometry>
        <surface>
          <contact>
            <ode/>
          </contact>
          <friction>
            <ode>
              <mu>0.5</mu>
              <mu2>0.5</mu2>
            </ode>
          </friction>
        </surface>
      </collision>
      <visual name='LFinger33_link_visual'>
        <pose>0 0 0 -1.57 0 0</pose>
        <geometry>
          <mesh>
            <scale>0.1 0.1 0.1</scale>
            <uri>model://pepper_robot_description/pepper_robot/meshes/LFinger33.dae</uri>
          </mesh>
        </geometry>
      </visual>
      <gravity>true</gravity>
      <self_collide>false</self_collide>
    </link>
    <joint name='LFinger41' type='revolute'>
      <pose relative_to='l_wrist'>0.074 0.0309 0 1.39757 1.04064 0.06833939999999999</pose>
      <parent>l_wrist</parent>
      <child>LFinger41_link</child>
      <axis>
        <xyz>0 0 1</xyz>
        <limit>
          <lower>0</lower>
          <upper>0.87266500000000002</upper>
          <effort>0.14399999999999999</effort>
          <velocity>1</velocity>
        </limit>
        <dynamics>
          <spring_reference>0</spring_reference>
          <spring_stiffness>0</spring_stiffness>
        </dynamics>
      </axis>
    </joint>
    <link name='LFinger41_link'>
      <pose relative_to='LFinger41'>0 0 0 0 0 0</pose>
      <inertial>
        <pose>0 0 0 -1.57 0 0</pose>
        <mass>0.002</mass>
        <inertia>
          <ixx>1.0999999999999999e-09</ixx>
          <ixy>0</ixy>
          <ixz>0</ixz>
          <iyy>1.0999999999999999e-09</iyy>
          <iyz>0</iyz>
          <izz>1.0999999999999999e-09</izz>
        </inertia>
      </inertial>
      <collision name='LFinger41_link_collision'>
        <pose>0 0 0 -1.57 0 0</pose>
        <geometry>
          <mesh>
            <scale>0.1 0.1 0.1</scale>
            <uri>model://pepper_robot_description/pepper_robot/meshes/LFinger41_0.10.stl</uri>
          </mesh>
        </geometry>
        <surface>
          <contact>
            <ode/>
          </contact>
          <friction>
            <ode>
              <mu>0.5</mu>
              <mu2>0.5</mu2>
            </ode>
          </friction>
        </surface>
      </collision>
      <visual name='LFinger41_link_visual'>
        <pose>0 0 0 -1.57 0 0</pose>
        <geometry>
          <mesh>
            <scale>0.1 0.1 0.1</scale>
            <uri>model://pepper_robot_description/pepper_robot/meshes/LFinger41.dae</uri>
          </mesh>
        </geometry>
      </visual>
      <gravity>true</gravity>
      <self_collide>false</self_collide>
    </link>
    <joint name='LFinger42' type='revolute'>
      <pose relative_to='LFinger41_link'>0.018 0 0 0 0 -1.0472</pose>
      <parent>LFinger41_link</parent>
      <child>LFinger42_link</child>
      <axis>
        <xyz>0 0 1</xyz>
        <limit>
          <lower>0</lower>
          <upper>0.87266500000000002</upper>
          <effort>0.14399999999999999</effort>
          <velocity>1</velocity>
        </limit>
        <dynamics>
          <spring_reference>0</spring_reference>
          <spring_stiffness>0</spring_stiffness>
        </dynamics>
      </axis>
    </joint>
    <link name='LFinger42_link'>
      <pose relative_to='LFinger42'>0 0 0 0 0 0</pose>
      <inertial>
        <pose>0 0 0 -1.57 0 0</pose>
        <mass>0.002</mass>
        <inertia>
          <ixx>1.0999999999999999e-09</ixx>
          <ixy>0</ixy>
          <ixz>0</ixz>
          <iyy>1.0999999999999999e-09</iyy>
          <iyz>0</iyz>
          <izz>1.0999999999999999e-09</izz>
        </inertia>
      </inertial>
      <collision name='LFinger42_link_collision'>
        <pose>0 0 0 -1.57 0 0</pose>
        <geometry>
          <mesh>
            <scale>0.1 0.1 0.1</scale>
            <uri>model://pepper_robot_description/pepper_robot/meshes/LFinger42_0.10.stl</uri>
          </mesh>
        </geometry>
        <surface>
          <contact>
            <ode/>
          </contact>
          <friction>
            <ode>
              <mu>0.5</mu>
              <mu2>0.5</mu2>
            </ode>
          </friction>
        </surface>
      </collision>
      <visual name='LFinger42_link_visual'>
        <pose>0 0 0 -1.57 0 0</pose>
        <geometry>
          <mesh>
            <scale>0.1 0.1 0.1</scale>
            <uri>model://pepper_robot_description/pepper_robot/meshes/LFinger42.dae</uri>
          </mesh>
        </geometry>
      </visual>
      <gravity>true</gravity>
      <self_collide>false</self_collide>
    </link>
    <joint name='LFinger43' type='revolute'>
      <pose relative_to='LFinger42_link'>0.018 0 0 0 0 -1.0472</pose>
      <parent>LFinger42_link</parent>
      <child>LFinger43_link</child>
      <axis>
        <xyz>0 0 1</xyz>
        <limit>
          <lower>0</lower>
          <upper>0.87266500000000002</upper>
          <effort>0.14399999999999999</effort>
          <velocity>1</velocity>
        </limit>
        <dynamics>
          <spring_reference>0</spring_reference>
          <spring_stiffness>0</spring_stiffness>
        </dynamics>
      </axis>
    </joint>
    <link name='LFinger43_link'>
      <pose relative_to='LFinger43'>0 0 0 0 0 0</pose>
      <inertial>
        <pose>0 0 0 -1.57 0 0</pose>
        <mass>0.002</mass>
        <inertia>
          <ixx>1.0999999999999999e-09</ixx>
          <ixy>0</ixy>
          <ixz>0</ixz>
          <iyy>1.0999999999999999e-09</iyy>
          <iyz>0</iyz>
          <izz>1.0999999999999999e-09</izz>
        </inertia>
      </inertial>
      <collision name='LFinger43_link_collision'>
        <pose>0 0 0 -1.57 0 0</pose>
        <geometry>
          <mesh>
            <scale>0.1 0.1 0.1</scale>
            <uri>model://pepper_robot_description/pepper_robot/meshes/LFinger43_0.10.stl</uri>
          </mesh>
        </geometry>
        <surface>
          <contact>
            <ode/>
          </contact>
          <friction>
            <ode>
              <mu>0.5</mu>
              <mu2>0.5</mu2>
            </ode>
          </friction>
        </surface>
      </collision>
      <visual name='LFinger43_link_visual'>
        <pose>0 0 0 -1.57 0 0</pose>
        <geometry>
          <mesh>
            <scale>0.1 0.1 0.1</scale>
            <uri>model://pepper_robot_description/pepper_robot/meshes/LFinger43.dae</uri>
          </mesh>
        </geometry>
      </visual>
      <gravity>true</gravity>
      <self_collide>false</self_collide>
    </link>
    <joint name='LHand' type='revolute'>
      <pose relative_to='l_wrist'>0.025 0 0 0 0 0</pose>
      <parent>l_wrist</parent>
      <child>l_hand</child>
      <axis>
        <xyz>1 0 0</xyz>
        <limit>
          <lower>0.02</lower>
          <upper>0.97999999999999998</upper>
          <effort>0.14399999999999999</effort>
          <velocity>1</velocity>
        </limit>
        <dynamics>
          <spring_reference>0</spring_reference>
          <spring_stiffness>0</spring_stiffness>
        </dynamics>
      </axis>
    </joint>
    <link name='l_hand'>
      <pose relative_to='LHand'>0 0 0 0 0 0</pose>
      <inertial>
        <pose>0 0 0 0 0 0</pose>
        <mass>0.002</mass>
        <inertia>
          <ixx>1.0999999999999999e-09</ixx>
          <ixy>0</ixy>
          <ixz>0</ixz>
          <iyy>1.0999999999999999e-09</iyy>
          <iyz>0</iyz>
          <izz>1.0999999999999999e-09</izz>
        </inertia>
      </inertial>
    </link>
    <joint name='LThumb1' type='revolute'>
      <pose relative_to='l_wrist'>0.0482 -0.0357 -0.0199 -2.55836 0.8062599999999999 0.533978</pose>
      <parent>l_wrist</parent>
      <child>LThumb1_link</child>
      <axis>
        <xyz>0 0 1</xyz>
        <limit>
          <lower>0</lower>
          <upper>0.87266500000000002</upper>
          <effort>0.14399999999999999</effort>
          <velocity>1</velocity>
        </limit>
        <dynamics>
          <spring_reference>0</spring_reference>
          <spring_stiffness>0</spring_stiffness>
        </dynamics>
      </axis>
    </joint>
    <link name='LThumb1_link'>
      <pose relative_to='LThumb1'>0 0 0 0 0 0</pose>
      <inertial>
        <pose>0 0 0 -1.57 0 0</pose>
        <mass>0.002</mass>
        <inertia>
          <ixx>1.0999999999999999e-09</ixx>
          <ixy>0</ixy>
          <ixz>0</ixz>
          <iyy>1.0999999999999999e-09</iyy>
          <iyz>0</iyz>
          <izz>1.0999999999999999e-09</izz>
        </inertia>
      </inertial>
      <collision name='LThumb1_link_collision'>
        <pose>0 0 0 -1.57 0 0</pose>
        <geometry>
          <mesh>
            <scale>0.1 0.1 0.1</scale>
            <uri>model://pepper_robot_description/pepper_robot/meshes/LThumb1_0.10.stl</uri>
          </mesh>
        </geometry>
        <surface>
          <contact>
            <ode/>
          </contact>
          <friction>
            <ode>
              <mu>0.5</mu>
              <mu2>0.5</mu2>
            </ode>
          </friction>
        </surface>
      </collision>
      <visual name='LThumb1_link_visual'>
        <pose>0 0 0 -1.57 0 0</pose>
        <geometry>
          <mesh>
            <scale>0.1 0.1 0.1</scale>
            <uri>model://pepper_robot_description/pepper_robot/meshes/LThumb1.dae</uri>
          </mesh>
        </geometry>
      </visual>
      <gravity>true</gravity>
      <self_collide>false</self_collide>
    </link>
    <joint name='LThumb2' type='revolute'>
      <pose relative_to='LThumb1_link'>0.022 0 0 0 0 -1.0472</pose>
      <parent>LThumb1_link</parent>
      <child>LThumb2_link</child>
      <axis>
        <xyz>0 0 1</xyz>
        <limit>
          <lower>0</lower>
          <upper>0.87266500000000002</upper>
          <effort>0.14399999999999999</effort>
          <velocity>1</velocity>
        </limit>
        <dynamics>
          <spring_reference>0</spring_reference>
          <spring_stiffness>0</spring_stiffness>
        </dynamics>
      </axis>
    </joint>
    <link name='LThumb2_link'>
      <pose relative_to='LThumb2'>0 0 0 0 0 0</pose>
      <inertial>
        <pose>0 0 0 -1.57 0 0</pose>
        <mass>0.002</mass>
        <inertia>
          <ixx>1.0999999999999999e-09</ixx>
          <ixy>0</ixy>
          <ixz>0</ixz>
          <iyy>1.0999999999999999e-09</iyy>
          <iyz>0</iyz>
          <izz>1.0999999999999999e-09</izz>
        </inertia>
      </inertial>
      <collision name='LThumb2_link_collision'>
        <pose>0 0 0 -1.57 0 0</pose>
        <geometry>
          <mesh>
            <scale>0.1 0.1 0.1</scale>
            <uri>model://pepper_robot_description/pepper_robot/meshes/LThumb2_0.10.stl</uri>
          </mesh>
        </geometry>
        <surface>
          <contact>
            <ode/>
          </contact>
          <friction>
            <ode>
              <mu>0.5</mu>
              <mu2>0.5</mu2>
            </ode>
          </friction>
        </surface>
      </collision>
      <visual name='LThumb2_link_visual'>
        <pose>0 0 0 -1.57 0 0</pose>
        <geometry>
          <mesh>
            <scale>0.1 0.1 0.1</scale>
            <uri>model://pepper_robot_description/pepper_robot/meshes/LThumb2.dae</uri>
          </mesh>
        </geometry>
      </visual>
      <gravity>true</gravity>
      <self_collide>false</self_collide>
    </link>
    <joint name='RShoulderPitch' type='revolute'>
      <pose relative_to='torso'>-0.057 -0.14974 0.22582 0 0 0</pose>
      <parent>torso</parent>
      <child>RShoulder</child>
      <axis>
        <xyz>0 1 0</xyz>
        <limit>
          <lower>-2.0856699999999999</lower>
          <upper>2.0856699999999999</upper>
          <effort>5.4279999999999999</effort>
          <velocity>7.3399799999999997</velocity>
        </limit>
        <dynamics>
          <spring_reference>0</spring_reference>
          <spring_stiffness>0</spring_stiffness>
        </dynamics>
      </axis>
    </joint>
    <link name='RShoulder'>
      <pose relative_to='RShoulderPitch'>0 0 0 0 0 0</pose>
      <inertial>
        <pose>0.00018 0.01856 0.00099 0 0 0</pose>
        <mass>0.3125</mass>
        <inertia>
          <ixx>0.00036119800000000002</ixx>
          <ixy>1.9834700000000002e-06</ixy>
          <ixz>6.35907e-07</ixz>
          <iyy>0.000137229</iyy>
          <iyz>5.6887799999999999e-06</iyz>
          <izz>0.00039919400000000001</izz>
        </inertia>
      </inertial>
      <collision name='RShoulder_collision'>
        <pose>0 0 0 0 0 0</pose>
        <geometry>
          <mesh>
            <scale>0.1 0.1 0.1</scale>
            <uri>model://pepper_robot_description/pepper_robot/meshes/RShoulderPitch_0.10.stl</uri>
          </mesh>
        </geometry>
        <surface>
          <contact>
            <ode/>
          </contact>
          <friction>
            <ode>
              <mu>0.5</mu>
              <mu2>0.5</mu2>
            </ode>
          </friction>
        </surface>
      </collision>
      <visual name='RShoulder_visual'>
        <pose>0 0 0 0 0 0</pose>
        <geometry>
          <mesh>
            <scale>0.1 0.1 0.1</scale>
            <uri>model://pepper_robot_description/pepper_robot/meshes/RShoulderPitch.dae</uri>
          </mesh>
        </geometry>
      </visual>
      <gravity>true</gravity>
      <self_collide>false</self_collide>
    </link>
    <joint name='RShoulderRoll' type='revolute'>
      <pose relative_to='RShoulder'>0 0 0 0 0 0</pose>
      <parent>RShoulder</parent>
      <child>RBicep</child>
      <axis>
        <xyz>0 0 1</xyz>
        <limit>
          <lower>-1.5620700000000001</lower>
          <upper>-0.0087266500000000007</upper>
          <effort>2.6659999999999999</effort>
          <velocity>9.2275600000000004</velocity>
        </limit>
        <dynamics>
          <spring_reference>0</spring_reference>
          <spring_stiffness>0</spring_stiffness>
        </dynamics>
      </axis>
    </joint>
    <link name='RBicep'>
      <pose relative_to='RShoulderRoll'>0 0 0 0 0 0</pose>
      <inertial>
        <pose>0.08151 -0.01284 -0.01017 0 0 0</pose>
        <mass>0.50527</mass>
        <inertia>
          <ixx>0.00050087199999999997</ixx>
          <ixy>3.55918e-05</ixy>
          <ixz>8.5126300000000005e-05</ixz>
          <iyy>0.0012628400000000001</iyy>
          <iyz>-9.0681299999999992e-06</iyz>
          <izz>0.0011571800000000001</izz>
        </inertia>
      </inertial>
      <collision name='RBicep_collision'>
        <pose>0 0 0 0 0 0</pose>
        <geometry>
          <mesh>
            <scale>0.1 0.1 0.1</scale>
            <uri>model://pepper_robot_description/pepper_robot/meshes/RShoulderRoll_0.10.stl</uri>
          </mesh>
        </geometry>
        <surface>
          <contact>
            <ode/>
          </contact>
          <friction>
            <ode>
              <mu>0.5</mu>
              <mu2>0.5</mu2>
            </ode>
          </friction>
        </surface>
      </collision>
      <visual name='RBicep_visual'>
        <pose>0 0 0 0 0 0</pose>
        <geometry>
          <mesh>
            <scale>0.1 0.1 0.1</scale>
            <uri>model://pepper_robot_description/pepper_robot/meshes/RShoulderRoll.dae</uri>
          </mesh>
        </geometry>
      </visual>
      <gravity>true</gravity>
      <self_collide>false</self_collide>
    </link>
    <joint name='RElbowYaw' type='revolute'>
      <pose relative_to='RBicep'>0.1812 -0.015 0.00013 0 -0.1570790000000001 0</pose>
      <parent>RBicep</parent>
      <child>RElbow</child>
      <axis>
        <xyz>1 0 0</xyz>
        <limit>
          <lower>-2.0856699999999999</lower>
          <upper>2.0856699999999999</upper>
          <effort>5.4279999999999999</effort>
          <velocity>7.3399799999999997</velocity>
        </limit>
        <dynamics>
          <spring_reference>0</spring_reference>
          <spring_stiffness>0</spring_stiffness>
        </dynamics>
      </axis>
    </joint>
    <link name='RElbow'>
      <pose relative_to='RElbowYaw'>0 0 0 0 0 0</pose>
      <inertial>
        <pose>-0.02297 0.00019 0.00119 0 0 0</pose>
        <mass>0.27495000000000003</mass>
        <inertia>
          <ixx>0.00012297100000000001</ixx>
          <ixy>-9.8602399999999999e-07</ixy>
          <ixz>-2.5583800000000001e-05</ixz>
          <iyy>0.00033176599999999999</iyy>
          <iyz>1.9892500000000001e-06</iyz>
          <izz>0.00030304699999999997</izz>
        </inertia>
      </inertial>
      <collision name='RElbow_collision'>
        <pose>0 0 0 0 0 0</pose>
        <geometry>
          <mesh>
            <scale>0.1 0.1 0.1</scale>
            <uri>model://pepper_robot_description/pepper_robot/meshes/RElbowYaw_0.10.stl</uri>
          </mesh>
        </geometry>
        <surface>
          <contact>
            <ode/>
          </contact>
          <friction>
            <ode>
              <mu>0.5</mu>
              <mu2>0.5</mu2>
            </ode>
          </friction>
        </surface>
      </collision>
      <visual name='RElbow_visual'>
        <pose>0 0 0 0 0 0</pose>
        <geometry>
          <mesh>
            <scale>0.1 0.1 0.1</scale>
            <uri>model://pepper_robot_description/pepper_robot/meshes/RElbowYaw.dae</uri>
          </mesh>
        </geometry>
      </visual>
      <gravity>true</gravity>
      <self_collide>false</self_collide>
    </link>
    <joint name='RElbowRoll' type='revolute'>
      <pose relative_to='RElbow'>0 0 0 0 0 0</pose>
      <parent>RElbow</parent>
      <child>RForeArm</child>
      <axis>
        <xyz>0 0 1</xyz>
        <limit>
          <lower>0.0087266500000000007</lower>
          <upper>1.5620700000000001</upper>
          <effort>2.6659999999999999</effort>
          <velocity>9.2275600000000004</velocity>
        </limit>
        <dynamics>
          <spring_reference>0</spring_reference>
          <spring_stiffness>0</spring_stiffness>
        </dynamics>
      </axis>
    </joint>
    <link name='RForeArm'>
      <pose relative_to='RElbowRoll'>0 0 0 0 0 0</pose>
      <inertial>
        <pose>0.0593 -0.00271 -0.01014 0 0.3927 0</pose>
        <mass>0.16578999999999999</mass>
        <inertia>
          <ixx>0.000156513</ixx>
          <ixy>-1.47517e-05</ixy>
          <ixz>-6.0574600000000001e-05</ixz>
          <iyy>0.00037321899999999999</iyy>
          <iyz>1.7618999999999999e-07</iyz>
          <izz>0.000273081</izz>
        </inertia>
      </inertial>
      <collision name='RForeArm_collision'>
        <pose>0 0 0 0 0 0</pose>
        <geometry>
          <mesh>
            <scale>0.1 0.1 0.1</scale>
            <uri>model://pepper_robot_description/pepper_robot/meshes/RElbowRoll_0.10.stl</uri>
          </mesh>
        </geometry>
        <surface>
          <contact>
            <ode/>
          </contact>
          <friction>
            <ode>
              <mu>0.5</mu>
              <mu2>0.5</mu2>
            </ode>
          </friction>
        </surface>
      </collision>
      <visual name='RForeArm_visual'>
        <pose>0 0 0 0 0 0</pose>
        <geometry>
          <mesh>
            <scale>0.1 0.1 0.1</scale>
            <uri>model://pepper_robot_description/pepper_robot/meshes/RElbowRoll.dae</uri>
          </mesh>
        </geometry>
      </visual>
      <gravity>true</gravity>
      <self_collide>false</self_collide>
    </link>
    <joint name='RWristYaw' type='revolute'>
      <pose relative_to='RForeArm'>0.15 0 0 0 0 0</pose>
      <parent>RForeArm</parent>
      <child>r_wrist</child>
      <axis>
        <xyz>1 0 0</xyz>
        <limit>
          <lower>-1.8238700000000001</lower>
          <upper>1.8238700000000001</upper>
          <effort>0.2014</effort>
          <velocity>17.383500000000002</velocity>
        </limit>
        <dynamics>
          <spring_reference>0</spring_reference>
          <spring_stiffness>0</spring_stiffness>
        </dynamics>
      </axis>
    </joint>
    <link name='r_wrist'>
      <pose relative_to='RWristYaw'>0 0 0 0 0 0</pose>
      <inertial>
        <pose>0.03560961268239957 0.0007148117456314178 -0.002184957234228067 0 0 0</pose>
        <mass>0.27755000000000002</mass>
        <inertia>
          <ixx>0.00015215047001351179</ixx>
          <ixy>-1.061337784226265e-05</ixy>
          <ixz>3.9923627784830811e-06</ixz>
          <iyy>0.00043398800671796143</iyy>
          <iyz>3.1143429445580879e-06</iyz>
          <izz>0.00045855669536227697</izz>
        </inertia>
      </inertial>
      <collision name='r_wrist_collision'>
        <pose>0 0 0 0 0 0</pose>
        <geometry>
          <mesh>
            <scale>0.1 0.1 0.1</scale>
            <uri>model://pepper_robot_description/pepper_robot/meshes/RWristYaw_0.10.stl</uri>
          </mesh>
        </geometry>
        <surface>
          <contact>
            <ode/>
          </contact>
          <friction>
            <ode>
              <mu>0.5</mu>
              <mu2>0.5</mu2>
            </ode>
          </friction>
        </surface>
      </collision>
      <visual name='r_wrist_visual'>
        <pose>0 0 0 0 0 0</pose>
        <geometry>
          <mesh>
            <scale>0.1 0.1 0.1</scale>
            <uri>model://pepper_robot_description/pepper_robot/meshes/RWristYaw.dae</uri>
          </mesh>
        </geometry>
      </visual>
      <gravity>true</gravity>
      <self_collide>false</self_collide>
    </link>
    <joint name='RFinger11' type='revolute'>
      <pose relative_to='r_wrist'>0.08210000000000001 0.0268 0.004 1.39757 1.04064 0.03343349999999972</pose>
      <parent>r_wrist</parent>
      <child>RFinger11_link</child>
      <axis>
        <xyz>0 0 1</xyz>
        <limit>
          <lower>0</lower>
          <upper>0.87266500000000002</upper>
          <effort>0.14399999999999999</effort>
          <velocity>1</velocity>
        </limit>
        <dynamics>
          <spring_reference>0</spring_reference>
          <spring_stiffness>0</spring_stiffness>
        </dynamics>
      </axis>
    </joint>
    <link name='RFinger11_link'>
      <pose relative_to='RFinger11'>0 0 0 0 0 0</pose>
      <inertial>
        <pose>0 0 0 -1.57 0 0</pose>
        <mass>0.002</mass>
        <inertia>
          <ixx>1.0999999999999999e-09</ixx>
          <ixy>0</ixy>
          <ixz>0</ixz>
          <iyy>1.0999999999999999e-09</iyy>
          <iyz>0</iyz>
          <izz>1.0999999999999999e-09</izz>
        </inertia>
      </inertial>
      <collision name='RFinger11_link_collision'>
        <pose>0 0 0 -1.57 0 0</pose>
        <geometry>
          <mesh>
            <scale>0.1 0.1 0.1</scale>
            <uri>model://pepper_robot_description/pepper_robot/meshes/RFinger11_0.10.stl</uri>
          </mesh>
        </geometry>
        <surface>
          <contact>
            <ode/>
          </contact>
          <friction>
            <ode>
              <mu>0.5</mu>
              <mu2>0.5</mu2>
            </ode>
          </friction>
        </surface>
      </collision>
      <visual name='RFinger11_link_visual'>
        <pose>0 0 0 -1.57 0 0</pose>
        <geometry>
          <mesh>
            <scale>0.1 0.1 0.1</scale>
            <uri>model://pepper_robot_description/pepper_robot/meshes/RFinger11.dae</uri>
          </mesh>
        </geometry>
      </visual>
      <gravity>true</gravity>
      <self_collide>false</self_collide>
    </link>
    <joint name='RFinger12' type='revolute'>
      <pose relative_to='RFinger11_link'>0.018 0 0 0 0 -1.0472</pose>
      <parent>RFinger11_link</parent>
      <child>RFinger12_link</child>
      <axis>
        <xyz>0 0 1</xyz>
        <limit>
          <lower>0</lower>
          <upper>0.87266500000000002</upper>
          <effort>0.14399999999999999</effort>
          <velocity>1</velocity>
        </limit>
        <dynamics>
          <spring_reference>0</spring_reference>
          <spring_stiffness>0</spring_stiffness>
        </dynamics>
      </axis>
    </joint>
    <link name='RFinger12_link'>
      <pose relative_to='RFinger12'>0 0 0 0 0 0</pose>
      <inertial>
        <pose>0 0 0 -1.57 0 0</pose>
        <mass>0.002</mass>
        <inertia>
          <ixx>1.0999999999999999e-09</ixx>
          <ixy>0</ixy>
          <ixz>0</ixz>
          <iyy>1.0999999999999999e-09</iyy>
          <iyz>0</iyz>
          <izz>1.0999999999999999e-09</izz>
        </inertia>
      </inertial>
      <collision name='RFinger12_link_collision'>
        <pose>0 0 0 -1.57 0 0</pose>
        <geometry>
          <mesh>
            <scale>0.1 0.1 0.1</scale>
            <uri>model://pepper_robot_description/pepper_robot/meshes/RFinger12_0.10.stl</uri>
          </mesh>
        </geometry>
        <surface>
          <contact>
            <ode/>
          </contact>
          <friction>
            <ode>
              <mu>0.5</mu>
              <mu2>0.5</mu2>
            </ode>
          </friction>
        </surface>
      </collision>
      <visual name='RFinger12_link_visual'>
        <pose>0 0 0 -1.57 0 0</pose>
        <geometry>
          <mesh>
            <scale>0.1 0.1 0.1</scale>
            <uri>model://pepper_robot_description/pepper_robot/meshes/RFinger12.dae</uri>
          </mesh>
        </geometry>
      </visual>
      <gravity>true</gravity>
      <self_collide>false</self_collide>
    </link>
    <joint name='RFinger13' type='revolute'>
      <pose relative_to='RFinger12_link'>0.018 0 0 0 0 -1.0472</pose>
      <parent>RFinger12_link</parent>
      <child>RFinger13_link</child>
      <axis>
        <xyz>0 0 1</xyz>
        <limit>
          <lower>0</lower>
          <upper>0.87266500000000002</upper>
          <effort>0.14399999999999999</effort>
          <velocity>1</velocity>
        </limit>
        <dynamics>
          <spring_reference>0</spring_reference>
          <spring_stiffness>0</spring_stiffness>
        </dynamics>
      </axis>
    </joint>
    <link name='RFinger13_link'>
      <pose relative_to='RFinger13'>0 0 0 0 0 0</pose>
      <inertial>
        <pose>0 0 0 -1.57 0 0</pose>
        <mass>0.002</mass>
        <inertia>
          <ixx>1.0999999999999999e-09</ixx>
          <ixy>0</ixy>
          <ixz>0</ixz>
          <iyy>1.0999999999999999e-09</iyy>
          <iyz>0</iyz>
          <izz>1.0999999999999999e-09</izz>
        </inertia>
      </inertial>
      <collision name='RFinger13_link_collision'>
        <pose>0 0 0 -1.57 0 0</pose>
        <geometry>
          <mesh>
            <scale>0.1 0.1 0.1</scale>
            <uri>model://pepper_robot_description/pepper_robot/meshes/RFinger13_0.10.stl</uri>
          </mesh>
        </geometry>
        <surface>
          <contact>
            <ode/>
          </contact>
          <friction>
            <ode>
              <mu>0.5</mu>
              <mu2>0.5</mu2>
            </ode>
          </friction>
        </surface>
      </collision>
      <visual name='RFinger13_link_visual'>
        <pose>0 0 0 -1.57 0 0</pose>
        <geometry>
          <mesh>
            <scale>0.1 0.1 0.1</scale>
            <uri>model://pepper_robot_description/pepper_robot/meshes/RFinger13.dae</uri>
          </mesh>
        </geometry>
      </visual>
      <gravity>true</gravity>
      <self_collide>false</self_collide>
    </link>
    <joint name='RFinger21' type='revolute'>
      <pose relative_to='r_wrist'>0.0873 0.0073 0.006 1.5708 1.0472 0.06108600000000022</pose>
      <parent>r_wrist</parent>
      <child>RFinger21_link</child>
      <axis>
        <xyz>0 0 1</xyz>
        <limit>
          <lower>0</lower>
          <upper>0.87266500000000002</upper>
          <effort>0.14399999999999999</effort>
          <velocity>1</velocity>
        </limit>
        <dynamics>
          <spring_reference>0</spring_reference>
          <spring_stiffness>0</spring_stiffness>
        </dynamics>
      </axis>
    </joint>
    <link name='RFinger21_link'>
      <pose relative_to='RFinger21'>0 0 0 0 0 0</pose>
      <inertial>
        <pose>0 0 0 -1.57 0 0</pose>
        <mass>0.002</mass>
        <inertia>
          <ixx>1.0999999999999999e-09</ixx>
          <ixy>0</ixy>
          <ixz>0</ixz>
          <iyy>1.0999999999999999e-09</iyy>
          <iyz>0</iyz>
          <izz>1.0999999999999999e-09</izz>
        </inertia>
      </inertial>
      <collision name='RFinger21_link_collision'>
        <pose>0 0 0 -1.57 0 0</pose>
        <geometry>
          <mesh>
            <scale>0.1 0.1 0.1</scale>
            <uri>model://pepper_robot_description/pepper_robot/meshes/RFinger21_0.10.stl</uri>
          </mesh>
        </geometry>
        <surface>
          <contact>
            <ode/>
          </contact>
          <friction>
            <ode>
              <mu>0.5</mu>
              <mu2>0.5</mu2>
            </ode>
          </friction>
        </surface>
      </collision>
      <visual name='RFinger21_link_visual'>
        <pose>0 0 0 -1.57 0 0</pose>
        <geometry>
          <mesh>
            <scale>0.1 0.1 0.1</scale>
            <uri>model://pepper_robot_description/pepper_robot/meshes/RFinger21.dae</uri>
          </mesh>
        </geometry>
      </visual>
      <gravity>true</gravity>
      <self_collide>false</self_collide>
    </link>
    <joint name='RFinger22' type='revolute'>
      <pose relative_to='RFinger21_link'>0.018 0 0 0 0 -1.0472</pose>
      <parent>RFinger21_link</parent>
      <child>RFinger22_link</child>
      <axis>
        <xyz>0 0 1</xyz>
        <limit>
          <lower>0</lower>
          <upper>0.87266500000000002</upper>
          <effort>0.14399999999999999</effort>
          <velocity>1</velocity>
        </limit>
        <dynamics>
          <spring_reference>0</spring_reference>
          <spring_stiffness>0</spring_stiffness>
        </dynamics>
      </axis>
    </joint>
    <link name='RFinger22_link'>
      <pose relative_to='RFinger22'>0 0 0 0 0 0</pose>
      <inertial>
        <pose>0 0 0 -1.57 0 0</pose>
        <mass>0.002</mass>
        <inertia>
          <ixx>1.0999999999999999e-09</ixx>
          <ixy>0</ixy>
          <ixz>0</ixz>
          <iyy>1.0999999999999999e-09</iyy>
          <iyz>0</iyz>
          <izz>1.0999999999999999e-09</izz>
        </inertia>
      </inertial>
      <collision name='RFinger22_link_collision'>
        <pose>0 0 0 -1.57 0 0</pose>
        <geometry>
          <mesh>
            <scale>0.1 0.1 0.1</scale>
            <uri>model://pepper_robot_description/pepper_robot/meshes/RFinger22_0.10.stl</uri>
          </mesh>
        </geometry>
        <surface>
          <contact>
            <ode/>
          </contact>
          <friction>
            <ode>
              <mu>0.5</mu>
              <mu2>0.5</mu2>
            </ode>
          </friction>
        </surface>
      </collision>
      <visual name='RFinger22_link_visual'>
        <pose>0 0 0 -1.57 0 0</pose>
        <geometry>
          <mesh>
            <scale>0.1 0.1 0.1</scale>
            <uri>model://pepper_robot_description/pepper_robot/meshes/RFinger22.dae</uri>
          </mesh>
        </geometry>
      </visual>
      <gravity>true</gravity>
      <self_collide>false</self_collide>
    </link>
    <joint name='RFinger23' type='revolute'>
      <pose relative_to='RFinger22_link'>0.018 0 0 0 0 -1.0472</pose>
      <parent>RFinger22_link</parent>
      <child>RFinger23_link</child>
      <axis>
        <xyz>0 0 1</xyz>
        <limit>
          <lower>0</lower>
          <upper>0.87266500000000002</upper>
          <effort>0.14399999999999999</effort>
          <velocity>1</velocity>
        </limit>
        <dynamics>
          <spring_reference>0</spring_reference>
          <spring_stiffness>0</spring_stiffness>
        </dynamics>
      </axis>
    </joint>
    <link name='RFinger23_link'>
      <pose relative_to='RFinger23'>0 0 0 0 0 0</pose>
      <inertial>
        <pose>0 0 0 -1.57 0 0</pose>
        <mass>0.002</mass>
        <inertia>
          <ixx>1.0999999999999999e-09</ixx>
          <ixy>0</ixy>
          <ixz>0</ixz>
          <iyy>1.0999999999999999e-09</iyy>
          <iyz>0</iyz>
          <izz>1.0999999999999999e-09</izz>
        </inertia>
      </inertial>
      <collision name='RFinger23_link_collision'>
        <pose>0 0 0 -1.57 0 0</pose>
        <geometry>
          <mesh>
            <scale>0.1 0.1 0.1</scale>
            <uri>model://pepper_robot_description/pepper_robot/meshes/RFinger23_0.10.stl</uri>
          </mesh>
        </geometry>
        <surface>
          <contact>
            <ode/>
          </contact>
          <friction>
            <ode>
              <mu>0.5</mu>
              <mu2>0.5</mu2>
            </ode>
          </friction>
        </surface>
      </collision>
      <visual name='RFinger23_link_visual'>
        <pose>0 0 0 -1.57 0 0</pose>
        <geometry>
          <mesh>
            <scale>0.1 0.1 0.1</scale>
            <uri>model://pepper_robot_description/pepper_robot/meshes/RFinger23.dae</uri>
          </mesh>
        </geometry>
      </visual>
      <gravity>true</gravity>
      <self_collide>false</self_collide>
    </link>
    <joint name='RFinger31' type='revolute'>
      <pose relative_to='r_wrist'>0.0833 -0.0123 0.004 1.67523 1.04483 0.02931599999999992</pose>
      <parent>r_wrist</parent>
      <child>RFinger31_link</child>
      <axis>
        <xyz>0 0 1</xyz>
        <limit>
          <lower>0</lower>
          <upper>0.87266500000000002</upper>
          <effort>0.14399999999999999</effort>
          <velocity>1</velocity>
        </limit>
        <dynamics>
          <spring_reference>0</spring_reference>
          <spring_stiffness>0</spring_stiffness>
        </dynamics>
      </axis>
    </joint>
    <link name='RFinger31_link'>
      <pose relative_to='RFinger31'>0 0 0 0 0 0</pose>
      <inertial>
        <pose>0 0 0 -1.57 0 0</pose>
        <mass>0.002</mass>
        <inertia>
          <ixx>1.0999999999999999e-09</ixx>
          <ixy>0</ixy>
          <ixz>0</ixz>
          <iyy>1.0999999999999999e-09</iyy>
          <iyz>0</iyz>
          <izz>1.0999999999999999e-09</izz>
        </inertia>
      </inertial>
      <collision name='RFinger31_link_collision'>
        <pose>0 0 0 -1.57 0 0</pose>
        <geometry>
          <mesh>
            <scale>0.1 0.1 0.1</scale>
            <uri>model://pepper_robot_description/pepper_robot/meshes/RFinger31_0.10.stl</uri>
          </mesh>
        </geometry>
        <surface>
          <contact>
            <ode/>
          </contact>
          <friction>
            <ode>
              <mu>0.5</mu>
              <mu2>0.5</mu2>
            </ode>
          </friction>
        </surface>
      </collision>
      <visual name='RFinger31_link_visual'>
        <pose>0 0 0 -1.57 0 0</pose>
        <geometry>
          <mesh>
            <scale>0.1 0.1 0.1</scale>
            <uri>model://pepper_robot_description/pepper_robot/meshes/RFinger31.dae</uri>
          </mesh>
        </geometry>
      </visual>
      <gravity>true</gravity>
      <self_collide>false</self_collide>
    </link>
    <joint name='RFinger32' type='revolute'>
      <pose relative_to='RFinger31_link'>0.018 0 0 0 0 -1.0472</pose>
      <parent>RFinger31_link</parent>
      <child>RFinger32_link</child>
      <axis>
        <xyz>0 0 1</xyz>
        <limit>
          <lower>0</lower>
          <upper>0.87266500000000002</upper>
          <effort>0.14399999999999999</effort>
          <velocity>1</velocity>
        </limit>
        <dynamics>
          <spring_reference>0</spring_reference>
          <spring_stiffness>0</spring_stiffness>
        </dynamics>
      </axis>
    </joint>
    <link name='RFinger32_link'>
      <pose relative_to='RFinger32'>0 0 0 0 0 0</pose>
      <inertial>
        <pose>0 0 0 -1.57 0 0</pose>
        <mass>0.002</mass>
        <inertia>
          <ixx>1.0999999999999999e-09</ixx>
          <ixy>0</ixy>
          <ixz>0</ixz>
          <iyy>1.0999999999999999e-09</iyy>
          <iyz>0</iyz>
          <izz>1.0999999999999999e-09</izz>
        </inertia>
      </inertial>
      <collision name='RFinger32_link_collision'>
        <pose>0 0 0 -1.57 0 0</pose>
        <geometry>
          <mesh>
            <scale>0.1 0.1 0.1</scale>
            <uri>model://pepper_robot_description/pepper_robot/meshes/RFinger32_0.10.stl</uri>
          </mesh>
        </geometry>
        <surface>
          <contact>
            <ode/>
          </contact>
          <friction>
            <ode>
              <mu>0.5</mu>
              <mu2>0.5</mu2>
            </ode>
          </friction>
        </surface>
      </collision>
      <visual name='RFinger32_link_visual'>
        <pose>0 0 0 -1.57 0 0</pose>
        <geometry>
          <mesh>
            <scale>0.1 0.1 0.1</scale>
            <uri>model://pepper_robot_description/pepper_robot/meshes/RFinger32.dae</uri>
          </mesh>
        </geometry>
      </visual>
      <gravity>true</gravity>
      <self_collide>false</self_collide>
    </link>
    <joint name='RFinger33' type='revolute'>
      <pose relative_to='RFinger32_link'>0.018 0 0 0 0 -1.0472</pose>
      <parent>RFinger32_link</parent>
      <child>RFinger33_link</child>
      <axis>
        <xyz>0 0 1</xyz>
        <limit>
          <lower>0</lower>
          <upper>0.87266500000000002</upper>
          <effort>0.14399999999999999</effort>
          <velocity>1</velocity>
        </limit>
        <dynamics>
          <spring_reference>0</spring_reference>
          <spring_stiffness>0</spring_stiffness>
        </dynamics>
      </axis>
    </joint>
    <link name='RFinger33_link'>
      <pose relative_to='RFinger33'>0 0 0 0 0 0</pose>
      <inertial>
        <pose>0 0 0 -1.57 0 0</pose>
        <mass>0.002</mass>
        <inertia>
          <ixx>1.0999999999999999e-09</ixx>
          <ixy>0</ixy>
          <ixz>0</ixz>
          <iyy>1.0999999999999999e-09</iyy>
          <iyz>0</iyz>
          <izz>1.0999999999999999e-09</izz>
        </inertia>
      </inertial>
      <collision name='RFinger33_link_collision'>
        <pose>0 0 0 -1.57 0 0</pose>
        <geometry>
          <mesh>
            <scale>0.1 0.1 0.1</scale>
            <uri>model://pepper_robot_description/pepper_robot/meshes/RFinger33_0.10.stl</uri>
          </mesh>
        </geometry>
        <surface>
          <contact>
            <ode/>
          </contact>
          <friction>
            <ode>
              <mu>0.5</mu>
              <mu2>0.5</mu2>
            </ode>
          </friction>
        </surface>
      </collision>
      <visual name='RFinger33_link_visual'>
        <pose>0 0 0 -1.57 0 0</pose>
        <geometry>
          <mesh>
            <scale>0.1 0.1 0.1</scale>
            <uri>model://pepper_robot_description/pepper_robot/meshes/RFinger33.dae</uri>
          </mesh>
        </geometry>
      </visual>
      <gravity>true</gravity>
      <self_collide>false</self_collide>
    </link>
    <joint name='RFinger41' type='revolute'>
      <pose relative_to='r_wrist'>0.074 -0.0309 0 1.744019999999999 1.04064 -0.06833940000000031</pose>
      <parent>r_wrist</parent>
      <child>RFinger41_link</child>
      <axis>
        <xyz>0 0 1</xyz>
        <limit>
          <lower>0</lower>
          <upper>0.87266500000000002</upper>
          <effort>0.14399999999999999</effort>
          <velocity>1</velocity>
        </limit>
        <dynamics>
          <spring_reference>0</spring_reference>
          <spring_stiffness>0</spring_stiffness>
        </dynamics>
      </axis>
    </joint>
    <link name='RFinger41_link'>
      <pose relative_to='RFinger41'>0 0 0 0 0 0</pose>
      <inertial>
        <pose>0 0 0 -1.57 0 0</pose>
        <mass>0.002</mass>
        <inertia>
          <ixx>1.0999999999999999e-09</ixx>
          <ixy>0</ixy>
          <ixz>0</ixz>
          <iyy>1.0999999999999999e-09</iyy>
          <iyz>0</iyz>
          <izz>1.0999999999999999e-09</izz>
        </inertia>
      </inertial>
      <collision name='RFinger41_link_collision'>
        <pose>0 0 0 -1.57 0 0</pose>
        <geometry>
          <mesh>
            <scale>0.1 0.1 0.1</scale>
            <uri>model://pepper_robot_description/pepper_robot/meshes/RFinger41_0.10.stl</uri>
          </mesh>
        </geometry>
        <surface>
          <contact>
            <ode/>
          </contact>
          <friction>
            <ode>
              <mu>0.5</mu>
              <mu2>0.5</mu2>
            </ode>
          </friction>
        </surface>
      </collision>
      <visual name='RFinger41_link_visual'>
        <pose>0 0 0 -1.57 0 0</pose>
        <geometry>
          <mesh>
            <scale>0.1 0.1 0.1</scale>
            <uri>model://pepper_robot_description/pepper_robot/meshes/RFinger41.dae</uri>
          </mesh>
        </geometry>
      </visual>
      <gravity>true</gravity>
      <self_collide>false</self_collide>
    </link>
    <joint name='RFinger42' type='revolute'>
      <pose relative_to='RFinger41_link'>0.018 0 0 0 0 -1.0472</pose>
      <parent>RFinger41_link</parent>
      <child>RFinger42_link</child>
      <axis>
        <xyz>0 0 1</xyz>
        <limit>
          <lower>0</lower>
          <upper>0.87266500000000002</upper>
          <effort>0.14399999999999999</effort>
          <velocity>1</velocity>
        </limit>
        <dynamics>
          <spring_reference>0</spring_reference>
          <spring_stiffness>0</spring_stiffness>
        </dynamics>
      </axis>
    </joint>
    <link name='RFinger42_link'>
      <pose relative_to='RFinger42'>0 0 0 0 0 0</pose>
      <inertial>
        <pose>0 0 0 -1.57 0 0</pose>
        <mass>0.002</mass>
        <inertia>
          <ixx>1.0999999999999999e-09</ixx>
          <ixy>0</ixy>
          <ixz>0</ixz>
          <iyy>1.0999999999999999e-09</iyy>
          <iyz>0</iyz>
          <izz>1.0999999999999999e-09</izz>
        </inertia>
      </inertial>
      <collision name='RFinger42_link_collision'>
        <pose>0 0 0 -1.57 0 0</pose>
        <geometry>
          <mesh>
            <scale>0.1 0.1 0.1</scale>
            <uri>model://pepper_robot_description/pepper_robot/meshes/RFinger42_0.10.stl</uri>
          </mesh>
        </geometry>
        <surface>
          <contact>
            <ode/>
          </contact>
          <friction>
            <ode>
              <mu>0.5</mu>
              <mu2>0.5</mu2>
            </ode>
          </friction>
        </surface>
      </collision>
      <visual name='RFinger42_link_visual'>
        <pose>0 0 0 -1.57 0 0</pose>
        <geometry>
          <mesh>
            <scale>0.1 0.1 0.1</scale>
            <uri>model://pepper_robot_description/pepper_robot/meshes/RFinger42.dae</uri>
          </mesh>
        </geometry>
      </visual>
      <gravity>true</gravity>
      <self_collide>false</self_collide>
    </link>
    <joint name='RFinger43' type='revolute'>
      <pose relative_to='RFinger42_link'>0.018 0 0 0 0 -1.0472</pose>
      <parent>RFinger42_link</parent>
      <child>RFinger43_link</child>
      <axis>
        <xyz>0 0 1</xyz>
        <limit>
          <lower>0</lower>
          <upper>0.87266500000000002</upper>
          <effort>0.14399999999999999</effort>
          <velocity>1</velocity>
        </limit>
        <dynamics>
          <spring_reference>0</spring_reference>
          <spring_stiffness>0</spring_stiffness>
        </dynamics>
      </axis>
    </joint>
    <link name='RFinger43_link'>
      <pose relative_to='RFinger43'>0 0 0 0 0 0</pose>
      <inertial>
        <pose>0 0 0 -1.57 0 0</pose>
        <mass>0.002</mass>
        <inertia>
          <ixx>1.0999999999999999e-09</ixx>
          <ixy>0</ixy>
          <ixz>0</ixz>
          <iyy>1.0999999999999999e-09</iyy>
          <iyz>0</iyz>
          <izz>1.0999999999999999e-09</izz>
        </inertia>
      </inertial>
      <collision name='RFinger43_link_collision'>
        <pose>0 0 0 -1.57 0 0</pose>
        <geometry>
          <mesh>
            <scale>0.1 0.1 0.1</scale>
            <uri>model://pepper_robot_description/pepper_robot/meshes/RFinger43_0.10.stl</uri>
          </mesh>
        </geometry>
        <surface>
          <contact>
            <ode/>
          </contact>
          <friction>
            <ode>
              <mu>0.5</mu>
              <mu2>0.5</mu2>
            </ode>
          </friction>
        </surface>
      </collision>
      <visual name='RFinger43_link_visual'>
        <pose>0 0 0 -1.57 0 0</pose>
        <geometry>
          <mesh>
            <scale>0.1 0.1 0.1</scale>
            <uri>model://pepper_robot_description/pepper_robot/meshes/RFinger43.dae</uri>
          </mesh>
        </geometry>
      </visual>
      <gravity>true</gravity>
      <self_collide>false</self_collide>
    </link>
    <joint name='RHand' type='revolute'>
      <pose relative_to='r_wrist'>0.025 0 0 0 0 0</pose>
      <parent>r_wrist</parent>
      <child>r_hand</child>
      <axis>
        <xyz>1 0 0</xyz>
        <limit>
          <lower>0.02</lower>
          <upper>0.97999999999999998</upper>
          <effort>0.14399999999999999</effort>
          <velocity>1</velocity>
        </limit>
        <dynamics>
          <spring_reference>0</spring_reference>
          <spring_stiffness>0</spring_stiffness>
        </dynamics>
      </axis>
    </joint>
    <link name='r_hand'>
      <pose relative_to='RHand'>0 0 0 0 0 0</pose>
      <inertial>
        <pose>0 0 0 0 0 0</pose>
        <mass>0.002</mass>
        <inertia>
          <ixx>1.0999999999999999e-09</ixx>
          <ixy>0</ixy>
          <ixz>0</ixz>
          <iyy>1.0999999999999999e-09</iyy>
          <iyz>0</iyz>
          <izz>1.0999999999999999e-09</izz>
        </inertia>
      </inertial>
    </link>
    <joint name='RThumb1' type='revolute'>
      <pose relative_to='r_wrist'>0.0482 0.0357 -0.0199 -0.5832300000000002 0.8062599999999999 -0.5339780000000001</pose>
      <parent>r_wrist</parent>
      <child>RThumb1_link</child>
      <axis>
        <xyz>0 0 1</xyz>
        <limit>
          <lower>0</lower>
          <upper>0.87266500000000002</upper>
          <effort>0.14399999999999999</effort>
          <velocity>1</velocity>
        </limit>
        <dynamics>
          <spring_reference>0</spring_reference>
          <spring_stiffness>0</spring_stiffness>
        </dynamics>
      </axis>
    </joint>
    <link name='RThumb1_link'>
      <pose relative_to='RThumb1'>0 0 0 0 0 0</pose>
      <inertial>
        <pose>0 0 0 -1.57 0 0</pose>
        <mass>0.002</mass>
        <inertia>
          <ixx>1.0999999999999999e-09</ixx>
          <ixy>0</ixy>
          <ixz>0</ixz>
          <iyy>1.0999999999999999e-09</iyy>
          <iyz>0</iyz>
          <izz>1.0999999999999999e-09</izz>
        </inertia>
      </inertial>
      <collision name='RThumb1_link_collision'>
        <pose>0 0 0 -1.57 0 0</pose>
        <geometry>
          <mesh>
            <scale>0.1 0.1 0.1</scale>
            <uri>model://pepper_robot_description/pepper_robot/meshes/RThumb1_0.10.stl</uri>
          </mesh>
        </geometry>
        <surface>
          <contact>
            <ode/>
          </contact>
          <friction>
            <ode>
              <mu>0.5</mu>
              <mu2>0.5</mu2>
            </ode>
          </friction>
        </surface>
      </collision>
      <visual name='RThumb1_link_visual'>
        <pose>0 0 0 -1.57 0 0</pose>
        <geometry>
          <mesh>
            <scale>0.1 0.1 0.1</scale>
            <uri>model://pepper_robot_description/pepper_robot/meshes/RThumb1.dae</uri>
          </mesh>
        </geometry>
      </visual>
      <gravity>true</gravity>
      <self_collide>false</self_collide>
    </link>
    <joint name='RThumb2' type='revolute'>
      <pose relative_to='RThumb1_link'>0.022 0 0 0 0 -1.0472</pose>
      <parent>RThumb1_link</parent>
      <child>RThumb2_link</child>
      <axis>
        <xyz>0 0 1</xyz>
        <limit>
          <lower>0</lower>
          <upper>0.87266500000000002</upper>
          <effort>0.14399999999999999</effort>
          <velocity>1</velocity>
        </limit>
        <dynamics>
          <spring_reference>0</spring_reference>
          <spring_stiffness>0</spring_stiffness>
        </dynamics>
      </axis>
    </joint>
    <link name='RThumb2_link'>
      <pose relative_to='RThumb2'>0 0 0 0 0 0</pose>
      <inertial>
        <pose>0 0 0 -1.57 0 0</pose>
        <mass>0.002</mass>
        <inertia>
          <ixx>1.0999999999999999e-09</ixx>
          <ixy>0</ixy>
          <ixz>0</ixz>
          <iyy>1.0999999999999999e-09</iyy>
          <iyz>0</iyz>
          <izz>1.0999999999999999e-09</izz>
        </inertia>
      </inertial>
      <collision name='RThumb2_link_collision'>
        <pose>0 0 0 -1.57 0 0</pose>
        <geometry>
          <mesh>
            <scale>0.1 0.1 0.1</scale>
            <uri>model://pepper_robot_description/pepper_robot/meshes/RThumb2_0.10.stl</uri>
          </mesh>
        </geometry>
        <surface>
          <contact>
            <ode/>
          </contact>
          <friction>
            <ode>
              <mu>0.5</mu>
              <mu2>0.5</mu2>
            </ode>
          </friction>
        </surface>
      </collision>
      <visual name='RThumb2_link_visual'>
        <pose>0 0 0 -1.57 0 0</pose>
        <geometry>
          <mesh>
            <scale>0.1 0.1 0.1</scale>
            <uri>model://pepper_robot_description/pepper_robot/meshes/RThumb2.dae</uri>
          </mesh>
        </geometry>
      </visual>
      <gravity>true</gravity>
      <self_collide>false</self_collide>
    </link>
    <joint name='WheelB' type='revolute'>
      <pose relative_to='base_link'>-0.17 0 0.07000000000000001 0 0 -3.14159</pose>
      <parent>base_link</parent>
      <child>WheelB_link</child>
      <axis>
        <xyz>1 0 0</xyz>
        <limit>
          <effort>3.25</effort>
          <velocity>6.2831900000000003</velocity>
          <lower>-10000000000000000</lower>
          <upper>10000000000000000</upper>
        </limit>
        <dynamics>
          <spring_reference>0</spring_reference>
          <spring_stiffness>0</spring_stiffness>
        </dynamics>
      </axis>
    </joint>
    <link name='WheelB_link'>
      <pose relative_to='WheelB'>0 0 0 0 0 0</pose>
      <inertial>
        <pose>0 0 0 0 0 0</pose>
        <mass>1.5802799999999999</mass>
        <inertia>
          <ixx>0.0029975599999999998</ixx>
          <ixy>6.3068000000000003e-07</ixy>
          <ixz>5.5690299999999999e-06</ixz>
          <iyy>0.00303229</iyy>
          <iyz>-9.0408000000000003e-07</iyz>
          <izz>0.0029658499999999999</izz>
        </inertia>
      </inertial>
      <collision name='WheelB_link_collision'>
        <pose>0 0 0 0 0 0</pose>
        <geometry>
          <mesh>
            <scale>0.1 0.1 0.1</scale>
            <uri>model://pepper_robot_description/pepper_robot/meshes/WheelB_0.10.stl</uri>
          </mesh>
        </geometry>
        <surface>
          <contact>
            <ode/>
          </contact>
          <friction>
            <ode>
              <mu>0.5</mu>
              <mu2>0.5</mu2>
              <fdir1>1 0 0</fdir1>
            </ode>
          </friction>
        </surface>
      </collision>
      <visual name='WheelB_link_visual'>
        <pose>0 0 0 0 0 0</pose>
        <geometry>
          <mesh>
            <scale>0.1 0.1 0.1</scale>
            <uri>model://pepper_robot_description/pepper_robot/meshes/WheelB.dae</uri>
          </mesh>
        </geometry>
      </visual>
      <gravity>true</gravity>
    </link>
    <joint name='WheelFL' type='revolute'>
      <pose relative_to='base_link'>0.09 0.155 0.07000000000000001 0 0 1.07517</pose>
      <parent>base_link</parent>
      <child>WheelFL_link</child>
      <axis>
        <xyz>1 0 0</xyz>
        <limit>
          <effort>3.25</effort>
          <velocity>6.2831900000000003</velocity>
          <lower>-10000000000000000</lower>
          <upper>10000000000000000</upper>
        </limit>
        <dynamics>
          <spring_reference>0</spring_reference>
          <spring_stiffness>0</spring_stiffness>
        </dynamics>
      </axis>
    </joint>
    <link name='WheelFL_link'>
      <pose relative_to='WheelFL'>0 0 0 0 0 0</pose>
      <inertial>
        <pose>0 0 0 0 0 0</pose>
        <mass>1.5802799999999999</mass>
        <inertia>
          <ixx>0.0029975599999999998</ixx>
          <ixy>6.3068000000000003e-07</ixy>
          <ixz>5.5690299999999999e-06</ixz>
          <iyy>0.00303229</iyy>
          <iyz>-9.0408000000000003e-07</iyz>
          <izz>0.0029658499999999999</izz>
        </inertia>
      </inertial>
      <collision name='WheelFL_link_collision'>
        <pose>0 0 0 0 0 0</pose>
        <geometry>
          <mesh>
            <scale>0.1 0.1 0.1</scale>
            <uri>model://pepper_robot_description/pepper_robot/meshes/WheelFL_0.10.stl</uri>
          </mesh>
        </geometry>
        <surface>
          <contact>
            <ode/>
          </contact>
          <friction>
            <ode>
              <mu>1</mu>
              <mu2>0</mu2>
              <fdir1>1 0 0</fdir1>
            </ode>
          </friction>
        </surface>
      </collision>
      <visual name='WheelFL_link_visual'>
        <pose>0 0 0 0 0 0</pose>
        <geometry>
          <mesh>
            <scale>0.1 0.1 0.1</scale>
            <uri>model://pepper_robot_description/pepper_robot/meshes/WheelFL.dae</uri>
          </mesh>
        </geometry>
      </visual>
      <gravity>true</gravity>
    </link>
    <joint name='WheelFR' type='revolute'>
      <pose relative_to='base_link'>0.09 -0.155 0.07000000000000001 0 0 -1.07517</pose>
      <parent>base_link</parent>
      <child>WheelFR_link</child>
      <axis>
        <xyz>1 0 0</xyz>
        <limit>
          <effort>3.25</effort>
          <velocity>6.2831900000000003</velocity>
          <lower>-10000000000000000</lower>
          <upper>10000000000000000</upper>
        </limit>
        <dynamics>
          <spring_reference>0</spring_reference>
          <spring_stiffness>0</spring_stiffness>
        </dynamics>
      </axis>
    </joint>
    <link name='WheelFR_link'>
      <pose relative_to='WheelFR'>0 0 0 0 0 0</pose>
      <inertial>
        <pose>0 0 0 0 0 0</pose>
        <mass>1.5802799999999999</mass>
        <inertia>
          <ixx>0.0029975599999999998</ixx>
          <ixy>6.3068000000000003e-07</ixy>
          <ixz>5.5690299999999999e-06</ixz>
          <iyy>0.00303229</iyy>
          <iyz>-9.0408000000000003e-07</iyz>
          <izz>0.0029658499999999999</izz>
        </inertia>
      </inertial>
      <collision name='WheelFR_link_collision'>
        <pose>0 0 0 0 0 0</pose>
        <geometry>
          <mesh>
            <scale>0.1 0.1 0.1</scale>
            <uri>model://pepper_robot_description/pepper_robot/meshes/WheelFR_0.10.stl</uri>
          </mesh>
        </geometry>
        <surface>
          <contact>
            <ode/>
          </contact>
          <friction>
            <ode>
              <mu>0</mu>
              <mu2>1</mu2>
              <fdir1>0 1 0</fdir1>
            </ode>
          </friction>
        </surface>
      </collision>
      <visual name='WheelFR_link_visual'>
        <pose>0 0 0 0 0 0</pose>
        <geometry>
          <mesh>
            <scale>0.1 0.1 0.1</scale>
            <uri>model://pepper_robot_description/pepper_robot/meshes/WheelFR.dae</uri>
          </mesh>
        </geometry>
      </visual>
      <gravity>true</gravity>
    </link>
    <plugin name='ignition::gazebo::systems::DiffDrive' filename='ignition-gazebo-diff-drive-system'>
      <left_joint>WheelFL</left_joint>
      <right_joint>WheelFR</right_joint>
      <back_joint>WheelB</back_joint>
      <wheel_separation>0.170</wheel_separation>
      <wheel_radius>0.07</wheel_radius>
    </plugin>
    <plugin name='ign_ros2_control::IgnitionROS2ControlPlugin' filename='ign_ros2_control-system'>
      <parameters>/root/ws/src/pepper_ign_moveit2/pepper_robot_moveit_config/config/controllers_effort.yaml</parameters>
    </plugin>
    <plugin name='ignition::gazebo::systems::PosePublisher' filename='ignition-gazebo-pose-publisher-system'>
      <use_pose_vector_msg>true</use_pose_vector_msg>
      <publish_nested_model_pose>true</publish_nested_model_pose>
      <publish_link_pose>false</publish_link_pose>
      <publish_collision_pose>false</publish_collision_pose>
      <publish_visual_pose>false</publish_visual_pose>
    </plugin>
    <frame name='base_footprint_joint' attached_to='base_footprint'>
      <pose>0 0 0.334 0 -0 0</pose>
    </frame>
    <frame name='Tibia' attached_to='base_footprint_joint'/>
    <frame name='LGripper' attached_to='l_wrist'>
      <pose>0.07 0 -0.018023 -3.14 0 -1.57</pose>
    </frame>
    <frame name='l_gripper' attached_to='LGripper'/>
    <frame name='RGripper' attached_to='r_wrist'>
      <pose>0.07 0 -0.018023 3.14 0 1.57</pose>
    </frame>
    <frame name='r_gripper' attached_to='RGripper'/>
    <frame name='base_link_joint' attached_to='base_link'>
      <pose>0 0 0 0 -0 0</pose>
    </frame>
    <frame name='base_footprint' attached_to='base_link_joint'/>
  </model>
</sdf>
