<sdf version='1.9'>
  <model name='pepper_robot'>
    <link name='base_link'>
      <inertial>
        <pose>-0.0333667 -5.76754e-05 -1.66002 0 0 0</pose>
        <mass>12.34415815217273</mass>
        <inertia>
          <ixx>20.137807259763001</ixx>
          <ixy>-0.0011573869694506641</ixy>
          <ixz>0.66336947444265981</ixz>
          <iyy>18.055269240696521</iyy>
          <iyz>-0.00060930161651136933</iyz>
          <izz>21.81987274144166</izz>
        </inertia>
      </inertial>
      <collision name='base_link_fixed_joint_lump__Tibia_collision'>
        <pose>0 0 0.334 0 0 0</pose>
        <geometry>
          <mesh>
            <scale>0.1 0.1 0.1</scale>
            <uri>meshes/KneePitch_0.10.stl</uri>
          </mesh>
        </geometry>
        <surface>
          <contact>
            <ode/>
          </contact>
          <friction>
            <ode>
              <mu>0.5</mu>
              <mu2>0.5</mu2>
            </ode>
          </friction>
        </surface>
      </collision>
      <visual name='base_link_fixed_joint_lump__Tibia_visual'>
        <pose>0 0 0.334 0 0 0</pose>
        <geometry>
          <mesh>
            <scale>0.1 0.1 0.1</scale>
            <uri>meshes/KneePitch.dae</uri>
          </mesh>
        </geometry>
      </visual>
      <gravity>true</gravity>
      <self_collide>false</self_collide>
    </link>
    <joint name='KneePitch' type='revolute'>
      <pose relative_to='base_link'>0 0 0.334 0 0 0</pose>
      <parent>base_link</parent>
      <child>Pelvis</child>
      <axis>
        <xyz>0 -1 0</xyz>
        <limit>
          <lower>-0.514872</lower>
          <upper>0.514872</upper>
          <effort>27.702000000000002</effort>
          <velocity>2.93276</velocity>
        </limit>
        <dynamics>
          <spring_reference>0</spring_reference>
          <spring_stiffness>0</spring_stiffness>
        </dynamics>
      </axis>
    </joint>
    <link name='Pelvis'>
      <pose relative_to='KneePitch'>0 0 0 0 0 0</pose>
      <inertial>
        <pose>0.09083280000000001 0.000167721 -1.0109 0 0 0</pose>
        <mass>3.7955398538315381</mass>
        <inertia>
          <ixx>3.6832086564286159</ixx>
          <ixy>0.00041889033001187899</ixy>
          <ixz>0.022603422116371889</ixz>
          <iyy>2.907879699570989</iyy>
          <iyz>0.0005006966355005746</iyz>
          <izz>1.850724392595924</izz>
        </inertia>
      </inertial>
      <collision name='Pelvis_collision'>
        <pose>0 0 0.268 0 0 0</pose>
        <geometry>
          <mesh>
            <scale>0.1 0.1 0.1</scale>
            <uri>meshes/HipPitch_0.10.stl</uri>
          </mesh>
        </geometry>
        <surface>
          <contact>
            <ode/>
          </contact>
          <friction>
            <ode>
              <mu>0.5</mu>
              <mu2>0.5</mu2>
            </ode>
          </friction>
        </surface>
      </collision>
      <visual name='Pelvis_visual'>
        <pose>0 0 0.268 0 0 0</pose>
        <geometry>
          <mesh>
            <scale>0.1 0.1 0.1</scale>
            <uri>meshes/HipPitch.dae</uri>
          </mesh>
        </geometry>
      </visual>
      <gravity>true</gravity>
      <self_collide>false</self_collide>
    </link>
    <joint name='HipPitch' type='revolute'>
      <pose relative_to='Pelvis'>0 0 0.268 0 0 0</pose>
      <parent>Pelvis</parent>
      <child>Hip</child>
      <axis>
        <xyz>0 -1 0</xyz>
        <limit>
          <lower>-1.03847</lower>
          <upper>1.03847</upper>
          <effort>19.786999999999999</effort>
          <velocity>2.93276</velocity>
        </limit>
        <dynamics>
          <spring_reference>0</spring_reference>
          <spring_stiffness>0</spring_stiffness>
        </dynamics>
      </axis>
    </joint>
    <link name='Hip'>
      <pose relative_to='HipPitch'>0 0 0 0 0 0</pose>
      <inertial>
        <pose>0.0110062 -0.00150986 -0.650903 0 0 0</pose>
        <mass>1.007402858772892</mass>
        <inertia>
          <ixx>0.25689377741157771</ixx>
          <ixy>-9.0969573347688543e-05</ixy>
          <ixz>0.0040559866891777992</ixz>
          <iyy>0.35295735919431731</iyy>
          <iyz>-0.0012970391194746069</iyz>
          <izz>0.18078541923077679</izz>
        </inertia>
      </inertial>
      <collision name='Hip_collision'>
        <pose>0 0 0.079 0 0 0</pose>
        <geometry>
          <mesh>
            <scale>0.1 0.1 0.1</scale>
            <uri>meshes/HipRoll_0.10.stl</uri>
          </mesh>
        </geometry>
        <surface>
          <contact>
            <ode/>
          </contact>
          <friction>
            <ode>
              <mu>0.5</mu>
              <mu2>0.5</mu2>
            </ode>
          </friction>
        </surface>
      </collision>
      <visual name='Hip_visual'>
        <pose>0 0 0.079 0 0 0</pose>
        <geometry>
          <mesh>
            <scale>0.1 0.1 0.1</scale>
            <uri>meshes/HipRoll.dae</uri>
          </mesh>
        </geometry>
      </visual>
      <gravity>true</gravity>
      <self_collide>false</self_collide>
    </link>
    <joint name='HipRoll' type='revolute'>
      <pose relative_to='Hip'>0 0 0.079 0 0 0</pose>
      <parent>Hip</parent>
      <child>torso</child>
      <axis>
        <xyz>-1 0 0</xyz>
        <limit>
          <lower>-0.514872</lower>
          <upper>0.514872</upper>
          <effort>10.1884</effort>
          <velocity>2.2703199999999999</velocity>
        </limit>
        <dynamics>
          <spring_reference>0</spring_reference>
          <spring_stiffness>0</spring_stiffness>
        </dynamics>
      </axis>
    </joint>
    <link name='torso'>
      <pose relative_to='HipRoll'>0 0 0 0 0 0</pose>
      <inertial>
        <pose>-0.255593 3.02341e-05 0.391816 0 0 0</pose>
        <mass>4.8948172401406298</mass>
        <inertia>
          <ixx>4.5666112072079859</ixx>
          <ixy>6.2959586472871465e-05</ixy>
          <ixz>0.66565070418768835</ixz>
          <iyy>4.047538877310803</iyy>
          <iyz>-0.00019790396903388951</iyz>
          <izz>3.3831913767348221</izz>
        </inertia>
      </inertial>
      <collision name='torso_collision'>
        <pose>2e-05 0 0.139 0 0 0</pose>
        <geometry>
          <mesh>
            <scale>0.1 0.1 0.1</scale>
            <uri>meshes/Torso_0.10.stl</uri>
          </mesh>
        </geometry>
        <surface>
          <contact>
            <ode/>
          </contact>
          <friction>
            <ode>
              <mu>0.5</mu>
              <mu2>0.5</mu2>
            </ode>
          </friction>
        </surface>
      </collision>
      <visual name='torso_visual'>
        <pose>2e-05 0 0.139 0 0 0</pose>
        <geometry>
          <mesh>
            <scale>0.1 0.1 0.1</scale>
            <uri>meshes/Torso.dae</uri>
          </mesh>
        </geometry>
      </visual>
      <gravity>true</gravity>
      <self_collide>false</self_collide>
    </link>
    <joint name='HeadYaw' type='revolute'>
      <pose relative_to='torso'>-0.038 0 0.3089 0 0 0</pose>
      <parent>torso</parent>
      <child>Neck</child>
      <axis>
        <xyz>0 0 1</xyz>
        <limit>
          <lower>-2.0856699999999999</lower>
          <upper>2.0856699999999999</upper>
          <effort>5.4279999999999999</effort>
          <velocity>7.3399799999999997</velocity>
        </limit>
        <dynamics>
          <spring_reference>0</spring_reference>
          <spring_stiffness>0</spring_stiffness>
        </dynamics>
      </axis>
    </joint>
    <link name='Neck'>
      <pose relative_to='HeadYaw'>0 0 0 0 0 0</pose>
      <inertial>
        <pose>-0.0122611 -8.256409999999999e-07 0.0292341 0 0 0</pose>
        <mass>0.091465686032588159</mass>
        <inertia>
          <ixx>0.0043941585685860953</ixx>
          <ixy>-2.227492593175832e-10</ixy>
          <ixz>0.0001185197263643396</ixz>
          <iyy>0.0046796444923100609</iyy>
          <iyz>1.4572477784340021e-09</iyz>
          <izz>0.0043841432021901024</izz>
        </inertia>
      </inertial>
      <collision name='Neck_collision'>
        <pose>0 0 0 0 0 0</pose>
        <geometry>
          <mesh>
            <scale>0.1 0.1 0.1</scale>
            <uri>meshes/HeadYaw_0.10.stl</uri>
          </mesh>
        </geometry>
        <surface>
          <contact>
            <ode/>
          </contact>
          <friction>
            <ode>
              <mu>0.5</mu>
              <mu2>0.5</mu2>
            </ode>
          </friction>
        </surface>
      </collision>
      <visual name='Neck_visual'>
        <pose>0 0 0 0 0 0</pose>
        <geometry>
          <mesh>
            <scale>0.1 0.1 0.1</scale>
            <uri>meshes/HeadYaw.dae</uri>
          </mesh>
        </geometry>
      </visual>
      <gravity>true</gravity>
      <self_collide>false</self_collide>
    </link>
    <joint name='HeadPitch' type='revolute'>
      <pose relative_to='Neck'>0 0 0 0 0 0</pose>
      <parent>Neck</parent>
      <child>Head</child>
      <axis>
        <xyz>0 1 0</xyz>
        <limit>
          <lower>-0.70685799999999999</lower>
          <upper>0.4451</upper>
          <effort>2.6659999999999999</effort>
          <velocity>9.2275600000000004</velocity>
        </limit>
        <dynamics>
          <spring_reference>0</spring_reference>
          <spring_stiffness>0</spring_stiffness>
        </dynamics>
      </axis>
    </joint>
    <link name='Head'>
      <pose relative_to='HeadPitch'>0 0 0 0 0 0</pose>
      <inertial>
        <pose>0.09083280000000001 0.000167721 -1.0109 0 0 0</pose>
        <mass>3.7955398538315381</mass>
        <inertia>
          <ixx>3.6832086564286159</ixx>
          <ixy>0.00041889033001187899</ixy>
          <ixz>0.022603422116371889</ixz>
          <iyy>2.907879699570989</iyy>
          <iyz>0.0005006966355005746</iyz>
          <izz>1.850724392595924</izz>
        </inertia>
      </inertial>
      <collision name='Head_collision'>
        <pose>0 0 0 0 0 0</pose>
        <geometry>
          <mesh>
            <scale>0.1 0.1 0.1</scale>
            <uri>meshes/HeadPitch_0.10.stl</uri>
          </mesh>
        </geometry>
        <surface>
          <contact>
            <ode/>
          </contact>
          <friction>
            <ode>
              <mu>0.5</mu>
              <mu2>0.5</mu2>
            </ode>
          </friction>
        </surface>
      </collision>
      <visual name='Head_visual'>
        <pose>0 0 0 0 0 0</pose>
        <geometry>
          <mesh>
            <scale>0.1 0.1 0.1</scale>
            <uri>meshes/HeadPitch.dae</uri>
          </mesh>
        </geometry>
      </visual>
      <gravity>true</gravity>
      <self_collide>false</self_collide>
    </link>
    <joint name='LShoulderPitch' type='revolute'>
      <pose relative_to='torso'>-0.057 0.14974 0.22582 0 0 0</pose>
      <parent>torso</parent>
      <child>LShoulder</child>
      <axis>
        <xyz>0 1 0</xyz>
        <limit>
          <lower>-2.0856699999999999</lower>
          <upper>2.0856699999999999</upper>
          <effort>5.4279999999999999</effort>
          <velocity>7.3399799999999997</velocity>
        </limit>
        <dynamics>
          <spring_reference>0</spring_reference>
          <spring_stiffness>0</spring_stiffness>
        </dynamics>
      </axis>
    </joint>
    <link name='LShoulder'>
      <pose relative_to='LShoulderPitch'>0 0 0 0 0 0</pose>
      <inertial>
        <pose>-7.402849999999999e-08 -7.32303e-08 -1.30517e-07 0 0 0</pose>
        <mass>0.14071507216157689</mass>
        <inertia>
          <ixx>0.0085324652949196854</ixx>
          <ixy>-1.9218712572811561e-09</ixy>
          <ixz>6.3544486676232566e-10</ixz>
          <iyy>0.0085324639364187625</iyy>
          <iyz>-2.0716583314902061e-09</iyz>
          <izz>0.01025275079353366</izz>
        </inertia>
      </inertial>
      <collision name='LShoulder_collision'>
        <pose>0 0 0 0 0 0</pose>
        <geometry>
          <mesh>
            <scale>0.1 0.1 0.1</scale>
            <uri>meshes/LShoulderPitch_0.10.stl</uri>
          </mesh>
        </geometry>
        <surface>
          <contact>
            <ode/>
          </contact>
          <friction>
            <ode>
              <mu>0.5</mu>
              <mu2>0.5</mu2>
            </ode>
          </friction>
        </surface>
      </collision>
      <visual name='LShoulder_visual'>
        <pose>0 0 0 0 0 0</pose>
        <geometry>
          <mesh>
            <scale>0.1 0.1 0.1</scale>
            <uri>meshes/LShoulderPitch.dae</uri>
          </mesh>
        </geometry>
      </visual>
      <gravity>true</gravity>
      <self_collide>false</self_collide>
    </link>
    <joint name='LShoulderRoll' type='revolute'>
      <pose relative_to='LShoulder'>0 0 0 0 0 0</pose>
      <parent>LShoulder</parent>
      <child>LBicep</child>
      <axis>
        <xyz>0 0 1</xyz>
        <limit>
          <lower>0.0087266500000000007</lower>
          <upper>1.5620700000000001</upper>
          <effort>2.6659999999999999</effort>
          <velocity>9.2275600000000004</velocity>
        </limit>
        <dynamics>
          <spring_reference>0</spring_reference>
          <spring_stiffness>0</spring_stiffness>
        </dynamics>
      </axis>
    </joint>
    <link name='LBicep'>
      <pose relative_to='LShoulderRoll'>0 0 0 0 0 0</pose>
      <inertial>
        <pose>0.902599 -0.162517 -0.0061116 0 0 0</pose>
        <mass>0.31370324379943892</mass>
        <inertia>
          <ixx>0.024698531239164299</ixx>
          <ixy>0.001281786483549858</ixy>
          <ixz>0.0017029391719427639</ixz>
          <iyy>0.071673513547853729</iyy>
          <iyz>6.8745322669604082e-05</iyz>
          <izz>0.067663578533357652</izz>
        </inertia>
      </inertial>
      <collision name='LBicep_collision'>
        <pose>0 0 0 0 0 0</pose>
        <geometry>
          <mesh>
            <scale>0.1 0.1 0.1</scale>
            <uri>meshes/LShoulderRoll_0.10.stl</uri>
          </mesh>
        </geometry>
        <surface>
          <contact>
            <ode/>
          </contact>
          <friction>
            <ode>
              <mu>0.5</mu>
              <mu2>0.5</mu2>
            </ode>
          </friction>
        </surface>
      </collision>
      <visual name='LBicep_visual'>
        <pose>0 0 0 0 0 0</pose>
        <geometry>
          <mesh>
            <scale>0.1 0.1 0.1</scale>
            <uri>meshes/LShoulderRoll.dae</uri>
          </mesh>
        </geometry>
      </visual>
      <gravity>true</gravity>
      <self_collide>false</self_collide>
    </link>
    <joint name='LElbowYaw' type='revolute'>
      <pose relative_to='LBicep'>0.1812 0.015 0.00013 0 -0.1570790000000001 0</pose>
      <parent>LBicep</parent>
      <child>LElbow</child>
      <axis>
        <xyz>1 0 0</xyz>
        <limit>
          <lower>-2.0856699999999999</lower>
          <upper>2.0856699999999999</upper>
          <effort>5.4279999999999999</effort>
          <velocity>7.3399799999999997</velocity>
        </limit>
        <dynamics>
          <spring_reference>0</spring_reference>
          <spring_stiffness>0</spring_stiffness>
        </dynamics>
      </axis>
    </joint>
    <link name='LElbow'>
      <pose relative_to='LElbowYaw'>0 0 0 0 0 0</pose>
      <inertial>
        <pose>-7.34206e-08 1.48077e-09 -4.87585e-08 0 0 0</pose>
        <mass>0.07380464672624755</mass>
        <inertia>
          <ixx>0.0029965021096465139</ixx>
          <ixy>-1.038800875829926e-10</ixy>
          <ixz>-4.2002518090263304e-12</ixz>
          <iyy>0.0030276726644025741</iyy>
          <iyz>-2.9936815578853858e-10</iyz>
          <izz>0.0030276710620920628</izz>
        </inertia>
      </inertial>
      <collision name='LElbow_collision'>
        <pose>0 0 0 0 0 0</pose>
        <geometry>
          <mesh>
            <scale>0.1 0.1 0.1</scale>
            <uri>meshes/LElbowYaw_0.10.stl</uri>
          </mesh>
        </geometry>
        <surface>
          <contact>
            <ode/>
          </contact>
          <friction>
            <ode>
              <mu>0.5</mu>
              <mu2>0.5</mu2>
            </ode>
          </friction>
        </surface>
      </collision>
      <visual name='LElbow_visual'>
        <pose>0 0 0 0 0 0</pose>
        <geometry>
          <mesh>
            <scale>0.1 0.1 0.1</scale>
            <uri>meshes/LElbowYaw.dae</uri>
          </mesh>
        </geometry>
      </visual>
      <gravity>true</gravity>
      <self_collide>false</self_collide>
    </link>
    <joint name='LElbowRoll' type='revolute'>
      <pose relative_to='LElbow'>0 0 0 0 0 0</pose>
      <parent>LElbow</parent>
      <child>LForeArm</child>
      <axis>
        <xyz>0 0 1</xyz>
        <limit>
          <lower>-1.5620700000000001</lower>
          <upper>-0.0087266500000000007</upper>
          <effort>2.6659999999999999</effort>
          <velocity>9.2275600000000004</velocity>
        </limit>
        <dynamics>
          <spring_reference>0</spring_reference>
          <spring_stiffness>0</spring_stiffness>
        </dynamics>
      </axis>
    </joint>
    <link name='LForeArm'>
      <pose relative_to='LElbowRoll'>0 0 0 0 0 0</pose>
      <inertial>
        <pose>0.470716 0.0367563 -0.00106886 0 0 0</pose>
        <mass>0.1332111481578373</mass>
        <inertia>
          <ixx>0.0071573638437460486</ixx>
          <ixy>0.001127561101952054</ixy>
          <ixz>4.2730568374252698e-05</ixz>
          <iyy>0.0099149161993504781</iyy>
          <iyz>1.7673061298494219e-06</iyz>
          <izz>0.0096222934744772878</izz>
        </inertia>
      </inertial>
      <collision name='LForeArm_collision'>
        <pose>0 0 0 0 0 0</pose>
        <geometry>
          <mesh>
            <scale>0.1 0.1 0.1</scale>
            <uri>meshes/LElbowRoll_0.10.stl</uri>
          </mesh>
        </geometry>
        <surface>
          <contact>
            <ode/>
          </contact>
          <friction>
            <ode>
              <mu>0.5</mu>
              <mu2>0.5</mu2>
            </ode>
          </friction>
        </surface>
      </collision>
      <visual name='LForeArm_visual'>
        <pose>0 0 0 0 0 0</pose>
        <geometry>
          <mesh>
            <scale>0.1 0.1 0.1</scale>
            <uri>meshes/LElbowRoll.dae</uri>
          </mesh>
        </geometry>
      </visual>
      <gravity>true</gravity>
      <self_collide>false</self_collide>
    </link>
    <joint name='LWristYaw' type='revolute'>
      <pose relative_to='LForeArm'>0.15 0 0 0 0 0</pose>
      <parent>LForeArm</parent>
      <child>l_wrist</child>
      <axis>
        <xyz>1 0 0</xyz>
        <limit>
          <lower>-1.8238700000000001</lower>
          <upper>1.8238700000000001</upper>
          <effort>0.2014</effort>
          <velocity>17.383500000000002</velocity>
        </limit>
        <dynamics>
          <spring_reference>0</spring_reference>
          <spring_stiffness>0</spring_stiffness>
        </dynamics>
      </axis>
    </joint>
    <link name='l_wrist'>
      <pose relative_to='LWristYaw'>0 0 0 0 0 0</pose>
      <inertial>
        <pose>0.110379 -0.0272187 0.0250071 0 0 0</pose>
        <mass>0.20759187418056399</mass>
        <inertia>
          <ixx>0.01170340413343585</ixx>
          <ixy>0.00081774415090919987</ixy>
          <ixz>-0.0033215793821857898</ixz>
          <iyy>0.037840363877038402</iyy>
          <iyz>-0.00014926583294427479</iyz>
          <izz>0.040272676675503362</izz>
        </inertia>
      </inertial>
      <collision name='l_wrist_collision'>
        <pose>0 0 0 0 0 0</pose>
        <geometry>
          <mesh>
            <scale>0.1 0.1 0.1</scale>
            <uri>meshes/LWristYaw_0.10.stl</uri>
          </mesh>
        </geometry>
        <surface>
          <contact>
            <ode/>
          </contact>
          <friction>
            <ode>
              <mu>0.5</mu>
              <mu2>0.5</mu2>
            </ode>
          </friction>
        </surface>
      </collision>
      <visual name='l_wrist_visual'>
        <pose>0 0 0 0 0 0</pose>
        <geometry>
          <mesh>
            <scale>0.1 0.1 0.1</scale>
            <uri>meshes/LWristYaw.dae</uri>
          </mesh>
        </geometry>
      </visual>
      <gravity>true</gravity>
      <self_collide>false</self_collide>
    </link>
    <joint name='LFinger11' type='revolute'>
      <pose relative_to='l_wrist'>0.08210000000000001 -0.0268 0.004 1.74402 1.04064 -0.03343350000000005</pose>
      <parent>l_wrist</parent>
      <child>LFinger11_link</child>
      <axis>
        <xyz>0 0 1</xyz>
        <limit>
          <lower>-10000000000000000</lower>
          <upper>10000000000000000</upper>
        </limit>
        <dynamics>
          <spring_reference>0</spring_reference>
          <spring_stiffness>0</spring_stiffness>
        </dynamics>
      </axis>
    </joint>
    <link name='LFinger11_link'>
      <pose relative_to='LFinger11'>0 0 0 0 0 0</pose>
      <inertial>
        <pose>0 0 0 0 0 0</pose>
        <mass>0.001734202261175038</mass>
        <inertia>
          <ixx>3.4678130376738111e-06</ixx>
          <ixy>-3.2590510087003849e-08</ixy>
          <ixz>-1.775716101749067e-07</ixz>
          <iyy>9.0679597833730339e-06</iyy>
          <iyz>-5.0426978117144053e-08</iyz>
          <izz>9.9814064894198014e-06</izz>
        </inertia>
      </inertial>
      <collision name='LFinger11_link_collision'>
        <pose>0 0 0 0 0 0</pose>
        <geometry>
          <mesh>
            <scale>0.1 0.1 0.1</scale>
            <uri>meshes/LFinger11_0.10.stl</uri>
          </mesh>
        </geometry>
        <surface>
          <contact>
            <ode/>
          </contact>
          <friction>
            <ode>
              <mu>0.5</mu>
              <mu2>0.5</mu2>
            </ode>
          </friction>
        </surface>
      </collision>
      <visual name='LFinger11_link_visual'>
        <pose>0 0 0 0 0 0</pose>
        <geometry>
          <mesh>
            <scale>0.1 0.1 0.1</scale>
            <uri>meshes/LFinger11.dae</uri>
          </mesh>
        </geometry>
      </visual>
      <gravity>true</gravity>
      <self_collide>false</self_collide>
    </link>
    <joint name='LFinger12' type='revolute'>
      <pose relative_to='LFinger11_link'>0.018 0 0 0 0 -1.0472</pose>
      <parent>LFinger11_link</parent>
      <child>LFinger12_link</child>
      <axis>
        <xyz>0 0 1</xyz>
        <limit>
          <lower>-10000000000000000</lower>
          <upper>10000000000000000</upper>
        </limit>
        <dynamics>
          <spring_reference>0</spring_reference>
          <spring_stiffness>0</spring_stiffness>
        </dynamics>
      </axis>
    </joint>
    <link name='LFinger12_link'>
      <pose relative_to='LFinger12'>0 0 0 0 0 0</pose>
      <inertial>
        <pose>0 0 0 0 0 0</pose>
        <mass>0.001734202280194698</mass>
        <inertia>
          <ixx>3.4678131132210499e-06</ixx>
          <ixy>-3.2590542520134938e-08</ixy>
          <ixz>-1.7757159744336221e-07</ixz>
          <iyy>9.0679598408827441e-06</iyy>
          <iyz>-5.0426962301906762e-08</iyz>
          <izz>9.9814065117924809e-06</izz>
        </inertia>
      </inertial>
      <collision name='LFinger12_link_collision'>
        <pose>0 0 0 0 0 0</pose>
        <geometry>
          <mesh>
            <scale>0.1 0.1 0.1</scale>
            <uri>meshes/LFinger12_0.10.stl</uri>
          </mesh>
        </geometry>
        <surface>
          <contact>
            <ode/>
          </contact>
          <friction>
            <ode>
              <mu>0.5</mu>
              <mu2>0.5</mu2>
            </ode>
          </friction>
        </surface>
      </collision>
      <visual name='LFinger12_link_visual'>
        <pose>0 0 0 0 0 0</pose>
        <geometry>
          <mesh>
            <scale>0.1 0.1 0.1</scale>
            <uri>meshes/LFinger12.dae</uri>
          </mesh>
        </geometry>
      </visual>
      <gravity>true</gravity>
      <self_collide>false</self_collide>
    </link>
    <joint name='LFinger13' type='revolute'>
      <pose relative_to='LFinger12_link'>0.018 0 0 0 0 -1.0472</pose>
      <parent>LFinger12_link</parent>
      <child>LFinger13_link</child>
      <axis>
        <xyz>0 0 1</xyz>
        <limit>
          <lower>-10000000000000000</lower>
          <upper>10000000000000000</upper>
        </limit>
        <dynamics>
          <spring_reference>0</spring_reference>
          <spring_stiffness>0</spring_stiffness>
        </dynamics>
      </axis>
    </joint>
    <link name='LFinger13_link'>
      <pose relative_to='LFinger13'>0 0 0 0 0 0</pose>
      <inertial>
        <pose>0 0 0 0 0 0</pose>
        <mass>0.001211966381471568</mass>
        <inertia>
          <ixx>2.0922392266947092e-06</ixx>
          <ixy>-1.1457419844015849e-07</ixy>
          <ixz>1.4167922235814149e-08</ixz>
          <iyy>4.0499921605015474e-06</iyy>
          <iyz>-5.704188035340379e-09</iyz>
          <izz>4.4165365735760226e-06</izz>
        </inertia>
      </inertial>
      <collision name='LFinger13_link_collision'>
        <pose>0 0 0 0 0 0</pose>
        <geometry>
          <mesh>
            <scale>0.1 0.1 0.1</scale>
            <uri>meshes/LFinger13_0.10.stl</uri>
          </mesh>
        </geometry>
        <surface>
          <contact>
            <ode/>
          </contact>
          <friction>
            <ode>
              <mu>0.5</mu>
              <mu2>0.5</mu2>
            </ode>
          </friction>
        </surface>
      </collision>
      <visual name='LFinger13_link_visual'>
        <pose>0 0 0 0 0 0</pose>
        <geometry>
          <mesh>
            <scale>0.1 0.1 0.1</scale>
            <uri>meshes/LFinger13.dae</uri>
          </mesh>
        </geometry>
      </visual>
      <gravity>true</gravity>
      <self_collide>false</self_collide>
    </link>
    <joint name='LFinger21' type='revolute'>
      <pose relative_to='l_wrist'>0.0873 -0.0073 0.006 1.5708 1.0472 -0.06108599999999988</pose>
      <parent>l_wrist</parent>
      <child>LFinger21_link</child>
      <axis>
        <xyz>0 0 1</xyz>
        <limit>
          <lower>-10000000000000000</lower>
          <upper>10000000000000000</upper>
        </limit>
        <dynamics>
          <spring_reference>0</spring_reference>
          <spring_stiffness>0</spring_stiffness>
        </dynamics>
      </axis>
    </joint>
    <link name='LFinger21_link'>
      <pose relative_to='LFinger21'>0 0 0 0 0 0</pose>
      <inertial>
        <pose>0 0 0 0 0 0</pose>
        <mass>0.00173420224806078</mass>
        <inertia>
          <ixx>3.4678129900481898e-06</ixx>
          <ixy>-3.2590624281102048e-08</ixy>
          <ixz>-1.7757153533455459e-07</ixz>
          <iyy>9.0679598767719028e-06</iyy>
          <iyz>-5.0426968074891452e-08</iyz>
          <izz>9.9814065131534392e-06</izz>
        </inertia>
      </inertial>
      <collision name='LFinger21_link_collision'>
        <pose>0 0 0 0 0 0</pose>
        <geometry>
          <mesh>
            <scale>0.1 0.1 0.1</scale>
            <uri>meshes/LFinger21_0.10.stl</uri>
          </mesh>
        </geometry>
        <surface>
          <contact>
            <ode/>
          </contact>
          <friction>
            <ode>
              <mu>0.5</mu>
              <mu2>0.5</mu2>
            </ode>
          </friction>
        </surface>
      </collision>
      <visual name='LFinger21_link_visual'>
        <pose>0 0 0 0 0 0</pose>
        <geometry>
          <mesh>
            <scale>0.1 0.1 0.1</scale>
            <uri>meshes/LFinger21.dae</uri>
          </mesh>
        </geometry>
      </visual>
      <gravity>true</gravity>
      <self_collide>false</self_collide>
    </link>
    <joint name='LFinger22' type='revolute'>
      <pose relative_to='LFinger21_link'>0.018 0 0 0 0 -1.0472</pose>
      <parent>LFinger21_link</parent>
      <child>LFinger22_link</child>
      <axis>
        <xyz>0 0 1</xyz>
        <limit>
          <lower>-10000000000000000</lower>
          <upper>10000000000000000</upper>
        </limit>
        <dynamics>
          <spring_reference>0</spring_reference>
          <spring_stiffness>0</spring_stiffness>
        </dynamics>
      </axis>
    </joint>
    <link name='LFinger22_link'>
      <pose relative_to='LFinger22'>0 0 0 0 0 0</pose>
      <inertial>
        <pose>0 0 0 0 0 0</pose>
        <mass>0.001734202428057582</mass>
        <inertia>
          <ixx>3.4678136128088389e-06</ixx>
          <ixy>-3.2591429893149237e-08</ixy>
          <ixz>-1.775718802040381e-07</ixz>
          <iyy>9.0679621450442563e-06</iyy>
          <iyz>-5.0427098486528039e-08</iyz>
          <izz>9.9814092737652281e-06</izz>
        </inertia>
      </inertial>
      <collision name='LFinger22_link_collision'>
        <pose>0 0 0 0 0 0</pose>
        <geometry>
          <mesh>
            <scale>0.1 0.1 0.1</scale>
            <uri>meshes/LFinger22_0.10.stl</uri>
          </mesh>
        </geometry>
        <surface>
          <contact>
            <ode/>
          </contact>
          <friction>
            <ode>
              <mu>0.5</mu>
              <mu2>0.5</mu2>
            </ode>
          </friction>
        </surface>
      </collision>
      <visual name='LFinger22_link_visual'>
        <pose>0 0 0 0 0 0</pose>
        <geometry>
          <mesh>
            <scale>0.1 0.1 0.1</scale>
            <uri>meshes/LFinger22.dae</uri>
          </mesh>
        </geometry>
      </visual>
      <gravity>true</gravity>
      <self_collide>false</self_collide>
    </link>
    <joint name='LFinger23' type='revolute'>
      <pose relative_to='LFinger22_link'>0.018 0 0 0 0 -1.0472</pose>
      <parent>LFinger22_link</parent>
      <child>LFinger23_link</child>
      <axis>
        <xyz>0 0 1</xyz>
        <limit>
          <lower>-10000000000000000</lower>
          <upper>10000000000000000</upper>
        </limit>
        <dynamics>
          <spring_reference>0</spring_reference>
          <spring_stiffness>0</spring_stiffness>
        </dynamics>
      </axis>
    </joint>
    <link name='LFinger23_link'>
      <pose relative_to='LFinger23'>0 0 0 0 0 0</pose>
      <inertial>
        <pose>0 0 0 0 0 0</pose>
        <mass>0.001211966369925541</mass>
        <inertia>
          <ixx>2.092239047891544e-06</ixx>
          <ixy>-1.145742296959502e-07</ixy>
          <ixz>1.41678106632915e-08</ixz>
          <iyy>4.0499924049460343e-06</iyy>
          <iyz>-5.704156613549065e-09</iyz>
          <izz>4.4165365528987541e-06</izz>
        </inertia>
      </inertial>
      <collision name='LFinger23_link_collision'>
        <pose>0 0 0 0 0 0</pose>
        <geometry>
          <mesh>
            <scale>0.1 0.1 0.1</scale>
            <uri>meshes/LFinger23_0.10.stl</uri>
          </mesh>
        </geometry>
        <surface>
          <contact>
            <ode/>
          </contact>
          <friction>
            <ode>
              <mu>0.5</mu>
              <mu2>0.5</mu2>
            </ode>
          </friction>
        </surface>
      </collision>
      <visual name='LFinger23_link_visual'>
        <pose>0 0 0 0 0 0</pose>
        <geometry>
          <mesh>
            <scale>0.1 0.1 0.1</scale>
            <uri>meshes/LFinger23.dae</uri>
          </mesh>
        </geometry>
      </visual>
      <gravity>true</gravity>
      <self_collide>false</self_collide>
    </link>
    <joint name='LFinger31' type='revolute'>
      <pose relative_to='l_wrist'>0.0833 0.0123 0.004 1.46636 1.04483 -0.02931400000000012</pose>
      <parent>l_wrist</parent>
      <child>LFinger31_link</child>
      <axis>
        <xyz>0 0 1</xyz>
        <limit>
          <lower>-10000000000000000</lower>
          <upper>10000000000000000</upper>
        </limit>
        <dynamics>
          <spring_reference>0</spring_reference>
          <spring_stiffness>0</spring_stiffness>
        </dynamics>
      </axis>
    </joint>
    <link name='LFinger31_link'>
      <pose relative_to='LFinger31'>0 0 0 0 0 0</pose>
      <inertial>
        <pose>0 0 0 0 0 0</pose>
        <mass>0.0017342022712585441</mass>
        <inertia>
          <ixx>3.467813135465312e-06</ixx>
          <ixy>-3.2590501458069509e-08</ixy>
          <ixz>-1.775715550954204e-07</ixz>
          <iyy>9.0679596157997931e-06</iyy>
          <iyz>-5.0427022839883737e-08</iyz>
          <izz>9.9814063267372237e-06</izz>
        </inertia>
      </inertial>
      <collision name='LFinger31_link_collision'>
        <pose>0 0 0 0 0 0</pose>
        <geometry>
          <mesh>
            <scale>0.1 0.1 0.1</scale>
            <uri>meshes/LFinger31_0.10.stl</uri>
          </mesh>
        </geometry>
        <surface>
          <contact>
            <ode/>
          </contact>
          <friction>
            <ode>
              <mu>0.5</mu>
              <mu2>0.5</mu2>
            </ode>
          </friction>
        </surface>
      </collision>
      <visual name='LFinger31_link_visual'>
        <pose>0 0 0 0 0 0</pose>
        <geometry>
          <mesh>
            <scale>0.1 0.1 0.1</scale>
            <uri>meshes/LFinger31.dae</uri>
          </mesh>
        </geometry>
      </visual>
      <gravity>true</gravity>
      <self_collide>false</self_collide>
    </link>
    <joint name='LFinger32' type='revolute'>
      <pose relative_to='LFinger31_link'>0.018 0 0 0 0 -1.0472</pose>
      <parent>LFinger31_link</parent>
      <child>LFinger32_link</child>
      <axis>
        <xyz>0 0 1</xyz>
        <limit>
          <lower>-10000000000000000</lower>
          <upper>10000000000000000</upper>
        </limit>
        <dynamics>
          <spring_reference>0</spring_reference>
          <spring_stiffness>0</spring_stiffness>
        </dynamics>
      </axis>
    </joint>
    <link name='LFinger32_link'>
      <pose relative_to='LFinger32'>0 0 0 0 0 0</pose>
      <inertial>
        <pose>0 0 0 0 0 0</pose>
        <mass>0.001734202223583049</mass>
        <inertia>
          <ixx>3.467812920370958e-06</ixx>
          <ixy>-3.259059292999676e-08</ixy>
          <ixz>-1.7757164855882871e-07</ixz>
          <iyy>9.067959555576335e-06</iyy>
          <iyz>-5.0426979983568877e-08</iyz>
          <izz>9.9814061853856547e-06</izz>
        </inertia>
      </inertial>
      <collision name='LFinger32_link_collision'>
        <pose>0 0 0 0 0 0</pose>
        <geometry>
          <mesh>
            <scale>0.1 0.1 0.1</scale>
            <uri>meshes/LFinger32_0.10.stl</uri>
          </mesh>
        </geometry>
        <surface>
          <contact>
            <ode/>
          </contact>
          <friction>
            <ode>
              <mu>0.5</mu>
              <mu2>0.5</mu2>
            </ode>
          </friction>
        </surface>
      </collision>
      <visual name='LFinger32_link_visual'>
        <pose>0 0 0 0 0 0</pose>
        <geometry>
          <mesh>
            <scale>0.1 0.1 0.1</scale>
            <uri>meshes/LFinger32.dae</uri>
          </mesh>
        </geometry>
      </visual>
      <gravity>true</gravity>
      <self_collide>false</self_collide>
    </link>
    <joint name='LFinger33' type='revolute'>
      <pose relative_to='LFinger32_link'>0.018 0 0 0 0 -1.0472</pose>
      <parent>LFinger32_link</parent>
      <child>LFinger33_link</child>
      <axis>
        <xyz>0 0 1</xyz>
        <limit>
          <lower>-10000000000000000</lower>
          <upper>10000000000000000</upper>
        </limit>
        <dynamics>
          <spring_reference>0</spring_reference>
          <spring_stiffness>0</spring_stiffness>
        </dynamics>
      </axis>
    </joint>
    <link name='LFinger33_link'>
      <pose relative_to='LFinger33'>0 0 0 0 0 0</pose>
      <inertial>
        <pose>0 0 0 0 0 0</pose>
        <mass>0.0012119665608007831</mass>
        <inertia>
          <ixx>2.0922397962844701e-06</ixx>
          <ixy>-1.1457416792102811e-07</ixy>
          <ixz>1.4168110404002699e-08</ixz>
          <iyy>4.0499929966690558e-06</iyy>
          <iyz>-5.7041902027368457e-09</iyz>
          <izz>4.4165371343443801e-06</izz>
        </inertia>
      </inertial>
      <collision name='LFinger33_link_collision'>
        <pose>0 0 0 0 0 0</pose>
        <geometry>
          <mesh>
            <scale>0.1 0.1 0.1</scale>
            <uri>meshes/LFinger33_0.10.stl</uri>
          </mesh>
        </geometry>
        <surface>
          <contact>
            <ode/>
          </contact>
          <friction>
            <ode>
              <mu>0.5</mu>
              <mu2>0.5</mu2>
            </ode>
          </friction>
        </surface>
      </collision>
      <visual name='LFinger33_link_visual'>
        <pose>0 0 0 0 0 0</pose>
        <geometry>
          <mesh>
            <scale>0.1 0.1 0.1</scale>
            <uri>meshes/LFinger33.dae</uri>
          </mesh>
        </geometry>
      </visual>
      <gravity>true</gravity>
      <self_collide>false</self_collide>
    </link>
    <joint name='LFinger41' type='revolute'>
      <pose relative_to='l_wrist'>0.074 0.0309 0 1.39757 1.04064 0.06833939999999999</pose>
      <parent>l_wrist</parent>
      <child>LFinger41_link</child>
      <axis>
        <xyz>0 0 1</xyz>
        <limit>
          <lower>-10000000000000000</lower>
          <upper>10000000000000000</upper>
        </limit>
        <dynamics>
          <spring_reference>0</spring_reference>
          <spring_stiffness>0</spring_stiffness>
        </dynamics>
      </axis>
    </joint>
    <link name='LFinger41_link'>
      <pose relative_to='LFinger41'>0 0 0 0 0 0</pose>
      <inertial>
        <pose>0 0 0 0 0 0</pose>
        <mass>0.001734202288839783</mass>
        <inertia>
          <ixx>3.467813181776431e-06</ixx>
          <ixy>-3.2590475824677093e-08</ixy>
          <ixz>-1.77571604507356e-07</ixz>
          <iyy>9.0679598701961387e-06</iyy>
          <iyz>-5.0427021387489981e-08</iyz>
          <izz>9.981406591519867e-06</izz>
        </inertia>
      </inertial>
      <collision name='LFinger41_link_collision'>
        <pose>0 0 0 0 0 0</pose>
        <geometry>
          <mesh>
            <scale>0.1 0.1 0.1</scale>
            <uri>meshes/LFinger41_0.10.stl</uri>
          </mesh>
        </geometry>
        <surface>
          <contact>
            <ode/>
          </contact>
          <friction>
            <ode>
              <mu>0.5</mu>
              <mu2>0.5</mu2>
            </ode>
          </friction>
        </surface>
      </collision>
      <visual name='LFinger41_link_visual'>
        <pose>0 0 0 0 0 0</pose>
        <geometry>
          <mesh>
            <scale>0.1 0.1 0.1</scale>
            <uri>meshes/LFinger41.dae</uri>
          </mesh>
        </geometry>
      </visual>
      <gravity>true</gravity>
      <self_collide>false</self_collide>
    </link>
    <joint name='LFinger42' type='revolute'>
      <pose relative_to='LFinger41_link'>0.018 0 0 0 0 -1.0472</pose>
      <parent>LFinger41_link</parent>
      <child>LFinger42_link</child>
      <axis>
        <xyz>0 0 1</xyz>
        <limit>
          <lower>-10000000000000000</lower>
          <upper>10000000000000000</upper>
        </limit>
        <dynamics>
          <spring_reference>0</spring_reference>
          <spring_stiffness>0</spring_stiffness>
        </dynamics>
      </axis>
    </joint>
    <link name='LFinger42_link'>
      <pose relative_to='LFinger42'>0 0 0 0 0 0</pose>
      <inertial>
        <pose>0 0 0 0 0 0</pose>
        <mass>0.001734202216782887</mass>
        <inertia>
          <ixx>3.4678129025584819e-06</ixx>
          <ixy>-3.2590475824677093e-08</ixy>
          <ixz>-1.77571604507356e-07</ixz>
          <iyy>9.0679595117135181e-06</iyy>
          <iyz>-5.0427021387489981e-08</iyz>
          <izz>9.981406591519867e-06</izz>
        </inertia>
      </inertial>
      <collision name='LFinger42_link_collision'>
        <pose>0 0 0 0 0 0</pose>
        <geometry>
          <mesh>
            <scale>0.1 0.1 0.1</scale>
            <uri>meshes/LFinger42_0.10.stl</uri>
          </mesh>
        </geometry>
        <surface>
          <contact>
            <ode/>
          </contact>
          <friction>
            <ode>
              <mu>0.5</mu>
              <mu2>0.5</mu2>
            </ode>
          </friction>
        </surface>
      </collision>
      <visual name='LFinger42_link_visual'>
        <pose>0 0 0 0 0 0</pose>
        <geometry>
          <mesh>
            <scale>0.1 0.1 0.1</scale>
            <uri>meshes/LFinger42.dae</uri>
          </mesh>
        </geometry>
      </visual>
      <gravity>true</gravity>
      <self_collide>false</self_collide>
    </link>
    <joint name='LFinger43' type='revolute'>
      <pose relative_to='LFinger42_link'>0.018 0 0 0 0 -1.0472</pose>
      <parent>LFinger42_link</parent>
      <child>LFinger43_link</child>
      <axis>
        <xyz>0 0 1</xyz>
        <limit>
          <lower>-10000000000000000</lower>
          <upper>10000000000000000</upper>
        </limit>
        <dynamics>
          <spring_reference>0</spring_reference>
          <spring_stiffness>0</spring_stiffness>
        </dynamics>
      </axis>
    </joint>
    <link name='LFinger43_link'>
      <pose relative_to='LFinger43'>0 0 0 0 0 0</pose>
      <inertial>
        <pose>0 0 0 0 0 0</pose>
        <mass>0.001211966307047606</mass>
        <inertia>
          <ixx>2.092238933011463e-06</ixx>
          <ixy>-1.145741021305972e-07</ixy>
          <ixz>1.4168138791312869e-08</ixz>
          <iyy>4.0499919164935509e-06</iyy>
          <iyz>-5.70412920072251e-09</iyz>
          <izz>4.4165362986986566e-06</izz>
        </inertia>
      </inertial>
      <collision name='LFinger43_link_collision'>
        <pose>0 0 0 0 0 0</pose>
        <geometry>
          <mesh>
            <scale>0.1 0.1 0.1</scale>
            <uri>meshes/LFinger43_0.10.stl</uri>
          </mesh>
        </geometry>
        <surface>
          <contact>
            <ode/>
          </contact>
          <friction>
            <ode>
              <mu>0.5</mu>
              <mu2>0.5</mu2>
            </ode>
          </friction>
        </surface>
      </collision>
      <visual name='LFinger43_link_visual'>
        <pose>0 0 0 0 0 0</pose>
        <geometry>
          <mesh>
            <scale>0.1 0.1 0.1</scale>
            <uri>meshes/LFinger43.dae</uri>
          </mesh>
        </geometry>
      </visual>
      <gravity>true</gravity>
      <self_collide>false</self_collide>
    </link>
    <joint name='LHand' type='revolute'>
      <pose relative_to='l_wrist'>0.025 0 0 0 0 0</pose>
      <parent>l_wrist</parent>
      <child>l_gripper</child>
      <axis>
        <xyz>1 0 0</xyz>
        <limit>
          <lower>0.02</lower>
          <upper>0.97999999999999998</upper>
          <effort>0.14399999999999999</effort>
          <velocity>12.56</velocity>
        </limit>
        <dynamics>
          <spring_reference>0</spring_reference>
          <spring_stiffness>0</spring_stiffness>
        </dynamics>
      </axis>
    </joint>
    <link name='l_gripper'>
      <pose relative_to='LHand'>0 0 0 0 0 0</pose>
      <inertial>
        <pose>0 0 0 0 0 0</pose>
        <mass>0.20759187418056399</mass>
        <inertia>
          <ixx>0.01170340413343585</ixx>
          <ixy>0.00081774415090919987</ixy>
          <ixz>-0.0033215793821857898</ixz>
          <iyy>0.037840363877038402</iyy>
          <iyz>-0.00014926583294427479</iyz>
          <izz>0.040272676675503362</izz>
        </inertia>
      </inertial>
      <gravity>true</gravity>
      <self_collide>false</self_collide>
    </link>
    <joint name='LThumb1' type='revolute'>
      <pose relative_to='l_wrist'>0.0482 -0.0357 -0.0199 -1.95836 0.60626 0.5339780000000001</pose>
      <parent>l_wrist</parent>
      <child>LThumb1_link</child>
      <axis>
        <xyz>0 0 1</xyz>
        <limit>
          <lower>-10000000000000000</lower>
          <upper>10000000000000000</upper>
        </limit>
        <dynamics>
          <spring_reference>0</spring_reference>
          <spring_stiffness>0</spring_stiffness>
        </dynamics>
      </axis>
    </joint>
    <link name='LThumb1_link'>
      <pose relative_to='LThumb1'>0 0 0 0 0 0</pose>
      <inertial>
        <pose>0 0 0 0 0 0</pose>
        <mass>0.001734202297980581</mass>
        <inertia>
          <ixx>3.4678131551882408e-06</ixx>
          <ixy>-3.2590509182655968e-08</ixy>
          <ixz>-1.7757154946525151e-07</ixz>
          <iyy>9.0679602117147256e-06</iyy>
          <iyz>-5.0426946362754547e-08</iyz>
          <izz>9.981406956932862e-06</izz>
        </inertia>
      </inertial>
      <collision name='LThumb1_link_collision'>
        <pose>0 0 0 0 0 0</pose>
        <geometry>
          <mesh>
            <scale>0.1 0.1 0.1</scale>
            <uri>meshes/LThumb1_0.10.stl</uri>
          </mesh>
        </geometry>
        <surface>
          <contact>
            <ode/>
          </contact>
          <friction>
            <ode>
              <mu>0.5</mu>
              <mu2>0.5</mu2>
            </ode>
          </friction>
        </surface>
      </collision>
      <visual name='LThumb1_link_visual'>
        <pose>0 0 0 0 0 0</pose>
        <geometry>
          <mesh>
            <scale>0.1 0.1 0.1</scale>
            <uri>meshes/LThumb1.dae</uri>
          </mesh>
        </geometry>
      </visual>
      <gravity>true</gravity>
      <self_collide>false</self_collide>
    </link>
    <joint name='LThumb2' type='revolute'>
      <pose relative_to='LThumb1_link'>0.022 0 0 0 0 -1.0472</pose>
      <parent>LThumb1_link</parent>
      <child>LThumb2_link</child>
      <axis>
        <xyz>0 0 1</xyz>
        <limit>
          <lower>-10000000000000000</lower>
          <upper>10000000000000000</upper>
        </limit>
        <dynamics>
          <spring_reference>0</spring_reference>
          <spring_stiffness>0</spring_stiffness>
        </dynamics>
      </axis>
    </joint>
    <link name='LThumb2_link'>
      <pose relative_to='LThumb2'>0 0 0 0 0 0</pose>
      <inertial>
        <pose>0 0 0 0 0 0</pose>
        <mass>0.001211966381471568</mass>
        <inertia>
          <ixx>2.0922392266947092e-06</ixx>
          <ixy>-1.1457419844015849e-07</ixy>
          <ixz>1.4167922235814149e-08</ixz>
          <iyy>4.0499921605015474e-06</iyy>
          <iyz>-5.704188035340379e-09</iyz>
          <izz>4.4165365735760226e-06</izz>
        </inertia>
      </inertial>
      <collision name='LThumb2_link_collision'>
        <pose>0 0 0 0 0 0</pose>
        <geometry>
          <mesh>
            <scale>0.1 0.1 0.1</scale>
            <uri>meshes/LThumb2_0.10.stl</uri>
          </mesh>
        </geometry>
        <surface>
          <contact>
            <ode/>
          </contact>
          <friction>
            <ode>
              <mu>0.5</mu>
              <mu2>0.5</mu2>
            </ode>
          </friction>
        </surface>
      </collision>
      <visual name='LThumb2_link_visual'>
        <pose>0 0 0 0 0 0</pose>
        <geometry>
          <mesh>
            <scale>0.1 0.1 0.1</scale>
            <uri>meshes/LThumb2.dae</uri>
          </mesh>
        </geometry>
      </visual>
      <gravity>true</gravity>
      <self_collide>false</self_collide>
    </link>
    <joint name='RShoulderPitch' type='revolute'>
      <pose relative_to='torso'>-0.057 -0.14974 0.22582 0 0 0</pose>
      <parent>torso</parent>
      <child>RShoulder</child>
      <axis>
        <xyz>0 1 0</xyz>
        <limit>
          <lower>-2.0856699999999999</lower>
          <upper>2.0856699999999999</upper>
          <effort>5.4279999999999999</effort>
          <velocity>7.3399799999999997</velocity>
        </limit>
        <dynamics>
          <spring_reference>0</spring_reference>
          <spring_stiffness>0</spring_stiffness>
        </dynamics>
      </axis>
    </joint>
    <link name='RShoulder'>
      <pose relative_to='RShoulderPitch'>0 0 0 0 0 0</pose>
      <inertial>
        <pose>-7.402849999999999e-08 -7.32303e-08 -1.30517e-07 0 0 0</pose>
        <mass>0.14071507216157689</mass>
        <inertia>
          <ixx>0.0085324652949196854</ixx>
          <ixy>-1.9218712572811561e-09</ixy>
          <ixz>6.3544486676232566e-10</ixz>
          <iyy>0.0085324639364187625</iyy>
          <iyz>-2.0716583314902061e-09</iyz>
          <izz>0.01025275079353366</izz>
        </inertia>
      </inertial>
      <collision name='RShoulder_collision'>
        <pose>0 0 0 0 0 0</pose>
        <geometry>
          <mesh>
            <scale>0.1 0.1 0.1</scale>
            <uri>meshes/RShoulderPitch_0.10.stl</uri>
          </mesh>
        </geometry>
        <surface>
          <contact>
            <ode/>
          </contact>
          <friction>
            <ode>
              <mu>0.5</mu>
              <mu2>0.5</mu2>
            </ode>
          </friction>
        </surface>
      </collision>
      <visual name='RShoulder_visual'>
        <pose>0 0 0 0 0 0</pose>
        <geometry>
          <mesh>
            <scale>0.1 0.1 0.1</scale>
            <uri>meshes/RShoulderPitch.dae</uri>
          </mesh>
        </geometry>
      </visual>
      <gravity>true</gravity>
      <self_collide>false</self_collide>
    </link>
    <joint name='RShoulderRoll' type='revolute'>
      <pose relative_to='RShoulder'>0 0 0 0 0 0</pose>
      <parent>RShoulder</parent>
      <child>RBicep</child>
      <axis>
        <xyz>0 0 1</xyz>
        <limit>
          <lower>-1.5620700000000001</lower>
          <upper>-0.0087266500000000007</upper>
          <effort>2.6659999999999999</effort>
          <velocity>9.2275600000000004</velocity>
        </limit>
        <dynamics>
          <spring_reference>0</spring_reference>
          <spring_stiffness>0</spring_stiffness>
        </dynamics>
      </axis>
    </joint>
    <link name='RBicep'>
      <pose relative_to='RShoulderRoll'>0 0 0 0 0 0</pose>
      <inertial>
        <pose>0.902599 -0.162517 -0.0061116 0 0 0</pose>
        <mass>0.31370324379943892</mass>
        <inertia>
          <ixx>0.024698531239164299</ixx>
          <ixy>0.001281786483549858</ixy>
          <ixz>0.0017029391719427639</ixz>
          <iyy>0.071673513547853729</iyy>
          <iyz>6.8745322669604082e-05</iyz>
          <izz>0.067663578533357652</izz>
        </inertia>
      </inertial>
      <collision name='RBicep_collision'>
        <pose>0 0 0 0 0 0</pose>
        <geometry>
          <mesh>
            <scale>0.1 0.1 0.1</scale>
            <uri>meshes/RShoulderRoll_0.10.stl</uri>
          </mesh>
        </geometry>
        <surface>
          <contact>
            <ode/>
          </contact>
          <friction>
            <ode>
              <mu>0.5</mu>
              <mu2>0.5</mu2>
            </ode>
          </friction>
        </surface>
      </collision>
      <visual name='RBicep_visual'>
        <pose>0 0 0 0 0 0</pose>
        <geometry>
          <mesh>
            <scale>0.1 0.1 0.1</scale>
            <uri>meshes/RShoulderRoll.dae</uri>
          </mesh>
        </geometry>
      </visual>
      <gravity>true</gravity>
      <self_collide>false</self_collide>
    </link>
    <joint name='RElbowYaw' type='revolute'>
      <pose relative_to='RBicep'>0.1812 -0.015 0.00013 0 -0.1570790000000001 0</pose>
      <parent>RBicep</parent>
      <child>RElbow</child>
      <axis>
        <xyz>1 0 0</xyz>
        <limit>
          <lower>-2.0856699999999999</lower>
          <upper>2.0856699999999999</upper>
          <effort>5.4279999999999999</effort>
          <velocity>7.3399799999999997</velocity>
        </limit>
        <dynamics>
          <spring_reference>0</spring_reference>
          <spring_stiffness>0</spring_stiffness>
        </dynamics>
      </axis>
    </joint>
    <link name='RElbow'>
      <pose relative_to='RElbowYaw'>0 0 0 0 0 0</pose>
      <inertial>
        <pose>-7.34206e-08 1.48077e-09 -4.87585e-08 0 0 0</pose>
        <mass>0.07380464672624755</mass>
        <inertia>
          <ixx>0.0029965021096465139</ixx>
          <ixy>-1.038800875829926e-10</ixy>
          <ixz>-4.2002518090263304e-12</ixz>
          <iyy>0.0030276726644025741</iyy>
          <iyz>-2.9936815578853858e-10</iyz>
          <izz>0.0030276710620920628</izz>
        </inertia>
      </inertial>
      <collision name='RElbow_collision'>
        <pose>0 0 0 0 0 0</pose>
        <geometry>
          <mesh>
            <scale>0.1 0.1 0.1</scale>
            <uri>meshes/RElbowYaw_0.10.stl</uri>
          </mesh>
        </geometry>
        <surface>
          <contact>
            <ode/>
          </contact>
          <friction>
            <ode>
              <mu>0.5</mu>
              <mu2>0.5</mu2>
            </ode>
          </friction>
        </surface>
      </collision>
      <visual name='RElbow_visual'>
        <pose>0 0 0 0 0 0</pose>
        <geometry>
          <mesh>
            <scale>0.1 0.1 0.1</scale>
            <uri>meshes/RElbowYaw.dae</uri>
          </mesh>
        </geometry>
      </visual>
      <gravity>true</gravity>
      <self_collide>false</self_collide>
    </link>
    <joint name='RElbowRoll' type='revolute'>
      <pose relative_to='RElbow'>0 0 0 0 0 0</pose>
      <parent>RElbow</parent>
      <child>RForeArm</child>
      <axis>
        <xyz>0 0 1</xyz>
        <limit>
          <lower>0.0087266500000000007</lower>
          <upper>1.5620700000000001</upper>
          <effort>2.6659999999999999</effort>
          <velocity>9.2275600000000004</velocity>
        </limit>
        <dynamics>
          <spring_reference>0</spring_reference>
          <spring_stiffness>0</spring_stiffness>
        </dynamics>
      </axis>
    </joint>
    <link name='RForeArm'>
      <pose relative_to='RElbowRoll'>0 0 0 0 0 0</pose>
      <inertial>
        <pose>0.470716 -0.0367563 -0.00106886 0 0 0</pose>
        <mass>0.1332111481578373</mass>
        <inertia>
          <ixx>0.0071573638437460504</ixx>
          <ixy>-0.001127561101952054</ixy>
          <ixz>4.2730568374252407e-05</ixz>
          <iyy>0.0099149161993504712</iyy>
          <iyz>-1.767306129849456e-06</iyz>
          <izz>0.0096222934744772809</izz>
        </inertia>
      </inertial>
      <collision name='RForeArm_collision'>
        <pose>0 0 0 0 0 0</pose>
        <geometry>
          <mesh>
            <scale>0.1 0.1 0.1</scale>
            <uri>meshes/RElbowRoll_0.10.stl</uri>
          </mesh>
        </geometry>
        <surface>
          <contact>
            <ode/>
          </contact>
          <friction>
            <ode>
              <mu>0.5</mu>
              <mu2>0.5</mu2>
            </ode>
          </friction>
        </surface>
      </collision>
      <visual name='RForeArm_visual'>
        <pose>0 0 0 0 0 0</pose>
        <geometry>
          <mesh>
            <scale>0.1 0.1 0.1</scale>
            <uri>meshes/RElbowRoll.dae</uri>
          </mesh>
        </geometry>
      </visual>
      <gravity>true</gravity>
      <self_collide>false</self_collide>
    </link>
    <joint name='RWristYaw' type='revolute'>
      <pose relative_to='RForeArm'>0.15 0 0 0 0 0</pose>
      <parent>RForeArm</parent>
      <child>r_wrist</child>
      <axis>
        <xyz>1 0 0</xyz>
        <limit>
          <lower>-1.8238700000000001</lower>
          <upper>1.8238700000000001</upper>
          <effort>0.2014</effort>
          <velocity>17.383500000000002</velocity>
        </limit>
        <dynamics>
          <spring_reference>0</spring_reference>
          <spring_stiffness>0</spring_stiffness>
        </dynamics>
      </axis>
    </joint>
    <link name='r_wrist'>
      <pose relative_to='RWristYaw'>0 0 0 0 0 0</pose>
      <inertial>
        <pose>0.110379 0.0272187 0.0250071 0 0 0</pose>
        <mass>0.20759187418056391</mass>
        <inertia>
          <ixx>0.01170340413343585</ixx>
          <ixy>-0.00081774415090919966</ixy>
          <ixz>-0.0033215793821857911</ixz>
          <iyy>0.037840363877038402</iyy>
          <iyz>0.00014926583294427479</iyz>
          <izz>0.040272676675503362</izz>
        </inertia>
      </inertial>
      <collision name='r_wrist_collision'>
        <pose>0 0 0 0 0 0</pose>
        <geometry>
          <mesh>
            <scale>0.1 0.1 0.1</scale>
            <uri>meshes/RWristYaw_0.10.stl</uri>
          </mesh>
        </geometry>
        <surface>
          <contact>
            <ode/>
          </contact>
          <friction>
            <ode>
              <mu>0.5</mu>
              <mu2>0.5</mu2>
            </ode>
          </friction>
        </surface>
      </collision>
      <visual name='r_wrist_visual'>
        <pose>0 0 0 0 0 0</pose>
        <geometry>
          <mesh>
            <scale>0.1 0.1 0.1</scale>
            <uri>meshes/RWristYaw.dae</uri>
          </mesh>
        </geometry>
      </visual>
      <gravity>true</gravity>
      <self_collide>false</self_collide>
    </link>
    <joint name='RFinger11' type='revolute'>
      <pose relative_to='r_wrist'>0.08210000000000001 0.0268 0.004 1.39757 1.04064 0.03343349999999972</pose>
      <parent>r_wrist</parent>
      <child>RFinger11_link</child>
      <axis>
        <xyz>0 0 1</xyz>
        <limit>
          <lower>-10000000000000000</lower>
          <upper>10000000000000000</upper>
        </limit>
        <dynamics>
          <spring_reference>0</spring_reference>
          <spring_stiffness>0</spring_stiffness>
        </dynamics>
      </axis>
    </joint>
    <link name='RFinger11_link'>
      <pose relative_to='RFinger11'>0 0 0 0 0 0</pose>
      <inertial>
        <pose>0 0 0 0 0 0</pose>
        <mass>0.001734202261175038</mass>
        <inertia>
          <ixx>3.4678130376738111e-06</ixx>
          <ixy>-3.2590510087003849e-08</ixy>
          <ixz>-1.775716101749067e-07</ixz>
          <iyy>9.0679597833730339e-06</iyy>
          <iyz>-5.0426978117144053e-08</iyz>
          <izz>9.9814064894198014e-06</izz>
        </inertia>
      </inertial>
      <collision name='RFinger11_link_collision'>
        <pose>0 0 0 0 0 0</pose>
        <geometry>
          <mesh>
            <scale>0.1 0.1 0.1</scale>
            <uri>meshes/RFinger11_0.10.stl</uri>
          </mesh>
        </geometry>
        <surface>
          <contact>
            <ode/>
          </contact>
          <friction>
            <ode>
              <mu>0.5</mu>
              <mu2>0.5</mu2>
            </ode>
          </friction>
        </surface>
      </collision>
      <visual name='RFinger11_link_visual'>
        <pose>0 0 0 0 0 0</pose>
        <geometry>
          <mesh>
            <scale>0.1 0.1 0.1</scale>
            <uri>meshes/RFinger11.dae</uri>
          </mesh>
        </geometry>
      </visual>
      <gravity>true</gravity>
      <self_collide>false</self_collide>
    </link>
    <joint name='RFinger12' type='revolute'>
      <pose relative_to='RFinger11_link'>0.018 0 0 0 0 -1.0472</pose>
      <parent>RFinger11_link</parent>
      <child>RFinger12_link</child>
      <axis>
        <xyz>0 0 1</xyz>
        <limit>
          <lower>-10000000000000000</lower>
          <upper>10000000000000000</upper>
        </limit>
        <dynamics>
          <spring_reference>0</spring_reference>
          <spring_stiffness>0</spring_stiffness>
        </dynamics>
      </axis>
    </joint>
    <link name='RFinger12_link'>
      <pose relative_to='RFinger12'>0 0 0 0 0 0</pose>
      <inertial>
        <pose>0 0 0 0 0 0</pose>
        <mass>0.001734202280194698</mass>
        <inertia>
          <ixx>3.4678131132210499e-06</ixx>
          <ixy>-3.2590542520134938e-08</ixy>
          <ixz>-1.7757159744336221e-07</ixz>
          <iyy>9.0679598408827441e-06</iyy>
          <iyz>-5.0426962301906762e-08</iyz>
          <izz>9.9814065117924809e-06</izz>
        </inertia>
      </inertial>
      <collision name='RFinger12_link_collision'>
        <pose>0 0 0 0 0 0</pose>
        <geometry>
          <mesh>
            <scale>0.1 0.1 0.1</scale>
            <uri>meshes/RFinger12_0.10.stl</uri>
          </mesh>
        </geometry>
        <surface>
          <contact>
            <ode/>
          </contact>
          <friction>
            <ode>
              <mu>0.5</mu>
              <mu2>0.5</mu2>
            </ode>
          </friction>
        </surface>
      </collision>
      <visual name='RFinger12_link_visual'>
        <pose>0 0 0 0 0 0</pose>
        <geometry>
          <mesh>
            <scale>0.1 0.1 0.1</scale>
            <uri>meshes/RFinger12.dae</uri>
          </mesh>
        </geometry>
      </visual>
      <gravity>true</gravity>
      <self_collide>false</self_collide>
    </link>
    <joint name='RFinger13' type='revolute'>
      <pose relative_to='RFinger12_link'>0.018 0 0 0 0 -1.0472</pose>
      <parent>RFinger12_link</parent>
      <child>RFinger13_link</child>
      <axis>
        <xyz>0 0 1</xyz>
        <limit>
          <lower>-10000000000000000</lower>
          <upper>10000000000000000</upper>
        </limit>
        <dynamics>
          <spring_reference>0</spring_reference>
          <spring_stiffness>0</spring_stiffness>
        </dynamics>
      </axis>
    </joint>
    <link name='RFinger13_link'>
      <pose relative_to='RFinger13'>0 0 0 0 0 0</pose>
      <inertial>
        <pose>0 0 0 0 0 0</pose>
        <mass>0.001211966381471568</mass>
        <inertia>
          <ixx>2.0922392266947092e-06</ixx>
          <ixy>-1.1457419844015849e-07</ixy>
          <ixz>1.4167922235814149e-08</ixz>
          <iyy>4.0499921605015474e-06</iyy>
          <iyz>-5.704188035340379e-09</iyz>
          <izz>4.4165365735760226e-06</izz>
        </inertia>
      </inertial>
      <collision name='RFinger13_link_collision'>
        <pose>0 0 0 0 0 0</pose>
        <geometry>
          <mesh>
            <scale>0.1 0.1 0.1</scale>
            <uri>meshes/RFinger13_0.10.stl</uri>
          </mesh>
        </geometry>
        <surface>
          <contact>
            <ode/>
          </contact>
          <friction>
            <ode>
              <mu>0.5</mu>
              <mu2>0.5</mu2>
            </ode>
          </friction>
        </surface>
      </collision>
      <visual name='RFinger13_link_visual'>
        <pose>0 0 0 0 0 0</pose>
        <geometry>
          <mesh>
            <scale>0.1 0.1 0.1</scale>
            <uri>meshes/RFinger13.dae</uri>
          </mesh>
        </geometry>
      </visual>
      <gravity>true</gravity>
      <self_collide>false</self_collide>
    </link>
    <joint name='RFinger21' type='revolute'>
      <pose relative_to='r_wrist'>0.0873 0.0073 0.006 1.5708 1.0472 0.06108600000000022</pose>
      <parent>r_wrist</parent>
      <child>RFinger21_link</child>
      <axis>
        <xyz>0 0 1</xyz>
        <limit>
          <lower>-10000000000000000</lower>
          <upper>10000000000000000</upper>
        </limit>
        <dynamics>
          <spring_reference>0</spring_reference>
          <spring_stiffness>0</spring_stiffness>
        </dynamics>
      </axis>
    </joint>
    <link name='RFinger21_link'>
      <pose relative_to='RFinger21'>0 0 0 0 0 0</pose>
      <inertial>
        <pose>0 0 0 0 0 0</pose>
        <mass>0.00173420224806078</mass>
        <inertia>
          <ixx>3.4678129900481898e-06</ixx>
          <ixy>-3.2590624281102048e-08</ixy>
          <ixz>-1.7757153533455459e-07</ixz>
          <iyy>9.0679598767719028e-06</iyy>
          <iyz>-5.0426968074891452e-08</iyz>
          <izz>9.9814065131534392e-06</izz>
        </inertia>
      </inertial>
      <collision name='RFinger21_link_collision'>
        <pose>0 0 0 0 0 0</pose>
        <geometry>
          <mesh>
            <scale>0.1 0.1 0.1</scale>
            <uri>meshes/RFinger21_0.10.stl</uri>
          </mesh>
        </geometry>
        <surface>
          <contact>
            <ode/>
          </contact>
          <friction>
            <ode>
              <mu>0.5</mu>
              <mu2>0.5</mu2>
            </ode>
          </friction>
        </surface>
      </collision>
      <visual name='RFinger21_link_visual'>
        <pose>0 0 0 0 0 0</pose>
        <geometry>
          <mesh>
            <scale>0.1 0.1 0.1</scale>
            <uri>meshes/RFinger21.dae</uri>
          </mesh>
        </geometry>
      </visual>
      <gravity>true</gravity>
      <self_collide>false</self_collide>
    </link>
    <joint name='RFinger22' type='revolute'>
      <pose relative_to='RFinger21_link'>0.018 0 0 0 0 -1.0472</pose>
      <parent>RFinger21_link</parent>
      <child>RFinger22_link</child>
      <axis>
        <xyz>0 0 1</xyz>
        <limit>
          <lower>-10000000000000000</lower>
          <upper>10000000000000000</upper>
        </limit>
        <dynamics>
          <spring_reference>0</spring_reference>
          <spring_stiffness>0</spring_stiffness>
        </dynamics>
      </axis>
    </joint>
    <link name='RFinger22_link'>
      <pose relative_to='RFinger22'>0 0 0 0 0 0</pose>
      <inertial>
        <pose>0 0 0 0 0 0</pose>
        <mass>0.001734202428057582</mass>
        <inertia>
          <ixx>3.4678136128088389e-06</ixx>
          <ixy>-3.2591429893149237e-08</ixy>
          <ixz>-1.775718802040381e-07</ixz>
          <iyy>9.0679621450442563e-06</iyy>
          <iyz>-5.0427098486528039e-08</iyz>
          <izz>9.9814092737652281e-06</izz>
        </inertia>
      </inertial>
      <collision name='RFinger22_link_collision'>
        <pose>0 0 0 0 0 0</pose>
        <geometry>
          <mesh>
            <scale>0.1 0.1 0.1</scale>
            <uri>meshes/RFinger22_0.10.stl</uri>
          </mesh>
        </geometry>
        <surface>
          <contact>
            <ode/>
          </contact>
          <friction>
            <ode>
              <mu>0.5</mu>
              <mu2>0.5</mu2>
            </ode>
          </friction>
        </surface>
      </collision>
      <visual name='RFinger22_link_visual'>
        <pose>0 0 0 0 0 0</pose>
        <geometry>
          <mesh>
            <scale>0.1 0.1 0.1</scale>
            <uri>meshes/RFinger22.dae</uri>
          </mesh>
        </geometry>
      </visual>
      <gravity>true</gravity>
      <self_collide>false</self_collide>
    </link>
    <joint name='RFinger23' type='revolute'>
      <pose relative_to='RFinger22_link'>0.018 0 0 0 0 -1.0472</pose>
      <parent>RFinger22_link</parent>
      <child>RFinger23_link</child>
      <axis>
        <xyz>0 0 1</xyz>
        <limit>
          <lower>-10000000000000000</lower>
          <upper>10000000000000000</upper>
        </limit>
        <dynamics>
          <spring_reference>0</spring_reference>
          <spring_stiffness>0</spring_stiffness>
        </dynamics>
      </axis>
    </joint>
    <link name='RFinger23_link'>
      <pose relative_to='RFinger23'>0 0 0 0 0 0</pose>
      <inertial>
        <pose>0 0 0 0 0 0</pose>
        <mass>0.001211966369925541</mass>
        <inertia>
          <ixx>2.092239047891544e-06</ixx>
          <ixy>-1.145742296959502e-07</ixy>
          <ixz>1.41678106632915e-08</ixz>
          <iyy>4.0499924049460343e-06</iyy>
          <iyz>-5.704156613549065e-09</iyz>
          <izz>4.4165365528987541e-06</izz>
        </inertia>
      </inertial>
      <collision name='RFinger23_link_collision'>
        <pose>0 0 0 0 0 0</pose>
        <geometry>
          <mesh>
            <scale>0.1 0.1 0.1</scale>
            <uri>meshes/RFinger23_0.10.stl</uri>
          </mesh>
        </geometry>
        <surface>
          <contact>
            <ode/>
          </contact>
          <friction>
            <ode>
              <mu>0.5</mu>
              <mu2>0.5</mu2>
            </ode>
          </friction>
        </surface>
      </collision>
      <visual name='RFinger23_link_visual'>
        <pose>0 0 0 0 0 0</pose>
        <geometry>
          <mesh>
            <scale>0.1 0.1 0.1</scale>
            <uri>meshes/RFinger23.dae</uri>
          </mesh>
        </geometry>
      </visual>
      <gravity>true</gravity>
      <self_collide>false</self_collide>
    </link>
    <joint name='RFinger31' type='revolute'>
      <pose relative_to='r_wrist'>0.0833 -0.0123 0.004 1.67523 1.04483 0.02931599999999992</pose>
      <parent>r_wrist</parent>
      <child>RFinger31_link</child>
      <axis>
        <xyz>0 0 1</xyz>
        <limit>
          <lower>-10000000000000000</lower>
          <upper>10000000000000000</upper>
        </limit>
        <dynamics>
          <spring_reference>0</spring_reference>
          <spring_stiffness>0</spring_stiffness>
        </dynamics>
      </axis>
    </joint>
    <link name='RFinger31_link'>
      <pose relative_to='RFinger31'>0 0 0 0 0 0</pose>
      <inertial>
        <pose>0 0 0 0 0 0</pose>
        <mass>0.0017342022712585441</mass>
        <inertia>
          <ixx>3.467813135465312e-06</ixx>
          <ixy>-3.2590501458069509e-08</ixy>
          <ixz>-1.775715550954204e-07</ixz>
          <iyy>9.0679596157997931e-06</iyy>
          <iyz>-5.0427022839883737e-08</iyz>
          <izz>9.9814063267372237e-06</izz>
        </inertia>
      </inertial>
      <collision name='RFinger31_link_collision'>
        <pose>0 0 0 0 0 0</pose>
        <geometry>
          <mesh>
            <scale>0.1 0.1 0.1</scale>
            <uri>meshes/RFinger31_0.10.stl</uri>
          </mesh>
        </geometry>
        <surface>
          <contact>
            <ode/>
          </contact>
          <friction>
            <ode>
              <mu>0.5</mu>
              <mu2>0.5</mu2>
            </ode>
          </friction>
        </surface>
      </collision>
      <visual name='RFinger31_link_visual'>
        <pose>0 0 0 0 0 0</pose>
        <geometry>
          <mesh>
            <scale>0.1 0.1 0.1</scale>
            <uri>meshes/RFinger31.dae</uri>
          </mesh>
        </geometry>
      </visual>
      <gravity>true</gravity>
      <self_collide>false</self_collide>
    </link>
    <joint name='RFinger32' type='revolute'>
      <pose relative_to='RFinger31_link'>0.018 0 0 0 0 -1.0472</pose>
      <parent>RFinger31_link</parent>
      <child>RFinger32_link</child>
      <axis>
        <xyz>0 0 1</xyz>
        <limit>
          <lower>-10000000000000000</lower>
          <upper>10000000000000000</upper>
        </limit>
        <dynamics>
          <spring_reference>0</spring_reference>
          <spring_stiffness>0</spring_stiffness>
        </dynamics>
      </axis>
    </joint>
    <link name='RFinger32_link'>
      <pose relative_to='RFinger32'>0 0 0 0 0 0</pose>
      <inertial>
        <pose>0 0 0 0 0 0</pose>
        <mass>0.001734202223583049</mass>
        <inertia>
          <ixx>3.467812920370958e-06</ixx>
          <ixy>-3.259059292999676e-08</ixy>
          <ixz>-1.7757164855882871e-07</ixz>
          <iyy>9.067959555576335e-06</iyy>
          <iyz>-5.0426979983568877e-08</iyz>
          <izz>9.9814061853856547e-06</izz>
        </inertia>
      </inertial>
      <collision name='RFinger32_link_collision'>
        <pose>0 0 0 0 0 0</pose>
        <geometry>
          <mesh>
            <scale>0.1 0.1 0.1</scale>
            <uri>meshes/RFinger32_0.10.stl</uri>
          </mesh>
        </geometry>
        <surface>
          <contact>
            <ode/>
          </contact>
          <friction>
            <ode>
              <mu>0.5</mu>
              <mu2>0.5</mu2>
            </ode>
          </friction>
        </surface>
      </collision>
      <visual name='RFinger32_link_visual'>
        <pose>0 0 0 0 0 0</pose>
        <geometry>
          <mesh>
            <scale>0.1 0.1 0.1</scale>
            <uri>meshes/RFinger32.dae</uri>
          </mesh>
        </geometry>
      </visual>
      <gravity>true</gravity>
      <self_collide>false</self_collide>
    </link>
    <joint name='RFinger33' type='revolute'>
      <pose relative_to='RFinger32_link'>0.018 0 0 0 0 -1.0472</pose>
      <parent>RFinger32_link</parent>
      <child>RFinger33_link</child>
      <axis>
        <xyz>0 0 1</xyz>
        <limit>
          <lower>-10000000000000000</lower>
          <upper>10000000000000000</upper>
        </limit>
        <dynamics>
          <spring_reference>0</spring_reference>
          <spring_stiffness>0</spring_stiffness>
        </dynamics>
      </axis>
    </joint>
    <link name='RFinger33_link'>
      <pose relative_to='RFinger33'>0 0 0 0 0 0</pose>
      <inertial>
        <pose>0 0 0 0 0 0</pose>
        <mass>0.0012119665608007831</mass>
        <inertia>
          <ixx>2.0922397962844701e-06</ixx>
          <ixy>-1.1457416792102811e-07</ixy>
          <ixz>1.4168110404002699e-08</ixz>
          <iyy>4.0499929966690558e-06</iyy>
          <iyz>-5.7041902027368457e-09</iyz>
          <izz>4.4165371343443801e-06</izz>
        </inertia>
      </inertial>
      <collision name='RFinger33_link_collision'>
        <pose>0 0 0 0 0 0</pose>
        <geometry>
          <mesh>
            <scale>0.1 0.1 0.1</scale>
            <uri>meshes/RFinger33_0.10.stl</uri>
          </mesh>
        </geometry>
        <surface>
          <contact>
            <ode/>
          </contact>
          <friction>
            <ode>
              <mu>0.5</mu>
              <mu2>0.5</mu2>
            </ode>
          </friction>
        </surface>
      </collision>
      <visual name='RFinger33_link_visual'>
        <pose>0 0 0 0 0 0</pose>
        <geometry>
          <mesh>
            <scale>0.1 0.1 0.1</scale>
            <uri>meshes/RFinger33.dae</uri>
          </mesh>
        </geometry>
      </visual>
      <gravity>true</gravity>
      <self_collide>false</self_collide>
    </link>
    <joint name='RFinger41' type='revolute'>
      <pose relative_to='r_wrist'>0.074 -0.0309 0 1.744019999999999 1.04064 -0.06833940000000031</pose>
      <parent>r_wrist</parent>
      <child>RFinger41_link</child>
      <axis>
        <xyz>0 0 1</xyz>
        <limit>
          <lower>-10000000000000000</lower>
          <upper>10000000000000000</upper>
        </limit>
        <dynamics>
          <spring_reference>0</spring_reference>
          <spring_stiffness>0</spring_stiffness>
        </dynamics>
      </axis>
    </joint>
    <link name='RFinger41_link'>
      <pose relative_to='RFinger41'>0 0 0 0 0 0</pose>
      <inertial>
        <pose>0 0 0 0 0 0</pose>
        <mass>0.001734202288839783</mass>
        <inertia>
          <ixx>3.467813181776431e-06</ixx>
          <ixy>-3.2590475824677093e-08</ixy>
          <ixz>-1.77571604507356e-07</ixz>
          <iyy>9.0679598701961387e-06</iyy>
          <iyz>-5.0427021387489981e-08</iyz>
          <izz>9.981406591519867e-06</izz>
        </inertia>
      </inertial>
      <collision name='RFinger41_link_collision'>
        <pose>0 0 0 0 0 0</pose>
        <geometry>
          <mesh>
            <scale>0.1 0.1 0.1</scale>
            <uri>meshes/RFinger41_0.10.stl</uri>
          </mesh>
        </geometry>
        <surface>
          <contact>
            <ode/>
          </contact>
          <friction>
            <ode>
              <mu>0.5</mu>
              <mu2>0.5</mu2>
            </ode>
          </friction>
        </surface>
      </collision>
      <visual name='RFinger41_link_visual'>
        <pose>0 0 0 0 0 0</pose>
        <geometry>
          <mesh>
            <scale>0.1 0.1 0.1</scale>
            <uri>meshes/RFinger41.dae</uri>
          </mesh>
        </geometry>
      </visual>
      <gravity>true</gravity>
      <self_collide>false</self_collide>
    </link>
    <joint name='RFinger42' type='revolute'>
      <pose relative_to='RFinger41_link'>0.018 0 0 0 0 -1.0472</pose>
      <parent>RFinger41_link</parent>
      <child>RFinger42_link</child>
      <axis>
        <xyz>0 0 1</xyz>
        <limit>
          <lower>-10000000000000000</lower>
          <upper>10000000000000000</upper>
        </limit>
        <dynamics>
          <spring_reference>0</spring_reference>
          <spring_stiffness>0</spring_stiffness>
        </dynamics>
      </axis>
    </joint>
    <link name='RFinger42_link'>
      <pose relative_to='RFinger42'>0 0 0 0 0 0</pose>
      <inertial>
        <pose>0 0 0 0 0 0</pose>
        <mass>0.001734202216782887</mass>
        <inertia>
          <ixx>3.4678129025584819e-06</ixx>
          <ixy>-3.2590475824677093e-08</ixy>
          <ixz>-1.77571604507356e-07</ixz>
          <iyy>9.0679595117135181e-06</iyy>
          <iyz>-5.0427021387489981e-08</iyz>
          <izz>9.981406591519867e-06</izz>
        </inertia>
      </inertial>
      <collision name='RFinger42_link_collision'>
        <pose>0 0 0 0 0 0</pose>
        <geometry>
          <mesh>
            <scale>0.1 0.1 0.1</scale>
            <uri>meshes/RFinger42_0.10.stl</uri>
          </mesh>
        </geometry>
        <surface>
          <contact>
            <ode/>
          </contact>
          <friction>
            <ode>
              <mu>0.5</mu>
              <mu2>0.5</mu2>
            </ode>
          </friction>
        </surface>
      </collision>
      <visual name='RFinger42_link_visual'>
        <pose>0 0 0 0 0 0</pose>
        <geometry>
          <mesh>
            <scale>0.1 0.1 0.1</scale>
            <uri>meshes/RFinger42.dae</uri>
          </mesh>
        </geometry>
      </visual>
      <gravity>true</gravity>
      <self_collide>false</self_collide>
    </link>
    <joint name='RFinger43' type='revolute'>
      <pose relative_to='RFinger42_link'>0.018 0 0 0 0 -1.0472</pose>
      <parent>RFinger42_link</parent>
      <child>RFinger43_link</child>
      <axis>
        <xyz>0 0 1</xyz>
        <limit>
          <lower>-10000000000000000</lower>
          <upper>10000000000000000</upper>
        </limit>
        <dynamics>
          <spring_reference>0</spring_reference>
          <spring_stiffness>0</spring_stiffness>
        </dynamics>
      </axis>
    </joint>
    <link name='RFinger43_link'>
      <pose relative_to='RFinger43'>0 0 0 0 0 0</pose>
      <inertial>
        <pose>0 0 0 0 0 0</pose>
        <mass>0.001211966307047606</mass>
        <inertia>
          <ixx>2.092238933011463e-06</ixx>
          <ixy>-1.145741021305972e-07</ixy>
          <ixz>1.4168138791312869e-08</ixz>
          <iyy>4.0499919164935509e-06</iyy>
          <iyz>-5.70412920072251e-09</iyz>
          <izz>4.4165362986986566e-06</izz>
        </inertia>
      </inertial>
      <collision name='RFinger43_link_collision'>
        <pose>0 0 0 0 0 0</pose>
        <geometry>
          <mesh>
            <scale>0.1 0.1 0.1</scale>
            <uri>meshes/RFinger43_0.10.stl</uri>
          </mesh>
        </geometry>
        <surface>
          <contact>
            <ode/>
          </contact>
          <friction>
            <ode>
              <mu>0.5</mu>
              <mu2>0.5</mu2>
            </ode>
          </friction>
        </surface>
      </collision>
      <visual name='RFinger43_link_visual'>
        <pose>0 0 0 0 0 0</pose>
        <geometry>
          <mesh>
            <scale>0.1 0.1 0.1</scale>
            <uri>meshes/RFinger43.dae</uri>
          </mesh>
        </geometry>
      </visual>
      <gravity>true</gravity>
      <self_collide>false</self_collide>
    </link>
    <joint name='RHand' type='revolute'>
      <pose relative_to='r_wrist'>0.025 0 0 0 0 0</pose>
      <parent>r_wrist</parent>
      <child>r_gripper</child>
      <axis>
        <xyz>1 0 0</xyz>
        <limit>
          <lower>0.02</lower>
          <upper>0.97999999999999998</upper>
          <effort>0.14399999999999999</effort>
          <velocity>12.56</velocity>
        </limit>
        <dynamics>
          <spring_reference>0</spring_reference>
          <spring_stiffness>0</spring_stiffness>
        </dynamics>
      </axis>
    </joint>
    <link name='r_gripper'>
      <pose relative_to='RHand'>0 0 0 0 0 0</pose>
      <inertial>
        <pose>0 0 0 0 0 0</pose>
        <mass>0.20759187418056391</mass>
        <inertia>
          <ixx>0.01170340413343585</ixx>
          <ixy>-0.00081774415090919966</ixy>
          <ixz>-0.0033215793821857911</ixz>
          <iyy>0.037840363877038402</iyy>
          <iyz>0.00014926583294427479</iyz>
          <izz>0.040272676675503362</izz>
        </inertia>
      </inertial>
      <gravity>true</gravity>
      <self_collide>false</self_collide>
    </link>
    <joint name='RThumb1' type='revolute'>
      <pose relative_to='r_wrist'>0.0482 0.0357 -0.0199 -1.18323 0.6062599999999999 -0.5339780000000001</pose>
      <parent>r_wrist</parent>
      <child>RThumb1_link</child>
      <axis>
        <xyz>0 0 1</xyz>
        <limit>
          <lower>-10000000000000000</lower>
          <upper>10000000000000000</upper>
        </limit>
        <dynamics>
          <spring_reference>0</spring_reference>
          <spring_stiffness>0</spring_stiffness>
        </dynamics>
      </axis>
    </joint>
    <link name='RThumb1_link'>
      <pose relative_to='RThumb1'>0 0 0 0 0 0</pose>
      <inertial>
        <pose>0 0 0 0 0 0</pose>
        <mass>0.001734202297980581</mass>
        <inertia>
          <ixx>3.4678131551882408e-06</ixx>
          <ixy>-3.2590509182655968e-08</ixy>
          <ixz>-1.7757154946525151e-07</ixz>
          <iyy>9.0679602117147256e-06</iyy>
          <iyz>-5.0426946362754547e-08</iyz>
          <izz>9.981406956932862e-06</izz>
        </inertia>
      </inertial>
      <collision name='RThumb1_link_collision'>
        <pose>0 0 0 0 0 0</pose>
        <geometry>
          <mesh>
            <scale>0.1 0.1 0.1</scale>
            <uri>meshes/RThumb1_0.10.stl</uri>
          </mesh>
        </geometry>
        <surface>
          <contact>
            <ode/>
          </contact>
          <friction>
            <ode>
              <mu>0.5</mu>
              <mu2>0.5</mu2>
            </ode>
          </friction>
        </surface>
      </collision>
      <visual name='RThumb1_link_visual'>
        <pose>0 0 0 0 0 0</pose>
        <geometry>
          <mesh>
            <scale>0.1 0.1 0.1</scale>
            <uri>meshes/RThumb1.dae</uri>
          </mesh>
        </geometry>
      </visual>
      <gravity>true</gravity>
      <self_collide>false</self_collide>
    </link>
    <joint name='RThumb2' type='revolute'>
      <pose relative_to='RThumb1_link'>0.022 0 0 0 0 -1.0472</pose>
      <parent>RThumb1_link</parent>
      <child>RThumb2_link</child>
      <axis>
        <xyz>0 0 1</xyz>
        <limit>
          <lower>-10000000000000000</lower>
          <upper>10000000000000000</upper>
        </limit>
        <dynamics>
          <spring_reference>0</spring_reference>
          <spring_stiffness>0</spring_stiffness>
        </dynamics>
      </axis>
    </joint>
    <link name='RThumb2_link'>
      <pose relative_to='RThumb2'>0 0 0 0 0 0</pose>
      <inertial>
        <pose>0 0 0 0 0 0</pose>
        <mass>0.001211966381471568</mass>
        <inertia>
          <ixx>2.0922392266947092e-06</ixx>
          <ixy>-1.1457419844015849e-07</ixy>
          <ixz>1.4167922235814149e-08</ixz>
          <iyy>4.0499921605015474e-06</iyy>
          <iyz>-5.704188035340379e-09</iyz>
          <izz>4.4165365735760226e-06</izz>
        </inertia>
      </inertial>
      <collision name='RThumb2_link_collision'>
        <pose>0 0 0 0 0 0</pose>
        <geometry>
          <mesh>
            <scale>0.1 0.1 0.1</scale>
            <uri>meshes/RThumb2_0.10.stl</uri>
          </mesh>
        </geometry>
        <surface>
          <contact>
            <ode/>
          </contact>
          <friction>
            <ode>
              <mu>0.5</mu>
              <mu2>0.5</mu2>
            </ode>
          </friction>
        </surface>
      </collision>
      <visual name='RThumb2_link_visual'>
        <pose>0 0 0 0 0 0</pose>
        <geometry>
          <mesh>
            <scale>0.1 0.1 0.1</scale>
            <uri>meshes/RThumb2.dae</uri>
          </mesh>
        </geometry>
      </visual>
      <gravity>true</gravity>
      <self_collide>false</self_collide>
    </link>
    <joint name='WheelB' type='revolute'>
      <pose relative_to='base_link'>-0.17 0 0.07000000000000001 0 0 -3.14159</pose>
      <parent>base_link</parent>
      <child>WheelB_link</child>
      <axis>
        <xyz>1 0 0</xyz>
        <limit>
          <effort>3.25</effort>
          <velocity>6.2831900000000003</velocity>
          <lower>-10000000000000000</lower>
          <upper>10000000000000000</upper>
        </limit>
        <dynamics>
          <spring_reference>0</spring_reference>
          <spring_stiffness>0</spring_stiffness>
        </dynamics>
      </axis>
    </joint>
    <link name='WheelB_link'>
      <pose relative_to='WheelB'>0 0 0 0 0 0</pose>
      <inertial>
        <pose>1.19122e-06 -8.10876e-08 1.02822e-07 0 0 0</pose>
        <mass>0.75756902663051162</mass>
        <inertia>
          <ixx>0.14666764930611681</ixx>
          <ixy>2.1646351782621929e-09</ixy>
          <ixz>-1.604289224924931e-08</ixz>
          <iyy>0.1454623748429566</iyy>
          <iyz>9.6864198208542656e-10</iyz>
          <izz>0.1466676359065566</izz>
        </inertia>
      </inertial>
      <collision name='WheelB_link_collision'>
        <pose>0 0 0 0 0 0</pose>
        <geometry>
          <mesh>
            <scale>0.1 0.1 0.1</scale>
            <uri>meshes/WheelB_0.10.stl</uri>
          </mesh>
        </geometry>
        <surface>
          <contact>
            <ode>
              <kp>10000000</kp>
              <kd>1</kd>
              <min_depth>0.0030000000000000001</min_depth>
            </ode>
          </contact>
          <friction>
            <ode>
              <mu>0.5</mu>
              <mu2>0.5</mu2>
              <fdir1>1 0 0</fdir1>
            </ode>
          </friction>
        </surface>
      </collision>
      <visual name='WheelB_link_visual'>
        <pose>0 0 0 0 0 0</pose>
        <geometry>
          <mesh>
            <scale>0.1 0.1 0.1</scale>
            <uri>meshes/WheelB.dae</uri>
          </mesh>
        </geometry>
      </visual>
      <gravity>true</gravity>
    </link>
    <joint name='WheelFL' type='revolute'>
      <pose relative_to='base_link'>0.09 0.155 0.07000000000000001 0 0 1.07517</pose>
      <parent>base_link</parent>
      <child>WheelFL_link</child>
      <axis>
        <xyz>1 0 0</xyz>
        <limit>
          <effort>3.25</effort>
          <velocity>6.2831900000000003</velocity>
          <lower>-10000000000000000</lower>
          <upper>10000000000000000</upper>
        </limit>
        <dynamics>
          <spring_reference>0</spring_reference>
          <spring_stiffness>0</spring_stiffness>
        </dynamics>
      </axis>
    </joint>
    <link name='WheelFL_link'>
      <pose relative_to='WheelFL'>0 0 0 0 0 0</pose>
      <inertial>
        <pose>-6.000450000000001e-07 6.99637e-07 9.85261e-08 0 0 0</pose>
        <mass>0.75756903791548669</mass>
        <inertia>
          <ixx>0.1466676495397822</ixx>
          <ixy>1.3894893658228e-09</ixy>
          <ixz>-1.8477421648222889e-08</ixz>
          <iyy>0.14546237703524981</iyy>
          <iyz>-1.6825643126483951e-10</iyz>
          <izz>0.1466676444244662</izz>
        </inertia>
      </inertial>
      <collision name='WheelFL_link_collision'>
        <pose>0 0 0 0 0 0</pose>
        <geometry>
          <mesh>
            <scale>0.1 0.1 0.1</scale>
            <uri>meshes/WheelFL_0.10.stl</uri>
          </mesh>
        </geometry>
        <surface>
          <contact>
            <ode>
              <kp>10000000</kp>
              <kd>1</kd>
              <min_depth>0.0030000000000000001</min_depth>
            </ode>
          </contact>
          <friction>
            <ode>
              <mu>1</mu>
              <mu2>0</mu2>
              <fdir1>1 0 0</fdir1>
            </ode>
          </friction>
        </surface>
      </collision>
      <visual name='WheelFL_link_visual'>
        <pose>0 0 0 0 0 0</pose>
        <geometry>
          <mesh>
            <scale>0.1 0.1 0.1</scale>
            <uri>meshes/WheelFL.dae</uri>
          </mesh>
        </geometry>
      </visual>
      <gravity>true</gravity>
    </link>
    <joint name='WheelFR' type='revolute'>
      <pose relative_to='base_link'>0.09 -0.155 0.07000000000000001 0 0 -1.07517</pose>
      <parent>base_link</parent>
      <child>WheelFR_link</child>
      <axis>
        <xyz>1 0 0</xyz>
        <limit>
          <effort>3.25</effort>
          <velocity>6.2831900000000003</velocity>
          <lower>-10000000000000000</lower>
          <upper>10000000000000000</upper>
        </limit>
        <dynamics>
          <spring_reference>0</spring_reference>
          <spring_stiffness>0</spring_stiffness>
        </dynamics>
      </axis>
    </joint>
    <link name='WheelFR_link'>
      <pose relative_to='WheelFR'>0 0 0 0 0 0</pose>
      <inertial>
        <pose>1.47446e-07 -8.33076e-07 9.57624e-08 0 0 0</pose>
        <mass>0.75756900450011</mass>
        <inertia>
          <ixx>0.14666763705575159</ixx>
          <ixy>-1.2974614176969169e-09</ixy>
          <ixz>-1.745944386185611e-08</ixz>
          <iyy>0.1454623687461343</iyy>
          <iyz>2.1976487590695161e-10</iyz>
          <izz>0.14666763285273129</izz>
        </inertia>
      </inertial>
      <collision name='WheelFR_link_collision'>
        <pose>0 0 0 0 0 0</pose>
        <geometry>
          <mesh>
            <scale>0.1 0.1 0.1</scale>
            <uri>meshes/WheelFR_0.10.stl</uri>
          </mesh>
        </geometry>
        <surface>
          <contact>
            <ode>
              <kp>10000000</kp>
              <kd>1</kd>
              <min_depth>0.0030000000000000001</min_depth>
            </ode>
          </contact>
          <friction>
            <ode>
              <mu>0</mu>
              <mu2>1</mu2>
              <fdir1>0 1 0</fdir1>
            </ode>
          </friction>
        </surface>
      </collision>
      <visual name='WheelFR_link_visual'>
        <pose>0 0 0 0 0 0</pose>
        <geometry>
          <mesh>
            <scale>0.1 0.1 0.1</scale>
            <uri>meshes/WheelFR.dae</uri>
          </mesh>
        </geometry>
      </visual>
      <gravity>true</gravity>
    </link>
    <plugin name='ignition::gazebo::systems::DiffDrive' filename='ignition-gazebo-diff-drive-system'>
      <left_joint>WheelFL</left_joint>
      <right_joint>WheelFR</right_joint>
      <back_joint>WheelB</back_joint>
      <wheel_separation>0.170</wheel_separation>
      <wheel_radius>0.07</wheel_radius>
    </plugin>
    <plugin name='ign_ros2_control::IgnitionROS2ControlPlugin' filename='ign_ros2_control-system'>
      <parameters>/root/ws/src/pepper_ign_moveit2/pepper_robot_moveit_config/config/controllers_effort.yaml</parameters>
    </plugin>
    <static>false</static>
    <plugin name='ignition::gazebo::systems::PosePublisher' filename='ignition-gazebo-pose-publisher-system'>
      <use_pose_vector_msg>true</use_pose_vector_msg>
      <publish_nested_model_pose>true</publish_nested_model_pose>
      <publish_link_pose>false</publish_link_pose>
      <publish_collision_pose>false</publish_collision_pose>
      <publish_visual_pose>false</publish_visual_pose>
    </plugin>
  </model>
</sdf>
