<sdf version='1.9'>
  <model name='pepper_robot'>
    <link name='base_link'>
      <inertial>
        <pose>-0.0333667 -5.76754e-05 -1.99402 0 0 0</pose>
        <mass>7.973462086816875</mass>
        <inertia>
          <ixx>13.007613862196331</ixx>
          <iyy>11.662440077586432</iyy>
          <izz>14.094110420355513</izz>
          <ixy>-0.0007475909662633769</ixy>
          <ixz>0.4284902452492633</ixz>
          <iyz>-0.0003935661937249666</iyz>
        </inertia>
      </inertial>
      <collision name='base_link_fixed_joint_lump__Tibia_collision'>
        <pose>0 0 0.334 0 -0 0</pose>
        <geometry>
          <mesh>
            <scale>0.1 0.1 0.1</scale>
            <uri>meshes/KneePitch_0.10.stl</uri>
          </mesh>
        </geometry>
        <surface>
          <contact>
            <ode/>
          </contact>
          <friction>
            <ode>
              <mu>0.5</mu>
              <mu2>0.5</mu2>
            </ode>
          </friction>
        </surface>
      </collision>
      <visual name='base_link_fixed_joint_lump__Tibia_visual'>
        <pose>0 0 0.334 0 -0 0</pose>
        <geometry>
          <mesh>
            <scale>0.1 0.1 0.1</scale>
            <uri>meshes/KneePitch.dae</uri>
          </mesh>
        </geometry>
      </visual>
      <gravity>0</gravity>
      <self_collide>0</self_collide>
    </link>
    <joint name='KneePitch' type='revolute'>
      <pose relative_to='base_link'>0 0 0.334 0 -0 0</pose>
      <parent>base_link</parent>
      <child>Pelvis</child>
      <axis>
        <xyz>0 -1 0</xyz>
        <limit>
          <lower>-0.514872</lower>
          <upper>0.514872</upper>
          <effort>27.702</effort>
          <velocity>2.93276</velocity>
        </limit>
        <dynamics>
          <spring_reference>0</spring_reference>
          <spring_stiffness>0</spring_stiffness>
        </dynamics>
      </axis>
    </joint>
    <link name='Pelvis'>
      <pose relative_to='KneePitch'>0 0 0 0 -0 0</pose>
      <inertial>
        <pose>0.0908328 0.000167721 -1.0109 0 0 0</pose>
        <mass>2.4516530613471974</mass>
        <inertia>
          <ixx>2.379094970903315</ixx>
          <iyy>1.878286737072687</iyy>
          <izz>1.1954384086462333</izz>
          <ixy>0.0002705738312576661</ixy>
          <ixz>0.014600228468839486</ixz>
          <iyz>0.00032341497823874744</iyz>
        </inertia>
      </inertial>
      <collision name='Pelvis_collision'>
        <pose>0 0 0.268 0 -0 0</pose>
        <geometry>
          <mesh>
            <scale>0.1 0.1 0.1</scale>
            <uri>meshes/HipPitch_0.10.stl</uri>
          </mesh>
        </geometry>
        <surface>
          <contact>
            <ode/>
          </contact>
          <friction>
            <ode>
              <mu>0.5</mu>
              <mu2>0.5</mu2>
            </ode>
          </friction>
        </surface>
      </collision>
      <visual name='Pelvis_visual'>
        <pose>0 0 0.268 0 -0 0</pose>
        <geometry>
          <mesh>
            <scale>0.1 0.1 0.1</scale>
            <uri>meshes/HipPitch.dae</uri>
          </mesh>
        </geometry>
      </visual>
      <gravity>0</gravity>
      <self_collide>0</self_collide>
    </link>
    <joint name='HipPitch' type='revolute'>
      <pose relative_to='Pelvis'>0 0 0.268 0 -0 0</pose>
      <parent>Pelvis</parent>
      <child>Hip</child>
      <axis>
        <xyz>0 -1 0</xyz>
        <limit>
          <lower>-1.03847</lower>
          <upper>1.03847</upper>
          <effort>19.787</effort>
          <velocity>2.93276</velocity>
        </limit>
        <dynamics>
          <spring_reference>0</spring_reference>
          <spring_stiffness>0</spring_stiffness>
        </dynamics>
      </axis>
    </joint>
    <link name='Hip'>
      <pose relative_to='HipPitch'>0 0 0 0 -0 0</pose>
      <inertial>
        <pose>0.0110062 -0.00150986 -0.650903 0 0 0</pose>
        <mass>0.6507117295125363</mass>
        <inertia>
          <ixx>0.1659353978845334</ixx>
          <iyy>0.2279857473556059</iyy>
          <izz>0.11677472601338748</izz>
          <ixy>-5.87599765978397e-05</ixy>
          <ixz>0.0026198834859468157</ixz>
          <iyz>-0.0008377964796593942</iyz>
        </inertia>
      </inertial>
      <collision name='Hip_collision'>
        <pose>0 0 0.079 0 -0 0</pose>
        <geometry>
          <mesh>
            <scale>0.1 0.1 0.1</scale>
            <uri>meshes/HipRoll_0.10.stl</uri>
          </mesh>
        </geometry>
        <surface>
          <contact>
            <ode/>
          </contact>
          <friction>
            <ode>
              <mu>0.5</mu>
              <mu2>0.5</mu2>
            </ode>
          </friction>
        </surface>
      </collision>
      <visual name='Hip_visual'>
        <pose>0 0 0.079 0 -0 0</pose>
        <geometry>
          <mesh>
            <scale>0.1 0.1 0.1</scale>
            <uri>meshes/HipRoll.dae</uri>
          </mesh>
        </geometry>
      </visual>
      <gravity>0</gravity>
      <self_collide>0</self_collide>
    </link>
    <joint name='HipRoll' type='revolute'>
      <pose relative_to='Hip'>0 0 0.079 0 -0 0</pose>
      <parent>Hip</parent>
      <child>torso</child>
      <axis>
        <xyz>-1 0 0</xyz>
        <limit>
          <lower>-0.514872</lower>
          <upper>0.514872</upper>
          <effort>10.1884</effort>
          <velocity>2.27032</velocity>
        </limit>
        <dynamics>
          <spring_reference>0</spring_reference>
          <spring_stiffness>0</spring_stiffness>
        </dynamics>
      </axis>
    </joint>
    <link name='torso'>
      <pose relative_to='HipRoll'>0 0 0 0 -0 0</pose>
      <inertial>
        <pose>-0.255593 3.02341e-05 0.391816 0 0 0</pose>
        <mass>3.161709304517408</mass>
        <inertia>
          <ixx>2.9497111813572316</ixx>
          <iyy>2.6144267908196395</iyy>
          <izz>2.185304809149162</izz>
          <ixy>4.06674857495041e-05</ixy>
          <ixz>0.4299637599806103</ixz>
          <iyz>-0.00012783211090377635</iyz>
        </inertia>
      </inertial>
      <collision name='torso_collision'>
        <pose>2e-05 0 0.139 0 -0 0</pose>
        <geometry>
          <mesh>
            <scale>0.1 0.1 0.1</scale>
            <uri>meshes/Torso_0.10.stl</uri>
          </mesh>
        </geometry>
        <surface>
          <contact>
            <ode/>
          </contact>
          <friction>
            <ode>
              <mu>0.5</mu>
              <mu2>0.5</mu2>
            </ode>
          </friction>
        </surface>
      </collision>
      <visual name='torso_visual'>
        <pose>2e-05 0 0.139 0 -0 0</pose>
        <geometry>
          <mesh>
            <scale>0.1 0.1 0.1</scale>
            <uri>meshes/Torso.dae</uri>
          </mesh>
        </geometry>
      </visual>
      <gravity>0</gravity>
      <self_collide>0</self_collide>
    </link>
    <joint name='HeadYaw' type='revolute'>
      <pose relative_to='torso'>-0.038 0 0.3089 0 -0 0</pose>
      <parent>torso</parent>
      <child>Neck</child>
      <axis>
        <xyz>0 0 1</xyz>
        <limit>
          <lower>-2.08567</lower>
          <upper>2.08567</upper>
          <effort>5.428</effort>
          <velocity>7.33998</velocity>
        </limit>
        <dynamics>
          <spring_reference>0</spring_reference>
          <spring_stiffness>0</spring_stiffness>
        </dynamics>
      </axis>
    </joint>
    <link name='Neck'>
      <pose relative_to='HeadYaw'>0 0 0 0 -0 0</pose>
      <inertial>
        <pose>-0.0122611 -8.25641e-07 0.0292341 0 0 0</pose>
        <mass>0.05908043066486246</mass>
        <inertia>
          <ixx>0.002838318848330362</ixx>
          <iyy>0.003022722771309287</iyy>
          <izz>0.002831849622704799</izz>
          <ixy>-1.4388042928003782e-10</ixy>
          <ixz>7.65554469617386e-05</ixz>
          <iyz>9.412800588913784e-10</iyz>
        </inertia>
      </inertial>
      <collision name='Neck_collision'>
        <pose>0 0 0 0 -0 0</pose>
        <geometry>
          <mesh>
            <scale>0.1 0.1 0.1</scale>
            <uri>meshes/HeadYaw_0.10.stl</uri>
          </mesh>
        </geometry>
        <surface>
          <contact>
            <ode/>
          </contact>
          <friction>
            <ode>
              <mu>0.5</mu>
              <mu2>0.5</mu2>
            </ode>
          </friction>
        </surface>
      </collision>
      <visual name='Neck_visual'>
        <pose>0 0 0 0 -0 0</pose>
        <geometry>
          <mesh>
            <scale>0.1 0.1 0.1</scale>
            <uri>meshes/HeadYaw.dae</uri>
          </mesh>
        </geometry>
      </visual>
      <gravity>0</gravity>
      <self_collide>0</self_collide>
    </link>
    <joint name='HeadPitch' type='revolute'>
      <pose relative_to='Neck'>0 0 0 0 -0 0</pose>
      <parent>Neck</parent>
      <child>Head</child>
      <axis>
        <xyz>0 1 0</xyz>
        <limit>
          <lower>-0.706858</lower>
          <upper>0.4451</upper>
          <effort>2.666</effort>
          <velocity>9.22756</velocity>
        </limit>
        <dynamics>
          <spring_reference>0</spring_reference>
          <spring_stiffness>0</spring_stiffness>
        </dynamics>
      </axis>
    </joint>
    <link name='Head'>
      <pose relative_to='HeadPitch'>0 0 0 0 -0 0</pose>
      <inertial>
        <pose>0.0412698 -0.000245383 1.18841 0 0 0</pose>
        <mass>1.4899704467588573</mass>
        <inertia>
          <ixx>0.596602005328218</ixx>
          <iyy>0.5875707077425764</iyy>
          <izz>0.6126214476974164</izz>
          <ixy>0.00037681928343074824</ixy>
          <ixz>0.0252060918877959</ixz>
          <iyz>3.2903993407527802e-06</iyz>
        </inertia>
      </inertial>
      <collision name='Head_collision'>
        <pose>0 0 0 0 -0 0</pose>
        <geometry>
          <mesh>
            <scale>0.1 0.1 0.1</scale>
            <uri>meshes/HeadPitch_0.10.stl</uri>
          </mesh>
        </geometry>
        <surface>
          <contact>
            <ode/>
          </contact>
          <friction>
            <ode>
              <mu>0.5</mu>
              <mu2>0.5</mu2>
            </ode>
          </friction>
        </surface>
      </collision>
      <visual name='Head_visual'>
        <pose>0 0 0 0 -0 0</pose>
        <geometry>
          <mesh>
            <scale>0.1 0.1 0.1</scale>
            <uri>meshes/HeadPitch.dae</uri>
          </mesh>
        </geometry>
      </visual>
      <gravity>0</gravity>
      <self_collide>0</self_collide>
    </link>
    <joint name='LShoulderPitch' type='revolute'>
      <pose relative_to='torso'>-0.057 0.14974 0.22582 0 -0 0</pose>
      <parent>torso</parent>
      <child>LShoulder</child>
      <axis>
        <xyz>0 1 0</xyz>
        <limit>
          <lower>-2.08567</lower>
          <upper>2.08567</upper>
          <effort>5.428</effort>
          <velocity>7.33998</velocity>
        </limit>
        <dynamics>
          <spring_reference>0</spring_reference>
          <spring_stiffness>0</spring_stiffness>
        </dynamics>
      </axis>
    </joint>
    <link name='LShoulder'>
      <pose relative_to='LShoulderPitch'>0 0 0 0 -0 0</pose>
      <inertial>
        <pose>-7.40285e-08 -7.32303e-08 -1.30517e-07 0 0 0</pose>
        <mass>0.09089208669337652</mass>
        <inertia>
          <ixx>0.005511375315954468</ixx>
          <iyy>0.005511374438457965</iyy>
          <izz>0.006622559329688531</izz>
          <ixy>-1.2413943030191304e-09</ixy>
          <ixz>4.1045290338410017e-10</ixz>
          <iyz>-1.3381462680035447e-09</iyz>
        </inertia>
      </inertial>
      <collision name='LShoulder_collision'>
        <pose>0 0 0 0 -0 0</pose>
        <geometry>
          <mesh>
            <scale>0.1 0.1 0.1</scale>
            <uri>meshes/LShoulderPitch_0.10.stl</uri>
          </mesh>
        </geometry>
        <surface>
          <contact>
            <ode/>
          </contact>
          <friction>
            <ode>
              <mu>0.5</mu>
              <mu2>0.5</mu2>
            </ode>
          </friction>
        </surface>
      </collision>
      <visual name='LShoulder_visual'>
        <pose>0 0 0 0 -0 0</pose>
        <geometry>
          <mesh>
            <scale>0.1 0.1 0.1</scale>
            <uri>meshes/LShoulderPitch.dae</uri>
          </mesh>
        </geometry>
      </visual>
      <gravity>0</gravity>
      <self_collide>0</self_collide>
    </link>
    <joint name='LShoulderRoll' type='revolute'>
      <pose relative_to='LShoulder'>0 0 0 0 -0 0</pose>
      <parent>LShoulder</parent>
      <child>LBicep</child>
      <axis>
        <xyz>0 0 1</xyz>
        <limit>
          <lower>0.00872665</lower>
          <upper>1.56207</upper>
          <effort>2.666</effort>
          <velocity>9.22756</velocity>
        </limit>
        <dynamics>
          <spring_reference>0</spring_reference>
          <spring_stiffness>0</spring_stiffness>
        </dynamics>
      </axis>
    </joint>
    <link name='LBicep'>
      <pose relative_to='LShoulderRoll'>0 0 0 0 -0 0</pose>
      <inertial>
        <pose>0.902599 -0.162517 -0.0061116 0 0 0</pose>
        <mass>0.20263033656175547</mass>
        <inertia>
          <ixx>0.015953522306490872</ixx>
          <iyy>0.04629607267322468</iyy>
          <izz>0.04370593534554824</izz>
          <ixy>0.0008279443445222074</ixy>
          <ixz>0.0010999795009310539</ixz>
          <iyz>4.440466633648902e-05</iyz>
        </inertia>
      </inertial>
      <collision name='LBicep_collision'>
        <pose>0 0 0 0 -0 0</pose>
        <geometry>
          <mesh>
            <scale>0.1 0.1 0.1</scale>
            <uri>meshes/LShoulderRoll_0.10.stl</uri>
          </mesh>
        </geometry>
        <surface>
          <contact>
            <ode/>
          </contact>
          <friction>
            <ode>
              <mu>0.5</mu>
              <mu2>0.5</mu2>
            </ode>
          </friction>
        </surface>
      </collision>
      <visual name='LBicep_visual'>
        <pose>0 0 0 0 -0 0</pose>
        <geometry>
          <mesh>
            <scale>0.1 0.1 0.1</scale>
            <uri>meshes/LShoulderRoll.dae</uri>
          </mesh>
        </geometry>
      </visual>
      <gravity>0</gravity>
      <self_collide>0</self_collide>
    </link>
    <joint name='LElbowYaw' type='revolute'>
      <pose relative_to='LBicep'>0.1812 0.015 0.00013 0 -0.157079 0</pose>
      <parent>LBicep</parent>
      <child>LElbow</child>
      <axis>
        <xyz>1 0 0</xyz>
        <limit>
          <lower>-2.08567</lower>
          <upper>2.08567</upper>
          <effort>5.428</effort>
          <velocity>7.33998</velocity>
        </limit>
        <dynamics>
          <spring_reference>0</spring_reference>
          <spring_stiffness>0</spring_stiffness>
        </dynamics>
      </axis>
    </joint>
    <link name='LElbow'>
      <pose relative_to='LElbowYaw'>0 0 0 0 -0 0</pose>
      <inertial>
        <pose>-7.34206e-08 1.48077e-09 -4.87585e-08 0 0 0</pose>
        <mass>0.04767263552914448</mass>
        <inertia>
          <ixx>0.0019355306104959361</ixx>
          <iyy>0.001955664606958768</iyy>
          <izz>0.0019556635719783387</izz>
          <ixy>-6.709926506996504e-11</ixy>
          <ixz>-2.713068654945957e-12</ixz>
          <iyz>-1.9337087314942235e-10</iyz>
        </inertia>
      </inertial>
      <collision name='LElbow_collision'>
        <pose>0 0 0 0 -0 0</pose>
        <geometry>
          <mesh>
            <scale>0.1 0.1 0.1</scale>
            <uri>meshes/LElbowYaw_0.10.stl</uri>
          </mesh>
        </geometry>
        <surface>
          <contact>
            <ode/>
          </contact>
          <friction>
            <ode>
              <mu>0.5</mu>
              <mu2>0.5</mu2>
            </ode>
          </friction>
        </surface>
      </collision>
      <visual name='LElbow_visual'>
        <pose>0 0 0 0 -0 0</pose>
        <geometry>
          <mesh>
            <scale>0.1 0.1 0.1</scale>
            <uri>meshes/LElbowYaw.dae</uri>
          </mesh>
        </geometry>
      </visual>
      <gravity>0</gravity>
      <self_collide>0</self_collide>
    </link>
    <joint name='LElbowRoll' type='revolute'>
      <pose relative_to='LElbow'>0 0 0 0 -0 0</pose>
      <parent>LElbow</parent>
      <child>LForeArm</child>
      <axis>
        <xyz>0 0 1</xyz>
        <limit>
          <lower>-1.56207</lower>
          <upper>-0.00872665</upper>
          <effort>2.666</effort>
          <velocity>9.22756</velocity>
        </limit>
        <dynamics>
          <spring_reference>0</spring_reference>
          <spring_stiffness>0</spring_stiffness>
        </dynamics>
      </axis>
    </joint>
    <link name='LForeArm'>
      <pose relative_to='LElbowRoll'>0 0 0 0 -0 0</pose>
      <inertial>
        <pose>0.470716 0.0367563 -0.00106886 0 0 0</pose>
        <mass>0.0860450770545992</mass>
        <inertia>
          <ixx>0.004623156034307464</ixx>
          <iyy>0.006404341829950763</iyy>
          <izz>0.0062153280329988216</izz>
          <ixy>0.0007283255436420108</ixy>
          <ixz>2.7600956070080062e-05</ixz>
          <iyz>1.141556050112104e-06</iyz>
        </inertia>
      </inertial>
      <collision name='LForeArm_collision'>
        <pose>0 0 0 0 -0 0</pose>
        <geometry>
          <mesh>
            <scale>0.1 0.1 0.1</scale>
            <uri>meshes/LElbowRoll_0.10.stl</uri>
          </mesh>
        </geometry>
        <surface>
          <contact>
            <ode/>
          </contact>
          <friction>
            <ode>
              <mu>0.5</mu>
              <mu2>0.5</mu2>
            </ode>
          </friction>
        </surface>
      </collision>
      <visual name='LForeArm_visual'>
        <pose>0 0 0 0 -0 0</pose>
        <geometry>
          <mesh>
            <scale>0.1 0.1 0.1</scale>
            <uri>meshes/LElbowRoll.dae</uri>
          </mesh>
        </geometry>
      </visual>
      <gravity>0</gravity>
      <self_collide>0</self_collide>
    </link>
    <joint name='LWristYaw' type='revolute'>
      <pose relative_to='LForeArm'>0.15 0 0 0 -0 0</pose>
      <parent>LForeArm</parent>
      <child>l_wrist</child>
      <axis>
        <xyz>1 0 0</xyz>
        <limit>
          <lower>-1.82387</lower>
          <upper>1.82387</upper>
          <effort>0.2014</effort>
          <velocity>17.3835</velocity>
        </limit>
        <dynamics>
          <spring_reference>0</spring_reference>
          <spring_stiffness>0</spring_stiffness>
        </dynamics>
      </axis>
    </joint>
    <link name='l_wrist'>
      <pose relative_to='LWristYaw'>0 0 0 0 -0 0</pose>
      <inertial>
        <pose>0.110379 -0.0272187 0.0250071 0 0 0</pose>
        <mass>0.13408981948425908</mass>
        <inertia>
          <ixx>0.007559579842892875</ixx>
          <iyy>0.024442226274605388</iyy>
          <izz>0.02601333008280038</izz>
          <ixy>0.000528205480164163</ixy>
          <ixz>-0.002145507773452288</ixz>
          <iyz>-9.641527961376876e-05</iyz>
        </inertia>
      </inertial>
      <collision name='l_wrist_collision'>
        <pose>0 0 0 0 -0 0</pose>
        <geometry>
          <mesh>
            <scale>0.1 0.1 0.1</scale>
            <uri>meshes/LWristYaw_0.10.stl</uri>
          </mesh>
        </geometry>
        <surface>
          <contact>
            <ode/>
          </contact>
          <friction>
            <ode>
              <mu>0.5</mu>
              <mu2>0.5</mu2>
            </ode>
          </friction>
        </surface>
      </collision>
      <visual name='l_wrist_visual'>
        <pose>0 0 0 0 -0 0</pose>
        <geometry>
          <mesh>
            <scale>0.1 0.1 0.1</scale>
            <uri>meshes/LWristYaw.dae</uri>
          </mesh>
        </geometry>
      </visual>
      <gravity>0</gravity>
      <self_collide>0</self_collide>
    </link>
    <joint name='LFinger11' type='revolute'>
      <pose relative_to='l_wrist'>0.0821 -0.0268 0.004 1.74402 1.04064 -0.033434</pose>
      <parent>l_wrist</parent>
      <child>LFinger11_link</child>
      <axis>
        <xyz>0 0 1</xyz>
        <limit>
          <lower>-1e+16</lower>
          <upper>1e+16</upper>
        </limit>
        <dynamics>
          <spring_reference>0</spring_reference>
          <spring_stiffness>0</spring_stiffness>
        </dynamics>
      </axis>
    </joint>
    <link name='LFinger11_link'>
      <pose relative_to='LFinger11'>0 0 0 0 -0 0</pose>
      <inertial>
        <pose>0.0822134 -0.00014806 0.00693314 0 0 0</pose>
        <mass>0.001120173268188194</mass>
        <inertia>
          <ixx>2.2399644786788934e-06</ixx>
          <iyy>5.857267271383655e-06</iyy>
          <izz>6.447289903077635e-06</izz>
          <ixy>-2.105118821108183e-08</ixy>
          <ixz>-1.1469883032691336e-07</ixz>
          <iyz>-3.25722980225283e-08</iyz>
        </inertia>
      </inertial>
      <collision name='LFinger11_link_collision'>
        <pose>0 0 0 0 -0 0</pose>
        <geometry>
          <mesh>
            <scale>0.1 0.1 0.1</scale>
            <uri>meshes/LFinger11_0.10.stl</uri>
          </mesh>
        </geometry>
        <surface>
          <contact>
            <ode/>
          </contact>
          <friction>
            <ode>
              <mu>0.5</mu>
              <mu2>0.5</mu2>
            </ode>
          </friction>
        </surface>
      </collision>
      <visual name='LFinger11_link_visual'>
        <pose>0 0 0 0 -0 0</pose>
        <geometry>
          <mesh>
            <scale>0.1 0.1 0.1</scale>
            <uri>meshes/LFinger11.dae</uri>
          </mesh>
        </geometry>
      </visual>
      <gravity>0</gravity>
      <self_collide>0</self_collide>
    </link>
    <joint name='LFinger12' type='revolute'>
      <pose relative_to='LFinger11_link'>0.018 0 0 0 0 -1.0472</pose>
      <parent>LFinger11_link</parent>
      <child>LFinger12_link</child>
      <axis>
        <xyz>0 0 1</xyz>
        <limit>
          <lower>-1e+16</lower>
          <upper>1e+16</upper>
        </limit>
        <dynamics>
          <spring_reference>0</spring_reference>
          <spring_stiffness>0</spring_stiffness>
        </dynamics>
      </axis>
    </joint>
    <link name='LFinger12_link'>
      <pose relative_to='LFinger12'>0 0 0 0 -0 0</pose>
      <inertial>
        <pose>0.0822134 -0.00014806 0.00693314 0 0 0</pose>
        <mass>0.001120173280473563</mass>
        <inertia>
          <ixx>2.2399645274771213e-06</ixx>
          <iyy>5.857267308530903e-06</iyy>
          <izz>6.447289917528821e-06</izz>
          <ixy>-2.1051209160614223e-08</ixy>
          <ixz>-1.1469882210322685e-07</ixz>
          <iyz>-3.257228780699206e-08</iyz>
        </inertia>
      </inertial>
      <collision name='LFinger12_link_collision'>
        <pose>0 0 0 0 -0 0</pose>
        <geometry>
          <mesh>
            <scale>0.1 0.1 0.1</scale>
            <uri>meshes/LFinger12_0.10.stl</uri>
          </mesh>
        </geometry>
        <surface>
          <contact>
            <ode/>
          </contact>
          <friction>
            <ode>
              <mu>0.5</mu>
              <mu2>0.5</mu2>
            </ode>
          </friction>
        </surface>
      </collision>
      <visual name='LFinger12_link_visual'>
        <pose>0 0 0 0 -0 0</pose>
        <geometry>
          <mesh>
            <scale>0.1 0.1 0.1</scale>
            <uri>meshes/LFinger12.dae</uri>
          </mesh>
        </geometry>
      </visual>
      <gravity>0</gravity>
      <self_collide>0</self_collide>
    </link>
    <joint name='LFinger13' type='revolute'>
      <pose relative_to='LFinger12_link'>0.018 0 0 0 0 -1.0472</pose>
      <parent>LFinger12_link</parent>
      <child>LFinger13_link</child>
      <axis>
        <xyz>0 0 1</xyz>
        <limit>
          <lower>-1e+16</lower>
          <upper>1e+16</upper>
        </limit>
        <dynamics>
          <spring_reference>0</spring_reference>
          <spring_stiffness>0</spring_stiffness>
        </dynamics>
      </axis>
    </joint>
    <link name='LFinger13_link'>
      <pose relative_to='LFinger13'>0 0 0 0 -0 0</pose>
      <inertial>
        <pose>0.0575085 0.00263446 0.00891102 0 0 0</pose>
        <mass>0.0007828454459212576</mass>
        <inertia>
          <ixx>1.3514400856623022e-06</ixx>
          <iyy>2.616011440033339e-06</iyy>
          <izz>2.8527734731145056e-06</izz>
          <ixy>-7.400691210596976e-08</ixy>
          <ixz>9.151486023074825e-09</ixz>
          <iyz>-3.684506183020308e-09</iyz>
        </inertia>
      </inertial>
      <collision name='LFinger13_link_collision'>
        <pose>0 0 0 0 -0 0</pose>
        <geometry>
          <mesh>
            <scale>0.1 0.1 0.1</scale>
            <uri>meshes/LFinger13_0.10.stl</uri>
          </mesh>
        </geometry>
        <surface>
          <contact>
            <ode/>
          </contact>
          <friction>
            <ode>
              <mu>0.5</mu>
              <mu2>0.5</mu2>
            </ode>
          </friction>
        </surface>
      </collision>
      <visual name='LFinger13_link_visual'>
        <pose>0 0 0 0 -0 0</pose>
        <geometry>
          <mesh>
            <scale>0.1 0.1 0.1</scale>
            <uri>meshes/LFinger13.dae</uri>
          </mesh>
        </geometry>
      </visual>
      <gravity>0</gravity>
      <self_collide>0</self_collide>
    </link>
    <joint name='LFinger21' type='revolute'>
      <pose relative_to='l_wrist'>0.0873 -0.0073 0.006 1.5708 1.0472 -0.061086</pose>
      <parent>l_wrist</parent>
      <child>LFinger21_link</child>
      <axis>
        <xyz>0 0 1</xyz>
        <limit>
          <lower>-1e+16</lower>
          <upper>1e+16</upper>
        </limit>
        <dynamics>
          <spring_reference>0</spring_reference>
          <spring_stiffness>0</spring_stiffness>
        </dynamics>
      </axis>
    </joint>
    <link name='LFinger21_link'>
      <pose relative_to='LFinger21'>0 0 0 0 -0 0</pose>
      <inertial>
        <pose>0.0822134 -0.00014806 0.00693313 0 0 0</pose>
        <mass>0.0011201732597173012</mass>
        <inertia>
          <ixx>2.2399644479160755e-06</ixx>
          <iyy>5.857267331712786e-06</iyy>
          <izz>6.447289918407904e-06</izz>
          <ixy>-2.1051261972475785e-08</ixy>
          <ixz>-1.1469878198528467e-07</ixz>
          <iyz>-3.257229153593606e-08</iyz>
        </inertia>
      </inertial>
      <collision name='LFinger21_link_collision'>
        <pose>0 0 0 0 -0 0</pose>
        <geometry>
          <mesh>
            <scale>0.1 0.1 0.1</scale>
            <uri>meshes/LFinger21_0.10.stl</uri>
          </mesh>
        </geometry>
        <surface>
          <contact>
            <ode/>
          </contact>
          <friction>
            <ode>
              <mu>0.5</mu>
              <mu2>0.5</mu2>
            </ode>
          </friction>
        </surface>
      </collision>
      <visual name='LFinger21_link_visual'>
        <pose>0 0 0 0 -0 0</pose>
        <geometry>
          <mesh>
            <scale>0.1 0.1 0.1</scale>
            <uri>meshes/LFinger21.dae</uri>
          </mesh>
        </geometry>
      </visual>
      <gravity>0</gravity>
      <self_collide>0</self_collide>
    </link>
    <joint name='LFinger22' type='revolute'>
      <pose relative_to='LFinger21_link'>0.018 0 0 0 0 -1.0472</pose>
      <parent>LFinger21_link</parent>
      <child>LFinger22_link</child>
      <axis>
        <xyz>0 0 1</xyz>
        <limit>
          <lower>-1e+16</lower>
          <upper>1e+16</upper>
        </limit>
        <dynamics>
          <spring_reference>0</spring_reference>
          <spring_stiffness>0</spring_stiffness>
        </dynamics>
      </axis>
    </joint>
    <link name='LFinger22_link'>
      <pose relative_to='LFinger22'>0 0 0 0 -0 0</pose>
      <inertial>
        <pose>0.0822134 -0.000148055 0.00693314 0 0 0</pose>
        <mass>0.0011201733759826358</mass>
        <inertia>
          <ixx>2.2399648501758626e-06</ixx>
          <iyy>5.85726879685795e-06</iyy>
          <izz>6.44729170156988e-06</izz>
          <ixy>-2.1051782341466184e-08</ixy>
          <ixz>-1.1469900474683047e-07</ixz>
          <iyz>-3.257237577272461e-08</iyz>
        </inertia>
      </inertial>
      <collision name='LFinger22_link_collision'>
        <pose>0 0 0 0 -0 0</pose>
        <geometry>
          <mesh>
            <scale>0.1 0.1 0.1</scale>
            <uri>meshes/LFinger22_0.10.stl</uri>
          </mesh>
        </geometry>
        <surface>
          <contact>
            <ode/>
          </contact>
          <friction>
            <ode>
              <mu>0.5</mu>
              <mu2>0.5</mu2>
            </ode>
          </friction>
        </surface>
      </collision>
      <visual name='LFinger22_link_visual'>
        <pose>0 0 0 0 -0 0</pose>
        <geometry>
          <mesh>
            <scale>0.1 0.1 0.1</scale>
            <uri>meshes/LFinger22.dae</uri>
          </mesh>
        </geometry>
      </visual>
      <gravity>0</gravity>
      <self_collide>0</self_collide>
    </link>
    <joint name='LFinger23' type='revolute'>
      <pose relative_to='LFinger22_link'>0.018 0 0 0 0 -1.0472</pose>
      <parent>LFinger22_link</parent>
      <child>LFinger23_link</child>
      <axis>
        <xyz>0 0 1</xyz>
        <limit>
          <lower>-1e+16</lower>
          <upper>1e+16</upper>
        </limit>
        <dynamics>
          <spring_reference>0</spring_reference>
          <spring_stiffness>0</spring_stiffness>
        </dynamics>
      </axis>
    </joint>
    <link name='LFinger23_link'>
      <pose relative_to='LFinger23'>0 0 0 0 -0 0</pose>
      <inertial>
        <pose>0.0575085 0.00266157 0.00909151 0 0 0</pose>
        <mass>0.0007828454384633327</mass>
        <inertia>
          <ixx>1.351439970167974e-06</ixx>
          <iyy>2.6160115979273665e-06</iyy>
          <izz>2.852773459758437e-06</izz>
          <ixy>-7.400693229502334e-08</ixy>
          <ixz>9.151413955035165e-09</ixz>
          <iyz>-3.684485886742615e-09</iyz>
        </inertia>
      </inertial>
      <collision name='LFinger23_link_collision'>
        <pose>0 0 0 0 -0 0</pose>
        <geometry>
          <mesh>
            <scale>0.1 0.1 0.1</scale>
            <uri>meshes/LFinger23_0.10.stl</uri>
          </mesh>
        </geometry>
        <surface>
          <contact>
            <ode/>
          </contact>
          <friction>
            <ode>
              <mu>0.5</mu>
              <mu2>0.5</mu2>
            </ode>
          </friction>
        </surface>
      </collision>
      <visual name='LFinger23_link_visual'>
        <pose>0 0 0 0 -0 0</pose>
        <geometry>
          <mesh>
            <scale>0.1 0.1 0.1</scale>
            <uri>meshes/LFinger23.dae</uri>
          </mesh>
        </geometry>
      </visual>
      <gravity>0</gravity>
      <self_collide>0</self_collide>
    </link>
    <joint name='LFinger31' type='revolute'>
      <pose relative_to='l_wrist'>0.0833 0.0123 0.004 1.46636 1.04483 -0.029314</pose>
      <parent>l_wrist</parent>
      <child>LFinger31_link</child>
      <axis>
        <xyz>0 0 1</xyz>
        <limit>
          <lower>-1e+16</lower>
          <upper>1e+16</upper>
        </limit>
        <dynamics>
          <spring_reference>0</spring_reference>
          <spring_stiffness>0</spring_stiffness>
        </dynamics>
      </axis>
    </joint>
    <link name='LFinger31_link'>
      <pose relative_to='LFinger31'>0 0 0 0 -0 0</pose>
      <inertial>
        <pose>0.0822134 -0.000148061 0.00693314 0 0 0</pose>
        <mass>0.0011201732747014332</mass>
        <inertia>
          <ixx>2.2399645418453573e-06</ixx>
          <iyy>5.857267163143072e-06</iyy>
          <izz>6.447289797996078e-06</izz>
          <ixy>-2.105118263739426e-08</ixy>
          <ixz>-1.1469879474942076e-07</ixz>
          <iyz>-3.2572326910287594e-08</iyz>
        </inertia>
      </inertial>
      <collision name='LFinger31_link_collision'>
        <pose>0 0 0 0 -0 0</pose>
        <geometry>
          <mesh>
            <scale>0.1 0.1 0.1</scale>
            <uri>meshes/LFinger31_0.10.stl</uri>
          </mesh>
        </geometry>
        <surface>
          <contact>
            <ode/>
          </contact>
          <friction>
            <ode>
              <mu>0.5</mu>
              <mu2>0.5</mu2>
            </ode>
          </friction>
        </surface>
      </collision>
      <visual name='LFinger31_link_visual'>
        <pose>0 0 0 0 -0 0</pose>
        <geometry>
          <mesh>
            <scale>0.1 0.1 0.1</scale>
            <uri>meshes/LFinger31.dae</uri>
          </mesh>
        </geometry>
      </visual>
      <gravity>0</gravity>
      <self_collide>0</self_collide>
    </link>
    <joint name='LFinger32' type='revolute'>
      <pose relative_to='LFinger31_link'>0.018 0 0 0 0 -1.0472</pose>
      <parent>LFinger31_link</parent>
      <child>LFinger32_link</child>
      <axis>
        <xyz>0 0 1</xyz>
        <limit>
          <lower>-1e+16</lower>
          <upper>1e+16</upper>
        </limit>
        <dynamics>
          <spring_reference>0</spring_reference>
          <spring_stiffness>0</spring_stiffness>
        </dynamics>
      </axis>
    </joint>
    <link name='LFinger32_link'>
      <pose relative_to='LFinger32'>0 0 0 0 -0 0</pose>
      <inertial>
        <pose>0.0822134 -0.00014806 0.00693314 0 0 0</pose>
        <mass>0.001120173243906400</mass>
        <inertia>
          <ixx>2.2399644029094614e-06</ixx>
          <iyy>5.857267124242934e-06</iyy>
          <izz>6.44728970669286e-06</izz>
          <ixy>-2.1051241721856316e-08</ixy>
          <ixz>-1.1469885512024016e-07</ixz>
          <iyz>-3.257229922810809e-08</iyz>
        </inertia>
      </inertial>
      <collision name='LFinger32_link_collision'>
        <pose>0 0 0 0 -0 0</pose>
        <geometry>
          <mesh>
            <scale>0.1 0.1 0.1</scale>
            <uri>meshes/LFinger32_0.10.stl</uri>
          </mesh>
        </geometry>
        <surface>
          <contact>
            <ode/>
          </contact>
          <friction>
            <ode>
              <mu>0.5</mu>
              <mu2>0.5</mu2>
            </ode>
          </friction>
        </surface>
      </collision>
      <visual name='LFinger32_link_visual'>
        <pose>0 0 0 0 -0 0</pose>
        <geometry>
          <mesh>
            <scale>0.1 0.1 0.1</scale>
            <uri>meshes/LFinger32.dae</uri>
          </mesh>
        </geometry>
      </visual>
      <gravity>0</gravity>
      <self_collide>0</self_collide>
    </link>
    <joint name='LFinger33' type='revolute'>
      <pose relative_to='LFinger32_link'>0.018 0 0 0 0 -1.0472</pose>
      <parent>LFinger32_link</parent>
      <child>LFinger33_link</child>
      <axis>
        <xyz>0 0 1</xyz>
        <limit>
          <lower>-1e+16</lower>
          <upper>1e+16</upper>
        </limit>
        <dynamics>
          <spring_reference>0</spring_reference>
          <spring_stiffness>0</spring_stiffness>
        </dynamics>
      </axis>
    </joint>
    <link name='LFinger33_link'>
      <pose relative_to='LFinger33'>0 0 0 0 -0 0</pose>
      <inertial>
        <pose>0.0575085 0.00266156 0.00909151 0 0 0</pose>
        <mass>0.0007828455617553774</mass>
        <inertia>
          <ixx>1.3514404535774175e-06</ixx>
          <iyy>2.6160119801390183e-06</iyy>
          <izz>2.852773835331611e-06</izz>
          <ixy>-7.400689239274784e-08</ixy>
          <ixz>9.151607566553035e-09</ixz>
          <iyz>-3.6845075830067094e-09</iyz>
        </inertia>
      </inertial>
      <collision name='LFinger33_link_collision'>
        <pose>0 0 0 0 -0 0</pose>
        <geometry>
          <mesh>
            <scale>0.1 0.1 0.1</scale>
            <uri>meshes/LFinger33_0.10.stl</uri>
          </mesh>
        </geometry>
        <surface>
          <contact>
            <ode/>
          </contact>
          <friction>
            <ode>
              <mu>0.5</mu>
              <mu2>0.5</mu2>
            </ode>
          </friction>
        </surface>
      </collision>
      <visual name='LFinger33_link_visual'>
        <pose>0 0 0 0 -0 0</pose>
        <geometry>
          <mesh>
            <scale>0.1 0.1 0.1</scale>
            <uri>meshes/LFinger33.dae</uri>
          </mesh>
        </geometry>
      </visual>
      <gravity>0</gravity>
      <self_collide>0</self_collide>
    </link>
    <joint name='LFinger41' type='revolute'>
      <pose relative_to='l_wrist'>0.074 0.0309 0 1.39757 1.04064 0.068339</pose>
      <parent>l_wrist</parent>
      <child>LFinger41_link</child>
      <axis>
        <xyz>0 0 1</xyz>
        <limit>
          <lower>-1e+16</lower>
          <upper>1e+16</upper>
        </limit>
        <dynamics>
          <spring_reference>0</spring_reference>
          <spring_stiffness>0</spring_stiffness>
        </dynamics>
      </axis>
    </joint>
    <link name='LFinger41_link'>
      <pose relative_to='LFinger41'>0 0 0 0 -0 0</pose>
      <inertial>
        <pose>0.0822134 -0.000148061 0.00693314 0 0 0</pose>
        <mass>0.0011201732860576827</mass>
        <inertia>
          <ixx>2.2399645717590983e-06</ixx>
          <iyy>5.8572673274653036e-06</iyy>
          <izz>6.447289969027131e-06</izz>
          <ixy>-2.1051166080017066e-08</ixy>
          <ixz>-1.1469882666607233e-07</ixz>
          <iyz>-3.2572325972142886e-08</iyz>
        </inertia>
      </inertial>
      <collision name='LFinger41_link_collision'>
        <pose>0 0 0 0 -0 0</pose>
        <geometry>
          <mesh>
            <scale>0.1 0.1 0.1</scale>
            <uri>meshes/LFinger41_0.10.stl</uri>
          </mesh>
        </geometry>
        <surface>
          <contact>
            <ode/>
          </contact>
          <friction>
            <ode>
              <mu>0.5</mu>
              <mu2>0.5</mu2>
            </ode>
          </friction>
        </surface>
      </collision>
      <visual name='LFinger41_link_visual'>
        <pose>0 0 0 0 -0 0</pose>
        <geometry>
          <mesh>
            <scale>0.1 0.1 0.1</scale>
            <uri>meshes/LFinger41.dae</uri>
          </mesh>
        </geometry>
      </visual>
      <gravity>0</gravity>
      <self_collide>0</self_collide>
    </link>
    <joint name='LFinger42' type='revolute'>
      <pose relative_to='LFinger41_link'>0.018 0 0 0 0 -1.0472</pose>
      <parent>LFinger41_link</parent>
      <child>LFinger42_link</child>
      <axis>
        <xyz>0 0 1</xyz>
        <limit>
          <lower>-1e+16</lower>
          <upper>1e+16</upper>
        </limit>
        <dynamics>
          <spring_reference>0</spring_reference>
          <spring_stiffness>0</spring_stiffness>
        </dynamics>
      </axis>
    </joint>
    <link name='LFinger42_link'>
      <pose relative_to='LFinger42'>0 0 0 0 -0 0</pose>
      <inertial>
        <pose>0.0822134 -0.00014806 0.00693314 0 0 0</pose>
        <mass>0.0011201732395139717</mass>
        <inertia>
          <ixx>2.239964391403848e-06</ixx>
          <iyy>5.8572670959106235e-06</iyy>
          <izz>6.447289672897159e-06</izz>
          <ixy>-2.1051247654377564e-08</ixy>
          <ixz>-1.1469885243760228e-07</ixz>
          <iyz>-3.257230366135826e-08</iyz>
        </inertia>
      </inertial>
      <collision name='LFinger42_link_collision'>
        <pose>0 0 0 0 -0 0</pose>
        <geometry>
          <mesh>
            <scale>0.1 0.1 0.1</scale>
            <uri>meshes/LFinger42_0.10.stl</uri>
          </mesh>
        </geometry>
        <surface>
          <contact>
            <ode/>
          </contact>
          <friction>
            <ode>
              <mu>0.5</mu>
              <mu2>0.5</mu2>
            </ode>
          </friction>
        </surface>
      </collision>
      <visual name='LFinger42_link_visual'>
        <pose>0 0 0 0 -0 0</pose>
        <geometry>
          <mesh>
            <scale>0.1 0.1 0.1</scale>
            <uri>meshes/LFinger42.dae</uri>
          </mesh>
        </geometry>
      </visual>
      <gravity>0</gravity>
      <self_collide>0</self_collide>
    </link>
    <joint name='LFinger43' type='revolute'>
      <pose relative_to='LFinger42_link'>0.018 0 0 0 0 -1.0472</pose>
      <parent>LFinger42_link</parent>
      <child>LFinger43_link</child>
      <axis>
        <xyz>0 0 1</xyz>
        <limit>
          <lower>-1e+16</lower>
          <upper>1e+16</upper>
        </limit>
        <dynamics>
          <spring_reference>0</spring_reference>
          <spring_stiffness>0</spring_stiffness>
        </dynamics>
      </axis>
    </joint>
    <link name='LFinger43_link'>
      <pose relative_to='LFinger43'>0 0 0 0 -0 0</pose>
      <inertial>
        <pose>0.0575085 0.00266156 0.00909151 0 0 0</pose>
        <mass>0.0007828453978485874</mass>
        <inertia>
          <ixx>1.3514398959634833e-06</ixx>
          <iyy>2.6160112824212533e-06</iyy>
          <izz>2.8527732955629684e-06</izz>
          <ixy>-7.400684989673474e-08</ixy>
          <ixz>9.151625902768317e-09</ixz>
          <iyz>-3.6844681799755328e-09</iyz>
        </inertia>
      </inertial>
      <collision name='LFinger43_link_collision'>
        <pose>0 0 0 0 -0 0</pose>
        <geometry>
          <mesh>
            <scale>0.1 0.1 0.1</scale>
            <uri>meshes/LFinger43_0.10.stl</uri>
          </mesh>
        </geometry>
        <surface>
          <contact>
            <ode/>
          </contact>
          <friction>
            <ode>
              <mu>0.5</mu>
              <mu2>0.5</mu2>
            </ode>
          </friction>
        </surface>
      </collision>
      <visual name='LFinger43_link_visual'>
        <pose>0 0 0 0 -0 0</pose>
        <geometry>
          <mesh>
            <scale>0.1 0.1 0.1</scale>
            <uri>meshes/LFinger43.dae</uri>
          </mesh>
        </geometry>
      </visual>
      <gravity>0</gravity>
      <self_collide>0</self_collide>
    </link>
    <joint name='LThumb1' type='revolute'>
      <pose relative_to='l_wrist'>0.0482 -0.0357 -0.0199 -1.95836 0.60626 0.533978</pose>
      <parent>l_wrist</parent>
      <child>LThumb1_link</child>
      <axis>
        <xyz>0 0 1</xyz>
        <limit>
          <lower>-1e+16</lower>
          <upper>1e+16</upper>
        </limit>
        <dynamics>
          <spring_reference>0</spring_reference>
          <spring_stiffness>0</spring_stiffness>
        </dynamics>
      </axis>
    </joint>
    <link name='LThumb1_link'>
      <pose relative_to='LThumb1'>0 0 0 0 -0 0</pose>
      <inertial>
        <pose>0.0822134 -0.00014806 0.00693314 0 0 0</pose>
        <mass>0.0011201732919619983</mass>
        <inertia>
          <ixx>2.239964554584989e-06</ixx>
          <iyy>5.8572675480624046e-06</iyy>
          <izz>6.447290205058348e-06</izz>
          <ixy>-2.1051187626936403e-08</ixy>
          <ixz>-1.1469879111272574e-07</ixz>
          <iyz>-3.257227751141546e-08</iyz>
        </inertia>
      </inertial>
      <collision name='LThumb1_link_collision'>
        <pose>0 0 0 0 -0 0</pose>
        <geometry>
          <mesh>
            <scale>0.1 0.1 0.1</scale>
            <uri>meshes/LThumb1_0.10.stl</uri>
          </mesh>
        </geometry>
        <surface>
          <contact>
            <ode/>
          </contact>
          <friction>
            <ode>
              <mu>0.5</mu>
              <mu2>0.5</mu2>
            </ode>
          </friction>
        </surface>
      </collision>
      <visual name='LThumb1_link_visual'>
        <pose>0 0 0 0 -0 0</pose>
        <geometry>
          <mesh>
            <scale>0.1 0.1 0.1</scale>
            <uri>meshes/LThumb1.dae</uri>
          </mesh>
        </geometry>
      </visual>
      <gravity>0</gravity>
      <self_collide>0</self_collide>
    </link>
    <joint name='LThumb2' type='revolute'>
      <pose relative_to='LThumb1_link'>0.022 0 0 0 0 -1.0472</pose>
      <parent>LThumb1_link</parent>
      <child>LThumb2_link</child>
      <axis>
        <xyz>0 0 1</xyz>
        <limit>
          <lower>-1e+16</lower>
          <upper>1e+16</upper>
        </limit>
        <dynamics>
          <spring_reference>0</spring_reference>
          <spring_stiffness>0</spring_stiffness>
        </dynamics>
      </axis>
    </joint>
    <link name='LThumb2_link'>
      <pose relative_to='LThumb2'>0 0 0 0 -0 0</pose>
      <inertial>
        <pose>0.0575085 0.00263446 0.00891102 0 0 0</pose>
        <mass>0.0007828454459212576</mass>
        <inertia>
          <ixx>1.3514400856623022e-06</ixx>
          <iyy>2.616011440033339e-06</iyy>
          <izz>2.8527734731145056e-06</izz>
          <ixy>-7.400691210596976e-08</ixy>
          <ixz>9.151486023074825e-09</ixz>
          <iyz>-3.684506183020308e-09</iyz>
        </inertia>
      </inertial>
      <collision name='LThumb2_link_collision'>
        <pose>0 0 0 0 -0 0</pose>
        <geometry>
          <mesh>
            <scale>0.1 0.1 0.1</scale>
            <uri>meshes/LThumb2_0.10.stl</uri>
          </mesh>
        </geometry>
        <surface>
          <contact>
            <ode/>
          </contact>
          <friction>
            <ode>
              <mu>0.5</mu>
              <mu2>0.5</mu2>
            </ode>
          </friction>
        </surface>
      </collision>
      <visual name='LThumb2_link_visual'>
        <pose>0 0 0 0 -0 0</pose>
        <geometry>
          <mesh>
            <scale>0.1 0.1 0.1</scale>
            <uri>meshes/LThumb2.dae</uri>
          </mesh>
        </geometry>
      </visual>
      <gravity>0</gravity>
      <self_collide>0</self_collide>
    </link>
    <joint name='RShoulderPitch' type='revolute'>
      <pose relative_to='torso'>-0.057 -0.14974 0.22582 0 -0 0</pose>
      <parent>torso</parent>
      <child>RShoulder</child>
      <axis>
        <xyz>0 1 0</xyz>
        <limit>
          <lower>-2.08567</lower>
          <upper>2.08567</upper>
          <effort>5.428</effort>
          <velocity>7.33998</velocity>
        </limit>
        <dynamics>
          <spring_reference>0</spring_reference>
          <spring_stiffness>0</spring_stiffness>
        </dynamics>
      </axis>
    </joint>
    <link name='RShoulder'>
      <pose relative_to='RShoulderPitch'>0 0 0 0 -0 0</pose>
      <inertial>
        <pose>-7.40285e-08 -7.32303e-08 -1.30517e-07 0 0 0</pose>
        <mass>0.09089208669337652</mass>
        <inertia>
          <ixx>0.005511375315954468</ixx>
          <iyy>0.005511374438457965</iyy>
          <izz>0.006622559329688531</izz>
          <ixy>-1.2413943030191304e-09</ixy>
          <ixz>4.1045290338410017e-10</ixz>
          <iyz>-1.3381462680035447e-09</iyz>
        </inertia>
      </inertial>
      <collision name='RShoulder_collision'>
        <pose>0 0 0 0 -0 0</pose>
        <geometry>
          <mesh>
            <scale>0.1 0.1 0.1</scale>
            <uri>meshes/RShoulderPitch_0.10.stl</uri>
          </mesh>
        </geometry>
        <surface>
          <contact>
            <ode/>
          </contact>
          <friction>
            <ode>
              <mu>0.5</mu>
              <mu2>0.5</mu2>
            </ode>
          </friction>
        </surface>
      </collision>
      <visual name='RShoulder_visual'>
        <pose>0 0 0 0 -0 0</pose>
        <geometry>
          <mesh>
            <scale>0.1 0.1 0.1</scale>
            <uri>meshes/RShoulderPitch.dae</uri>
          </mesh>
        </geometry>
      </visual>
      <gravity>0</gravity>
      <self_collide>0</self_collide>
    </link>
    <joint name='RShoulderRoll' type='revolute'>
      <pose relative_to='RShoulder'>0 0 0 0 -0 0</pose>
      <parent>RShoulder</parent>
      <child>RBicep</child>
      <axis>
        <xyz>0 0 1</xyz>
        <limit>
          <lower>-1.56207</lower>
          <upper>-0.00872665</upper>
          <effort>2.666</effort>
          <velocity>9.22756</velocity>
        </limit>
        <dynamics>
          <spring_reference>0</spring_reference>
          <spring_stiffness>0</spring_stiffness>
        </dynamics>
      </axis>
    </joint>
    <link name='RBicep'>
      <pose relative_to='RShoulderRoll'>0 0 0 0 -0 0</pose>
      <inertial>
        <pose>0.902599 -0.162517 -0.0061116 0 0 0</pose>
        <mass>0.20263033656175547</mass>
        <inertia>
          <ixx>0.015953522306490872</ixx>
          <iyy>0.04629607267322468</iyy>
          <izz>0.04370593534554824</izz>
          <ixy>0.0008279443445222074</ixy>
          <ixz>0.0010999795009310539</ixz>
          <iyz>4.440466633648902e-05</iyz>
        </inertia>
      </inertial>
      <collision name='RBicep_collision'>
        <pose>0 0 0 0 -0 0</pose>
        <geometry>
          <mesh>
            <scale>0.1 0.1 0.1</scale>
            <uri>meshes/RShoulderRoll_0.10.stl</uri>
          </mesh>
        </geometry>
        <surface>
          <contact>
            <ode/>
          </contact>
          <friction>
            <ode>
              <mu>0.5</mu>
              <mu2>0.5</mu2>
            </ode>
          </friction>
        </surface>
      </collision>
      <visual name='RBicep_visual'>
        <pose>0 0 0 0 -0 0</pose>
        <geometry>
          <mesh>
            <scale>0.1 0.1 0.1</scale>
            <uri>meshes/RShoulderRoll.dae</uri>
          </mesh>
        </geometry>
      </visual>
      <gravity>0</gravity>
      <self_collide>0</self_collide>
    </link>
    <joint name='RElbowYaw' type='revolute'>
      <pose relative_to='RBicep'>0.1812 -0.015 0.00013 0 -0.157079 0</pose>
      <parent>RBicep</parent>
      <child>RElbow</child>
      <axis>
        <xyz>1 0 0</xyz>
        <limit>
          <lower>-2.08567</lower>
          <upper>2.08567</upper>
          <effort>5.428</effort>
          <velocity>7.33998</velocity>
        </limit>
        <dynamics>
          <spring_reference>0</spring_reference>
          <spring_stiffness>0</spring_stiffness>
        </dynamics>
      </axis>
    </joint>
    <link name='RElbow'>
      <pose relative_to='RElbowYaw'>0 0 0 0 -0 0</pose>
      <inertial>
        <pose>-7.34206e-08 1.48077e-09 -4.87585e-08 0 0 0</pose>
        <mass>0.04767263552914448</mass>
        <inertia>
          <ixx>0.0019355306104959361</ixx>
          <iyy>0.001955664606958768</iyy>
          <izz>0.0019556635719783387</izz>
          <ixy>-6.709926506996504e-11</ixy>
          <ixz>-2.713068654945957e-12</ixz>
          <iyz>-1.9337087314942235e-10</iyz>
        </inertia>
      </inertial>
      <collision name='RElbow_collision'>
        <pose>0 0 0 0 -0 0</pose>
        <geometry>
          <mesh>
            <scale>0.1 0.1 0.1</scale>
            <uri>meshes/RElbowYaw_0.10.stl</uri>
          </mesh>
        </geometry>
        <surface>
          <contact>
            <ode/>
          </contact>
          <friction>
            <ode>
              <mu>0.5</mu>
              <mu2>0.5</mu2>
            </ode>
          </friction>
        </surface>
      </collision>
      <visual name='RElbow_visual'>
        <pose>0 0 0 0 -0 0</pose>
        <geometry>
          <mesh>
            <scale>0.1 0.1 0.1</scale>
            <uri>meshes/RElbowYaw.dae</uri>
          </mesh>
        </geometry>
      </visual>
      <gravity>0</gravity>
      <self_collide>0</self_collide>
    </link>
    <joint name='RElbowRoll' type='revolute'>
      <pose relative_to='RElbow'>0 0 0 0 -0 0</pose>
      <parent>RElbow</parent>
      <child>RForeArm</child>
      <axis>
        <xyz>0 0 1</xyz>
        <limit>
          <lower>0.00872665</lower>
          <upper>1.56207</upper>
          <effort>2.666</effort>
          <velocity>9.22756</velocity>
        </limit>
        <dynamics>
          <spring_reference>0</spring_reference>
          <spring_stiffness>0</spring_stiffness>
        </dynamics>
      </axis>
    </joint>
    <link name='RForeArm'>
      <pose relative_to='RElbowRoll'>0 0 0 0 -0 0</pose>
      <inertial>
        <pose>0.470716 -0.0367563 -0.00106886 0 0 0</pose>
        <mass>0.0860450770545992</mass>
        <inertia>
          <ixx>0.004623156034307465</ixx>
          <iyy>0.006404341829950758</iyy>
          <izz>0.006215328032998816</izz>
          <ixy>-0.0007283255436420105</ixy>
          <ixz>2.7600956070079872e-05</ixz>
          <iyz>-1.1415560501121258e-06</iyz>
        </inertia>
      </inertial>
      <collision name='RForeArm_collision'>
        <pose>0 0 0 0 -0 0</pose>
        <geometry>
          <mesh>
            <scale>0.1 0.1 0.1</scale>
            <uri>meshes/RElbowRoll_0.10.stl</uri>
          </mesh>
        </geometry>
        <surface>
          <contact>
            <ode/>
          </contact>
          <friction>
            <ode>
              <mu>0.5</mu>
              <mu2>0.5</mu2>
            </ode>
          </friction>
        </surface>
      </collision>
      <visual name='RForeArm_visual'>
        <pose>0 0 0 0 -0 0</pose>
        <geometry>
          <mesh>
            <scale>0.1 0.1 0.1</scale>
            <uri>meshes/RElbowRoll.dae</uri>
          </mesh>
        </geometry>
      </visual>
      <gravity>0</gravity>
      <self_collide>0</self_collide>
    </link>
    <joint name='RWristYaw' type='revolute'>
      <pose relative_to='RForeArm'>0.15 0 0 0 -0 0</pose>
      <parent>RForeArm</parent>
      <child>r_wrist</child>
      <axis>
        <xyz>1 0 0</xyz>
        <limit>
          <lower>-1.82387</lower>
          <upper>1.82387</upper>
          <effort>0.2014</effort>
          <velocity>17.3835</velocity>
        </limit>
        <dynamics>
          <spring_reference>0</spring_reference>
          <spring_stiffness>0</spring_stiffness>
        </dynamics>
      </axis>
    </joint>
    <link name='r_wrist'>
      <pose relative_to='RWristYaw'>0 0 0 0 -0 0</pose>
      <inertial>
        <pose>0.110379 0.0272187 0.0250071 0 0 0</pose>
        <mass>0.13408981948425902</mass>
        <inertia>
          <ixx>0.007559579842892873</ixx>
          <iyy>0.024442226274605388</iyy>
          <izz>0.02601333008280038</izz>
          <ixy>-0.0005282054801641629</ixy>
          <ixz>-0.0021455077734522884</ixz>
          <iyz>9.641527961376875e-05</iyz>
        </inertia>
      </inertial>
      <collision name='r_wrist_collision'>
        <pose>0 0 0 0 -0 0</pose>
        <geometry>
          <mesh>
            <scale>0.1 0.1 0.1</scale>
            <uri>meshes/RWristYaw_0.10.stl</uri>
          </mesh>
        </geometry>
        <surface>
          <contact>
            <ode/>
          </contact>
          <friction>
            <ode>
              <mu>0.5</mu>
              <mu2>0.5</mu2>
            </ode>
          </friction>
        </surface>
      </collision>
      <visual name='r_wrist_visual'>
        <pose>0 0 0 0 -0 0</pose>
        <geometry>
          <mesh>
            <scale>0.1 0.1 0.1</scale>
            <uri>meshes/RWristYaw.dae</uri>
          </mesh>
        </geometry>
      </visual>
      <gravity>0</gravity>
      <self_collide>0</self_collide>
    </link>
    <joint name='RFinger11' type='revolute'>
      <pose relative_to='r_wrist'>0.0821 0.0268 0.004 1.39757 1.04064 0.033433</pose>
      <parent>r_wrist</parent>
      <child>RFinger11_link</child>
      <axis>
        <xyz>0 0 1</xyz>
        <limit>
          <lower>-1e+16</lower>
          <upper>1e+16</upper>
        </limit>
        <dynamics>
          <spring_reference>0</spring_reference>
          <spring_stiffness>0</spring_stiffness>
        </dynamics>
      </axis>
    </joint>
    <link name='RFinger11_link'>
      <pose relative_to='RFinger11'>0 0 0 0 -0 0</pose>
      <inertial>
        <pose>0.0822134 -0.00014806 0.00693314 0 0 0</pose>
        <mass>0.001120173268188194</mass>
        <inertia>
          <ixx>2.2399644786788934e-06</ixx>
          <iyy>5.857267271383655e-06</iyy>
          <izz>6.447289903077635e-06</izz>
          <ixy>-2.105118821108183e-08</ixy>
          <ixz>-1.1469883032691336e-07</ixz>
          <iyz>-3.25722980225283e-08</iyz>
        </inertia>
      </inertial>
      <collision name='RFinger11_link_collision'>
        <pose>0 0 0 0 -0 0</pose>
        <geometry>
          <mesh>
            <scale>0.1 0.1 0.1</scale>
            <uri>meshes/RFinger11_0.10.stl</uri>
          </mesh>
        </geometry>
        <surface>
          <contact>
            <ode/>
          </contact>
          <friction>
            <ode>
              <mu>0.5</mu>
              <mu2>0.5</mu2>
            </ode>
          </friction>
        </surface>
      </collision>
      <visual name='RFinger11_link_visual'>
        <pose>0 0 0 0 -0 0</pose>
        <geometry>
          <mesh>
            <scale>0.1 0.1 0.1</scale>
            <uri>meshes/RFinger11.dae</uri>
          </mesh>
        </geometry>
      </visual>
      <gravity>0</gravity>
      <self_collide>0</self_collide>
    </link>
    <joint name='RFinger12' type='revolute'>
      <pose relative_to='RFinger11_link'>0.018 0 0 0 0 -1.0472</pose>
      <parent>RFinger11_link</parent>
      <child>RFinger12_link</child>
      <axis>
        <xyz>0 0 1</xyz>
        <limit>
          <lower>-1e+16</lower>
          <upper>1e+16</upper>
        </limit>
        <dynamics>
          <spring_reference>0</spring_reference>
          <spring_stiffness>0</spring_stiffness>
        </dynamics>
      </axis>
    </joint>
    <link name='RFinger12_link'>
      <pose relative_to='RFinger12'>0 0 0 0 -0 0</pose>
      <inertial>
        <pose>0.0822134 -0.00014806 0.00693314 0 0 0</pose>
        <mass>0.001120173280473563</mass>
        <inertia>
          <ixx>2.2399645274771213e-06</ixx>
          <iyy>5.857267308530903e-06</iyy>
          <izz>6.447289917528821e-06</izz>
          <ixy>-2.1051209160614223e-08</ixy>
          <ixz>-1.1469882210322685e-07</ixz>
          <iyz>-3.257228780699206e-08</iyz>
        </inertia>
      </inertial>
      <collision name='RFinger12_link_collision'>
        <pose>0 0 0 0 -0 0</pose>
        <geometry>
          <mesh>
            <scale>0.1 0.1 0.1</scale>
            <uri>meshes/RFinger12_0.10.stl</uri>
          </mesh>
        </geometry>
        <surface>
          <contact>
            <ode/>
          </contact>
          <friction>
            <ode>
              <mu>0.5</mu>
              <mu2>0.5</mu2>
            </ode>
          </friction>
        </surface>
      </collision>
      <visual name='RFinger12_link_visual'>
        <pose>0 0 0 0 -0 0</pose>
        <geometry>
          <mesh>
            <scale>0.1 0.1 0.1</scale>
            <uri>meshes/RFinger12.dae</uri>
          </mesh>
        </geometry>
      </visual>
      <gravity>0</gravity>
      <self_collide>0</self_collide>
    </link>
    <joint name='RFinger13' type='revolute'>
      <pose relative_to='RFinger12_link'>0.018 0 0 0 0 -1.0472</pose>
      <parent>RFinger12_link</parent>
      <child>RFinger13_link</child>
      <axis>
        <xyz>0 0 1</xyz>
        <limit>
          <lower>-1e+16</lower>
          <upper>1e+16</upper>
        </limit>
        <dynamics>
          <spring_reference>0</spring_reference>
          <spring_stiffness>0</spring_stiffness>
        </dynamics>
      </axis>
    </joint>
    <link name='RFinger13_link'>
      <pose relative_to='RFinger13'>0 0 0 0 -0 0</pose>
      <inertial>
        <pose>0.0822134 -0.00014806 0.00693314 0 0 0</pose>
        <mass>0.001120173280473563</mass>
        <inertia>
          <ixx>1.3514400856623022e-06</ixx>
          <iyy>2.616011440033339e-06</iyy>
          <izz>2.8527734731145056e-06</izz>
          <ixy>-7.400691210596976e-08</ixy>
          <ixz>9.151486023074825e-09</ixz>
          <iyz>-3.684506183020308e-09</iyz>
        </inertia>
      </inertial>
      <collision name='RFinger13_link_collision'>
        <pose>0 0 0 0 -0 0</pose>
        <geometry>
          <mesh>
            <scale>0.1 0.1 0.1</scale>
            <uri>meshes/RFinger13_0.10.stl</uri>
          </mesh>
        </geometry>
        <surface>
          <contact>
            <ode/>
          </contact>
          <friction>
            <ode>
              <mu>0.5</mu>
              <mu2>0.5</mu2>
            </ode>
          </friction>
        </surface>
      </collision>
      <visual name='RFinger13_link_visual'>
        <pose>0 0 0 0 -0 0</pose>
        <geometry>
          <mesh>
            <scale>0.1 0.1 0.1</scale>
            <uri>meshes/RFinger13.dae</uri>
          </mesh>
        </geometry>
      </visual>
      <gravity>0</gravity>
      <self_collide>0</self_collide>
    </link>
    <joint name='RFinger21' type='revolute'>
      <pose relative_to='r_wrist'>0.0873 0.0073 0.006 1.5708 1.0472 0.061086</pose>
      <parent>r_wrist</parent>
      <child>RFinger21_link</child>
      <axis>
        <xyz>0 0 1</xyz>
        <limit>
          <lower>-1e+16</lower>
          <upper>1e+16</upper>
        </limit>
        <dynamics>
          <spring_reference>0</spring_reference>
          <spring_stiffness>0</spring_stiffness>
        </dynamics>
      </axis>
    </joint>
    <link name='RFinger21_link'>
      <pose relative_to='RFinger21'>0 0 0 0 -0 0</pose>
      <inertial>
        <pose>0.0822134 -0.00014806 0.00693313 0 0 0</pose>
        <mass>0.0011201732597173012</mass>
        <inertia>
          <ixx>2.2399644479160755e-06</ixx>
          <iyy>5.857267331712786e-06</iyy>
          <izz>6.447289918407904e-06</izz>
          <ixy>-2.1051261972475785e-08</ixy>
          <ixz>-1.1469878198528467e-07</ixz>
          <iyz>-3.257229153593606e-08</iyz>
        </inertia>
      </inertial>
      <collision name='RFinger21_link_collision'>
        <pose>0 0 0 0 -0 0</pose>
        <geometry>
          <mesh>
            <scale>0.1 0.1 0.1</scale>
            <uri>meshes/RFinger21_0.10.stl</uri>
          </mesh>
        </geometry>
        <surface>
          <contact>
            <ode/>
          </contact>
          <friction>
            <ode>
              <mu>0.5</mu>
              <mu2>0.5</mu2>
            </ode>
          </friction>
        </surface>
      </collision>
      <visual name='RFinger21_link_visual'>
        <pose>0 0 0 0 -0 0</pose>
        <geometry>
          <mesh>
            <scale>0.1 0.1 0.1</scale>
            <uri>meshes/RFinger21.dae</uri>
          </mesh>
        </geometry>
      </visual>
      <gravity>0</gravity>
      <self_collide>0</self_collide>
    </link>
    <joint name='RFinger22' type='revolute'>
      <pose relative_to='RFinger21_link'>0.018 0 0 0 0 -1.0472</pose>
      <parent>RFinger21_link</parent>
      <child>RFinger22_link</child>
      <axis>
        <xyz>0 0 1</xyz>
        <limit>
          <lower>-1e+16</lower>
          <upper>1e+16</upper>
        </limit>
        <dynamics>
          <spring_reference>0</spring_reference>
          <spring_stiffness>0</spring_stiffness>
        </dynamics>
      </axis>
    </joint>
    <link name='RFinger22_link'>
      <pose relative_to='RFinger22'>0 0 0 0 -0 0</pose>
      <inertial>
        <pose>0.0822134 -0.000148055 0.00693314 0 0 0</pose>
        <mass>0.0011201733759826358</mass>
        <inertia>
          <ixx>2.2399648501758626e-06</ixx>
          <iyy>5.85726879685795e-06</iyy>
          <izz>6.44729170156988e-06</izz>
          <ixy>-2.1051782341466184e-08</ixy>
          <ixz>-1.1469900474683047e-07</ixz>
          <iyz>-3.257237577272461e-08</iyz>
        </inertia>
      </inertial>
      <collision name='RFinger22_link_collision'>
        <pose>0 0 0 0 -0 0</pose>
        <geometry>
          <mesh>
            <scale>0.1 0.1 0.1</scale>
            <uri>meshes/RFinger22_0.10.stl</uri>
          </mesh>
        </geometry>
        <surface>
          <contact>
            <ode/>
          </contact>
          <friction>
            <ode>
              <mu>0.5</mu>
              <mu2>0.5</mu2>
            </ode>
          </friction>
        </surface>
      </collision>
      <visual name='RFinger22_link_visual'>
        <pose>0 0 0 0 -0 0</pose>
        <geometry>
          <mesh>
            <scale>0.1 0.1 0.1</scale>
            <uri>meshes/RFinger22.dae</uri>
          </mesh>
        </geometry>
      </visual>
      <gravity>0</gravity>
      <self_collide>0</self_collide>
    </link>
    <joint name='RFinger23' type='revolute'>
      <pose relative_to='RFinger22_link'>0.018 0 0 0 0 -1.0472</pose>
      <parent>RFinger22_link</parent>
      <child>RFinger23_link</child>
      <axis>
        <xyz>0 0 1</xyz>
        <limit>
          <lower>-1e+16</lower>
          <upper>1e+16</upper>
        </limit>
        <dynamics>
          <spring_reference>0</spring_reference>
          <spring_stiffness>0</spring_stiffness>
        </dynamics>
      </axis>
    </joint>
    <link name='RFinger23_link'>
      <pose relative_to='RFinger23'>0 0 0 0 -0 0</pose>
      <inertial>
        <pose>0.0575085 0.00266157 0.00909151 0 0 0</pose>
        <mass>0.0007828454384633327</mass>
        <inertia>
          <ixx>1.351439970167974e-06</ixx>
          <iyy>2.6160115979273665e-06</iyy>
          <izz>2.852773459758437e-06</izz>
          <ixy>-7.400693229502334e-08</ixy>
          <ixz>9.151413955035165e-09</ixz>
          <iyz>-3.684485886742615e-09</iyz>
        </inertia>
      </inertial>
      <collision name='RFinger23_link_collision'>
        <pose>0 0 0 0 -0 0</pose>
        <geometry>
          <mesh>
            <scale>0.1 0.1 0.1</scale>
            <uri>meshes/RFinger23_0.10.stl</uri>
          </mesh>
        </geometry>
        <surface>
          <contact>
            <ode/>
          </contact>
          <friction>
            <ode>
              <mu>0.5</mu>
              <mu2>0.5</mu2>
            </ode>
          </friction>
        </surface>
      </collision>
      <visual name='RFinger23_link_visual'>
        <pose>0 0 0 0 -0 0</pose>
        <geometry>
          <mesh>
            <scale>0.1 0.1 0.1</scale>
            <uri>meshes/RFinger23.dae</uri>
          </mesh>
        </geometry>
      </visual>
      <gravity>0</gravity>
      <self_collide>0</self_collide>
    </link>
    <joint name='RFinger31' type='revolute'>
      <pose relative_to='r_wrist'>0.0833 -0.0123 0.004 1.67523 1.04483 0.029316</pose>
      <parent>r_wrist</parent>
      <child>RFinger31_link</child>
      <axis>
        <xyz>0 0 1</xyz>
        <limit>
          <lower>-1e+16</lower>
          <upper>1e+16</upper>
        </limit>
        <dynamics>
          <spring_reference>0</spring_reference>
          <spring_stiffness>0</spring_stiffness>
        </dynamics>
      </axis>
    </joint>
    <link name='RFinger31_link'>
      <pose relative_to='RFinger31'>0 0 0 0 -0 0</pose>
      <inertial>
        <pose>0.0822134 -0.000148061 0.00693314 0 0 0</pose>
        <mass>0.0011201732747014332</mass>
        <inertia>
          <ixx>2.2399645418453573e-06</ixx>
          <iyy>5.857267163143072e-06</iyy>
          <izz>6.447289797996078e-06</izz>
          <ixy>-2.105118263739426e-08</ixy>
          <ixz>-1.1469879474942076e-07</ixz>
          <iyz>-3.2572326910287594e-08</iyz>
        </inertia>
      </inertial>
      <collision name='RFinger31_link_collision'>
        <pose>0 0 0 0 -0 0</pose>
        <geometry>
          <mesh>
            <scale>0.1 0.1 0.1</scale>
            <uri>meshes/RFinger31_0.10.stl</uri>
          </mesh>
        </geometry>
        <surface>
          <contact>
            <ode/>
          </contact>
          <friction>
            <ode>
              <mu>0.5</mu>
              <mu2>0.5</mu2>
            </ode>
          </friction>
        </surface>
      </collision>
      <visual name='RFinger31_link_visual'>
        <pose>0 0 0 0 -0 0</pose>
        <geometry>
          <mesh>
            <scale>0.1 0.1 0.1</scale>
            <uri>meshes/RFinger31.dae</uri>
          </mesh>
        </geometry>
      </visual>
      <gravity>0</gravity>
      <self_collide>0</self_collide>
    </link>
    <joint name='RFinger32' type='revolute'>
      <pose relative_to='RFinger31_link'>0.018 0 0 0 0 -1.0472</pose>
      <parent>RFinger31_link</parent>
      <child>RFinger32_link</child>
      <axis>
        <xyz>0 0 1</xyz>
        <limit>
          <lower>-1e+16</lower>
          <upper>1e+16</upper>
        </limit>
        <dynamics>
          <spring_reference>0</spring_reference>
          <spring_stiffness>0</spring_stiffness>
        </dynamics>
      </axis>
    </joint>
    <link name='RFinger32_link'>
      <pose relative_to='RFinger32'>0 0 0 0 -0 0</pose>
      <inertial>
        <pose>0.0822134 -0.00014806 0.00693314 0 0 0</pose>
        <mass>0.0011201732439064006</mass>
        <inertia>
          <ixx>2.2399644029094614e-06</ixx>
          <iyy>5.857267124242934e-06</iyy>
          <izz>6.44728970669286e-06</izz>
          <ixy>-2.1051241721856316e-08</ixy>
          <ixz>-1.1469885512024016e-07</ixz>
          <iyz>-3.257229922810809e-08</iyz>
        </inertia>
      </inertial>
      <collision name='RFinger32_link_collision'>
        <pose>0 0 0 0 -0 0</pose>
        <geometry>
          <mesh>
            <scale>0.1 0.1 0.1</scale>
            <uri>meshes/RFinger32_0.10.stl</uri>
          </mesh>
        </geometry>
        <surface>
          <contact>
            <ode/>
          </contact>
          <friction>
            <ode>
              <mu>0.5</mu>
              <mu2>0.5</mu2>
            </ode>
          </friction>
        </surface>
      </collision>
      <visual name='RFinger32_link_visual'>
        <pose>0 0 0 0 -0 0</pose>
        <geometry>
          <mesh>
            <scale>0.1 0.1 0.1</scale>
            <uri>meshes/RFinger32.dae</uri>
          </mesh>
        </geometry>
      </visual>
      <gravity>0</gravity>
      <self_collide>0</self_collide>
    </link>
    <joint name='RFinger33' type='revolute'>
      <pose relative_to='RFinger32_link'>0.018 0 0 0 0 -1.0472</pose>
      <parent>RFinger32_link</parent>
      <child>RFinger33_link</child>
      <axis>
        <xyz>0 0 1</xyz>
        <limit>
          <lower>-1e+16</lower>
          <upper>1e+16</upper>
        </limit>
        <dynamics>
          <spring_reference>0</spring_reference>
          <spring_stiffness>0</spring_stiffness>
        </dynamics>
      </axis>
    </joint>
    <link name='RFinger33_link'>
      <pose relative_to='RFinger33'>0 0 0 0 -0 0</pose>
      <inertial>
        <pose>0.0575085 0.00266156 0.00909151 0 0 0</pose>
        <mass>0.0007828455617553774</mass>
        <inertia>
          <ixx>1.3514404535774175e-06</ixx>
          <iyy>2.6160119801390183e-06</iyy>
          <izz>2.852773835331611e-06</izz>
          <ixy>-7.400689239274784e-08</ixy>
          <ixz>9.151607566553035e-09</ixz>
          <iyz>-3.6845075830067094e-09</iyz>
        </inertia>
      </inertial>
      <collision name='RFinger33_link_collision'>
        <pose>0 0 0 0 -0 0</pose>
        <geometry>
          <mesh>
            <scale>0.1 0.1 0.1</scale>
            <uri>meshes/RFinger33_0.10.stl</uri>
          </mesh>
        </geometry>
        <surface>
          <contact>
            <ode/>
          </contact>
          <friction>
            <ode>
              <mu>0.5</mu>
              <mu2>0.5</mu2>
            </ode>
          </friction>
        </surface>
      </collision>
      <visual name='RFinger33_link_visual'>
        <pose>0 0 0 0 -0 0</pose>
        <geometry>
          <mesh>
            <scale>0.1 0.1 0.1</scale>
            <uri>meshes/RFinger33.dae</uri>
          </mesh>
        </geometry>
      </visual>
      <gravity>0</gravity>
      <self_collide>0</self_collide>
    </link>
    <joint name='RFinger41' type='revolute'>
      <pose relative_to='r_wrist'>0.074 -0.0309 0 1.74402 1.04064 -0.068339</pose>
      <parent>r_wrist</parent>
      <child>RFinger41_link</child>
      <axis>
        <xyz>0 0 1</xyz>
        <limit>
          <lower>-1e+16</lower>
          <upper>1e+16</upper>
        </limit>
        <dynamics>
          <spring_reference>0</spring_reference>
          <spring_stiffness>0</spring_stiffness>
        </dynamics>
      </axis>
    </joint>
    <link name='RFinger41_link'>
      <pose relative_to='RFinger41'>0 0 0 0 -0 0</pose>
      <inertial>
        <pose>0.0822134 -0.000148061 0.00693314 0 0 0</pose>
        <mass>0.0011201732860576827</mass>
        <inertia>
          <ixx>2.2399645717590983e-06</ixx>
          <iyy>5.8572673274653036e-06</iyy>
          <izz>6.447289969027131e-06</izz>
          <ixy>-2.1051166080017066e-08</ixy>
          <ixz>-1.1469882666607233e-07</ixz>
          <iyz>-3.2572325972142886e-08</iyz>
        </inertia>
      </inertial>
      <collision name='RFinger41_link_collision'>
        <pose>0 0 0 0 -0 0</pose>
        <geometry>
          <mesh>
            <scale>0.1 0.1 0.1</scale>
            <uri>meshes/RFinger41_0.10.stl</uri>
          </mesh>
        </geometry>
        <surface>
          <contact>
            <ode/>
          </contact>
          <friction>
            <ode>
              <mu>0.5</mu>
              <mu2>0.5</mu2>
            </ode>
          </friction>
        </surface>
      </collision>
      <visual name='RFinger41_link_visual'>
        <pose>0 0 0 0 -0 0</pose>
        <geometry>
          <mesh>
            <scale>0.1 0.1 0.1</scale>
            <uri>meshes/RFinger41.dae</uri>
          </mesh>
        </geometry>
      </visual>
      <gravity>0</gravity>
      <self_collide>0</self_collide>
    </link>
    <joint name='RFinger42' type='revolute'>
      <pose relative_to='RFinger41_link'>0.018 0 0 0 0 -1.0472</pose>
      <parent>RFinger41_link</parent>
      <child>RFinger42_link</child>
      <axis>
        <xyz>0 0 1</xyz>
        <limit>
          <lower>-1e+16</lower>
          <upper>1e+16</upper>
        </limit>
        <dynamics>
          <spring_reference>0</spring_reference>
          <spring_stiffness>0</spring_stiffness>
        </dynamics>
      </axis>
    </joint>
    <link name='RFinger42_link'>
      <pose relative_to='RFinger42'>0 0 0 0 -0 0</pose>
      <inertial>
        <pose>0.0822134 -0.00014806 0.00693314 0 0 0</pose>
        <mass>0.0011201732395139717</mass>
        <inertia>
          <ixx>2.239964391403848e-06</ixx>
          <iyy>5.8572670959106235e-06</iyy>
          <izz>6.447289672897159e-06</izz>
          <ixy>-2.1051247654377564e-08</ixy>
          <ixz>-1.1469885243760228e-07</ixz>
          <iyz>-3.257230366135826e-08</iyz>
        </inertia>
      </inertial>
      <collision name='RFinger42_link_collision'>
        <pose>0 0 0 0 -0 0</pose>
        <geometry>
          <mesh>
            <scale>0.1 0.1 0.1</scale>
            <uri>meshes/RFinger42_0.10.stl</uri>
          </mesh>
        </geometry>
        <surface>
          <contact>
            <ode/>
          </contact>
          <friction>
            <ode>
              <mu>0.5</mu>
              <mu2>0.5</mu2>
            </ode>
          </friction>
        </surface>
      </collision>
      <visual name='RFinger42_link_visual'>
        <pose>0 0 0 0 -0 0</pose>
        <geometry>
          <mesh>
            <scale>0.1 0.1 0.1</scale>
            <uri>meshes/RFinger42.dae</uri>
          </mesh>
        </geometry>
      </visual>
      <gravity>0</gravity>
      <self_collide>0</self_collide>
    </link>
    <joint name='RFinger43' type='revolute'>
      <pose relative_to='RFinger42_link'>0.018 0 0 0 0 -1.0472</pose>
      <parent>RFinger42_link</parent>
      <child>RFinger43_link</child>
      <axis>
        <xyz>0 0 1</xyz>
        <limit>
          <lower>-1e+16</lower>
          <upper>1e+16</upper>
        </limit>
        <dynamics>
          <spring_reference>0</spring_reference>
          <spring_stiffness>0</spring_stiffness>
        </dynamics>
      </axis>
    </joint>
    <link name='RFinger43_link'>
      <pose relative_to='RFinger43'>0 0 0 0 -0 0</pose>
      <inertial>
        <pose>0.0575085 0.00266156 0.00909151 0 0 0</pose>
        <mass>0.0007828453978485874</mass>
        <inertia>
          <ixx>1.3514398959634833e-06</ixx>
          <iyy>2.6160112824212533e-06</iyy>
          <izz>2.8527732955629684e-06</izz>
          <ixy>-7.400684989673474e-08</ixy>
          <ixz>9.151625902768317e-09</ixz>
          <iyz>-3.6844681799755328e-09</iyz>
        </inertia>
      </inertial>
      <collision name='RFinger43_link_collision'>
        <pose>0 0 0 0 -0 0</pose>
        <geometry>
          <mesh>
            <scale>0.1 0.1 0.1</scale>
            <uri>meshes/RFinger43_0.10.stl</uri>
          </mesh>
        </geometry>
        <surface>
          <contact>
            <ode/>
          </contact>
          <friction>
            <ode>
              <mu>0.5</mu>
              <mu2>0.5</mu2>
            </ode>
          </friction>
        </surface>
      </collision>
      <visual name='RFinger43_link_visual'>
        <pose>0 0 0 0 -0 0</pose>
        <geometry>
          <mesh>
            <scale>0.1 0.1 0.1</scale>
            <uri>meshes/RFinger43.dae</uri>
          </mesh>
        </geometry>
      </visual>
      <gravity>0</gravity>
      <self_collide>0</self_collide>
    </link>
    <joint name='RThumb1' type='revolute'>
      <pose relative_to='r_wrist'>0.0482 0.0357 -0.0199 -1.18323 0.60626 -0.533978</pose>
      <parent>r_wrist</parent>
      <child>RThumb1_link</child>
      <axis>
        <xyz>0 0 1</xyz>
        <limit>
          <lower>-1e+16</lower>
          <upper>1e+16</upper>
        </limit>
        <dynamics>
          <spring_reference>0</spring_reference>
          <spring_stiffness>0</spring_stiffness>
        </dynamics>
      </axis>
    </joint>
    <link name='RThumb1_link'>
      <pose relative_to='RThumb1'>0 0 0 0 -0 0</pose>
      <inertial>
        <pose>0.0822134 -0.00014806 0.00693314 0 0 0</pose>
        <mass>0.0011201732919619983</mass>
        <inertia>
          <ixx>2.239964554584989e-06</ixx>
          <iyy>5.8572675480624046e-06</iyy>
          <izz>6.447290205058348e-06</izz>
          <ixy>-2.1051187626936403e-08</ixy>
          <ixz>-1.1469879111272574e-07</ixz>
          <iyz>-3.257227751141546e-08</iyz>
        </inertia>
      </inertial>
      <collision name='RThumb1_link_collision'>
        <pose>0 0 0 0 -0 0</pose>
        <geometry>
          <mesh>
            <scale>0.1 0.1 0.1</scale>
            <uri>meshes/RThumb1_0.10.stl</uri>
          </mesh>
        </geometry>
        <surface>
          <contact>
            <ode/>
          </contact>
          <friction>
            <ode>
              <mu>0.5</mu>
              <mu2>0.5</mu2>
            </ode>
          </friction>
        </surface>
      </collision>
      <visual name='RThumb1_link_visual'>
        <pose>0 0 0 0 -0 0</pose>
        <geometry>
          <mesh>
            <scale>0.1 0.1 0.1</scale>
            <uri>meshes/RThumb1.dae</uri>
          </mesh>
        </geometry>
      </visual>
      <gravity>0</gravity>
      <self_collide>0</self_collide>
    </link>
    <joint name='RThumb2' type='revolute'>
      <pose relative_to='RThumb1_link'>0.022 0 0 0 0 -1.0472</pose>
      <parent>RThumb1_link</parent>
      <child>RThumb2_link</child>
      <axis>
        <xyz>0 0 1</xyz>
        <limit>
          <lower>-1e+16</lower>
          <upper>1e+16</upper>
        </limit>
        <dynamics>
          <spring_reference>0</spring_reference>
          <spring_stiffness>0</spring_stiffness>
        </dynamics>
      </axis>
    </joint>
    <link name='RThumb2_link'>
      <pose relative_to='RThumb2'>0 0 0 0 -0 0</pose>
      <inertial>
        <pose>0.0575085 0.00263446 0.00891102 0 0 0</pose>
        <mass>0.0007828454459212576</mass>
        <inertia>
          <ixx>1.3514400856623022e-06</ixx>
          <iyy>2.616011440033339e-06</iyy>
          <izz>2.8527734731145056e-06</izz>
          <ixy>-7.400691210596976e-08</ixy>
          <ixz>9.151486023074825e-09</ixz>
          <iyz>-3.684506183020308e-09</iyz>
        </inertia>
      </inertial>
      <collision name='RThumb2_link_collision'>
        <pose>0 0 0 0 -0 0</pose>
        <geometry>
          <mesh>
            <scale>0.1 0.1 0.1</scale>
            <uri>meshes/RThumb2_0.10.stl</uri>
          </mesh>
        </geometry>
        <surface>
          <contact>
            <ode/>
          </contact>
          <friction>
            <ode>
              <mu>0.5</mu>
              <mu2>0.5</mu2>
            </ode>
          </friction>
        </surface>
      </collision>
      <visual name='RThumb2_link_visual'>
        <pose>0 0 0 0 -0 0</pose>
        <geometry>
          <mesh>
            <scale>0.1 0.1 0.1</scale>
            <uri>meshes/RThumb2.dae</uri>
          </mesh>
        </geometry>
      </visual>
      <gravity>0</gravity>
      <self_collide>0</self_collide>
    </link>
    <joint name='WheelB' type='revolute'>
      <pose relative_to='base_link'>-0.17 0 0.07 0 0 -3.14159</pose>
      <parent>base_link</parent>
      <child>WheelB_link</child>
      <axis>
        <xyz>1 0 0</xyz>
        <limit>
          <effort>3.25</effort>
          <velocity>6.28319</velocity>
          <lower>-1e+16</lower>
          <upper>1e+16</upper>
        </limit>
        <dynamics>
          <spring_reference>0</spring_reference>
          <spring_stiffness>0</spring_stiffness>
        </dynamics>
      </axis>
    </joint>
    <link name='WheelB_link'>
      <pose relative_to='WheelB'>0 0 0 0 -0 0</pose>
      <inertial>
        <pose>1.19122e-06 -8.10876e-08 1.02822e-07 0 0 0</pose>
        <mass>0.48933656208236065</mass>
        <inertia>
          <ixx>0.0947370348539352</ixx>
          <iyy>0.09395851191881509</iyy>
          <izz>0.09473702619875725</izz>
          <ixy>1.3982028027262244e-09</ixy>
          <ixz>-1.0362585405612502e-08</ixz>
          <iyz>6.256749163974279e-10</iyz>
        </inertia>
      </inertial>
      <collision name='WheelB_link_collision'>
        <pose>0 0 0 0 -0 0</pose>
        <geometry>
          <mesh>
            <scale>0.1 0.1 0.1</scale>
            <uri>meshes/WheelB_0.10.stl</uri>
          </mesh>
        </geometry>
        <surface>
          <contact>
            <ode>
              <kp>1e+07</kp>
              <kd>1</kd>
              <min_depth>0.003</min_depth>
            </ode>
          </contact>
          <friction>
            <ode>
              <mu>0.5</mu>
              <mu2>0.5</mu2>
              <fdir1>1 0 0</fdir1>
            </ode>
          </friction>
        </surface>
      </collision>
      <visual name='WheelB_link_visual'>
        <pose>0 0 0 0 -0 0</pose>
        <geometry>
          <mesh>
            <scale>0.1 0.1 0.1</scale>
            <uri>meshes/WheelB.dae</uri>
          </mesh>
        </geometry>
      </visual>
      <gravity>0</gravity>
    </link>
    <joint name='WheelFL' type='revolute'>
      <pose relative_to='base_link'>0.09 0.155 0.07 0 -0 1.07517</pose>
      <parent>base_link</parent>
      <child>WheelFL_link</child>
      <axis>
        <xyz>1 0 0</xyz>
        <limit>
          <effort>3.25</effort>
          <velocity>6.28319</velocity>
          <lower>-1e+16</lower>
          <upper>1e+16</upper>
        </limit>
        <dynamics>
          <spring_reference>0</spring_reference>
          <spring_stiffness>0</spring_stiffness>
        </dynamics>
      </axis>
    </joint>
    <link name='WheelFL_link'>
      <pose relative_to='WheelFL'>0 0 0 0 -0 0</pose>
      <inertial>
        <pose>-6.00045e-07 6.99637e-07 9.85261e-08 0 0 0</pose>
        <mass>0.4893365693716646</mass>
        <inertia>
          <ixx>0.09473703500486667</ixx>
          <iyy>0.09395851333488305</iyy>
          <izz>0.0947370317007306</izz>
          <ixy>8.975128673698389e-10</ixy>
          <ixz>-1.1935120982576105e-08</ixz>
          <iyz>-1.0868187680479218e-10</iyz>
        </inertia>
      </inertial>
      <collision name='WheelFL_link_collision'>
        <pose>0 0 0 0 -0 0</pose>
        <geometry>
          <mesh>
            <scale>0.1 0.1 0.1</scale>
            <uri>meshes/WheelFL_0.10.stl</uri>
          </mesh>
        </geometry>
        <surface>
          <contact>
            <ode>
              <kp>1e+07</kp>
              <kd>1</kd>
              <min_depth>0.003</min_depth>
            </ode>
          </contact>
          <friction>
            <ode>
              <mu>1</mu>
              <mu2>0</mu2>
              <fdir1>1 0 0</fdir1>
            </ode>
          </friction>
        </surface>
      </collision>
      <visual name='WheelFL_link_visual'>
        <pose>0 0 0 0 -0 0</pose>
        <geometry>
          <mesh>
            <scale>0.1 0.1 0.1</scale>
            <uri>meshes/WheelFL.dae</uri>
          </mesh>
        </geometry>
      </visual>
      <gravity>0</gravity>
    </link>
    <joint name='WheelFR' type='revolute'>
      <pose relative_to='base_link'>0.09 -0.155 0.07 0 0 -1.07517</pose>
      <parent>base_link</parent>
      <child>WheelFR_link</child>
      <axis>
        <xyz>1 0 0</xyz>
        <limit>
          <effort>3.25</effort>
          <velocity>6.28319</velocity>
          <lower>-1e+16</lower>
          <upper>1e+16</upper>
        </limit>
        <dynamics>
          <spring_reference>0</spring_reference>
          <spring_stiffness>0</spring_stiffness>
        </dynamics>
      </axis>
    </joint>
    <link name='WheelFR_link'>
      <pose relative_to='WheelFR'>0 0 0 0 -0 0</pose>
      <inertial>
        <pose>1.47446e-07 -8.33076e-07 9.57624e-08 0 0 0</pose>
        <mass>0.48933654778767033</mass>
        <inertia>
          <ixx>0.09473702694105678</ixx>
          <iyy>0.09395850798069462</iyy>
          <izz>0.09473702422619991</izz>
          <ixy>-8.380692547505272e-10</ixy>
          <ixz>-1.1277578590072926e-08</ixz>
          <iyz>1.4195272650080792e-10</iyz>
        </inertia>
      </inertial>
      <collision name='WheelFR_link_collision'>
        <pose>0 0 0 0 -0 0</pose>
        <geometry>
          <mesh>
            <scale>0.1 0.1 0.1</scale>
            <uri>meshes/WheelFR_0.10.stl</uri>
          </mesh>
        </geometry>
        <surface>
          <contact>
            <ode>
              <kp>1e+07</kp>
              <kd>1</kd>
              <min_depth>0.003</min_depth>
            </ode>
          </contact>
          <friction>
            <ode>
              <mu>0</mu>
              <mu2>1</mu2>
              <fdir1>0 1 0</fdir1>
            </ode>
          </friction>
        </surface>
      </collision>
      <visual name='WheelFR_link_visual'>
        <pose>0 0 0 0 -0 0</pose>
        <geometry>
          <mesh>
            <scale>0.1 0.1 0.1</scale>
            <uri>meshes/WheelFR.dae</uri>
          </mesh>
        </geometry>
      </visual>
      <gravity>0</gravity>
    </link>
    <plugin name='ignition::gazebo::systems::DiffDrive' filename='ignition-gazebo-diff-drive-system'>
      <left_joint>WheelFL</left_joint>
      <right_joint>WheelFR</right_joint>
      <back_joint>WheelB</back_joint>
      <wheel_separation>0.170</wheel_separation>
      <wheel_radius>0.07</wheel_radius>
    </plugin>
    <plugin name='ign_ros2_control::IgnitionROS2ControlPlugin' filename='ign_ros2_control-system'>
      <parameters>/root/ws/src/pepper_ign_moveit2/pepper_robot_moveit_config/config/controllers_effort.yaml</parameters>
    </plugin>
    <static>0</static>
    <plugin name='ignition::gazebo::systems::PosePublisher' filename='ignition-gazebo-pose-publisher-system'>
      <use_pose_vector_msg>1</use_pose_vector_msg>
      <publish_nested_model_pose>1</publish_nested_model_pose>
      <publish_link_pose>0</publish_link_pose>
      <publish_collision_pose>0</publish_collision_pose>
      <publish_visual_pose>0</publish_visual_pose>
    </plugin>
  </model>
</sdf>