<?xml version="1.0" ?>
<robot name="pepper_robot" xmlns:xacro="http://www.ros.org/wiki/xacro">
    <material name="LightGrey">
        <texture />
        <color rgba="0.9 0.9 0.9 1" />
    </material>
    <link name="BumperB" />
    <link name="BumperFL" />
    <link name="BumperFR" />
    <link name="CameraBottom" />
    <link name="CameraDepth" />
    <link name="CameraTop" />
    <link name="Gaze" />
    <link name="Head" />
    <link name="HeadPitch" />
    <link name="HeadPitchSphereCollision_shape">
        <collision>
            <origin xyz="0 0 0" rpy="0 -0 0" />
            <geometry>
                <sphere radius="0.11" />
            </geometry>
        </collision>
    </link>
    <link name="HeadYaw" />
    <link name="HipPitch" />
    <link name="HipPitchPillCollision_shape">
        <collision>
            <origin xyz="0 0 0" rpy="0 -0 0" />
            <geometry>
                <cylinder radius="0.1275" length="0.355" />
            </geometry>
        </collision>
    </link>
    <link name="HipPitchSphereCollision_shape">
        <collision>
            <origin xyz="0 0 0" rpy="0 -0 0" />
            <geometry>
                <sphere radius="0.095" />
            </geometry>
        </collision>
    </link>
    <link name="HipRoll" />
    <link name="KneePitch" />
    <link name="LArm" />
    <link name="LArmFuse" />
    <link name="LElbowRoll" />
    <link name="LElbowRollDynamicCollision_shape">
        <collision>
            <origin xyz="0 0 0" rpy="0 -0 0" />
            <geometry>
                <cylinder radius="0.035" length="0.27" />
            </geometry>
        </collision>
    </link>
    <link name="LElbowRollPillCollision_shape">
        <collision>
            <origin xyz="0 0 0" rpy="0 -0 0" />
            <geometry>
                <cylinder radius="0.035" length="0.2" />
            </geometry>
        </collision>
    </link>
    <link name="LElbowRollSphereACollision_shape">
        <collision>
            <origin xyz="0 0 0" rpy="0 -0 0" />
            <geometry>
                <sphere radius="0.035" />
            </geometry>
        </collision>
    </link>
    <link name="LElbowRollSphereBCollision_shape">
        <collision>
            <origin xyz="0 0 0" rpy="0 -0 0" />
            <geometry>
                <sphere radius="0.035" />
            </geometry>
        </collision>
    </link>
    <link name="LElbowRollSphereCCollision_shape">
        <collision>
            <origin xyz="0 0 0" rpy="0 -0 0" />
            <geometry>
                <sphere radius="0.035" />
            </geometry>
        </collision>
    </link>
    <link name="LElbowRollSphereDCollision_shape">
        <collision>
            <origin xyz="0 0 0" rpy="0 -0 0" />
            <geometry>
                <sphere radius="0.035" />
            </geometry>
        </collision>
    </link>
    <link name="LElbowYaw" />
    <link name="LFinger11_link">
        <visual>
            <origin xyz="0 0 0" rpy="0 -0 0" />
            <geometry>
                <mesh filename="package://pepper_robot_description/pepper_robot/meshes/LFinger11.dae" scale="1 1 1" />
            </geometry>
            <material name="LightGrey">
                <texture />
                <color rgba="0.9 0.9 0.9 1" />
            </material>
        </visual>
    </link>
    <link name="LFinger12_link">
        <visual>
            <origin xyz="0 0 0" rpy="0 -0 0" />
            <geometry>
                <mesh filename="package://pepper_robot_description/pepper_robot/meshes/LFinger12.dae" scale="1 1 1" />
            </geometry>
            <material name="LightGrey">
                <texture />
                <color rgba="0.9 0.9 0.9 1" />
            </material>
        </visual>
    </link>
    <link name="LFinger13_link">
        <visual>
            <origin xyz="0 0 0" rpy="0 -0 0" />
            <geometry>
                <mesh filename="package://pepper_robot_description/pepper_robot/meshes/LFinger13.dae" scale="1 1 1" />
            </geometry>
            <material name="LightGrey">
                <texture />
                <color rgba="0.9 0.9 0.9 1" />
            </material>
        </visual>
    </link>
    <link name="LFinger21_link">
        <visual>
            <origin xyz="0 0 0" rpy="0 -0 0" />
            <geometry>
                <mesh filename="package://pepper_robot_description/pepper_robot/meshes/LFinger21.dae" scale="1 1 1" />
            </geometry>
            <material name="LightGrey">
                <texture />
                <color rgba="0.9 0.9 0.9 1" />
            </material>
        </visual>
    </link>
    <link name="LFinger22_link">
        <visual>
            <origin xyz="0 0 0" rpy="0 -0 0" />
            <geometry>
                <mesh filename="package://pepper_robot_description/pepper_robot/meshes/LFinger22.dae" scale="1 1 1" />
            </geometry>
            <material name="LightGrey">
                <texture />
                <color rgba="0.9 0.9 0.9 1" />
            </material>
        </visual>
    </link>
    <link name="LFinger23_link">
        <visual>
            <origin xyz="0 0 0" rpy="0 -0 0" />
            <geometry>
                <mesh filename="package://pepper_robot_description/pepper_robot/meshes/LFinger23.dae" scale="1 1 1" />
            </geometry>
            <material name="LightGrey">
                <texture />
                <color rgba="0.9 0.9 0.9 1" />
            </material>
        </visual>
    </link>
    <link name="LFinger31_link">
        <visual>
            <origin xyz="0 0 0" rpy="0 -0 0" />
            <geometry>
                <mesh filename="package://pepper_robot_description/pepper_robot/meshes/LFinger31.dae" scale="1 1 1" />
            </geometry>
            <material name="LightGrey">
                <texture />
                <color rgba="0.9 0.9 0.9 1" />
            </material>
        </visual>
    </link>
    <link name="LFinger32_link">
        <visual>
            <origin xyz="0 0 0" rpy="0 -0 0" />
            <geometry>
                <mesh filename="package://pepper_robot_description/pepper_robot/meshes/LFinger32.dae" scale="1 1 1" />
            </geometry>
            <material name="LightGrey">
                <texture />
                <color rgba="0.9 0.9 0.9 1" />
            </material>
        </visual>
    </link>
    <link name="LFinger33_link">
        <visual>
            <origin xyz="0 0 0" rpy="0 -0 0" />
            <geometry>
                <mesh filename="package://pepper_robot_description/pepper_robot/meshes/LFinger33.dae" scale="1 1 1" />
            </geometry>
            <material name="LightGrey">
                <texture />
                <color rgba="0.9 0.9 0.9 1" />
            </material>
        </visual>
    </link>
    <link name="LFinger41_link">
        <visual>
            <origin xyz="0 0 0" rpy="0 -0 0" />
            <geometry>
                <mesh filename="package://pepper_robot_description/pepper_robot/meshes/LFinger41.dae" scale="1 1 1" />
            </geometry>
            <material name="LightGrey">
                <texture />
                <color rgba="0.9 0.9 0.9 1" />
            </material>
        </visual>
    </link>
    <link name="LFinger42_link">
        <visual>
            <origin xyz="0 0 0" rpy="0 -0 0" />
            <geometry>
                <mesh filename="package://pepper_robot_description/pepper_robot/meshes/LFinger42.dae" scale="1 1 1" />
            </geometry>
            <material name="LightGrey">
                <texture />
                <color rgba="0.9 0.9 0.9 1" />
            </material>
        </visual>
    </link>
    <link name="LFinger43_link">
        <visual>
            <origin xyz="0 0 0" rpy="0 -0 0" />
            <geometry>
                <mesh filename="package://pepper_robot_description/pepper_robot/meshes/LFinger43.dae" scale="1 1 1" />
            </geometry>
            <material name="LightGrey">
                <texture />
                <color rgba="0.9 0.9 0.9 1" />
            </material>
        </visual>
    </link>
    <link name="LShoulderPitch" />
    <link name="LShoulderRoll" />
    <link name="LThumb1_link">
        <visual>
            <origin xyz="0 0 0" rpy="0 -0 0" />
            <geometry>
                <mesh filename="package://pepper_robot_description/pepper_robot/meshes/LThumb1.dae" scale="1 1 1" />
            </geometry>
            <material name="LightGrey">
                <texture />
                <color rgba="0.9 0.9 0.9 1" />
            </material>
        </visual>
    </link>
    <link name="LThumb2_link">
        <visual>
            <origin xyz="0 0 0" rpy="0 -0 0" />
            <geometry>
                <mesh filename="package://pepper_robot_description/pepper_robot/meshes/LThumb2.dae" scale="1 1 1" />
            </geometry>
            <material name="LightGrey">
                <texture />
                <color rgba="0.9 0.9 0.9 1" />
            </material>
        </visual>
    </link>
    <link name="LWristYaw" />
    <link name="LWristYawSphereCollision_shape">
        <collision>
            <origin xyz="0 0 0" rpy="0 -0 0" />
            <geometry>
                <sphere radius="0.052" />
            </geometry>
        </collision>
    </link>
    <link name="RElbowRoll" />
    <link name="RElbowRollDynamicCollision_shape">
        <collision>
            <origin xyz="0 0 0" rpy="0 -0 0" />
            <geometry>
                <cylinder radius="0.035" length="0.27" />
            </geometry>
        </collision>
    </link>
    <link name="RElbowRollPillCollision_shape">
        <collision>
            <origin xyz="0 0 0" rpy="0 -0 0" />
            <geometry>
                <cylinder radius="0.035" length="0.2" />
            </geometry>
        </collision>
    </link>
    <link name="RElbowRollSphereACollision_shape">
        <collision>
            <origin xyz="0 0 0" rpy="0 -0 0" />
            <geometry>
                <sphere radius="0.035" />
            </geometry>
        </collision>
    </link>
    <link name="RElbowRollSphereBCollision_shape">
        <collision>
            <origin xyz="0 0 0" rpy="0 -0 0" />
            <geometry>
                <sphere radius="0.035" />
            </geometry>
        </collision>
    </link>
    <link name="RElbowRollSphereCCollision_shape">
        <collision>
            <origin xyz="0 0 0" rpy="0 -0 0" />
            <geometry>
                <sphere radius="0.035" />
            </geometry>
        </collision>
    </link>
    <link name="RElbowRollSphereDCollision_shape">
        <collision>
            <origin xyz="0 0 0" rpy="0 -0 0" />
            <geometry>
                <sphere radius="0.035" />
            </geometry>
        </collision>
    </link>
    <link name="RElbowYaw" />
    <link name="RFinger11_link">
        <visual>
            <origin xyz="0 0 0" rpy="0 -0 0" />
            <geometry>
                <mesh filename="package://pepper_robot_description/pepper_robot/meshes/RFinger11.dae" scale="1 1 1" />
            </geometry>
            <material name="LightGrey">
                <texture />
                <color rgba="0.9 0.9 0.9 1" />
            </material>
        </visual>
    </link>
    <link name="RFinger12_link">
        <visual>
            <origin xyz="0 0 0" rpy="0 -0 0" />
            <geometry>
                <mesh filename="package://pepper_robot_description/pepper_robot/meshes/RFinger12.dae" scale="1 1 1" />
            </geometry>
            <material name="LightGrey">
                <texture />
                <color rgba="0.9 0.9 0.9 1" />
            </material>
        </visual>
    </link>
    <link name="RFinger13_link">
        <visual>
            <origin xyz="0 0 0" rpy="0 -0 0" />
            <geometry>
                <mesh filename="package://pepper_robot_description/pepper_robot/meshes/RFinger13.dae" scale="1 1 1" />
            </geometry>
            <material name="LightGrey">
                <texture />
                <color rgba="0.9 0.9 0.9 1" />
            </material>
        </visual>
    </link>
    <link name="RFinger21_link">
        <visual>
            <origin xyz="0 0 0" rpy="0 -0 0" />
            <geometry>
                <mesh filename="package://pepper_robot_description/pepper_robot/meshes/RFinger21.dae" scale="1 1 1" />
            </geometry>
            <material name="LightGrey">
                <texture />
                <color rgba="0.9 0.9 0.9 1" />
            </material>
        </visual>
    </link>
    <link name="RFinger22_link">
        <visual>
            <origin xyz="0 0 0" rpy="0 -0 0" />
            <geometry>
                <mesh filename="package://pepper_robot_description/pepper_robot/meshes/RFinger22.dae" scale="1 1 1" />
            </geometry>
            <material name="LightGrey">
                <texture />
                <color rgba="0.9 0.9 0.9 1" />
            </material>
        </visual>
    </link>
    <link name="RFinger23_link">
        <visual>
            <origin xyz="0 0 0" rpy="0 -0 0" />
            <geometry>
                <mesh filename="package://pepper_robot_description/pepper_robot/meshes/RFinger23.dae" scale="1 1 1" />
            </geometry>
            <material name="LightGrey">
                <texture />
                <color rgba="0.9 0.9 0.9 1" />
            </material>
        </visual>
    </link>
    <link name="RFinger31_link">
        <visual>
            <origin xyz="0 0 0" rpy="0 -0 0" />
            <geometry>
                <mesh filename="package://pepper_robot_description/pepper_robot/meshes/RFinger31.dae" scale="1 1 1" />
            </geometry>
            <material name="LightGrey">
                <texture />
                <color rgba="0.9 0.9 0.9 1" />
            </material>
        </visual>
    </link>
    <link name="RFinger32_link">
        <visual>
            <origin xyz="0 0 0" rpy="0 -0 0" />
            <geometry>
                <mesh filename="package://pepper_robot_description/pepper_robot/meshes/RFinger32.dae" scale="1 1 1" />
            </geometry>
            <material name="LightGrey">
                <texture />
                <color rgba="0.9 0.9 0.9 1" />
            </material>
        </visual>
    </link>
    <link name="RFinger33_link">
        <visual>
            <origin xyz="0 0 0" rpy="0 -0 0" />
            <geometry>
                <mesh filename="package://pepper_robot_description/pepper_robot/meshes/RFinger33.dae" scale="1 1 1" />
            </geometry>
            <material name="LightGrey">
                <texture />
                <color rgba="0.9 0.9 0.9 1" />
            </material>
        </visual>
    </link>
    <link name="RFinger41_link">
        <visual>
            <origin xyz="0 0 0" rpy="0 -0 0" />
            <geometry>
                <mesh filename="package://pepper_robot_description/pepper_robot/meshes/RFinger41.dae" scale="1 1 1" />
            </geometry>
            <material name="LightGrey">
                <texture />
                <color rgba="0.9 0.9 0.9 1" />
            </material>
        </visual>
    </link>
    <link name="RFinger42_link">
        <visual>
            <origin xyz="0 0 0" rpy="0 -0 0" />
            <geometry>
                <mesh filename="package://pepper_robot_description/pepper_robot/meshes/RFinger42.dae" scale="1 1 1" />
            </geometry>
            <material name="LightGrey">
                <texture />
                <color rgba="0.9 0.9 0.9 1" />
            </material>
        </visual>
    </link>
    <link name="RFinger43_link">
        <visual>
            <origin xyz="0 0 0" rpy="0 -0 0" />
            <geometry>
                <mesh filename="package://pepper_robot_description/pepper_robot/meshes/RFinger43.dae" scale="1 1 1" />
            </geometry>
            <material name="LightGrey">
                <texture />
                <color rgba="0.9 0.9 0.9 1" />
            </material>
        </visual>
    </link>
    <link name="RShoulderPitch" />
    <link name="RShoulderRoll" />
    <link name="RThumb1_link">
        <visual>
            <origin xyz="0 0 0" rpy="0 -0 0" />
            <geometry>
                <mesh filename="package://pepper_robot_description/pepper_robot/meshes/RThumb1.dae" scale="1 1 1" />
            </geometry>
            <material name="LightGrey">
                <texture />
                <color rgba="0.9 0.9 0.9 1" />
            </material>
        </visual>
    </link>
    <link name="RThumb2_link">
        <visual>
            <origin xyz="0 0 0" rpy="0 -0 0" />
            <geometry>
                <mesh filename="package://pepper_robot_description/pepper_robot/meshes/RThumb2.dae" scale="1 1 1" />
            </geometry>
            <material name="LightGrey">
                <texture />
                <color rgba="0.9 0.9 0.9 1" />
            </material>
        </visual>
    </link>
    <link name="RWristYaw" />
    <link name="RWristYawSphereCollision_shape">
        <collision>
            <origin xyz="0 0 0" rpy="0 -0 0" />
            <geometry>
                <sphere radius="0.052" />
            </geometry>
        </collision>
    </link>
    <link name="SonarBack" />
    <link name="SonarFront" />
    <link name="TorsoBackLeftSphereCollision_shape">
        <collision>
            <origin xyz="0 0 0" rpy="0 -0 0" />
            <geometry>
                <sphere radius="0.08" />
            </geometry>
        </collision>
    </link>
    <link name="TorsoBackRightSphereCollision_shape">
        <collision>
            <origin xyz="0 0 0" rpy="0 -0 0" />
            <geometry>
                <sphere radius="0.08" />
            </geometry>
        </collision>
    </link>
    <link name="TorsoSphereBackCollision_shape">
        <collision>
            <origin xyz="0 0 0" rpy="0 -0 0" />
            <geometry>
                <sphere radius="0.1" />
            </geometry>
        </collision>
    </link>
    <link name="TorsoSphereLeftCollision_shape">
        <collision>
            <origin xyz="0 0 0" rpy="0 -0 0" />
            <geometry>
                <sphere radius="0.07" />
            </geometry>
        </collision>
    </link>
    <link name="TorsoSphereRightCollision_shape">
        <collision>
            <origin xyz="0 0 0" rpy="0 -0 0" />
            <geometry>
                <sphere radius="0.07" />
            </geometry>
        </collision>
    </link>
    <link name="TorsoTabCollision_shape">
        <collision>
            <origin xyz="0 0 0" rpy="0 -0 0" />
            <geometry>
                <box size="0.2 0.256 0.1" />
            </geometry>
        </collision>
    </link>
    <link name="torso_link">
        <inertial>
            <mass value="3.99533" />
            <origin xyz="0.00322 0 -0.01029" rpy="0 -0 0" />
            <inertia ixx="0.0452761" ixy="0" ixz="0.00499091" iyy="0.0432702" iyz="-0.000266886" izz="0.0258881" />
        </inertial>
        <visual>
            <origin xyz="0 0 0" rpy="0 -0 0" />
            <geometry>
                <mesh filename="package://pepper_robot_description/pepper_robot/meshes/Torso.dae" scale="1 1 1" />
            </geometry>
            <material name="LightGrey">
                <texture />
                <color rgba="0.9 0.9 0.9 1" />
            </material>
        </visual>
    </link>
    <link name="Neck">
        <inertial>
            <mass value="0.27391" />
            <origin xyz="-0.00207 0 -0.02636" rpy="0 -0 0" />
            <inertia ixx="0.000343501" ixy="-0" ixz="-1.88563e-05" iyy="0.000493898" iyz="2.09863e-06" izz="0.000215252" />
        </inertial>
        <visual>
            <origin xyz="0 0 0" rpy="0 -0 0" />
            <geometry>
                <mesh filename="package://pepper_robot_description/pepper_robot/meshes/HeadYaw.dae" scale="1 1 1" />
            </geometry>
            <material name="LightGrey">
                <texture />
                <color rgba="0.9 0.9 0.9 1" />
            </material>
        </visual>
    </link>
    <link name="Head">
        <inertial>
            <mass value="1.51893" />
            <origin xyz="0.11152 0.00312 -4.87469e-09" rpy="1.5708 5.55112e-17 1.5708" />
            <inertia ixx="0.00597209" ixy="0" ixz="0.000125138" iyy="0.0059054" iyz="4.3428e-07" izz="0.00570374" />
        </inertial>
        <visual>
            <origin xyz="0 0 0" rpy="1.5708 5.55112e-17 1.5708" />
            <geometry>
                <mesh filename="package://pepper_robot_description/pepper_robot/meshes/HeadPitch.dae" scale="1 1 1" />
            </geometry>
            <material name="LightGrey">
                <texture />
                <color rgba="0.9 0.9 0.9 1" />
            </material>
        </visual>
    </link>
    <link name="LShoulderPitch">
        <inertial>
            <mass value="0.3125" />
            <origin xyz="0.00018 -0.000989999 -0.01856" rpy="1.5708 -0 0" />
            <inertia ixx="0.000361198" ixy="-1.98347e-06" ixz="6.35907e-07" iyy="0.000137229" iyz="-5.68878e-06" izz="0.000399194" />
        </inertial>
        <visual>
            <origin xyz="0 0 0" rpy="1.5708 -0 0" />
            <geometry>
                <mesh filename="package://pepper_robot_description/pepper_robot/meshes/LShoulderPitch.dae" scale="1 1 1" />
            </geometry>
            <material name="LightGrey">
                <texture />
                <color rgba="0.9 0.9 0.9 1" />
            </material>
        </visual>
    </link>
    <link name="LBicep">
        <inertial>
            <mass value="0.50527" />
            <origin xyz="0.01284 -0.08151 -0.01017" rpy="0 -0 -1.5708" />
            <inertia ixx="0.000500872" ixy="-3.55918e-05" ixz="8.51263e-05" iyy="0.00126284" iyz="9.06813e-06" izz="0.00115718" />
        </inertial>
        <visual>
            <origin xyz="0 0 0" rpy="0 -0 -1.5708" />
            <geometry>
                <mesh filename="package://pepper_robot_description/pepper_robot/meshes/LShoulderRoll.dae" scale="1 1 1" />
            </geometry>
            <material name="LightGrey">
                <texture />
                <color rgba="0.9 0.9 0.9 1" />
            </material>
        </visual>
    </link>
    <link name="LElbow">
        <inertial>
            <mass value="0.27495" />
            <origin xyz="-0.000190001 0.00119 -0.02297" rpy="-1.5708 -1.5708 8.76263e-08" />
            <inertia ixx="0.000122971" ixy="9.86024e-07" ixz="-2.55838e-05" iyy="0.000331766" iyz="-1.98925e-06" izz="0.000303047" />
        </inertial>
        <visual>
            <origin xyz="0 0 0" rpy="-1.5708 -1.5708 8.76263e-08" />
            <geometry>
                <mesh filename="package://pepper_robot_description/pepper_robot/meshes/LElbowYaw.dae" scale="1 1 1" />
            </geometry>
            <material name="LightGrey">
                <texture />
                <color rgba="0.9 0.9 0.9 1" />
            </material>
        </visual>
    </link>
    <link name="LForeArm">
        <inertial>
            <mass value="0.16579" />
            <origin xyz="0.00271 -0.0593 -0.01014" rpy="0 -0 -1.5708" />
            <inertia ixx="0.00156513" ixy="1.47517e-05" ixz="-6.05746e-05" iyy="0.00173219" iyz="-1.7619e-07" izz="0.000273081" />
        </inertial>
        <visual>
            <origin xyz="0 0 0" rpy="0 -0 -1.5708" />
            <geometry>
                <mesh filename="package://pepper_robot_description/pepper_robot/meshes/LElbowRoll.dae" scale="1 1 1" />
            </geometry>
            <material name="LightGrey">
                <texture />
                <color rgba="0.9 0.9 0.9 1" />
            </material>
        </visual>
    </link>
    <link name="l_wrist">
        <inertial>
            <mass value="0.27555" />
            <origin xyz="-0.000719998 -0.00207 0.03536" rpy="-1.5708 -1.5708 8.76263e-08" />
            <inertia ixx="0.000151643" ixy="1.06629e-05" ixz="2.89509e-06" iyy="0.000431099" iyz="-3.13715e-06" izz="0.000456172" />
        </inertial>
        <visual>
            <origin xyz="0 0 0" rpy="-1.5708 -1.5708 8.76263e-08" />
            <geometry>
                <mesh filename="package://pepper_robot_description/pepper_robot/meshes/LWristYaw.dae" scale="1 1 1" />
            </geometry>
            <material name="LightGrey">
                <texture />
                <color rgba="0.9 0.9 0.9 1" />
            </material>
        </visual>
    </link>
    <link name="Hip">
        <inertial>
            <mass value="1.02338" />
            <origin xyz="0.06039 0 0.000320003" rpy="3.14159 -1.5708 3.14159" />
            <inertia ixx="0.00502422" ixy="0" ixz="-2.54911e-05" iyy="0.00640971" iyz="0.000159449" izz="0.00441082" />
        </inertial>
        <visual>
            <origin xyz="0 0 0" rpy="3.14159 -1.5708 3.14159" />
            <geometry>
                <mesh filename="package://pepper_robot_description/pepper_robot/meshes/HipRoll.dae" scale="1 1 1" />
            </geometry>
            <material name="LightGrey">
                <texture />
                <color rgba="0.9 0.9 0.9 1" />
            </material>
        </visual>
    </link>
    <link name="Pelvis">
        <inertial>
            <mass value="2.45917" />
            <origin xyz="0.00237 0.09654 4.2199e-09" rpy="1.5708 -0 0" />
            <inertia ixx="0.034351" ixy="0" ixz="0.000223034" iyy="0.0303122" iyz="-8.37542e-05" izz="0.0143771" />
        </inertial>
        <visual>
            <origin xyz="0 0 0" rpy="1.5708 -0 0" />
            <geometry>
                <mesh filename="package://pepper_robot_description/pepper_robot/meshes/HipPitch.dae" scale="1 1 1" />
            </geometry>
            <material name="LightGrey">
                <texture />
                <color rgba="0.9 0.9 0.9 1" />
            </material>
        </visual>
    </link>
    <link name="Tibia">
        <inertial>
            <mass value="11.6015" />
            <origin xyz="0.00220451 0.185729 8.11846e-09" rpy="1.5708 -0 0" />
            <inertia ixx="0.129229" ixy="-0.000401943" ixz="0.00048556" iyy="0.122839" iyz="-1.01666e-08" izz="0.108168" />
        </inertial>
        <visual>
            <origin xyz="0 0 0" rpy="1.5708 -0 0" />
            <geometry>
                <mesh filename="package://pepper_robot_description/pepper_robot/meshes/KneePitch.dae" scale="1 1 1" />
            </geometry>
            <material name="LightGrey">
                <texture />
                <color rgba="0.9 0.9 0.9 1" />
            </material>
        </visual>
    </link>
    <link name="RShoulderPitch">
        <inertial>
            <mass value="0.3125" />
            <origin xyz="0.00018 -0.000990001 0.01856" rpy="1.5708 -0 0" />
            <inertia ixx="0.000361198" ixy="1.98347e-06" ixz="6.35907e-07" iyy="0.000137229" iyz="5.68878e-06" izz="0.000399194" />
        </inertial>
        <visual>
            <origin xyz="0 0 0" rpy="1.5708 -0 0" />
            <geometry>
                <mesh filename="package://pepper_robot_description/pepper_robot/meshes/RShoulderPitch.dae" scale="1 1 1" />
            </geometry>
            <material name="LightGrey">
                <texture />
                <color rgba="0.9 0.9 0.9 1" />
            </material>
        </visual>
    </link>
    <link name="RBicep">
        <inertial>
            <mass value="0.50527" />
            <origin xyz="-0.01284 -0.08151 -0.01017" rpy="0 -0 -1.5708" />
            <inertia ixx="0.000500872" ixy="3.55918e-05" ixz="8.51263e-05" iyy="0.00126284" iyz="-9.06813e-06" izz="0.00115718" />
        </inertial>
        <visual>
            <origin xyz="0 0 0" rpy="0 -0 -1.5708" />
            <geometry>
                <mesh filename="package://pepper_robot_description/pepper_robot/meshes/RShoulderRoll.dae" scale="1 1 1" />
            </geometry>
            <material name="LightGrey">
                <texture />
                <color rgba="0.9 0.9 0.9 1" />
            </material>
        </visual>
    </link>
    <link name="RElbowYaw">
        <inertial>
            <mass value="0.27495" />
            <origin xyz="0.000189999 0.00119 -0.02297" rpy="-1.5708 -1.5708 8.76263e-08" />
            <inertia ixx="0.000122971" ixy="-9.86024e-07" ixz="-2.55838e-05" iyy="0.000331766" iyz="1.98925e-06" izz="0.000303047" />
        </inertial>
        <visual>
            <origin xyz="0 0 0" rpy="-1.5708 -1.5708 8.76263e-08" />
            <geometry>
                <mesh filename="package://pepper_robot_description/pepper_robot/meshes/RElbowYaw.dae" scale="1 1 1" />
            </geometry>
            <material name="LightGrey">
                <texture />
                <color rgba="0.9 0.9 0.9 1" />
            </material>
        </visual>
    </link>
    <link name="RForeArm">
        <inertial>
            <mass value="0.16579" />
            <origin xyz="-0.00271 -0.0593 -0.01014" rpy="0 -0 -1.5708" />
            <inertia ixx="0.00156513" ixy="-1.47517e-05" ixz="-6.05746e-05" iyy="0.00173219" iyz="1.7619e-07" izz="0.000273081" />
        </inertial>
        <visual>
            <origin xyz="0 0 0" rpy="0 -0 -1.5708" />
            <geometry>
                <mesh filename="package://pepper_robot_description/pepper_robot/meshes/RElbowRoll.dae" scale="1 1 1" />
            </geometry>
            <material name="LightGrey">
                <texture />
                <color rgba="0.9 0.9 0.9 1" />
            </material>
        </visual>
    </link>
    <link name="r_wrist">
        <inertial>
            <mass value="0.27555" />
            <origin xyz="0.000720002 -0.00207 0.03536" rpy="-1.5708 -1.5708 8.76263e-08" />
            <inertia ixx="0.000151643" ixy="-1.06629e-05" ixz="2.89509e-06" iyy="0.000431099" iyz="3.13715e-06" izz="0.000456172" />
        </inertial>
        <visual>
            <origin xyz="0 0 0" rpy="-1.5708 -1.5708 8.76263e-08" />
            <geometry>
                <mesh filename="package://pepper_robot_description/pepper_robot/meshes/RWristYaw.dae" scale="1 1 1" />
            </geometry>
            <material name="LightGrey">
                <texture />
                <color rgba="0.9 0.9 0.9 1" />
            </material>
        </visual>
    </link>
    <link name="WheelB_link">
        <inertial>
            <mass value="1.58028" />
            <origin xyz="0 0 0" rpy="0 -0 0" />
            <inertia ixx="0.00299756" ixy="6.3068e-07" ixz="5.56903e-06" iyy="0.00303229" iyz="-9.0408e-07" izz="0.00296585" />
        </inertial>
        <visual>
            <origin xyz="0 0 0" rpy="0 -0 0" />
            <geometry>
                <mesh filename="package://pepper_robot_description/pepper_robot/meshes/WheelB.dae" scale="1 1 1" />
            </geometry>
            <material name="LightGrey">
                <texture />
                <color rgba="0.9 0.9 0.9 1" />
            </material>
        </visual>
    </link>
    <link name="WheelFL_link">
        <inertial>
            <mass value="1.58028" />
            <origin xyz="0 0 0" rpy="0 -0 0" />
            <inertia ixx="0.00299756" ixy="6.3068e-07" ixz="5.56903e-06" iyy="0.00303229" iyz="-9.0408e-07" izz="0.00296585" />
        </inertial>
        <visual>
            <origin xyz="0 0 0" rpy="0 -0 0" />
            <geometry>
                <mesh filename="package://pepper_robot_description/pepper_robot/meshes/WheelFL.dae" scale="1 1 1" />
            </geometry>
            <material name="LightGrey">
                <texture />
                <color rgba="0.9 0.9 0.9 1" />
            </material>
        </visual>
    </link>
    <link name="WheelFR_link">
        <inertial>
            <mass value="1.58028" />
            <origin xyz="0 0 0" rpy="0 -0 0" />
            <inertia ixx="0.00299756" ixy="6.3068e-07" ixz="5.56903e-06" iyy="0.00303229" iyz="-9.0408e-07" izz="0.00296585" />
        </inertial>
        <visual>
            <origin xyz="0 0 0" rpy="0 -0 0" />
            <geometry>
                <mesh filename="package://pepper_robot_description/pepper_robot/meshes/WheelFR.dae" scale="1 1 1" />
            </geometry>
            <material name="LightGrey">
                <texture />
                <color rgba="0.9 0.9 0.9 1" />
            </material>
        </visual>
    </link>
    <link name="base_link" />
    <joint name="BumperB_fixedjoint" type="fixed">
        <origin xyz="-0.251 0.264 0" rpy="-1.5708 -0 3.14159" />
        <axis xyz="0 0 0" />
        <parent link="Tibia" />
        <child link="BumperB" />
    </joint>
    <joint name="BumperFL_fixedjoint" type="fixed">
        <origin xyz="0.129 0.264 0.227" rpy="1.5708 -0.48886 0" />
        <axis xyz="0 0 0" />
        <parent link="Tibia" />
        <child link="BumperFL" />
    </joint>
    <joint name="BumperFR_fixedjoint" type="fixed">
        <origin xyz="0.129 0.264 -0.227" rpy="1.5708 0.48886 0" />
        <axis xyz="0 0 0" />
        <parent link="Tibia" />
        <child link="BumperFR" />
    </joint>
    <joint name="CameraBottom_fixedjoint" type="fixed">
        <origin xyz="0.06177 0.09262 0" rpy="1.5708 5.55112e-17 2.26893" />
        <axis xyz="0 0 0" />
        <parent link="Head" />
        <child link="CameraBottom" />
    </joint>
    <joint name="CameraDepth_fixedjoint" type="fixed">
        <origin xyz="0.1194 0.05138 0.039" rpy="1.5708 5.55112e-17 1.5708" />
        <axis xyz="0 0 0" />
        <parent link="Head" />
        <child link="CameraDepth" />
    </joint>
    <joint name="CameraTop_fixedjoint" type="fixed">
        <origin xyz="0.16284 0.08601 0" rpy="1.5708 5.55112e-17 1.5708" />
        <axis xyz="0 0 0" />
        <parent link="Head" />
        <child link="CameraTop" />
    </joint>
    <joint name="Gaze_fixedjoint" type="fixed">
        <origin xyz="0.1189 0.0657 0" rpy="1.5708 5.55112e-17 1.5708" />
        <axis xyz="0 0 0" />
        <parent link="Head" />
        <child link="Gaze" />
    </joint>
    <joint name="HeadPitchSphereCollision_shape_fixedjoint" type="fixed">
        <origin xyz="0.12 0.004 0" rpy="1.5708 5.55112e-17 1.5708" />
        <axis xyz="0 0 0" />
        <parent link="Head" />
        <child link="HeadPitchSphereCollision_shape" />
    </joint>
    <joint name="HeadPitch_fixedjoint" type="fixed">
        <origin xyz="0 0 0" rpy="1.5708 5.55112e-17 1.5708" />
        <axis xyz="0 0 0" />
        <parent link="Head" />
        <child link="HeadPitch" />
    </joint>
    <joint name="HeadYaw" type="revolute">
        <origin xyz="-0.038 0 0.1699" rpy="0 -0 0" />
        <axis xyz="0 0 1" />
        <parent link="torso" />
        <child link="Neck" />
        <limit effort="1.8721" velocity="7.33998" lower="-2.08567" upper="2.08567" />
    </joint>
    <joint name="HeadPitch" type="revolute">
        <origin xyz="0 0 0" rpy="1.5708 -1.5708 -3.14159" />
        <axis xyz="0 0 1" />
        <parent link="Neck" />
        <child link="Head" />
        <limit effort="2.66575" velocity="9.22756" lower="-0.706858" upper="0.445059" />
    </joint>
    <joint name="LShoulderPitch" type="revolute">
        <origin xyz="-0.057 0.14974 0.08682" rpy="-1.5708 -0 0" />
        <axis xyz="0 0 1" />
        <parent link="torso" />
        <child link="LShoulderPitch" />
        <limit effort="4.11862" velocity="7.33998" lower="-2.08567" upper="2.08567" />
    </joint>
    <joint name="LShoulderRoll" type="revolute">
        <origin xyz="0 0 0" rpy="-1.5708 -1.5708 3.14159" />
        <axis xyz="0 0 1" />
        <parent link="LShoulderPitch" />
        <child link="LBicep" />
        <limit effort="3.70244" velocity="9.22756" lower="0.00872665" upper="1.56207" />
    </joint>
    <joint name="LElbowYaw" type="revolute">
        <origin xyz="0.015 -0.1812 0.00013" rpy="1.41372 -0 0" />
        <axis xyz="0 0 1" />
        <parent link="LBicep" />
        <child link="LElbow" />
        <limit effort="2.80815" velocity="7.33998" lower="-2.08567" upper="2.08567" />
    </joint>
    <joint name="LElbowRoll" type="revolute">
        <origin xyz="0 0 0" rpy="-1.5708 -0 0" />
        <axis xyz="0 0 1" />
        <parent link="LElbow" />
        <child link="LForeArm" />
        <limit effort="2.22146" velocity="9.22756" lower="-1.56207" upper="-0.00872665" />
    </joint>
    <joint name="LWristYaw" type="revolute">
        <origin xyz="0 -0.15 0" rpy="1.5708 -0 0" />
        <axis xyz="0 0 1" />
        <parent link="LForeArm" />
        <child link="l_wrist" />
        <limit effort="0.134278" velocity="17.3835" lower="-1.82387" upper="1.82387" />
    </joint>
    <joint name="HipRoll" type="revolute">
        <origin xyz="2e-05 0 -0.139" rpy="3.14159 1.5708 3.14159" />
        <axis xyz="0 0 1" />
        <parent link="torso" />
        <child link="Hip" />
        <limit effort="10.1884" velocity="2.27032" lower="-0.514872" upper="0.514872" />
    </joint>
    <joint name="HipPitch" type="revolute">
        <origin xyz="0.079 0 0" rpy="1.5708 -1.5708 -3.14159" />
        <axis xyz="0 0 1" />
        <parent link="Hip" />
        <child link="Pelvis" />
        <limit effort="19.787" velocity="2.93276" lower="-1.03847" upper="1.03847" />
    </joint>
    <joint name="KneePitch" type="revolute">
        <origin xyz="0 0.268 0" rpy="0 -0 0" />
        <axis xyz="0 0 1" />
        <parent link="Pelvis" />
        <child link="Tibia" />
        <limit effort="27.702" velocity="2.93276" lower="-0.514872" upper="0.514872" />
    </joint>
    <joint name="RShoulderPitch" type="revolute">
        <origin xyz="-0.057 -0.14974 0.08682" rpy="-1.5708 -0 0" />
        <axis xyz="0 0 1" />
        <parent link="torso" />
        <child link="RShoulderPitch" />
        <limit effort="4.11862" velocity="7.33998" lower="-2.08567" upper="2.08567" />
    </joint>
    <joint name="RShoulderRoll" type="revolute">
        <origin xyz="0 0 0" rpy="-1.5708 -1.5708 3.14159" />
        <axis xyz="0 0 1" />
        <parent link="RShoulderPitch" />
        <child link="RBicep" />
        <limit effort="3.70244" velocity="9.22756" lower="-1.56207" upper="-0.00872665" />
    </joint>
    <joint name="RElbowYaw" type="revolute">
        <origin xyz="-0.015 -0.1812 0.00013" rpy="1.41372 -0 0" />
        <axis xyz="0 0 1" />
        <parent link="RBicep" />
        <child link="RElbowYaw" />
        <limit effort="2.80815" velocity="7.33998" lower="-2.08567" upper="2.08567" />
    </joint>
    <joint name="RElbowRoll" type="revolute">
        <origin xyz="0 0 0" rpy="-1.5708 -0 0" />
        <axis xyz="0 0 1" />
        <parent link="RElbowYaw" />
        <child link="RForeArm" />
        <limit effort="2.22146" velocity="9.22756" lower="0.00872665" upper="1.56207" />
    </joint>
    <joint name="RWristYaw" type="revolute">
        <origin xyz="0 -0.15 0" rpy="1.5708 -0 0" />
        <axis xyz="0 0 1" />
        <parent link="RForeArm" />
        <child link="r_wrist" />
        <limit effort="0.134278" velocity="17.3835" lower="-1.82387" upper="1.82387" />
    </joint>
    <joint name="HeadYaw_fixedjoint" type="fixed">
        <origin xyz="0 0 0" rpy="0 -0 0" />
        <axis xyz="0 0 0" />
        <parent link="Neck" />
        <child link="HeadYaw" />
    </joint>
    <joint name="Head_fixedjoint" type="fixed">
        <origin xyz="0 0 0" rpy="1.5708 5.55112e-17 1.5708" />
        <axis xyz="0 0 0" />
        <parent link="Head" />
        <child link="Head" />
    </joint>
    <joint name="HipPitchPillCollision_shape_fixedjoint" type="fixed">
        <origin xyz="-0.0075 0.07 0" rpy="1.5708 -0 -3.14159" />
        <axis xyz="0 0 0" />
        <parent link="Pelvis" />
        <child link="HipPitchPillCollision_shape" />
    </joint>
    <joint name="HipPitchSphereCollision_shape_fixedjoint" type="fixed">
        <origin xyz="-0.005 -0.05 0" rpy="1.5708 -0 0" />
        <axis xyz="0 0 0" />
        <parent link="Pelvis" />
        <child link="HipPitchSphereCollision_shape" />
    </joint>
    <joint name="HipPitch_fixedjoint" type="fixed">
        <origin xyz="0 0 0" rpy="1.5708 -0 0" />
        <axis xyz="0 0 0" />
        <parent link="Pelvis" />
        <child link="HipPitch" />
    </joint>
    <joint name="HipRoll_fixedjoint" type="fixed">
        <origin xyz="0 0 0" rpy="3.14159 -1.5708 3.14159" />
        <axis xyz="0 0 0" />
        <parent link="Hip" />
        <child link="HipRoll" />
    </joint>
    <joint name="KneePitch_fixedjoint" type="fixed">
        <origin xyz="0 0 0" rpy="1.5708 -0 0" />
        <axis xyz="0 0 0" />
        <parent link="Tibia" />
        <child link="KneePitch" />
    </joint>
    <joint name="LArmFuse_fixedjoint" type="fixed">
        <origin xyz="0 0 0" rpy="0 -0 0" />
        <axis xyz="0 0 0" />
        <parent link="torso" />
        <child link="LArmFuse" />
    </joint>
    <joint name="LArm_fixedjoint" type="fixed">
        <origin xyz="0 -0.0303 0.0695" rpy="1.5708 -1.5708 -3.14159" />
        <axis xyz="0 0 0" />
        <parent link="l_wrist" />
        <child link="LArm" />
    </joint>
    <joint name="LElbowRollDynamicCollision_shape_fixedjoint" type="fixed">
        <origin xyz="0 -0.15 0" rpy="1.5708 -0 0" />
        <axis xyz="0 0 0" />
        <parent link="LForeArm" />
        <child link="LElbowRollDynamicCollision_shape" />
    </joint>
    <joint name="LElbowRollPillCollision_shape_fixedjoint" type="fixed">
        <origin xyz="0 -0.115 0" rpy="1.5708 -0 0" />
        <axis xyz="0 0 0" />
        <parent link="LForeArm" />
        <child link="LElbowRollPillCollision_shape" />
    </joint>
    <joint name="LElbowRollSphereACollision_shape_fixedjoint" type="fixed">
        <origin xyz="0 -0.1875 0" rpy="0 -0 -1.5708" />
        <axis xyz="0 0 0" />
        <parent link="LForeArm" />
        <child link="LElbowRollSphereACollision_shape" />
    </joint>
    <joint name="LElbowRollSphereBCollision_shape_fixedjoint" type="fixed">
        <origin xyz="0 -0.125 0" rpy="0 -0 -1.5708" />
        <axis xyz="0 0 0" />
        <parent link="LForeArm" />
        <child link="LElbowRollSphereBCollision_shape" />
    </joint>
    <joint name="LElbowRollSphereCCollision_shape_fixedjoint" type="fixed">
        <origin xyz="0 -0.0625 0" rpy="0 -0 -1.5708" />
        <axis xyz="0 0 0" />
        <parent link="LForeArm" />
        <child link="LElbowRollSphereCCollision_shape" />
    </joint>
    <joint name="LElbowRollSphereDCollision_shape_fixedjoint" type="fixed">
        <origin xyz="0 0 0" rpy="0 -0 -1.5708" />
        <axis xyz="0 0 0" />
        <parent link="LForeArm" />
        <child link="LElbowRollSphereDCollision_shape" />
    </joint>
    <joint name="LElbowRoll_fixedjoint" type="fixed">
        <origin xyz="0 0 0" rpy="0 -0 -1.5708" />
        <axis xyz="0 0 0" />
        <parent link="LForeArm" />
        <child link="LElbowRoll" />
    </joint>
    <joint name="LElbowYaw_fixedjoint" type="fixed">
        <origin xyz="0 0 0" rpy="-1.5708 -1.5708 8.76263e-08" />
        <axis xyz="0 0 0" />
        <parent link="LElbow" />
        <child link="LElbowYaw" />
    </joint>
    <joint name="LFinger11" type="continuous">
        <origin xyz="-0.0268 0.004 0.0821" rpy="1.78277 -0.529825 -1.59039" />
        <axis xyz="0 0 1" />
        <parent link="l_wrist" />
        <child link="LFinger11_link" />
        <mimic offset="0" multiplier="0.872665" joint="LHand" />
    </joint>
    <joint name="LFinger12" type="continuous">
        <origin xyz="0.018 0 0" rpy="-0 -0 -1.0472" />
        <axis xyz="0 0 1" />
        <parent link="LFinger11_link" />
        <child link="LFinger12_link" />
        <mimic offset="0" multiplier="0.872665" joint="LHand" />
    </joint>
    <joint name="LFinger13" type="continuous">
        <origin xyz="0.018 0 0" rpy="-0 -0 -1.0472" />
        <axis xyz="0 0 1" />
        <parent link="LFinger12_link" />
        <child link="LFinger13_link" />
        <mimic offset="0" multiplier="0.872665" joint="LHand" />
    </joint>
    <joint name="LFinger21" type="continuous">
        <origin xyz="-0.0073 0.006 0.0873" rpy="1.6413 -0.522522 -1.60603" />
        <axis xyz="0 0 1" />
        <parent link="l_wrist" />
        <child link="LFinger21_link" />
        <mimic offset="0" multiplier="0.872665" joint="LHand" />
    </joint>
    <joint name="LFinger22" type="continuous">
        <origin xyz="0.018 0 0" rpy="-0 -0 -1.0472" />
        <axis xyz="0 0 1" />
        <parent link="LFinger21_link" />
        <child link="LFinger22_link" />
        <mimic offset="0" multiplier="0.872665" joint="LHand" />
    </joint>
    <joint name="LFinger23" type="continuous">
        <origin xyz="0.018 0 0" rpy="-0 -0 -1.0472" />
        <axis xyz="0 0 1" />
        <parent link="LFinger22_link" />
        <child link="LFinger23_link" />
        <mimic offset="0" multiplier="0.872665" joint="LHand" />
    </joint>
    <joint name="LFinger31" type="continuous">
        <origin xyz="0.0123 0.004 0.0833" rpy="1.50025 -0.525718 -1.58781" />
        <axis xyz="0 0 1" />
        <parent link="l_wrist" />
        <child link="LFinger31_link" />
        <mimic offset="0" multiplier="0.872665" joint="LHand" />
    </joint>
    <joint name="LFinger32" type="continuous">
        <origin xyz="0.018 0 0" rpy="-0 -0 -1.0472" />
        <axis xyz="0 0 1" />
        <parent link="LFinger31_link" />
        <child link="LFinger32_link" />
        <mimic offset="0" multiplier="0.872665" joint="LHand" />
    </joint>
    <joint name="LFinger33" type="continuous">
        <origin xyz="0.018 0 0" rpy="-0 -0 -1.0472" />
        <axis xyz="0 0 1" />
        <parent link="LFinger32_link" />
        <child link="LFinger33_link" />
        <mimic offset="0" multiplier="0.872665" joint="LHand" />
    </joint>
    <joint name="LFinger41" type="continuous">
        <origin xyz="0.0309 0 0.074" rpy="1.3184 -0.528785 -1.53079" />
        <axis xyz="0 0 1" />
        <parent link="l_wrist" />
        <child link="LFinger41_link" />
        <mimic offset="0" multiplier="0.872665" joint="LHand" />
    </joint>
    <joint name="LFinger42" type="continuous">
        <origin xyz="0.018 0 0" rpy="-0 -0 -1.0472" />
        <axis xyz="0 0 1" />
        <parent link="LFinger41_link" />
        <child link="LFinger42_link" />
        <mimic offset="0" multiplier="0.872665" joint="LHand" />
    </joint>
    <joint name="LFinger43" type="continuous">
        <origin xyz="0.018 0 0" rpy="-0 -0 -1.0472" />
        <axis xyz="0 0 1" />
        <parent link="LFinger42_link" />
        <child link="LFinger43_link" />
        <mimic offset="0" multiplier="0.872665" joint="LHand" />
    </joint>
    <joint name="LHand" type="revolute">
        <origin xyz="0 0 0.025" rpy="1.5708 -1.5708 -3.14159" />
        <axis xyz="1 0 0" />
        <parent link="l_wrist" />
        <child link="LHand_actuator_frame" />
        <limit effort="0.096152" velocity="12.56" lower="0.02" upper="0.98" />
    </joint>
    <joint name="LShoulderPitch_fixedjoint" type="fixed">
        <origin xyz="0 0 0" rpy="1.5708 -0 0" />
        <axis xyz="0 0 0" />
        <parent link="LShoulderPitch" />
        <child link="LShoulderPitch" />
    </joint>
    <joint name="LShoulderRoll_fixedjoint" type="fixed">
        <origin xyz="0 0 0" rpy="0 -0 -1.5708" />
        <axis xyz="0 0 0" />
        <parent link="LBicep" />
        <child link="LShoulderRoll" />
    </joint>
    <joint name="LThumb1" type="continuous">
        <origin xyz="-0.0357 -0.0199 0.0482" rpy="-2.76225 -0.785789 -0.937585" />
        <axis xyz="0 0 1" />
        <parent link="l_wrist" />
        <child link="LThumb1_link" />
        <mimic offset="0" multiplier="0.872665" joint="LHand" />
    </joint>
    <joint name="LThumb2" type="continuous">
        <origin xyz="0.022 0 0" rpy="-0 -0 -1.0472" />
        <axis xyz="0 0 1" />
        <parent link="LThumb1_link" />
        <child link="LThumb2_link" />
        <mimic offset="0" multiplier="0.872665" joint="LHand" />
    </joint>
    <joint name="LWristYawSphereCollision_shape_fixedjoint" type="fixed">
        <origin xyz="-0.01 -0.015 0.055" rpy="1.5708 -1.5708 -3.14159" />
        <axis xyz="0 0 0" />
        <parent link="l_wrist" />
        <child link="LWristYawSphereCollision_shape" />
    </joint>
    <joint name="LWristYaw_fixedjoint" type="fixed">
        <origin xyz="0 0 0" rpy="-1.5708 -1.5708 8.76263e-08" />
        <axis xyz="0 0 0" />
        <parent link="l_wrist" />
        <child link="LWristYaw" />
    </joint>
    <joint name="RArm_fixedjoint" type="fixed">
        <origin xyz="0 -0.0303 0.0695" rpy="1.5708 -1.5708 -3.14159" />
        <axis xyz="0 0 0" />
        <parent link="r_wrist" />
        <child link="RArm" />
    </joint>
    <joint name="RElbowRollDynamicCollision_shape_fixedjoint" type="fixed">
        <origin xyz="0 -0.15 0" rpy="1.5708 -0 0" />
        <axis xyz="0 0 0" />
        <parent link="RForeArm" />
        <child link="RElbowRollDynamicCollision_shape" />
    </joint>
    <joint name="RElbowRollPillCollision_shape_fixedjoint" type="fixed">
        <origin xyz="0 -0.115 0" rpy="1.5708 -0 0" />
        <axis xyz="0 0 0" />
        <parent link="RForeArm" />
        <child link="RElbowRollPillCollision_shape" />
    </joint>
    <joint name="RElbowRollSphereACollision_shape_fixedjoint" type="fixed">
        <origin xyz="0 -0.1875 0" rpy="0 -0 -1.5708" />
        <axis xyz="0 0 0" />
        <parent link="RForeArm" />
        <child link="RElbowRollSphereACollision_shape" />
    </joint>
    <joint name="RElbowRollSphereBCollision_shape_fixedjoint" type="fixed">
        <origin xyz="0 -0.125 0" rpy="0 -0 -1.5708" />
        <axis xyz="0 0 0" />
        <parent link="RForeArm" />
        <child link="RElbowRollSphereBCollision_shape" />
    </joint>
    <joint name="RElbowRollSphereCCollision_shape_fixedjoint" type="fixed">
        <origin xyz="0 -0.0625 0" rpy="0 -0 -1.5708" />
        <axis xyz="0 0 0" />
        <parent link="RForeArm" />
        <child link="RElbowRollSphereCCollision_shape" />
    </joint>
    <joint name="RElbowRollSphereDCollision_shape_fixedjoint" type="fixed">
        <origin xyz="0 0 0" rpy="0 -0 -1.5708" />
        <axis xyz="0 0 0" />
        <parent link="RForeArm" />
        <child link="RElbowRollSphereDCollision_shape" />
    </joint>
    <joint name="RElbowRoll_fixedjoint" type="fixed">
        <origin xyz="0 0 0" rpy="0 -0 -1.5708" />
        <axis xyz="0 0 0" />
        <parent link="RForeArm" />
        <child link="RElbowRoll" />
    </joint>
    <joint name="RElbowYaw_fixedjoint" type="fixed">
        <origin xyz="0 0 0" rpy="-1.5708 -1.5708 8.76263e-08" />
        <axis xyz="0 0 0" />
        <parent link="RElbowYaw" />
        <child link="RElbowYaw" />
    </joint>
    <joint name="RFinger11" type="continuous">
        <origin xyz="0.0268 0.004 0.0821" rpy="1.35882 -0.529825 -1.55121" />
        <axis xyz="0 0 1" />
        <parent link="r_wrist" />
        <child link="RFinger11_link" />
        <mimic offset="0" multiplier="0.872665" joint="RHand" />
    </joint>
    <joint name="RFinger12" type="continuous">
        <origin xyz="0.018 0 0" rpy="-0 -0 -1.0472" />
        <axis xyz="0 0 1" />
        <parent link="RFinger11_link" />
        <child link="RFinger12_link" />
        <mimic offset="0" multiplier="0.872665" joint="RHand" />
    </joint>
    <joint name="RFinger13" type="continuous">
        <origin xyz="0.018 0 0" rpy="-0 -0 -1.0472" />
        <axis xyz="0 0 1" />
        <parent link="RFinger12_link" />
        <child link="RFinger13_link" />
        <mimic offset="0" multiplier="0.872665" joint="RHand" />
    </joint>
    <joint name="RFinger21" type="continuous">
        <origin xyz="0.0073 0.006 0.0873" rpy="1.50029 -0.522522 -1.53556" />
        <axis xyz="0 0 1" />
        <parent link="r_wrist" />
        <child link="RFinger21_link" />
        <mimic offset="0" multiplier="0.872665" joint="RHand" />
    </joint>
    <joint name="RFinger22" type="continuous">
        <origin xyz="0.018 0 0" rpy="-0 -0 -1.0472" />
        <axis xyz="0 0 1" />
        <parent link="RFinger21_link" />
        <child link="RFinger22_link" />
        <mimic offset="0" multiplier="0.872665" joint="RHand" />
    </joint>
    <joint name="RFinger23" type="continuous">
        <origin xyz="0.018 0 0" rpy="-0 -0 -1.0472" />
        <axis xyz="0 0 1" />
        <parent link="RFinger22_link" />
        <child link="RFinger23_link" />
        <mimic offset="0" multiplier="0.872665" joint="RHand" />
    </joint>
    <joint name="RFinger31" type="continuous">
        <origin xyz="-0.0123 0.004 0.0833" rpy="1.64134 -0.525718 -1.55378" />
        <axis xyz="0 0 1" />
        <parent link="r_wrist" />
        <child link="RFinger31_link" />
        <mimic offset="0" multiplier="0.872665" joint="RHand" />
    </joint>
    <joint name="RFinger32" type="continuous">
        <origin xyz="0.018 0 0" rpy="-0 -0 -1.0472" />
        <axis xyz="0 0 1" />
        <parent link="RFinger31_link" />
        <child link="RFinger32_link" />
        <mimic offset="0" multiplier="0.872665" joint="RHand" />
    </joint>
    <joint name="RFinger33" type="continuous">
        <origin xyz="0.018 0 0" rpy="-0 -0 -1.0472" />
        <axis xyz="0 0 1" />
        <parent link="RFinger32_link" />
        <child link="RFinger33_link" />
        <mimic offset="0" multiplier="0.872665" joint="RHand" />
    </joint>
    <joint name="RFinger41" type="continuous">
        <origin xyz="-0.0309 0 0.074" rpy="1.82319 -0.528785 -1.6108" />
        <axis xyz="0 0 1" />
        <parent link="r_wrist" />
        <child link="RFinger41_link" />
        <mimic offset="0" multiplier="0.872665" joint="RHand" />
    </joint>
    <joint name="RFinger42" type="continuous">
        <origin xyz="0.018 0 0" rpy="-0 -0 -1.0472" />
        <axis xyz="0 0 1" />
        <parent link="RFinger41_link" />
        <child link="RFinger42_link" />
        <mimic offset="0" multiplier="0.872665" joint="RHand" />
    </joint>
    <joint name="RFinger43" type="continuous">
        <origin xyz="0.018 0 0" rpy="-0 -0 -1.0472" />
        <axis xyz="0 0 1" />
        <parent link="RFinger42_link" />
        <child link="RFinger43_link" />
        <mimic offset="0" multiplier="0.872665" joint="RHand" />
    </joint>
    <joint name="RHand" type="revolute">
        <origin xyz="0 0 0.025" rpy="1.5708 -1.5708 -3.14159" />
        <axis xyz="1 0 0" />
        <parent link="r_wrist" />
        <child link="RHand_actuator_frame" />
        <limit effort="0.096152" velocity="12.56" lower="0.02" upper="0.98" />
    </joint>
    <joint name="RHand/Touch/Back_fixedjoint" type="fixed">
        <origin xyz="0 0.0304 0.0523" rpy="1.5708 5.55112e-17 1.5708" />
        <axis xyz="0 0 0" />
        <parent link="r_wrist" />
        <child link="RHand/Touch/Back" />
    </joint>
    <joint name="RShoulderPitch_fixedjoint" type="fixed">
        <origin xyz="0 0 0" rpy="1.5708 -0 0" />
        <axis xyz="0 0 0" />
        <parent link="RShoulderPitch" />
        <child link="RShoulderPitch" />
    </joint>
    <joint name="RShoulderRoll_fixedjoint" type="fixed">
        <origin xyz="0 0 0" rpy="0 -0 -1.5708" />
        <axis xyz="0 0 0" />
        <parent link="RBicep" />
        <child link="RShoulderRoll" />
    </joint>
    <joint name="RThumb1" type="continuous">
        <origin xyz="0.0357 -0.0199 0.0482" rpy="-0.379338 -0.785789 -2.20401" />
        <axis xyz="0 0 1" />
        <parent link="r_wrist" />
        <child link="RThumb1_link" />
        <mimic offset="0" multiplier="0.872665" joint="RHand" />
    </joint>
    <joint name="RThumb2" type="continuous">
        <origin xyz="0.022 0 0" rpy="-0 -0 -1.0472" />
        <axis xyz="0 0 1" />
        <parent link="RThumb1_link" />
        <child link="RThumb2_link" />
        <mimic offset="0" multiplier="0.872665" joint="RHand" />
    </joint>
    <joint name="RWristYawSphereCollision_shape_fixedjoint" type="fixed">
        <origin xyz="0.01 -0.015 0.055" rpy="1.5708 -1.5708 -3.14159" />
        <axis xyz="0 0 0" />
        <parent link="r_wrist" />
        <child link="RWristYawSphereCollision_shape" />
    </joint>
    <joint name="RWristYaw_fixedjoint" type="fixed">
        <origin xyz="0 0 0" rpy="-1.5708 -1.5708 8.76263e-08" />
        <axis xyz="0 0 0" />
        <parent link="r_wrist" />
        <child link="RWristYaw" />
    </joint>
    <joint name="SonarBack_fixedjoint" type="fixed">
        <origin xyz="-0.0718 0.0534 0" rpy="-1.5708 1.38778e-17 -2.93215" />
        <axis xyz="0 0 0" />
        <parent link="Tibia" />
        <child link="SonarBack" />
    </joint>
    <joint name="SonarFront_fixedjoint" type="fixed">
        <origin xyz="0.0699 0.1023 0" rpy="1.5708 -0 -0.322858" />
        <axis xyz="0 0 0" />
        <parent link="Tibia" />
        <child link="SonarFront" />
    </joint>
    <joint name="TorsoBackLeftSphereCollision_shape_fixedjoint" type="fixed">
        <origin xyz="-0.08 0.055 -0.06" rpy="0 -0 0" />
        <axis xyz="0 0 0" />
        <parent link="torso" />
        <child link="TorsoBackLeftSphereCollision_shape" />
    </joint>
    <joint name="TorsoBackRightSphereCollision_shape_fixedjoint" type="fixed">
        <origin xyz="-0.08 -0.055 -0.06" rpy="0 -0 0" />
        <axis xyz="0 0 0" />
        <parent link="torso" />
        <child link="TorsoBackRightSphereCollision_shape" />
    </joint>
    <joint name="TorsoSphereBackCollision_shape_fixedjoint" type="fixed">
        <origin xyz="0 0 -0.08" rpy="0 -0 0" />
        <axis xyz="0 0 0" />
        <parent link="torso" />
        <child link="TorsoSphereBackCollision_shape" />
    </joint>
    <joint name="TorsoSphereLeftCollision_shape_fixedjoint" type="fixed">
        <origin xyz="0.08 0.05 0" rpy="0 -0 0" />
        <axis xyz="0 0 0" />
        <parent link="torso" />
        <child link="TorsoSphereLeftCollision_shape" />
    </joint>
    <joint name="TorsoSphereRightCollision_shape_fixedjoint" type="fixed">
        <origin xyz="0.08 -0.05 0" rpy="0 -0 0" />
        <axis xyz="0 0 0" />
        <parent link="torso" />
        <child link="TorsoSphereRightCollision_shape" />
    </joint>
    <joint name="TorsoTabCollision_shape_fixedjoint" type="fixed">
        <origin xyz="0.08 0 0.04" rpy="0 1.0472 0" />
        <axis xyz="0 0 0" />
        <parent link="torso" />
        <child link="TorsoTabCollision_shape" />
    </joint>
    <joint name="WheelB" type="continuous">
        <origin xyz="-0.17 0.264 0" rpy="-1.5708 -0 -3.14159" />
        <axis xyz="1 0 0" />
        <parent link="Tibia" />
        <child link="WheelB_link" />
        <limit effort="3.25" velocity="6.28319" lower="0" upper="0" />
    </joint>
    <joint name="WheelFL" type="continuous">
        <origin xyz="0.09 0.264 0.155" rpy="1.5708 -1.07517 -1.16723e-16" />
        <axis xyz="1 0 0" />
        <parent link="Tibia" />
        <child link="WheelFL_link" />
        <limit effort="3.25" velocity="6.28319" lower="0" upper="0" />
    </joint>
    <joint name="WheelFR" type="continuous">
        <origin xyz="0.09 0.264 -0.155" rpy="1.5708 1.07517 1.16723e-16" />
        <axis xyz="1 0 0" />
        <parent link="Tibia" />
        <child link="WheelFR_link" />
        <limit effort="3.25" velocity="6.28319" lower="0" upper="0" />
    </joint>
    <joint name="base_link_fixedjoint" type="fixed">
        <origin xyz="0 0 0" rpy="0 -0 0" />
        <axis xyz="0 0 0" />
        <parent link="base_link" />
        <child link="torso" />
    </joint>
    <!-- GAZEBO MATERIALS -->
  <gazebo reference="base_link">
    <turnGravityOff>true</turnGravityOff>
  </gazebo>
  <gazebo reference="torso">
    <mu1>0.5</mu1>
    <mu2>0.5</mu2>
    <selfCollide>false</selfCollide>
    <turnGravityOff>true</turnGravityOff>
  </gazebo>
  <gazebo reference="Neck">
    <mu1>0.5</mu1>
    <mu2>0.5</mu2>
    <selfCollide>false</selfCollide>
    <turnGravityOff>true</turnGravityOff>
  </gazebo>
  <gazebo reference="Head">
    <mu1>0.5</mu1>
    <mu2>0.5</mu2>
    <selfCollide>false</selfCollide>
    <turnGravityOff>true</turnGravityOff>
  </gazebo>
  <gazebo reference="gaze">
    <mu1>0.5</mu1>
    <mu2>0.5</mu2>
    <selfCollide>false</selfCollide>
    <turnGravityOff>true</turnGravityOff>
  </gazebo>
  <!-- ARMS -->
  <gazebo reference="LShoulder">
    <mu1>0.5</mu1>
    <mu2>0.5</mu2>
    <selfCollide>false</selfCollide>
    <turnGravityOff>true</turnGravityOff>
  </gazebo>
  <gazebo reference="LBicep">
    <mu1>0.5</mu1>
    <mu2>0.5</mu2>
    <selfCollide>false</selfCollide>
    <turnGravityOff>true</turnGravityOff>
  </gazebo>
  <gazebo reference="LElbow">
    <mu1>0.5</mu1>
    <mu2>0.5</mu2>
    <selfCollide>false</selfCollide>
    <turnGravityOff>true</turnGravityOff>
  </gazebo>
  <gazebo reference="LForeArm">
    <mu1>0.5</mu1>
    <mu2>0.5</mu2>
    <selfCollide>false</selfCollide>
    <turnGravityOff>true</turnGravityOff>
  </gazebo>
  <gazebo reference="l_wrist">
    <mu1>0.5</mu1>
    <mu2>0.5</mu2>
    <selfCollide>false</selfCollide>
    <turnGravityOff>true</turnGravityOff>
  </gazebo>
  <gazebo reference="l_gripper">
    <mu1>0.5</mu1>
    <mu2>0.5</mu2>
    <selfCollide>false</selfCollide>
    <turnGravityOff>true</turnGravityOff>
  </gazebo>
  <gazebo reference="RShoulder">
    <mu1>0.5</mu1>
    <mu2>0.5</mu2>
    <selfCollide>false</selfCollide>
    <turnGravityOff>true</turnGravityOff>
  </gazebo>
  <gazebo reference="RBicep">
    <mu1>0.5</mu1>
    <mu2>0.5</mu2>
    <selfCollide>false</selfCollide>
    <turnGravityOff>true</turnGravityOff>
  </gazebo>
  <gazebo reference="RElbow">
    <mu1>0.5</mu1>
    <mu2>0.5</mu2>
    <selfCollide>false</selfCollide>
    <turnGravityOff>true</turnGravityOff>
  </gazebo>
  <gazebo reference="RForeArm">
    <mu1>0.5</mu1>
    <mu2>0.5</mu2>
    <selfCollide>false</selfCollide>
    <turnGravityOff>true</turnGravityOff>
  </gazebo>
  <gazebo reference="r_wrist">
    <mu1>0.5</mu1>
    <mu2>0.5</mu2>
    <selfCollide>false</selfCollide>
    <turnGravityOff>true</turnGravityOff>
  </gazebo>
  <gazebo reference="r_gripper">
    <mu1>0.5</mu1>
    <mu2>0.5</mu2>
    <selfCollide>false</selfCollide>
    <turnGravityOff>true</turnGravityOff>
  </gazebo>
  <gazebo reference="LFinger11_link">
    <mu1>0.5</mu1>
    <mu2>0.5</mu2>
    <selfCollide>false</selfCollide>
    <turnGravityOff>true</turnGravityOff>
  </gazebo>
  <gazebo reference="LFinger12_link">
    <mu1>0.5</mu1>
    <mu2>0.5</mu2>
    <selfCollide>false</selfCollide>
    <turnGravityOff>true</turnGravityOff>
  </gazebo>
  <gazebo reference="LFinger13_link">
    <mu1>0.5</mu1>
    <mu2>0.5</mu2>
    <selfCollide>false</selfCollide>
    <turnGravityOff>true</turnGravityOff>
  </gazebo>
  <gazebo reference="LFinger21_link">
    <mu1>0.5</mu1>
    <mu2>0.5</mu2>
    <selfCollide>false</selfCollide>
    <turnGravityOff>true</turnGravityOff>
  </gazebo>
  <gazebo reference="LFinger22_link">
    <mu1>0.5</mu1>
    <mu2>0.5</mu2>
    <selfCollide>false</selfCollide>
    <turnGravityOff>true</turnGravityOff>
  </gazebo>
  <gazebo reference="LFinger23_link">
    <mu1>0.5</mu1>
    <mu2>0.5</mu2>
    <selfCollide>false</selfCollide>
    <turnGravityOff>true</turnGravityOff>
  </gazebo>
  <gazebo reference="LFinger31_link">
    <mu1>0.5</mu1>
    <mu2>0.5</mu2>
    <selfCollide>false</selfCollide>
    <turnGravityOff>true</turnGravityOff>
  </gazebo>
  <gazebo reference="LFinger32_link">
    <mu1>0.5</mu1>
    <mu2>0.5</mu2>
    <selfCollide>false</selfCollide>
    <turnGravityOff>true</turnGravityOff>
  </gazebo>
  <gazebo reference="LFinger33_link">
    <mu1>0.5</mu1>
    <mu2>0.5</mu2>
    <selfCollide>false</selfCollide>
    <turnGravityOff>true</turnGravityOff>
  </gazebo>
  <gazebo reference="LFinger41_link">
    <mu1>0.5</mu1>
    <mu2>0.5</mu2>
    <selfCollide>false</selfCollide>
    <turnGravityOff>true</turnGravityOff>
  </gazebo>
  <gazebo reference="LFinger42_link">
    <mu1>0.5</mu1>
    <mu2>0.5</mu2>
    <selfCollide>false</selfCollide>
    <turnGravityOff>true</turnGravityOff>
  </gazebo>
  <gazebo reference="LFinger43_link">
    <mu1>0.5</mu1>
    <mu2>0.5</mu2>
    <selfCollide>false</selfCollide>
    <turnGravityOff>true</turnGravityOff>
  </gazebo>
  <gazebo reference="LThumb1_link">
    <mu1>0.5</mu1>
    <mu2>0.5</mu2>
    <selfCollide>false</selfCollide>
    <turnGravityOff>true</turnGravityOff>
  </gazebo>
  <gazebo reference="LThumb2_link">
    <mu1>0.5</mu1>
    <mu2>0.5</mu2>
    <selfCollide>false</selfCollide>
    <turnGravityOff>true</turnGravityOff>
  </gazebo>
  <gazebo reference="Hip">
    <mu1>0.5</mu1>
    <mu2>0.5</mu2>
    <selfCollide>false</selfCollide>
    <turnGravityOff>true</turnGravityOff>
  </gazebo>
  <gazebo reference="Pelvis">
    <mu1>0.5</mu1>
    <mu2>0.5</mu2>
    <selfCollide>false</selfCollide>
    <turnGravityOff>true</turnGravityOff>
  </gazebo>
  <gazebo reference="Tibia">
    <mu1>0.5</mu1>
    <mu2>0.5</mu2>
    <selfCollide>false</selfCollide>
    <turnGravityOff>true</turnGravityOff>
  </gazebo>
  <gazebo reference="WheelFL_link">
    <mu1>1</mu1>
    <mu2>0</mu2>
    <kp value="10000000.0"/>
    <kd value="1.0"/>
    <fdir1 value="1 0 0"/>
    <minDepth>0.003</minDepth>
    <turnGravityOff>true</turnGravityOff>
  </gazebo>
  <gazebo reference="WheelB_link">
    <mu1>0.5</mu1>
    <mu2>0.5</mu2>
    <kp value="10000000.0"/>
    <kd value="1.0"/>
    <fdir1 value="1 0 0"/>
    <minDepth>0.003</minDepth>
    <turnGravityOff>true</turnGravityOff>
  </gazebo>
  <gazebo reference="WheelFR_link">
    <mu1>0</mu1>
    <mu2>1</mu2>
    <kp value="10000000.0"/>
    <kd value="1.0"/>
    <fdir1 value="0 1 0"/>
    <minDepth>0.003</minDepth>
    <turnGravityOff>true</turnGravityOff>
  </gazebo>
  <gazebo reference="RFinger11_link">
    <mu1>0.5</mu1>
    <mu2>0.5</mu2>
    <selfCollide>false</selfCollide>
    <turnGravityOff>true</turnGravityOff>
  </gazebo>
  <gazebo reference="RFinger12_link">
    <mu1>0.5</mu1>
    <mu2>0.5</mu2>
    <selfCollide>false</selfCollide>
    <turnGravityOff>true</turnGravityOff>
  </gazebo>
  <gazebo reference="RFinger13_link">
    <mu1>0.5</mu1>
    <mu2>0.5</mu2>
    <selfCollide>false</selfCollide>
    <turnGravityOff>true</turnGravityOff>
  </gazebo>
  <gazebo reference="RFinger21_link">
    <mu1>0.5</mu1>
    <mu2>0.5</mu2>
    <selfCollide>false</selfCollide>
    <turnGravityOff>true</turnGravityOff>
  </gazebo>
  <gazebo reference="RFinger22_link">
    <mu1>0.5</mu1>
    <mu2>0.5</mu2>
    <selfCollide>false</selfCollide>
    <turnGravityOff>true</turnGravityOff>
  </gazebo>
  <gazebo reference="RFinger23_link">
    <mu1>0.5</mu1>
    <mu2>0.5</mu2>
    <selfCollide>false</selfCollide>
    <turnGravityOff>true</turnGravityOff>
  </gazebo>
  <gazebo reference="RFinger31_link">
    <mu1>0.5</mu1>
    <mu2>0.5</mu2>
    <selfCollide>false</selfCollide>
    <turnGravityOff>true</turnGravityOff>
  </gazebo>
  <gazebo reference="RFinger32_link">
    <mu1>0.5</mu1>
    <mu2>0.5</mu2>
    <selfCollide>false</selfCollide>
    <turnGravityOff>true</turnGravityOff>
  </gazebo>
  <gazebo reference="RFinger33_link">
    <mu1>0.5</mu1>
    <mu2>0.5</mu2>
    <selfCollide>false</selfCollide>
    <turnGravityOff>true</turnGravityOff>
  </gazebo>
  <gazebo reference="RFinger41_link">
    <mu1>0.5</mu1>
    <mu2>0.5</mu2>
    <selfCollide>false</selfCollide>
    <turnGravityOff>true</turnGravityOff>
  </gazebo>
  <gazebo reference="RFinger42_link">
    <mu1>0.5</mu1>
    <mu2>0.5</mu2>
    <selfCollide>false</selfCollide>
    <turnGravityOff>true</turnGravityOff>
  </gazebo>
  <gazebo reference="RFinger43_link">
    <mu1>0.5</mu1>
    <mu2>0.5</mu2>
    <selfCollide>false</selfCollide>
    <turnGravityOff>true</turnGravityOff>
  </gazebo>
  <gazebo reference="RThumb1_link">
    <mu1>0.5</mu1>
    <mu2>0.5</mu2>
    <selfCollide>false</selfCollide>
    <turnGravityOff>true</turnGravityOff>
  </gazebo>
  <gazebo reference="RThumb2_link">
    <mu1>0.5</mu1>
    <mu2>0.5</mu2>
    <selfCollide>false</selfCollide>
    <turnGravityOff>true</turnGravityOff>
  </gazebo>
  <!--
        RGB CAMERAS
-->
  <gazebo reference="CameraTop_frame">
    <sensor name="CameraTop" type="camera">
      <update_rate>5.0</update_rate>
      <camera name="camera_top">
        <horizontal_fov>1.0</horizontal_fov>
        <image>
          <width>640</width>
          <height>480</height>
          <format>R8G8B8</format>
        </image>
        <clip>
          <near>0.3</near>
          <far>500</far>
        </clip>
        <noise>
          <type>gaussian</type>
          <mean>0.0</mean>
          <stddev>0.007</stddev>
        </noise>
      </camera>
    </sensor>
  </gazebo>
  <gazebo reference="CameraBottom_frame">
    <sensor name="CameraBottom" type="camera">
      <update_rate>5.0</update_rate>
      <camera name="camera_bottom">
        <horizontal_fov>1.0</horizontal_fov>
        <image>
          <width>640</width>
          <height>480</height>
          <format>R8G8B8</format>
        </image>
        <clip>
          <near>0.05</near>
          <far>500</far>
        </clip>
        <noise>
          <type>gaussian</type>
          <mean>0.0</mean>
          <stddev>0.007</stddev>
        </noise>
      </camera>
    </sensor>
  </gazebo>
  <gazebo reference="CameraDepth_frame">
    <sensor name="CameraDepth_frame_sensor" type="depth">
      <always_on>true</always_on>
      <update_rate>20.0</update_rate>
      <camera>
        <horizontal_fov>1.01229096616</horizontal_fov>
        <image>
          <format>B8G8R8</format>
          <width>320</width>
          <height>240</height>
        </image>
        <clip>
          <near>0.4</near>
          <far>8.0</far>
        </clip>
      </camera>
    </sensor>
  </gazebo>
  <!--
    BUMPERS
<gazebo reference="BumperB_frame">
  <mu1>0.5</mu1>
  <mu2>0.5</mu2>
  <selfCollide>false</selfCollide>
  <turnGravityOff>true</turnGravityOff>
  <fdir1>1 0 0</fdir1>
  <maxVel>0.1</maxVel>
  <minDepth>0.003</minDepth>
  <sensor name="BumperB" type="contact">
    <always_on>1</always_on>
    <update_rate>20</update_rate>
    <visualize>false</visualize>
    <contact>
      <collision>BumperB_frame_collision</collision>
    </contact>
  </sensor>
</gazebo>
<gazebo reference="BumperFL_frame">
  <mu1>0.5</mu1>
  <mu2>0.5</mu2>
  <selfCollide>false</selfCollide>
  <turnGravityOff>true</turnGravityOff>
  <fdir1>1 0 0</fdir1>
  <maxVel>0.1</maxVel>
  <minDepth>0.003</minDepth>
  <sensor name="BumperFL" type="contact">
    <always_on>1</always_on>
    <update_rate>20</update_rate>
    <visualize>false</visualize>
    <contact>
      <collision>BumperFL_frame_collision</collision>
    </contact>
  </sensor>
</gazebo>
<gazebo reference="BumperFR_frame">
  <mu1>0.5</mu1>
  <mu2>0.5</mu2>
  <selfCollide>false</selfCollide>
  <turnGravityOff>true</turnGravityOff>
  <fdir1>1 0 0</fdir1>
  <maxVel>0.1</maxVel>
  <minDepth>0.003</minDepth>
  <sensor name="BumperFR" type="contact">
    <always_on>1</always_on>
    <update_rate>20</update_rate>
    <visualize>false</visualize>
    <contact>
      <collision>BumperFR_frame_collision</collision>
    </contact>
  </sensor>
</gazebo>
-->
  <!--
    Sonars
-->
  <gazebo reference="SonarBack_frame">
    <sensor name="SonarBack" type="ray">
      <pose>0 0 0 0 0 0</pose>
      <update_rate>20</update_rate>
      <visualize>false</visualize>
      <ray>
        <scan>
          <horizontal>
            <samples>5</samples>
            <resolution>3</resolution>
            <min_angle>-0.52</min_angle>
            <max_angle>0.52</max_angle>
          </horizontal>
          <vertical>
            <samples>5</samples>
            <resolution>3</resolution>
            <min_angle>-0.52</min_angle>
            <max_angle>0.52</max_angle>
          </vertical>
        </scan>
        <range>
          <min>0.0</min>
          <max>5.0</max>
          <resolution>3</resolution>
        </range>
      </ray>
    </sensor>
  </gazebo>
  <gazebo reference="SonarFront_frame">
    <sensor name="SonarFront" type="ray">
      <pose>0 0 0 0 0 0</pose>
      <update_rate>20</update_rate>
      <visualize>false</visualize>
      <ray>
        <scan>
          <horizontal>
            <samples>5</samples>
            <resolution>3</resolution>
            <min_angle>-0.52</min_angle>
            <max_angle>0.52</max_angle>
          </horizontal>
          <vertical>
            <samples>5</samples>
            <resolution>3</resolution>
            <min_angle>-0.52</min_angle>
            <max_angle>0.52</max_angle>
          </vertical>
        </scan>
        <range>
          <min>0.0</min>
          <max>5.0</max>
          <resolution>3</resolution>
        </range>
      </ray>
    </sensor>
  </gazebo>
  <!-- Drive controller -->
<ros2_control name="pepper_robot_wheel_system" type="system">
    <hardware>
      <plugin>ign_ros2_control/IgnitionSystem</plugin>
    </hardware>
    <joint name="WheelFL">
      <param name="initial_position">0</param>
      <state_interface name="position"/>
      <state_interface name="velocity"/>
      <state_interface name="effort"/>
    </joint>
    <joint name="WheelB">
      <param name="initial_position">0</param>
      <state_interface name="position"/>
      <state_interface name="velocity"/>
      <state_interface name="effort"/>
    </joint>
    <joint name="WheelFR">
      <param name="initial_position">0</param>
      <state_interface name="position"/>
      <state_interface name="velocity"/>
      <state_interface name="effort"/>
    </joint>
  </ros2_control>
  <gazebo>
    <plugin filename="ignition-gazebo-diff-drive-system" name="ignition::gazebo::systems::DiffDrive">
    <left_joint>WheelFL</left_joint>
    <right_joint>WheelFR</right_joint>
    <back_joint>WheelB</back_joint>
    <wheel_separation>0.170</wheel_separation>
    <wheel_radius>0.07</wheel_radius>
    </plugin>
  </gazebo>

<!-- HEAD -->
  <transmission name="HeadYaw_Transmission">
    <type>transmission_interface/SimpleTransmission</type>
    <joint name="HeadYaw">
      <hardwareInterface>hardware_interface/PositionJointInterface</hardwareInterface>
    </joint>
    <actuator name="HeadYaw_Motor">
      <!-- Dummy Values -->
      <hardwareInterface>hardware_interface/PositionJointInterface</hardwareInterface>
      <mechanicalReduction>101.3</mechanicalReduction>
    </actuator>
  </transmission>
  <transmission name="HeadPitch_Transmission">
    <type>transmission_interface/SimpleTransmission</type>
    <joint name="HeadPitch">
      <hardwareInterface>hardware_interface/PositionJointInterface</hardwareInterface>
    </joint>
    <actuator name="HeadPitch_Motor">
      <!-- Dummy Values -->
      <hardwareInterface>hardware_interface/PositionJointInterface</hardwareInterface>
      <mechanicalReduction>118.1</mechanicalReduction>
    </actuator>
  </transmission>
  <!-- ARMS -->
  <!-- XACRO -->
  <transmission name="LShoulderPitch_Transmission">
    <type>transmission_interface/SimpleTransmission</type>
    <joint name="LShoulderPitch">
      <hardwareInterface>hardware_interface/EffortJointInterface</hardwareInterface>
    </joint>
    <actuator name="LShoulderPitch_Motor">
      <hardwareInterface>hardware_interface/EffortJointInterface</hardwareInterface>
      <mechanicalReduction>101.3</mechanicalReduction>
    </actuator>
  </transmission>
  <transmission name="LShoulderRoll_Transmission">
    <type>transmission_interface/SimpleTransmission</type>
    <joint name="LShoulderRoll">
      <hardwareInterface>hardware_interface/EffortJointInterface</hardwareInterface>
    </joint>
    <actuator name="LShoulderRoll_Motor">
      <hardwareInterface>hardware_interface/EffortJointInterface</hardwareInterface>
      <mechanicalReduction>118.1</mechanicalReduction>
    </actuator>
  </transmission>
  <transmission name="LElbowYaw_Transmission">
    <type>transmission_interface/SimpleTransmission</type>
    <joint name="LElbowYaw">
      <hardwareInterface>hardware_interface/EffortJointInterface</hardwareInterface>
    </joint>
    <actuator name="LElbowYaw_Motor">
      <hardwareInterface>hardware_interface/EffortJointInterface</hardwareInterface>
      <mechanicalReduction>101.3</mechanicalReduction>
    </actuator>
  </transmission>
  <transmission name="LElbowRoll_Transmission">
    <type>transmission_interface/SimpleTransmission</type>
    <joint name="LElbowRoll">
      <hardwareInterface>hardware_interface/EffortJointInterface</hardwareInterface>
    </joint>
    <actuator name="LElbowRoll_Motor">
      <hardwareInterface>hardware_interface/EffortJointInterface</hardwareInterface>
      <mechanicalReduction>118.1</mechanicalReduction>
    </actuator>
  </transmission>
  <transmission name="LWristYaw_Transmission">
    <type>transmission_interface/SimpleTransmission</type>
    <joint name="LWristYaw">
      <hardwareInterface>hardware_interface/EffortJointInterface</hardwareInterface>
    </joint>
    <actuator name="LWristYaw_Motor">
      <hardwareInterface>hardware_interface/EffortJointInterface</hardwareInterface>
      <mechanicalReduction>118.1</mechanicalReduction>
    </actuator>
  </transmission>
  <transmission name="LHand_Transmission">
    <type>transmission_interface/SimpleTransmission</type>
    <joint name="LHand">
      <hardwareInterface>hardware_interface/EffortJointInterface</hardwareInterface>
    </joint>
    <actuator name="LHand_Motor">
      <hardwareInterface>hardware_interface/EffortJointInterface</hardwareInterface>
      <mechanicalReduction>36.24</mechanicalReduction>
    </actuator>
  </transmission>
  <transmission name="RShoulderPitch_Transmission">
    <type>transmission_interface/SimpleTransmission</type>
    <joint name="RShoulderPitch">
      <hardwareInterface>hardware_interface/EffortJointInterface</hardwareInterface>
    </joint>
    <actuator name="RShoulderPitch_Motor">
      <hardwareInterface>hardware_interface/EffortJointInterface</hardwareInterface>
      <mechanicalReduction>101.3</mechanicalReduction>
    </actuator>
  </transmission>
  <transmission name="RShoulderRoll_Transmission">
    <type>transmission_interface/SimpleTransmission</type>
    <joint name="RShoulderRoll">
      <hardwareInterface>hardware_interface/EffortJointInterface</hardwareInterface>
    </joint>
    <actuator name="RShoulderRoll_Motor">
      <hardwareInterface>hardware_interface/EffortJointInterface</hardwareInterface>
      <mechanicalReduction>118.1</mechanicalReduction>
    </actuator>
  </transmission>
  <transmission name="RElbowYaw_Transmission">
    <type>transmission_interface/SimpleTransmission</type>
    <joint name="RElbowYaw">
      <hardwareInterface>hardware_interface/EffortJointInterface</hardwareInterface>
    </joint>
    <actuator name="RElbowYaw_Motor">
      <hardwareInterface>hardware_interface/EffortJointInterface</hardwareInterface>
      <mechanicalReduction>101.3</mechanicalReduction>
    </actuator>
  </transmission>
  <transmission name="RElbowRoll_Transmission">
    <type>transmission_interface/SimpleTransmission</type>
    <joint name="RElbowRoll">
      <hardwareInterface>hardware_interface/EffortJointInterface</hardwareInterface>
    </joint>
    <actuator name="RElbowRoll_Motor">
      <hardwareInterface>hardware_interface/EffortJointInterface</hardwareInterface>
      <mechanicalReduction>118.1</mechanicalReduction>
    </actuator>
  </transmission>
  <transmission name="RWristYaw_Transmission">
    <type>transmission_interface/SimpleTransmission</type>
    <joint name="RWristYaw">
      <hardwareInterface>hardware_interface/EffortJointInterface</hardwareInterface>
    </joint>
    <actuator name="RWristYaw_Motor">
      <hardwareInterface>hardware_interface/EffortJointInterface</hardwareInterface>
      <mechanicalReduction>118.1</mechanicalReduction>
    </actuator>
  </transmission>
  <transmission name="RHand_Transmission">
    <type>transmission_interface/SimpleTransmission</type>
    <joint name="RHand">
      <hardwareInterface>hardware_interface/EffortJointInterface</hardwareInterface>
    </joint>
    <actuator name="RHand_Motor">
      <hardwareInterface>hardware_interface/EffortJointInterface</hardwareInterface>
      <mechanicalReduction>36.24</mechanicalReduction>
    </actuator>
  </transmission>
  <!-- LEGS -->
  <transmission name="HipRoll_Transmission">
    <type>transmission_interface/SimpleTransmission</type>
    <joint name="HipRoll">
      <hardwareInterface>hardware_interface/EffortJointInterface</hardwareInterface>
    </joint>
    <actuator name="HipRoll_Motor">
      <!-- Dummy Values -->
      <hardwareInterface>hardware_interface/EffortJointInterface</hardwareInterface>
      <mechanicalReduction>108.33</mechanicalReduction>
    </actuator>
  </transmission>
  <transmission name="HipPitch_Transmission">
    <type>transmission_interface/SimpleTransmission</type>
    <joint name="HipPitch">
      <hardwareInterface>hardware_interface/EffortJointInterface</hardwareInterface>
    </joint>
    <actuator name="HipPitch_Motor">
      <!-- Dummy Values -->
      <hardwareInterface>hardware_interface/EffortJointInterface</hardwareInterface>
      <mechanicalReduction>108.33</mechanicalReduction>
    </actuator>
  </transmission>
  <transmission name="KneePitch_Transmission">
    <type>transmission_interface/SimpleTransmission</type>
    <joint name="KneePitch">
      <hardwareInterface>hardware_interface/EffortJointInterface</hardwareInterface>
    </joint>
    <actuator name="KneePitch_Motor">
      <!-- Dummy Values -->
      <hardwareInterface>hardware_interface/EffortJointInterface</hardwareInterface>
      <mechanicalReduction>108.33</mechanicalReduction>
    </actuator>
  </transmission>
  <!-- XACRO -->
  <transmission name="WheelFL_Transmission">
    <type>transmission_interface/SimpleTransmission</type>
    <joint name="WheelFL">
      <hardwareInterface>hardware_interface/VelocityJointInterface</hardwareInterface>
    </joint>
    <actuator name="WheelFL_Motor">
      <!-- Dummy Values -->
      <hardwareInterface>hardware_interface/VelocityJointInterface</hardwareInterface>
      <mechanicalReduction>25.0</mechanicalReduction>
    </actuator>
  </transmission>
  <transmission name="WheelB_Transmission">
    <type>transmission_interface/SimpleTransmission</type>
    <joint name="WheelB">
      <hardwareInterface>hardware_interface/VelocityJointInterface</hardwareInterface>
    </joint>
    <actuator name="WheelB_Motor">
      <!-- Dummy Values -->
      <hardwareInterface>hardware_interface/VelocityJointInterface</hardwareInterface>
      <mechanicalReduction>25.0</mechanicalReduction>
    </actuator>
  </transmission>
  <transmission name="WheelFR_Transmission">
    <type>transmission_interface/SimpleTransmission</type>
    <joint name="WheelFR">
      <hardwareInterface>hardware_interface/VelocityJointInterface</hardwareInterface>
    </joint>
    <actuator name="WheelFR_Motor">
      <!-- Dummy Values -->
      <hardwareInterface>hardware_interface/VelocityJointInterface</hardwareInterface>
      <mechanicalReduction>25.0</mechanicalReduction>
    </actuator>
  </transmission>
  <ros2_control name="pepper_robot_left_armSystem" type="system">
    <hardware>
      <plugin>ign_ros2_control/IgnitionSystem</plugin>
    </hardware>
    <joint name="LShoulderPitch">
      <param name="initial_position">0.0</param>
      <command_interface name="effort"/>
      <state_interface name="position"/>
      <state_interface name="velocity"/>
      <state_interface name="effort"/>
    </joint>
    <joint name="LShoulderRoll">
      <param name="initial_position">3.141592653589793</param>
      <command_interface name="effort"/>
      <state_interface name="position"/>
      <state_interface name="velocity"/>
      <state_interface name="effort"/>
    </joint>
    <joint name="LElbowYaw">
      <param name="initial_position">0.0</param>
      <command_interface name="effort"/>
      <state_interface name="position"/>
      <state_interface name="velocity"/>
      <state_interface name="effort"/>
    </joint>
    <joint name="LElbowRoll">
      <param name="initial_position">4.71238898038469</param>
      <command_interface name="effort"/>
      <state_interface name="position"/>
      <state_interface name="velocity"/>
      <state_interface name="effort"/>
    </joint>
    <joint name="LWristYaw">
      <param name="initial_position">0.0</param>
      <command_interface name="effort"/>
      <state_interface name="position"/>
      <state_interface name="velocity"/>
      <state_interface name="effort"/>
    </joint>
  </ros2_control>
  <ros2_control name="pepper_robot_right_armSystem" type="system">
    <hardware>
      <plugin>ign_ros2_control/IgnitionSystem</plugin>
    </hardware>
    <joint name="RShoulderPitch">
      <param name="initial_position">0.0</param>
      <command_interface name="effort"/>
      <state_interface name="position"/>
      <state_interface name="velocity"/>
      <state_interface name="effort"/>
    </joint>
    <joint name="RShoulderRoll">
      <param name="initial_position">3.141592653589793</param>
      <command_interface name="effort"/>
      <state_interface name="position"/>
      <state_interface name="velocity"/>
      <state_interface name="effort"/>
    </joint>
    <joint name="RElbowYaw">
      <param name="initial_position">0.0</param>
      <command_interface name="effort"/>
      <state_interface name="position"/>
      <state_interface name="velocity"/>
      <state_interface name="effort"/>
    </joint>
    <joint name="RElbowRoll">
      <param name="initial_position">4.71238898038469</param>
      <command_interface name="effort"/>
      <state_interface name="position"/>
      <state_interface name="velocity"/>
      <state_interface name="effort"/>
    </joint>
    <joint name="RWristYaw">
      <param name="initial_position">0.0</param>
      <command_interface name="effort"/>
      <state_interface name="position"/>
      <state_interface name="velocity"/>
      <state_interface name="effort"/>
    </joint>
  </ros2_control>
  <ros2_control name="pepper_robot_HeadSystem" type="system">
    <hardware>
      <plugin>ign_ros2_control/IgnitionSystem</plugin>
    </hardware>
    <joint name="HeadYaw">
      <param name="initial_position">0.0</param>
      <command_interface name="effort"/>
      <state_interface name="position"/>
      <state_interface name="velocity"/>
      <state_interface name="effort"/>
    </joint>
    <joint name="HeadPitch">
      <param name="initial_position">3.141592653589793</param>
      <command_interface name="effort"/>
      <state_interface name="position"/>
      <state_interface name="velocity"/>
      <state_interface name="effort"/>
    </joint>
  </ros2_control>
  <ros2_control name="pepper_robot_PelvisSystem" type="system">
    <hardware>
      <plugin>ign_ros2_control/IgnitionSystem</plugin>
    </hardware>
    <joint name="HipRoll">
      <param name="initial_position">0.0</param>
      <command_interface name="effort"/>
      <state_interface name="position"/>
      <state_interface name="velocity"/>
      <state_interface name="effort"/>
    </joint>
    <joint name="HipPitch">
      <param name="initial_position">3.141592653589793</param>
      <command_interface name="effort"/>
      <state_interface name="position"/>
      <state_interface name="velocity"/>
      <state_interface name="effort"/>
    </joint>
    <joint name="KneePitch">
      <param name="initial_position">3.141592653589793</param>
      <command_interface name="effort"/>
      <state_interface name="position"/>
      <state_interface name="velocity"/>
      <state_interface name="effort"/>
    </joint>
  </ros2_control>
  <ros2_control name="pepper_robot_LHandSystem" type="system">
    <hardware>
      <plugin>ign_ros2_control/IgnitionSystem</plugin>
    </hardware>
    <joint name="LHand">
      <param name="initial_position">0.0</param>
      <command_interface name="effort"/>
      <state_interface name="position"/>
      <state_interface name="velocity"/>
      <state_interface name="effort"/>
    </joint>
    <joint name="LFinger11">
      <param name="initial_position">0.2</param>
      <command_interface name="effort"/>
      <state_interface name="position"/>
      <state_interface name="velocity"/>
      <state_interface name="effort"/>
    </joint>
    <joint name="LFinger12">
      <param name="initial_position">0.2</param>
      <command_interface name="effort"/>
      <state_interface name="position"/>
      <state_interface name="velocity"/>
      <state_interface name="effort"/>
    </joint>
    <joint name="LFinger13">
      <param name="initial_position">0.2</param>
      <command_interface name="effort"/>
      <state_interface name="position"/>
      <state_interface name="velocity"/>
      <state_interface name="effort"/>
    </joint>
    <joint name="LFinger21">
      <param name="initial_position">0.2</param>
      <command_interface name="effort"/>
      <state_interface name="position"/>
      <state_interface name="velocity"/>
      <state_interface name="effort"/>
    </joint>
    <joint name="LFinger22">
      <param name="initial_position">0.2</param>
      <command_interface name="effort"/>
      <state_interface name="position"/>
      <state_interface name="velocity"/>
      <state_interface name="effort"/>
    </joint>
    <joint name="LFinger23">
      <param name="initial_position">0.2</param>
      <command_interface name="effort"/>
      <state_interface name="position"/>
      <state_interface name="velocity"/>
      <state_interface name="effort"/>
    </joint>
    <joint name="LFinger31">
      <param name="initial_position">0.2</param>
      <command_interface name="effort"/>
      <state_interface name="position"/>
      <state_interface name="velocity"/>
      <state_interface name="effort"/>
    </joint>
    <joint name="LFinger32">
      <param name="initial_position">0.2</param>
      <command_interface name="effort"/>
      <state_interface name="position"/>
      <state_interface name="velocity"/>
      <state_interface name="effort"/>
    </joint>
    <joint name="LFinger33">
      <param name="initial_position">0.2</param>
      <command_interface name="effort"/>
      <state_interface name="position"/>
      <state_interface name="velocity"/>
      <state_interface name="effort"/>
    </joint>
    <joint name="LFinger41">
      <param name="initial_position">0.2</param>
      <command_interface name="effort"/>
      <state_interface name="position"/>
      <state_interface name="velocity"/>
      <state_interface name="effort"/>
    </joint>
    <joint name="LFinger42">
      <param name="initial_position">0.2</param>
      <command_interface name="effort"/>
      <state_interface name="position"/>
      <state_interface name="velocity"/>
      <state_interface name="effort"/>
    </joint>
    <joint name="LFinger43">
      <param name="initial_position">0.2</param>
      <command_interface name="effort"/>
      <state_interface name="position"/>
      <state_interface name="velocity"/>
      <state_interface name="effort"/>
    </joint>
    <joint name="LThumb1">
      <param name="initial_position">0.2</param>
      <command_interface name="effort"/>
      <state_interface name="position"/>
      <state_interface name="velocity"/>
      <state_interface name="effort"/>
    </joint>
    <joint name="LThumb2">
      <param name="initial_position">0.2</param>
      <command_interface name="effort"/>
      <state_interface name="position"/>
      <state_interface name="velocity"/>
      <state_interface name="effort"/>
    </joint>
  </ros2_control>
  <ros2_control name="pepper_robot_RHandSystem" type="system">
    <hardware>
      <plugin>ign_ros2_control/IgnitionSystem</plugin>
    </hardware>
    <joint name="RHand">
      <param name="initial_position">0.0</param>
      <command_interface name="effort"/>
      <state_interface name="position"/>
      <state_interface name="velocity"/>
      <state_interface name="effort"/>
    </joint>
    <joint name="RFinger11">
      <param name="initial_position">0.2</param>
      <command_interface name="effort"/>
      <state_interface name="position"/>
      <state_interface name="velocity"/>
      <state_interface name="effort"/>
    </joint>
    <joint name="RFinger12">
      <param name="initial_position">0.2</param>
      <command_interface name="effort"/>
      <state_interface name="position"/>
      <state_interface name="velocity"/>
      <state_interface name="effort"/>
    </joint>
    <joint name="RFinger13">
      <param name="initial_position">0.2</param>
      <command_interface name="effort"/>
      <state_interface name="position"/>
      <state_interface name="velocity"/>
      <state_interface name="effort"/>
    </joint>
    <joint name="RFinger21">
      <param name="initial_position">0.2</param>
      <command_interface name="effort"/>
      <state_interface name="position"/>
      <state_interface name="velocity"/>
      <state_interface name="effort"/>
    </joint>
    <joint name="RFinger22">
      <param name="initial_position">0.2</param>
      <command_interface name="effort"/>
      <state_interface name="position"/>
      <state_interface name="velocity"/>
      <state_interface name="effort"/>
    </joint>
    <joint name="RFinger23">
      <param name="initial_position">0.2</param>
      <command_interface name="effort"/>
      <state_interface name="position"/>
      <state_interface name="velocity"/>
      <state_interface name="effort"/>
    </joint>
    <joint name="RFinger31">
      <param name="initial_position">0.2</param>
      <command_interface name="effort"/>
      <state_interface name="position"/>
      <state_interface name="velocity"/>
      <state_interface name="effort"/>
    </joint>
    <joint name="RFinger32">
      <param name="initial_position">0.2</param>
      <command_interface name="effort"/>
      <state_interface name="position"/>
      <state_interface name="velocity"/>
      <state_interface name="effort"/>
    </joint>
    <joint name="RFinger33">
      <param name="initial_position">0.2</param>
      <command_interface name="effort"/>
      <state_interface name="position"/>
      <state_interface name="velocity"/>
      <state_interface name="effort"/>
    </joint>
    <joint name="RFinger41">
      <param name="initial_position">0.2</param>
      <command_interface name="effort"/>
      <state_interface name="position"/>
      <state_interface name="velocity"/>
      <state_interface name="effort"/>
    </joint>
    <joint name="RFinger42">
      <param name="initial_position">0.2</param>
      <command_interface name="effort"/>
      <state_interface name="position"/>
      <state_interface name="velocity"/>
      <state_interface name="effort"/>
    </joint>
    <joint name="RFinger43">
      <param name="initial_position">0.2</param>
      <command_interface name="effort"/>
      <state_interface name="position"/>
      <state_interface name="velocity"/>
      <state_interface name="effort"/>
    </joint>
    <joint name="RThumb1">
      <param name="initial_position">0.2</param>
      <command_interface name="effort"/>
      <state_interface name="position"/>
      <state_interface name="velocity"/>
      <state_interface name="effort"/>
    </joint>
    <joint name="RThumb2">
      <param name="initial_position">0.2</param>
      <command_interface name="effort"/>
      <state_interface name="position"/>
      <state_interface name="velocity"/>
      <state_interface name="effort"/>
    </joint>
  </ros2_control>
   <gazebo>
    <plugin filename="ign_ros2_control-system" name="ign_ros2_control::IgnitionROS2ControlPlugin">
      <parameters>/root/ws/src/pepper_ign_moveit2/pepper_robot_moveit_config/config/controllers_effort.yaml</parameters>
    </plugin>
  </gazebo>
  <gazebo>
    <plugin filename="ignition-gazebo-pose-publisher-system" name="ignition::gazebo::systems::PosePublisher">
      <use_pose_vector_msg>true</use_pose_vector_msg>
      <publish_nested_model_pose>true</publish_nested_model_pose>
      <publish_link_pose>false</publish_link_pose>
      <publish_collision_pose>false</publish_collision_pose>
      <publish_visual_pose>false</publish_visual_pose>
    </plugin>
  </gazebo>
</robot>