<?xml version="1.0" ?>
<robot name="pepper_robot" xmlns:xacro="http://www.ros.org/wiki/xacro">
  <link name="base_link"/>
  <joint name="HeadYaw" type="revolute">
    <parent link="torso"/>
    <child link="Neck"/>
    <origin rpy="0 0 0" xyz="-0.038 0 0.3089"/>
    <axis xyz="0 0 1.0"/>
    <limit effort="5.428" lower="-2.08567" upper="2.08567" velocity="7.33998"/>
  </joint>
  <link name="Neck">
    <inertial>
      <mass value="0.09146568603258816"/>
      <inertia ixx="0.004394158568586095" ixy="-2.227492593175832e-10" ixz="0.00011851972636433963" iyy="0.004679644492310061" iyz="1.457247778434002e-09" izz="0.0043841432021901015"/>
      <origin rpy="0 0 0" xyz="-0.0122611 -8.25641e-07 0.0292341"/>
    </inertial>
    <visual>
      <geometry>
        <mesh filename="package://pepper_robot_description/pepper_robot/meshes/HeadYaw.dae" scale="0.1 0.1 0.1"/>
      </geometry>
      <origin rpy="0 0 0" xyz="0 0 0"/>
    </visual>
    <collision>
      <geometry>
        <mesh filename="package://pepper_robot_description/pepper_robot/meshes/HeadYaw_0.10.stl" scale="0.1 0.1 0.1"/>
      </geometry>
      <origin rpy="0 0 0" xyz="0 0 0"/>
    </collision>
  </link>
  <joint name="HeadPitch" type="revolute">
    <parent link="Neck"/>
    <child link="Head"/>
    <origin rpy="0 0 0" xyz="0 0 0"/>
    <axis xyz="0 1.0 0"/>
    <limit effort="2.666" lower="-0.706858" upper="0.4451" velocity="9.22756"/>
  </joint>
  <link name="Head">
    <inertial>
      <mass value="3.7955398538315377"/>
      <inertia ixx="3.683208656428616" ixy="0.00041889033001187904" ixz="0.022603422116371886" iyy="2.9078796995709886" iyz="0.0005006966355005746" izz="1.8507243925959245"/>
       <origin rpy="0 0 0" xyz="0.0908328 0.000167721 -1.0109"/>
    </inertial>
    <visual>
      <geometry>
        <mesh filename="package://pepper_robot_description/pepper_robot/meshes/HeadPitch.dae" scale="0.1 0.1 0.1"/>
      </geometry>
      <origin rpy="0 0 0" xyz="0 0 0"/>
    </visual>
    <collision>
      <geometry>
        <mesh filename="package://pepper_robot_description/pepper_robot/meshes/HeadPitch_0.10.stl" scale="0.1 0.1 0.1"/>
      </geometry>
      <origin rpy="0 0 0" xyz="0 0 0"/>
    </collision>
  </link>
  <joint name="HipRoll" type="revolute">
    <parent link="Hip"/>
    <child link="torso"/>
    <origin rpy="0 0 0" xyz="0 0 0.079"/>
    <axis xyz="-1.0 0 0"/>
    <limit effort="10.1884" lower="-0.514872" upper="0.514872" velocity="2.27032"/>
  </joint>
  <link name="Hip">
    <inertial>
      <mass value="1.007402858772892"/>
      <inertia ixx="0.2568937774115777" ixy="-9.096957334768854e-05" ixz="0.004055986689177799" iyy="0.35295735919431726" iyz="-0.0012970391194746071" izz="0.18078541923077684"/>
      <origin rpy="0 0 0" xyz="0.0110062 -0.00150986 -0.650903"/>
    </inertial>
    <visual>
      <geometry>
        <mesh filename="package://pepper_robot_description/pepper_robot/meshes/HipRoll.dae" scale="0.1 0.1 0.1"/>
      </geometry>
      <origin rpy="0 0 0" xyz="0 0 0.079"/>
    </visual>
    <collision>
      <geometry>
        <mesh filename="package://pepper_robot_description/pepper_robot/meshes/HipRoll_0.10.stl" scale="0.1 0.1 0.1"/>
      </geometry>
      <origin rpy="0 0 0" xyz="0 0 0.079"/>
    </collision>
  </link>
  <joint name="HipPitch" type="revolute">
    <parent link="Pelvis"/>
    <child link="Hip"/>
    <origin rpy="0 0 0" xyz="0 0 0.268"/>
    <axis xyz="0 -1.0 0"/>
    <limit effort="19.787" lower="-1.03847" upper="1.03847" velocity="2.93276"/>
  </joint>
  <link name="Pelvis">
    <inertial>
      <mass value="3.7955398538315377"/>
      <inertia ixx="3.683208656428616" ixy="0.00041889033001187904" ixz="0.022603422116371886" iyy="2.9078796995709886" iyz="0.0005006966355005746" izz="1.8507243925959245"/>
      <origin rpy="0 0 0" xyz="0.0908328 0.000167721 -1.0109"/>
    </inertial>
    <visual>
      <geometry>
        <mesh filename="package://pepper_robot_description/pepper_robot/meshes/HipPitch.dae" scale="0.1 0.1 0.1"/>
      </geometry>
      <origin rpy="0 0 0" xyz="0 0 0.268"/>
    </visual>
    <collision>
      <geometry>
        <mesh filename="package://pepper_robot_description/pepper_robot/meshes/HipPitch_0.10.stl" scale="0.1 0.1 0.1"/>
      </geometry>
      <origin rpy="0 0 0" xyz="0 0 0.268"/>
    </collision>
  </link>
  <joint name="KneePitch" type="revolute">
    <parent link="Tibia"/>
    <child link="Pelvis"/>
    <origin rpy="0 0 0" xyz="0 0 0"/>
    <axis xyz="0 -1.0 0"/>
    <limit effort="27.702" lower="-0.514872" upper="0.514872" velocity="2.93276"/>
  </joint>
  <link name="Tibia">
    <inertial>
      <mass value="12.344158152172728"/>
      <inertia ixx="20.137807259762987" ixy="-0.0011573869694506639" ixz="0.6633694744426599" iyy="18.055269240696504" iyz="-0.0006093016165113692" izz="21.81987274144166"/>
      <origin rpy="0 0 0" xyz="-0.0333667 -5.76754e-05 -1.99402"/>
    </inertial>
    <visual>
      <geometry>
        <mesh filename="package://pepper_robot_description/pepper_robot/meshes/KneePitch.dae" scale="0.1 0.1 0.1"/>
      </geometry>
      <origin rpy="0 0 0" xyz="0 0 0"/>
    </visual>
    <collision>
      <geometry>
        <mesh filename="package://pepper_robot_description/pepper_robot/meshes/KneePitch_0.10.stl" scale="0.1 0.1 0.1"/>
      </geometry>
      <origin rpy="0 0 0" xyz="0 0 0"/>
    </collision>
  </link>
  <link name="torso">
    <inertial>
      <mass value="4.89481724014063"/>
      <inertia ixx="4.566611207207986" ixy="6.295958647287147e-05" ixz="0.6656507041876883" iyy="4.047538877310803" iyz="-0.0001979039690338895" izz="3.383191376734822"/>
      <origin rpy="0 0 0" xyz="-0.255593 3.02341e-05 0.391816"/>
    </inertial>
    <visual>
      <geometry>
        <mesh filename="package://pepper_robot_description/pepper_robot/meshes/Torso.dae" scale="0.1 0.1 0.1"/>
      </geometry>
      <origin rpy="0 0 0" xyz="2e-05 0 0.139"/>
    </visual>
    <collision>
      <geometry>
        <mesh filename="package://pepper_robot_description/pepper_robot/meshes/Torso_0.10.stl" scale="0.1 0.1 0.1"/>
      </geometry>
      <origin rpy="0 0 0" xyz="2e-05 0 0.139"/>
    </collision>
  </link>
  <joint name="LShoulderPitch" type="revolute">
    <parent link="torso"/>
    <child link="LShoulder"/>
    <origin rpy="0 0 0" xyz="-0.057 0.14974 0.22582"/>
    <axis xyz="0 1.0 0"/>
    <limit effort="5.428" lower="-0.08567" upper="0.08567" velocity="7.33998"/>
  </joint>
  <link name="LShoulder">
    <inertial>
      <mass value="0.1407150721615769"/>
      <inertia ixx="0.008532465294919685" ixy="-1.921871257281156e-09" ixz="6.354448667623257e-10" iyy="0.008532463936418763" iyz="-2.0716583314902065e-09" izz="0.010252750793533655"/>
      <origin rpy="0 0 0" xyz="-7.40285e-08 -7.32303e-08 -1.30517e-07"/>
    </inertial>
    <visual>
      <geometry>
        <mesh filename="package://pepper_robot_description/pepper_robot/meshes/LShoulderPitch.dae" scale="0.1 0.1 0.1"/>
      </geometry>
      <origin rpy="0 0 0" xyz="0 0 0"/>
    </visual>
    <collision>
      <geometry>
        <mesh filename="package://pepper_robot_description/pepper_robot/meshes/LShoulderPitch_0.10.stl" scale="0.1 0.1 0.1"/>
      </geometry>
      <origin rpy="0 0 0" xyz="0 0 0"/>
    </collision>
  </link>
  <joint name="LShoulderRoll" type="revolute">
    <parent link="LShoulder"/>
    <child link="LBicep"/>
    <origin rpy="0 0 0" xyz="0 0 0"/>
    <axis xyz="0 0 1.0"/>
    <limit effort="2.666" lower="0.00872665" upper="1.56207" velocity="9.22756"/>
  </joint>
  <link name="LBicep">
    <inertial>
      <mass value="0.3137032437994389"/>
      <inertia ixx="0.0246985312391643" ixy="0.0012817864835498575" ixz="0.0017029391719427644" iyy="0.07167351354785373" iyz="6.874532266960408e-05" izz="0.06766357853335765"/>
      <origin rpy="0 0 0" xyz="0.902599 -0.162517 -0.0061116"/>
    </inertial>
    <visual>
      <geometry>
        <mesh filename="package://pepper_robot_description/pepper_robot/meshes/LShoulderRoll.dae" scale="0.1 0.1 0.1"/>
      </geometry>
      <origin rpy="0 0 0" xyz="0 0 0"/>
    </visual>
    <collision>
      <geometry>
        <mesh filename="package://pepper_robot_description/pepper_robot/meshes/LShoulderRoll_0.10.stl" scale="0.1 0.1 0.1"/>
      </geometry>
      <origin rpy="0 0 0" xyz="0 0 0"/>
    </collision>
  </link>
  <joint name="LElbowYaw" type="revolute">
    <parent link="LBicep"/>
    <child link="LElbow"/>
    <origin rpy="0 -0.157079 0" xyz="0.1812 0.015 0.00013"/>
    <axis xyz="1.0 0 0"/>
    <limit effort="5.428" lower="-2.08567" upper="2.08567" velocity="7.33998"/>
  </joint>
  <link name="LElbow">
    <inertial>
      <mass value="0.07380464672624755"/>
      <inertia ixx="0.0029965021096465144" ixy="-1.0388008758299257e-10" ixz="-4.2002518090263296e-12" iyy="0.0030276726644025737" iyz="-2.993681557885386e-10" izz="0.003027671062092063"/>
      <origin rpy="0 0 0" xyz="-7.34206e-08 1.48077e-09 -4.87585e-08"/>
    </inertial>
    <visual>
      <geometry>
        <mesh filename="package://pepper_robot_description/pepper_robot/meshes/LElbowYaw.dae" scale="0.1 0.1 0.1"/>
      </geometry>
      <origin rpy="0 0 0" xyz="0 0 0"/>
    </visual>
    <collision>
      <geometry>
        <mesh filename="package://pepper_robot_description/pepper_robot/meshes/LElbowYaw_0.10.stl" scale="0.1 0.1 0.1"/>
      </geometry>
      <origin rpy="0 0 0" xyz="0 0 0"/>
    </collision>
  </link>
  <joint name="LElbowRoll" type="revolute">
    <parent link="LElbow"/>
    <child link="LForeArm"/>
    <origin rpy="0 0 0" xyz="0 0 0"/>
    <axis xyz="0 0 1.0"/>
    <limit effort="2.666" lower="-1.56207" upper="-0.00872665" velocity="9.22756"/>
  </joint>
  <link name="LForeArm">
    <inertial>
      <mass value="0.13321114815783727"/>
      <inertia ixx="0.007157363843746049" ixy="0.0011275611019520542" ixz="4.27305683742527e-05" iyy="0.009914916199350478" iyz="1.7673061298494217e-06" izz="0.009622293474477288"/>
      <origin rpy="0 0 0" xyz="0.470716 0.0367563 -0.00106886"/>
    </inertial>
    <visual>
      <geometry>
        <mesh filename="package://pepper_robot_description/pepper_robot/meshes/LElbowRoll.dae" scale="0.1 0.1 0.1"/>
      </geometry>
      <origin rpy="0 0 0" xyz="0 0 0"/>
    </visual>
    <collision>
      <geometry>
        <mesh filename="package://pepper_robot_description/pepper_robot/meshes/LElbowRoll_0.10.stl" scale="0.1 0.1 0.1"/>
      </geometry>
      <origin rpy="0 0 0" xyz="0 0 0"/>
    </collision>
  </link>
  <joint name="LWristYaw" type="revolute">
    <parent link="LForeArm"/>
    <child link="l_wrist"/>
    <origin rpy="0 0 0" xyz="0.15 0 0"/>
    <axis xyz="1.0 0 0"/>
    <limit effort="0.2014" lower="-1.82387" upper="1.82387" velocity="17.3835"/>
  </joint>
  <link name="l_wrist">
    <inertial>
      <mass value="0.207591874180564"/>
      <inertia ixx="0.011703404133435855" ixy="0.0008177441509091999" ixz="-0.0033215793821857902" iyy="0.0378403638770384" iyz="-0.00014926583294427482" izz="0.04027267667550336"/>
      <origin rpy="0 0 0" xyz="0.110379 -0.0272187 0.0250071"/>
    </inertial>
    <visual>
      <geometry>
        <mesh filename="package://pepper_robot_description/pepper_robot/meshes/LWristYaw.dae" scale="0.1 0.1 0.1"/>
      </geometry>
      <origin rpy="0 0 0" xyz="0 0 0"/>
    </visual>
    <collision>
      <geometry>
        <mesh filename="package://pepper_robot_description/pepper_robot/meshes/LWristYaw_0.10.stl" scale="0.1 0.1 0.1"/>
      </geometry>
      <origin rpy="0 0 0" xyz="0 0 0"/>
    </collision>
  </link>
  <joint name="LHand" type="revolute">
    <parent link="l_wrist"/>
    <child link="l_gripper"/>
    <origin rpy="0 0 0" xyz="0.025 0 0"/>
    <axis xyz="1.0 0 0"/>
    <limit effort="0.144" lower="0.02" upper="0.98" velocity="12.56"/>
  </joint>
  <link name="l_gripper">
    <inertial>
      <mass value="0.207591874180564"/>
      <inertia ixx="0.011703404133435855" ixy="0.0008177441509091999" ixz="-0.0033215793821857902" iyy="0.0378403638770384" iyz="-0.00014926583294427482" izz="0.04027267667550336"/>
    </inertial>
  </link>
  <joint name="RShoulderPitch" type="revolute">
    <parent link="torso"/>
    <child link="RShoulder"/>
    <origin rpy="0 0 0" xyz="-0.057 -0.14974 0.22582"/>
    <axis xyz="0 1.0 0"/>
    <limit effort="5.428" lower="-0.08567" upper="0.08567" velocity="7.33998"/>
  </joint>
  <link name="RShoulder">
    <inertial>
      <mass value="0.1407150721615769"/>
      <inertia ixx="0.008532465294919685" ixy="-1.921871257281156e-09" ixz="6.354448667623257e-10" iyy="0.008532463936418763" iyz="-2.0716583314902065e-09" izz="0.010252750793533655"/>
      <origin rpy="0 0 0" xyz="-7.40285e-08 -7.32303e-08 -1.30517e-07"/>
    </inertial>
    <visual>
      <geometry>
        <mesh filename="package://pepper_robot_description/pepper_robot/meshes/RShoulderPitch.dae" scale="0.1 0.1 0.1"/>
      </geometry>
      <origin rpy="0 0 0" xyz="0 0 0"/>
    </visual>
    <collision>
      <geometry>
        <mesh filename="package://pepper_robot_description/pepper_robot/meshes/RShoulderPitch_0.10.stl" scale="0.1 0.1 0.1"/>
      </geometry>
      <origin rpy="0 0 0" xyz="0 0 0"/>
    </collision>
  </link>
  <joint name="RShoulderRoll" type="revolute">
    <parent link="RShoulder"/>
    <child link="RBicep"/>
    <origin rpy="0 0 0" xyz="0 0 0"/>
    <axis xyz="0 0 1.0"/>
    <limit effort="2.666" lower="-1.56207" upper="-0.00872665" velocity="9.22756"/>
  </joint>
  <link name="RBicep">
    <inertial>
      <mass value="0.3137032437994389"/>
      <inertia ixx="0.0246985312391643" ixy="0.0012817864835498575" ixz="0.0017029391719427644" iyy="0.07167351354785373" iyz="6.874532266960408e-05" izz="0.06766357853335765"/>
      <origin rpy="0 0 0" xyz="0.902599 -0.162517 -0.0061116"/>
    </inertial>
    <visual>
      <geometry>
        <mesh filename="package://pepper_robot_description/pepper_robot/meshes/RShoulderRoll.dae" scale="0.1 0.1 0.1"/>
      </geometry>
      <origin rpy="0 0 0" xyz="0 0 0"/>
    </visual>
    <collision>
      <geometry>
        <mesh filename="package://pepper_robot_description/pepper_robot/meshes/RShoulderRoll_0.10.stl" scale="0.1 0.1 0.1"/>
      </geometry>
      <origin rpy="0 0 0" xyz="0 0 0"/>
    </collision>
  </link>
  <joint name="RElbowYaw" type="revolute">
    <parent link="RBicep"/>
    <child link="RElbow"/>
    <origin rpy="0 -0.157079 0" xyz="0.1812 -0.015 0.00013"/>
    <axis xyz="1.0 0 0"/>
    <limit effort="5.428" lower="-2.08567" upper="2.08567" velocity="7.33998"/>
  </joint>
  <link name="RElbow">
    <inertial>
      <mass value="0.07380464672624755"/>
      <inertia ixx="0.0029965021096465144" ixy="-1.0388008758299257e-10" ixz="-4.2002518090263296e-12" iyy="0.0030276726644025737" iyz="-2.993681557885386e-10" izz="0.003027671062092063"/>
      <origin rpy="0 0 0" xyz="-7.34206e-08 1.48077e-09 -4.87585e-08"/>
    </inertial>
    <visual>
      <geometry>
        <mesh filename="package://pepper_robot_description/pepper_robot/meshes/RElbowYaw.dae" scale="0.1 0.1 0.1"/>
      </geometry>
      <origin rpy="0 0 0" xyz="0 0 0"/>
    </visual>
    <collision>
      <geometry>
        <mesh filename="package://pepper_robot_description/pepper_robot/meshes/RElbowYaw_0.10.stl" scale="0.1 0.1 0.1"/>
      </geometry>
      <origin rpy="0 0 0" xyz="0 0 0"/>
    </collision>
  </link>
  <joint name="RElbowRoll" type="revolute">
    <parent link="RElbow"/>
    <child link="RForeArm"/>
    <origin rpy="0 0 0" xyz="0 0 0"/>
    <axis xyz="0 0 1.0"/>
    <limit effort="2.666" lower="0.00872665" upper="1.56207" velocity="9.22756"/>
  </joint>
  <link name="RForeArm">
    <inertial>
      <mass value="0.13321114815783727"/>
      <inertia ixx="0.0071573638437460495" ixy="-0.0011275611019520536" ixz="4.273056837425241e-05" iyy="0.009914916199350471" iyz="-1.7673061298494556e-06" izz="0.009622293474477281"/>
      <origin rpy="0 0 0" xyz="0.470716 -0.0367563 -0.00106886"/>
    </inertial>
    <visual>
      <geometry>
        <mesh filename="package://pepper_robot_description/pepper_robot/meshes/RElbowRoll.dae" scale="0.1 0.1 0.1"/>
      </geometry>
      <origin rpy="0 0 0" xyz="0 0 0"/>
    </visual>
    <collision>
      <geometry>
        <mesh filename="package://pepper_robot_description/pepper_robot/meshes/RElbowRoll_0.10.stl" scale="0.1 0.1 0.1"/>
      </geometry>
      <origin rpy="0 0 0" xyz="0 0 0"/>
    </collision>
  </link>
  <joint name="RWristYaw" type="revolute">
    <parent link="RForeArm"/>
    <child link="r_wrist"/>
    <origin rpy="0 0 0" xyz="0.15 0 0"/>
    <axis xyz="1.0 0 0"/>
    <limit effort="0.2014" lower="-1.82387" upper="1.82387" velocity="17.3835"/>
  </joint>
  <link name="r_wrist">
    <inertial>
      <mass value="0.20759187418056393"/>
      <inertia ixx="0.011703404133435853" ixy="-0.0008177441509091997" ixz="-0.0033215793821857907" iyy="0.0378403638770384" iyz="0.0001492658329442748" izz="0.04027267667550336"/>
      <origin rpy="0 0 0" xyz="0.110379 0.0272187 0.0250071"/>
    </inertial>
    <visual>
      <geometry>
        <mesh filename="package://pepper_robot_description/pepper_robot/meshes/RWristYaw.dae" scale="0.1 0.1 0.1"/>
      </geometry>
      <origin rpy="0 0 0" xyz="0 0 0"/>
    </visual>
    <collision>
      <geometry>
        <mesh filename="package://pepper_robot_description/pepper_robot/meshes/RWristYaw_0.10.stl" scale="0.1 0.1 0.1"/>
      </geometry>
      <origin rpy="0 0 0" xyz="0 0 0"/>
    </collision>
  </link>
  <joint name="RHand" type="revolute">
    <parent link="r_wrist"/>
    <child link="r_gripper"/>
    <origin rpy="0 0 0" xyz="0.025 0 0"/>
    <axis xyz="1.0 0 0"/>
    <limit effort="0.144" lower="0.02" upper="0.98" velocity="12.56"/>
  </joint>
  <link name="r_gripper">
    <inertial>
      <mass value="0.20759187418056393"/>
      <inertia ixx="0.011703404133435853" ixy="-0.0008177441509091997" ixz="-0.0033215793821857907" iyy="0.0378403638770384" iyz="0.0001492658329442748" izz="0.04027267667550336"/>
    </inertial>
  </link>
  <link name="RFinger41_link">
    <inertial>
      <mass value="0.0017342022888397826"/>
      <inertia ixx="3.4678131817764306e-06" ixy="-3.2590475824677086e-08" ixz="-1.7757160450735597e-07" iyy="9.067959870196139e-06" iyz="-5.042702138748998e-08" izz="9.981406591519867e-06"/>
    </inertial>
    <visual>
      <geometry>
        <mesh filename="package://pepper_robot_description/pepper_robot/meshes/RFinger41.dae" scale="0.1 0.1 0.1"/>
      </geometry>
      <origin rpy="0 0 0" xyz="0 0 0"/>
    </visual>
    <collision>
      <geometry>
        <mesh filename="package://pepper_robot_description/pepper_robot/meshes/RFinger41_0.10.stl" scale="0.1 0.1 0.1"/>
      </geometry>
      <origin rpy="0 0 0" xyz="0 0 0"/>
    </collision>
  </link>
  <joint name="RFinger41" type="continuous">
    <parent link="r_wrist"/>
    <child link="RFinger41_link"/>
    <origin rpy="1.74402 1.04064 -0.0683394" xyz="0.074 -0.0309 0"/>
    <axis xyz="0 0 1.0"/>
    <mimic joint="RHand" multiplier="0.872665" offset="0"/>
  </joint>
  <link name="LFinger42_link">
    <inertial>
      <mass value="0.0017342022167828866"/>
      <inertia ixx="3.4678129025584815e-06" ixy="-3.2590475824677086e-08" ixz="-1.7757160450735597e-07" iyy="9.067959511713518e-06" iyz="-5.042702138748998e-08" izz="9.981406591519867e-06"/>
    </inertial>
    <visual>
      <geometry>
        <mesh filename="package://pepper_robot_description/pepper_robot/meshes/LFinger42.dae" scale="0.1 0.1 0.1"/>
      </geometry>
      <origin rpy="0 0 0" xyz="0 0 0"/>
    </visual>
    <collision>
      <geometry>
        <mesh filename="package://pepper_robot_description/pepper_robot/meshes/LFinger42_0.10.stl" scale="0.1 0.1 0.1"/>
      </geometry>
      <origin rpy="0 0 0" xyz="0 0 0"/>
    </collision>
  </link>
  <joint name="LFinger42" type="continuous">
    <parent link="LFinger41_link"/>
    <child link="LFinger42_link"/>
    <origin rpy="0 0 -1.0472" xyz="0.018 0 0"/>
    <axis xyz="0 0 1.0"/>
    <mimic joint="LHand" multiplier="0.872665" offset="0"/>
  </joint>
  <link name="RFinger12_link">
    <inertial>
      <mass value="0.001734202280194698"/>
      <inertia ixx="3.4678131132210503e-06" ixy="-3.2590542520134944e-08" ixz="-1.7757159744336223e-07" iyy="9.067959840882744e-06" iyz="-5.0426962301906756e-08" izz="9.981406511792481e-06"/>
    </inertial>
    <visual>
      <geometry>
        <mesh filename="package://pepper_robot_description/pepper_robot/meshes/RFinger12.dae" scale="0.1 0.1 0.1"/>
      </geometry>
      <origin rpy="0 0 0" xyz="0 0 0"/>
    </visual>
    <collision>
      <geometry>
        <mesh filename="package://pepper_robot_description/pepper_robot/meshes/RFinger12_0.10.stl" scale="0.1 0.1 0.1"/>
      </geometry>
      <origin rpy="0 0 0" xyz="0 0 0"/>
    </collision>
  </link>
  <joint name="RFinger12" type="continuous">
    <parent link="RFinger11_link"/>
    <child link="RFinger12_link"/>
    <origin rpy="0 0 -1.0472" xyz="0.018 0 0"/>
    <axis xyz="0 0 1.0"/>
    <mimic joint="RHand" multiplier="0.872665" offset="0"/>
  </joint>
  <link name="LFinger33_link">
    <inertial>
      <mass value="0.0012119665608007826"/>
      <inertia ixx="2.09223979628447e-06" ixy="-1.1457416792102813e-07" ixz="1.4168110404002701e-08" iyy="4.049992996669056e-06" iyz="-5.704190202736846e-09" izz="4.41653713434438e-06"/>
    </inertial>
    <visual>
      <geometry>
        <mesh filename="package://pepper_robot_description/pepper_robot/meshes/LFinger33.dae" scale="0.1 0.1 0.1"/>
      </geometry>
      <origin rpy="0 0 0" xyz="0 0 0"/>
    </visual>
    <collision>
      <geometry>
        <mesh filename="package://pepper_robot_description/pepper_robot/meshes/LFinger33_0.10.stl" scale="0.1 0.1 0.1"/>
      </geometry>
      <origin rpy="0 0 0" xyz="0 0 0"/>
    </collision>
  </link>
  <joint name="LFinger33" type="continuous">
    <parent link="LFinger32_link"/>
    <child link="LFinger33_link"/>
    <origin rpy="0 0 -1.0472" xyz="0.018 0 0"/>
    <axis xyz="0 0 1.0"/>
    <mimic joint="LHand" multiplier="0.872665" offset="0"/>
  </joint>
  <link name="RFinger31_link">
    <inertial>
      <mass value="0.001734202271258544"/>
      <inertia ixx="3.467813135465312e-06" ixy="-3.259050145806951e-08" ixz="-1.775715550954204e-07" iyy="9.067959615799793e-06" iyz="-5.0427022839883744e-08" izz="9.981406326737224e-06"/>
    </inertial>
    <visual>
      <geometry>
        <mesh filename="package://pepper_robot_description/pepper_robot/meshes/RFinger31.dae" scale="0.1 0.1 0.1"/>
      </geometry>
      <origin rpy="0 0 0" xyz="0 0 0"/>
    </visual>
    <collision>
      <geometry>
        <mesh filename="package://pepper_robot_description/pepper_robot/meshes/RFinger31_0.10.stl" scale="0.1 0.1 0.1"/>
      </geometry>
      <origin rpy="0 0 0" xyz="0 0 0"/>
    </collision>
  </link>
  <joint name="RFinger31" type="continuous">
    <parent link="r_wrist"/>
    <child link="RFinger31_link"/>
    <origin rpy="1.67523 1.04483 0.029316" xyz="0.0833 -0.0123 0.004"/>
    <axis xyz="0 0 1.0"/>
    <mimic joint="RHand" multiplier="0.872665" offset="0"/>
  </joint>
  <link name="LFinger21_link">
    <inertial>
      <mass value="0.0017342022480607796"/>
      <inertia ixx="3.46781299004819e-06" ixy="-3.259062428110205e-08" ixz="-1.775715353345546e-07" iyy="9.067959876771903e-06" iyz="-5.0426968074891446e-08" izz="9.98140651315344e-06"/>
    </inertial>
    <visual>
      <geometry>
        <mesh filename="package://pepper_robot_description/pepper_robot/meshes/LFinger21.dae" scale="0.1 0.1 0.1"/>
      </geometry>
      <origin rpy="0 0 0" xyz="0 0 0"/>
    </visual>
    <collision>
      <geometry>
        <mesh filename="package://pepper_robot_description/pepper_robot/meshes/LFinger21_0.10.stl" scale="0.1 0.1 0.1"/>
      </geometry>
      <origin rpy="0 0 0" xyz="0 0 0"/>
    </collision>
  </link>
  <joint name="LFinger21" type="continuous">
    <parent link="l_wrist"/>
    <child link="LFinger21_link"/>
    <origin rpy="1.5708 1.0472 -0.061086" xyz="0.0873 -0.0073 0.006"/>
    <axis xyz="0 0 1.0"/>
    <mimic joint="LHand" multiplier="0.872665" offset="0"/>
  </joint>
  <link name="RFinger32_link">
    <inertial>
      <mass value="0.0017342022235830492"/>
      <inertia ixx="3.467812920370958e-06" ixy="-3.259059292999676e-08" ixz="-1.775716485588287e-07" iyy="9.067959555576335e-06" iyz="-5.042697998356888e-08" izz="9.981406185385655e-06"/>
    </inertial>
    <visual>
      <geometry>
        <mesh filename="package://pepper_robot_description/pepper_robot/meshes/RFinger32.dae" scale="0.1 0.1 0.1"/>
      </geometry>
      <origin rpy="0 0 0" xyz="0 0 0"/>
    </visual>
    <collision>
      <geometry>
        <mesh filename="package://pepper_robot_description/pepper_robot/meshes/RFinger32_0.10.stl" scale="0.1 0.1 0.1"/>
      </geometry>
      <origin rpy="0 0 0" xyz="0 0 0"/>
    </collision>
  </link>
  <joint name="RFinger32" type="continuous">
    <parent link="RFinger31_link"/>
    <child link="RFinger32_link"/>
    <origin rpy="0 0 -1.0472" xyz="0.018 0 0"/>
    <axis xyz="0 0 1.0"/>
    <mimic joint="RHand" multiplier="0.872665" offset="0"/>
  </joint>
  <link name="LFinger13_link">
    <inertial>
      <mass value="0.001211966381471568"/>
      <inertia ixx="2.0922392266947087e-06" ixy="-1.1457419844015851e-07" ixz="1.4167922235814148e-08" iyy="4.049992160501547e-06" iyz="-5.704188035340379e-09" izz="4.416536573576023e-06"/>
    </inertial>
    <visual>
      <geometry>
        <mesh filename="package://pepper_robot_description/pepper_robot/meshes/LFinger13.dae" scale="0.1 0.1 0.1"/>
      </geometry>
      <origin rpy="0 0 0" xyz="0 0 0"/>
    </visual>
    <collision>
      <geometry>
        <mesh filename="package://pepper_robot_description/pepper_robot/meshes/LFinger13_0.10.stl" scale="0.1 0.1 0.1"/>
      </geometry>
      <origin rpy="0 0 0" xyz="0 0 0"/>
    </collision>
  </link>
  <joint name="LFinger13" type="continuous">
    <parent link="LFinger12_link"/>
    <child link="LFinger13_link"/>
    <origin rpy="0 0 -1.0472" xyz="0.018 0 0"/>
    <axis xyz="0 0 1.0"/>
    <mimic joint="LHand" multiplier="0.872665" offset="0"/>
  </joint>
  <link name="LFinger32_link">
    <inertial>
      <mass value="0.0017342022235830492"/>
      <inertia ixx="3.467812920370958e-06" ixy="-3.259059292999676e-08" ixz="-1.775716485588287e-07" iyy="9.067959555576335e-06" iyz="-5.042697998356888e-08" izz="9.981406185385655e-06"/>
    </inertial>
    <visual>
      <geometry>
        <mesh filename="package://pepper_robot_description/pepper_robot/meshes/LFinger32.dae" scale="0.1 0.1 0.1"/>
      </geometry>
      <origin rpy="0 0 0" xyz="0 0 0"/>
    </visual>
    <collision>
      <geometry>
        <mesh filename="package://pepper_robot_description/pepper_robot/meshes/LFinger32_0.10.stl" scale="0.1 0.1 0.1"/>
      </geometry>
      <origin rpy="0 0 0" xyz="0 0 0"/>
    </collision>
  </link>
  <joint name="LFinger32" type="continuous">
    <parent link="LFinger31_link"/>
    <child link="LFinger32_link"/>
    <origin rpy="0 0 -1.0472" xyz="0.018 0 0"/>
    <axis xyz="0 0 1.0"/>
    <mimic joint="LHand" multiplier="0.872665" offset="0"/>
  </joint>
  <link name="LFinger11_link">
    <inertial>
      <mass value="0.0017342022611750378"/>
      <inertia ixx="3.4678130376738107e-06" ixy="-3.259051008700385e-08" ixz="-1.7757161017490668e-07" iyy="9.067959783373034e-06" iyz="-5.042697811714405e-08" izz="9.981406489419801e-06"/>
    </inertial>
    <visual>
      <geometry>
        <mesh filename="package://pepper_robot_description/pepper_robot/meshes/LFinger11.dae" scale="0.1 0.1 0.1"/>
      </geometry>
      <origin rpy="0 0 0" xyz="0 0 0"/>
    </visual>
    <collision>
      <geometry>
        <mesh filename="package://pepper_robot_description/pepper_robot/meshes/LFinger11_0.10.stl" scale="0.1 0.1 0.1"/>
      </geometry>
      <origin rpy="0 0 0" xyz="0 0 0"/>
    </collision>
  </link>
  <joint name="LFinger11" type="continuous">
    <parent link="l_wrist"/>
    <child link="LFinger11_link"/>
    <origin rpy="1.74402 1.04064 -0.0334335" xyz="0.0821 -0.0268 0.004"/>
    <axis xyz="0 0 1.0"/>
    <mimic joint="LHand" multiplier="0.872665" offset="0"/>
  </joint>
  <link name="RFinger22_link">
    <inertial>
      <mass value="0.001734202428057582"/>
      <inertia ixx="3.4678136128088393e-06" ixy="-3.2591429893149244e-08" ixz="-1.775718802040381e-07" iyy="9.067962145044256e-06" iyz="-5.042709848652804e-08" izz="9.981409273765228e-06"/>
    </inertial>
    <visual>
      <geometry>
        <mesh filename="package://pepper_robot_description/pepper_robot/meshes/RFinger22.dae" scale="0.1 0.1 0.1"/>
      </geometry>
      <origin rpy="0 0 0" xyz="0 0 0"/>
    </visual>
    <collision>
      <geometry>
        <mesh filename="package://pepper_robot_description/pepper_robot/meshes/RFinger22_0.10.stl" scale="0.1 0.1 0.1"/>
      </geometry>
      <origin rpy="0 0 0" xyz="0 0 0"/>
    </collision>
  </link>
  <joint name="RFinger22" type="continuous">
    <parent link="RFinger21_link"/>
    <child link="RFinger22_link"/>
    <origin rpy="0 0 -1.0472" xyz="0.018 0 0"/>
    <axis xyz="0 0 1.0"/>
    <mimic joint="RHand" multiplier="0.872665" offset="0"/>
  </joint>
  <link name="RFinger13_link">
    <inertial>
      <mass value="0.001211966381471568"/>
      <inertia ixx="2.0922392266947087e-06" ixy="-1.1457419844015851e-07" ixz="1.4167922235814148e-08" iyy="4.049992160501547e-06" iyz="-5.704188035340379e-09" izz="4.416536573576023e-06"/>
    </inertial>
    <visual>
      <geometry>
        <mesh filename="package://pepper_robot_description/pepper_robot/meshes/RFinger13.dae" scale="0.1 0.1 0.1"/>
      </geometry>
      <origin rpy="0 0 0" xyz="0 0 0"/>
    </visual>
    <collision>
      <geometry>
        <mesh filename="package://pepper_robot_description/pepper_robot/meshes/RFinger13_0.10.stl" scale="0.1 0.1 0.1"/>
      </geometry>
      <origin rpy="0 0 0" xyz="0 0 0"/>
    </collision>
  </link>
  <joint name="RFinger13" type="continuous">
    <parent link="RFinger12_link"/>
    <child link="RFinger13_link"/>
    <origin rpy="0 0 -1.0472" xyz="0.018 0 0"/>
    <axis xyz="0 0 1.0"/>
    <mimic joint="RHand" multiplier="0.872665" offset="0"/>
  </joint>
  <link name="LFinger22_link">
    <inertial>
      <mass value="0.001734202428057582"/>
      <inertia ixx="3.4678136128088393e-06" ixy="-3.2591429893149244e-08" ixz="-1.775718802040381e-07" iyy="9.067962145044256e-06" iyz="-5.042709848652804e-08" izz="9.981409273765228e-06"/>
    </inertial>
    <visual>
      <geometry>
        <mesh filename="package://pepper_robot_description/pepper_robot/meshes/LFinger22.dae" scale="0.1 0.1 0.1"/>
      </geometry>
      <origin rpy="0 0 0" xyz="0 0 0"/>
    </visual>
    <collision>
      <geometry>
        <mesh filename="package://pepper_robot_description/pepper_robot/meshes/LFinger22_0.10.stl" scale="0.1 0.1 0.1"/>
      </geometry>
      <origin rpy="0 0 0" xyz="0 0 0"/>
    </collision>
  </link>
  <joint name="LFinger22" type="continuous">
    <parent link="LFinger21_link"/>
    <child link="LFinger22_link"/>
    <origin rpy="0 0 -1.0472" xyz="0.018 0 0"/>
    <axis xyz="0 0 1.0"/>
    <mimic joint="LHand" multiplier="0.872665" offset="0"/>
  </joint>
  <link name="RFinger21_link">
    <inertial>
      <mass value="0.0017342022480607796"/>
      <inertia ixx="3.46781299004819e-06" ixy="-3.259062428110205e-08" ixz="-1.775715353345546e-07" iyy="9.067959876771903e-06" iyz="-5.0426968074891446e-08" izz="9.98140651315344e-06"/>
    </inertial>
    <visual>
      <geometry>
        <mesh filename="package://pepper_robot_description/pepper_robot/meshes/RFinger21.dae" scale="0.1 0.1 0.1"/>
      </geometry>
      <origin rpy="0 0 0" xyz="0 0 0"/>
    </visual>
    <collision>
      <geometry>
        <mesh filename="package://pepper_robot_description/pepper_robot/meshes/RFinger21_0.10.stl" scale="0.1 0.1 0.1"/>
      </geometry>
      <origin rpy="0 0 0" xyz="0 0 0"/>
    </collision>
  </link>
  <joint name="RFinger21" type="continuous">
    <parent link="r_wrist"/>
    <child link="RFinger21_link"/>
    <origin rpy="1.5708 1.0472 0.061086" xyz="0.0873 0.0073 0.006"/>
    <axis xyz="0 0 1.0"/>
    <mimic joint="RHand" multiplier="0.872665" offset="0"/>
  </joint>
  <link name="LFinger41_link">
    <inertial>
      <mass value="0.0017342022888397826"/>
      <inertia ixx="3.4678131817764306e-06" ixy="-3.2590475824677086e-08" ixz="-1.7757160450735597e-07" iyy="9.067959870196139e-06" iyz="-5.042702138748998e-08" izz="9.981406591519867e-06"/>
    </inertial>
    <visual>
      <geometry>
        <mesh filename="package://pepper_robot_description/pepper_robot/meshes/LFinger41.dae" scale="0.1 0.1 0.1"/>
      </geometry>
      <origin rpy="0 0 0" xyz="0 0 0"/>
    </visual>
    <collision>
      <geometry>
        <mesh filename="package://pepper_robot_description/pepper_robot/meshes/LFinger41_0.10.stl" scale="0.1 0.1 0.1"/>
      </geometry>
      <origin rpy="0 0 0" xyz="0 0 0"/>
    </collision>
  </link>
  <joint name="LFinger41" type="continuous">
    <parent link="l_wrist"/>
    <child link="LFinger41_link"/>
    <origin rpy="1.39757 1.04064 0.0683394" xyz="0.074 0.0309 0"/>
    <axis xyz="0 0 1.0"/>
    <mimic joint="LHand" multiplier="0.872665" offset="0"/>
  </joint>
  <link name="LFinger12_link">
    <inertial>
      <mass value="0.001734202280194698"/>
      <inertia ixx="3.4678131132210503e-06" ixy="-3.2590542520134944e-08" ixz="-1.7757159744336223e-07" iyy="9.067959840882744e-06" iyz="-5.0426962301906756e-08" izz="9.981406511792481e-06"/>
    </inertial>
    <visual>
      <geometry>
        <mesh filename="package://pepper_robot_description/pepper_robot/meshes/LFinger12.dae" scale="0.1 0.1 0.1"/>
      </geometry>
      <origin rpy="0 0 0" xyz="0 0 0"/>
    </visual>
    <collision>
      <geometry>
        <mesh filename="package://pepper_robot_description/pepper_robot/meshes/LFinger12_0.10.stl" scale="0.1 0.1 0.1"/>
      </geometry>
      <origin rpy="0 0 0" xyz="0 0 0"/>
    </collision>
  </link>
  <joint name="LFinger12" type="continuous">
    <parent link="LFinger11_link"/>
    <child link="LFinger12_link"/>
    <origin rpy="0 0 -1.0472" xyz="0.018 0 0"/>
    <axis xyz="0 0 1.0"/>
    <mimic joint="LHand" multiplier="0.872665" offset="0"/>
  </joint>
  <link name="RFinger23_link">
    <inertial>
      <mass value="0.0012119663699255415"/>
      <inertia ixx="2.092239047891544e-06" ixy="-1.1457422969595025e-07" ixz="1.4167810663291497e-08" iyy="4.049992404946034e-06" iyz="-5.704156613549065e-09" izz="4.416536552898754e-06"/>
    </inertial>
    <visual>
      <geometry>
        <mesh filename="package://pepper_robot_description/pepper_robot/meshes/RFinger23.dae" scale="0.1 0.1 0.1"/>
      </geometry>
      <origin rpy="0 0 0" xyz="0 0 0"/>
    </visual>
    <collision>
      <geometry>
        <mesh filename="package://pepper_robot_description/pepper_robot/meshes/RFinger23_0.10.stl" scale="0.1 0.1 0.1"/>
      </geometry>
      <origin rpy="0 0 0" xyz="0 0 0"/>
    </collision>
  </link>
  <joint name="RFinger23" type="continuous">
    <parent link="RFinger22_link"/>
    <child link="RFinger23_link"/>
    <origin rpy="0 0 -1.0472" xyz="0.018 0 0"/>
    <axis xyz="0 0 1.0"/>
    <mimic joint="RHand" multiplier="0.872665" offset="0"/>
  </joint>
  <link name="RFinger11_link">
    <inertial>
      <mass value="0.0017342022611750378"/>
      <inertia ixx="3.4678130376738107e-06" ixy="-3.259051008700385e-08" ixz="-1.7757161017490668e-07" iyy="9.067959783373034e-06" iyz="-5.042697811714405e-08" izz="9.981406489419801e-06"/>
    </inertial>
    <visual>
      <geometry>
        <mesh filename="package://pepper_robot_description/pepper_robot/meshes/RFinger11.dae" scale="0.1 0.1 0.1"/>
      </geometry>
      <origin rpy="0 0 0" xyz="0 0 0"/>
    </visual>
    <collision>
      <geometry>
        <mesh filename="package://pepper_robot_description/pepper_robot/meshes/RFinger11_0.10.stl" scale="0.1 0.1 0.1"/>
      </geometry>
      <origin rpy="0 0 0" xyz="0 0 0"/>
    </collision>
  </link>
  <joint name="RFinger11" type="continuous">
    <parent link="r_wrist"/>
    <child link="RFinger11_link"/>
    <origin rpy="1.39757 1.04064 0.0334335" xyz="0.0821 0.0268 0.004"/>
    <axis xyz="0 0 1.0"/>
    <mimic joint="RHand" multiplier="0.872665" offset="0"/>
  </joint>
  <link name="LFinger23_link">
    <inertial>
      <mass value="0.0012119663699255415"/>
      <inertia ixx="2.092239047891544e-06" ixy="-1.1457422969595025e-07" ixz="1.4167810663291497e-08" iyy="4.049992404946034e-06" iyz="-5.704156613549065e-09" izz="4.416536552898754e-06"/>
    </inertial>
    <visual>
      <geometry>
        <mesh filename="package://pepper_robot_description/pepper_robot/meshes/LFinger23.dae" scale="0.1 0.1 0.1"/>
      </geometry>
      <origin rpy="0 0 0" xyz="0 0 0"/>
    </visual>
    <collision>
      <geometry>
        <mesh filename="package://pepper_robot_description/pepper_robot/meshes/LFinger23_0.10.stl" scale="0.1 0.1 0.1"/>
      </geometry>
      <origin rpy="0 0 0" xyz="0 0 0"/>
    </collision>
  </link>
  <joint name="LFinger23" type="continuous">
    <parent link="LFinger22_link"/>
    <child link="LFinger23_link"/>
    <origin rpy="0 0 -1.0472" xyz="0.018 0 0"/>
    <axis xyz="0 0 1.0"/>
    <mimic joint="LHand" multiplier="0.872665" offset="0"/>
  </joint>
  <link name="LFinger43_link">
    <inertial>
      <mass value="0.0012119663070476055"/>
      <inertia ixx="2.0922389330114635e-06" ixy="-1.1457410213059722e-07" ixz="1.4168138791312868e-08" iyy="4.049991916493551e-06" iyz="-5.70412920072251e-09" izz="4.416536298698657e-06"/>
    </inertial>
    <visual>
      <geometry>
        <mesh filename="package://pepper_robot_description/pepper_robot/meshes/LFinger43.dae" scale="0.1 0.1 0.1"/>
      </geometry>
      <origin rpy="0 0 0" xyz="0 0 0"/>
    </visual>
    <collision>
      <geometry>
        <mesh filename="package://pepper_robot_description/pepper_robot/meshes/LFinger43_0.10.stl" scale="0.1 0.1 0.1"/>
      </geometry>
      <origin rpy="0 0 0" xyz="0 0 0"/>
    </collision>
  </link>
  <joint name="LFinger43" type="continuous">
    <parent link="LFinger42_link"/>
    <child link="LFinger43_link"/>
    <origin rpy="0 0 -1.0472" xyz="0.018 0 0"/>
    <axis xyz="0 0 1.0"/>
    <mimic joint="LHand" multiplier="0.872665" offset="0"/>
  </joint>
  <link name="RFinger43_link">
    <inertial>
      <mass value="0.0012119663070476055"/>
      <inertia ixx="2.0922389330114635e-06" ixy="-1.1457410213059722e-07" ixz="1.4168138791312868e-08" iyy="4.049991916493551e-06" iyz="-5.70412920072251e-09" izz="4.416536298698657e-06"/>
    </inertial>
    <visual>
      <geometry>
        <mesh filename="package://pepper_robot_description/pepper_robot/meshes/RFinger43.dae" scale="0.1 0.1 0.1"/>
      </geometry>
      <origin rpy="0 0 0" xyz="0 0 0"/>
    </visual>
    <collision>
      <geometry>
        <mesh filename="package://pepper_robot_description/pepper_robot/meshes/RFinger43_0.10.stl" scale="0.1 0.1 0.1"/>
      </geometry>
      <origin rpy="0 0 0" xyz="0 0 0"/>
    </collision>
  </link>
  <joint name="RFinger43" type="continuous">
    <parent link="RFinger42_link"/>
    <child link="RFinger43_link"/>
    <origin rpy="0 0 -1.0472" xyz="0.018 0 0"/>
    <axis xyz="0 0 1.0"/>
    <mimic joint="RHand" multiplier="0.872665" offset="0"/>
  </joint>
  <link name="RFinger42_link">
    <inertial>
      <mass value="0.0017342022167828866"/>
      <inertia ixx="3.4678129025584815e-06" ixy="-3.2590475824677086e-08" ixz="-1.7757160450735597e-07" iyy="9.067959511713518e-06" iyz="-5.042702138748998e-08" izz="9.981406591519867e-06"/>
    </inertial>
    <visual>
      <geometry>
        <mesh filename="package://pepper_robot_description/pepper_robot/meshes/RFinger42.dae" scale="0.1 0.1 0.1"/>
      </geometry>
      <origin rpy="0 0 0" xyz="0 0 0"/>
    </visual>
    <collision>
      <geometry>
        <mesh filename="package://pepper_robot_description/pepper_robot/meshes/RFinger42_0.10.stl" scale="0.1 0.1 0.1"/>
      </geometry>
      <origin rpy="0 0 0" xyz="0 0 0"/>
    </collision>
  </link>
  <joint name="RFinger42" type="continuous">
    <parent link="RFinger41_link"/>
    <child link="RFinger42_link"/>
    <origin rpy="0 0 -1.0472" xyz="0.018 0 0"/>
    <axis xyz="0 0 1.0"/>
    <mimic joint="RHand" multiplier="0.872665" offset="0"/>
  </joint>
  <link name="LFinger31_link">
    <inertial>
      <mass value="0.001734202271258544"/>
      <inertia ixx="3.467813135465312e-06" ixy="-3.259050145806951e-08" ixz="-1.775715550954204e-07" iyy="9.067959615799793e-06" iyz="-5.0427022839883744e-08" izz="9.981406326737224e-06"/>
    </inertial>
    <visual>
      <geometry>
        <mesh filename="package://pepper_robot_description/pepper_robot/meshes/LFinger31.dae" scale="0.1 0.1 0.1"/>
      </geometry>
      <origin rpy="0 0 0" xyz="0 0 0"/>
    </visual>
    <collision>
      <geometry>
        <mesh filename="package://pepper_robot_description/pepper_robot/meshes/LFinger31_0.10.stl" scale="0.1 0.1 0.1"/>
      </geometry>
      <origin rpy="0 0 0" xyz="0 0 0"/>
    </collision>
  </link>
  <joint name="LFinger31" type="continuous">
    <parent link="l_wrist"/>
    <child link="LFinger31_link"/>
    <origin rpy="1.46636 1.04483 -0.029314" xyz="0.0833 0.0123 0.004"/>
    <axis xyz="0 0 1.0"/>
    <mimic joint="LHand" multiplier="0.872665" offset="0"/>
  </joint>
  <link name="RFinger33_link">
    <inertial>
      <mass value="0.0012119665608007826"/>
      <inertia ixx="2.09223979628447e-06" ixy="-1.1457416792102813e-07" ixz="1.4168110404002701e-08" iyy="4.049992996669056e-06" iyz="-5.704190202736846e-09" izz="4.41653713434438e-06"/>
    </inertial>
    <visual>
      <geometry>
        <mesh filename="package://pepper_robot_description/pepper_robot/meshes/RFinger33.dae" scale="0.1 0.1 0.1"/>
      </geometry>
      <origin rpy="0 0 0" xyz="0 0 0"/>
    </visual>
    <collision>
      <geometry>
        <mesh filename="package://pepper_robot_description/pepper_robot/meshes/RFinger33_0.10.stl" scale="0.1 0.1 0.1"/>
      </geometry>
      <origin rpy="0 0 0" xyz="0 0 0"/>
    </collision>
  </link>
  <joint name="RFinger33" type="continuous">
    <parent link="RFinger32_link"/>
    <child link="RFinger33_link"/>
    <origin rpy="0 0 -1.0472" xyz="0.018 0 0"/>
    <axis xyz="0 0 1.0"/>
    <mimic joint="RHand" multiplier="0.872665" offset="0"/>
  </joint>
  <link name="LThumb1_link">
    <inertial>
      <mass value="0.0017342022979805805"/>
      <inertia ixx="3.4678131551882413e-06" ixy="-3.2590509182655974e-08" ixz="-1.775715494652515e-07" iyy="9.067960211714726e-06" iyz="-5.0426946362754553e-08" izz="9.981406956932862e-06"/>
    </inertial>
    <visual>
      <geometry>
        <mesh filename="package://pepper_robot_description/pepper_robot/meshes/LThumb1.dae" scale="0.1 0.1 0.1"/>
      </geometry>
      <origin rpy="0 0 0" xyz="0 0 0"/>
    </visual>
    <collision>
      <geometry>
        <mesh filename="package://pepper_robot_description/pepper_robot/meshes/LThumb1_0.10.stl" scale="0.1 0.1 0.1"/>
      </geometry>
      <origin rpy="0 0 0" xyz="0 0 0"/>
    </collision>
  </link>
  <joint name="LThumb1" type="continuous">
    <parent link="l_wrist"/>
    <child link="LThumb1_link"/>
    <origin rpy="-1.95836 0.60626 0.533978" xyz="0.0482 -0.0357 -0.0199"/>
    <axis xyz="0 0 1.0"/>
    <mimic joint="LHand" multiplier="0.872665" offset="0"/>
  </joint>
  <link name="RThumb2_link">
    <inertial>
      <mass value="0.001211966381471568"/>
      <inertia ixx="2.0922392266947087e-06" ixy="-1.1457419844015851e-07" ixz="1.4167922235814148e-08" iyy="4.049992160501547e-06" iyz="-5.704188035340379e-09" izz="4.416536573576023e-06"/>
    </inertial>
    <visual>
      <geometry>
        <mesh filename="package://pepper_robot_description/pepper_robot/meshes/RThumb2.dae" scale="0.1 0.1 0.1"/>
      </geometry>
      <origin rpy="0 0 0" xyz="0 0 0"/>
    </visual>
    <collision>
      <geometry>
        <mesh filename="package://pepper_robot_description/pepper_robot/meshes/RThumb2_0.10.stl" scale="0.1 0.1 0.1"/>
      </geometry>
      <origin rpy="0 0 0" xyz="0 0 0"/>
    </collision>
  </link>
  <joint name="RThumb2" type="continuous">
    <parent link="RThumb1_link"/>
    <child link="RThumb2_link"/>
    <origin rpy="0 0 -1.0472" xyz="0.022 0 0"/>
    <axis xyz="0 0 1.0"/>
    <mimic joint="RHand" multiplier="0.872665" offset="0"/>
  </joint>
  <link name="RThumb1_link">
    <inertial>
      <mass value="0.0017342022979805805"/>
      <inertia ixx="3.4678131551882413e-06" ixy="-3.2590509182655974e-08" ixz="-1.775715494652515e-07" iyy="9.067960211714726e-06" iyz="-5.0426946362754553e-08" izz="9.981406956932862e-06"/>
    </inertial>
    <visual>
      <geometry>
        <mesh filename="package://pepper_robot_description/pepper_robot/meshes/RThumb1.dae" scale="0.1 0.1 0.1"/>
      </geometry>
      <origin rpy="0 0 0" xyz="0 0 0"/>
    </visual>
    <collision>
      <geometry>
        <mesh filename="package://pepper_robot_description/pepper_robot/meshes/RThumb1_0.10.stl" scale="0.1 0.1 0.1"/>
      </geometry>
      <origin rpy="0 0 0" xyz="0 0 0"/>
    </collision>
  </link>
  <joint name="RThumb1" type="continuous">
    <parent link="r_wrist"/>
    <child link="RThumb1_link"/>
    <origin rpy="-1.18323 0.60626 -0.533978" xyz="0.0482 0.0357 -0.0199"/>
    <axis xyz="0 0 1.0"/>
    <mimic joint="RHand" multiplier="0.872665" offset="0"/>
  </joint>
  <link name="LThumb2_link">
    <inertial>
      <mass value="0.001211966381471568"/>
      <inertia ixx="2.0922392266947087e-06" ixy="-1.1457419844015851e-07" ixz="1.4167922235814148e-08" iyy="4.049992160501547e-06" iyz="-5.704188035340379e-09" izz="4.416536573576023e-06"/>
    </inertial>
    <visual>
      <geometry>
        <mesh filename="package://pepper_robot_description/pepper_robot/meshes/LThumb2.dae" scale="0.1 0.1 0.1"/>
      </geometry>
      <origin rpy="0 0 0" xyz="0 0 0"/>
    </visual>
    <collision>
      <geometry>
        <mesh filename="package://pepper_robot_description/pepper_robot/meshes/LThumb2_0.10.stl" scale="0.1 0.1 0.1"/>
      </geometry>
      <origin rpy="0 0 0" xyz="0 0 0"/>
    </collision>
  </link>
  <joint name="LThumb2" type="continuous">
    <parent link="LThumb1_link"/>
    <child link="LThumb2_link"/>
    <origin rpy="0 0 -1.0472" xyz="0.022 0 0"/>
    <axis xyz="0 0 1.0"/>
    <mimic joint="LHand" multiplier="0.872665" offset="0"/>
  </joint>
  <link name="WheelFL_link">
    <inertial>
      <mass value="0.7575690379154867"/>
      <inertia ixx="0.1466676495397822" ixy="1.3894893658227998e-09" ixz="-1.847742164822289e-08" iyy="0.14546237703524983" iyz="-1.6825643126483954e-10" izz="0.1466676444244662"/>
      <origin rpy="0 0 0" xyz="-6.00045e-07 6.99637e-07 9.85261e-08"/>
    </inertial>
    <visual>
      <geometry>
        <mesh filename="package://pepper_robot_description/pepper_robot/meshes/WheelFL.dae" scale="0.1 0.1 0.1"/>
      </geometry>
      <origin rpy="0 0 0" xyz="0 0 0"/>
    </visual>
    <collision>
      <geometry>
        <mesh filename="package://pepper_robot_description/pepper_robot/meshes/WheelFL_0.10.stl" scale="0.1 0.1 0.1"/>
      </geometry>
      <origin rpy="0 0 0" xyz="0 0 0"/>
    </collision>
  </link>
  <joint name="WheelFL" type="continuous">
    <parent link="Tibia"/>
    <child link="WheelFL_link"/>
    <origin rpy="0 0 1.07517" xyz="0.09 0.155 -0.264"/>
    <axis xyz="1.0 0 0"/>
    <limit effort="3.25" lower="0" upper="0" velocity="6.28319"/>
  </joint>
  <link name="WheelB_link">
    <inertial>
      <mass value="0.7575690266305116"/>
      <inertia ixx="0.14666764930611684" ixy="2.1646351782621925e-09" ixz="-1.604289224924931e-08" iyy="0.14546237484295663" iyz="9.686419820854266e-10" izz="0.1466676359065566"/>
      <origin rpy="0 0 0" xyz="1.19122e-06 -8.10876e-08 1.02822e-07"/>
    </inertial>
    <visual>
      <geometry>
        <mesh filename="package://pepper_robot_description/pepper_robot/meshes/WheelB.dae" scale="0.1 0.1 0.1"/>
      </geometry>
      <origin rpy="0 0 0" xyz="0 0 0"/>
    </visual>
    <collision>
      <geometry>
        <mesh filename="package://pepper_robot_description/pepper_robot/meshes/WheelB_0.10.stl" scale="0.1 0.1 0.1"/>
      </geometry>
      <origin rpy="0 0 0" xyz="0 0 0"/>
    </collision>
  </link>
  <joint name="WheelB" type="continuous">
    <parent link="Tibia"/>
    <child link="WheelB_link"/>
    <origin rpy="0 0 -3.14159" xyz="-0.17 0 -0.264"/>
    <axis xyz="1.0 0 0"/>
    <limit effort="3.25" lower="0" upper="0" velocity="6.28319"/>
  </joint>
  <link name="WheelFR_link">
    <inertial>
      <mass value="0.75756900450011"/>
      <inertia ixx="0.1466676370557516" ixy="-1.2974614176969171e-09" ixz="-1.745944386185611e-08" iyy="0.14546236874613427" iyz="2.1976487590695156e-10" izz="0.14666763285273135"/>
      <origin rpy="0 0 0" xyz="1.47446e-07 -8.33076e-07 9.57624e-08"/>
    </inertial>
    <visual>
      <geometry>
        <mesh filename="package://pepper_robot_description/pepper_robot/meshes/WheelFR.dae" scale="0.1 0.1 0.1"/>
      </geometry>
      <origin rpy="0 0 0" xyz="0 0 0"/>
    </visual>
    <collision>
      <geometry>
        <mesh filename="package://pepper_robot_description/pepper_robot/meshes/WheelFR_0.10.stl" scale="0.1 0.1 0.1"/>
      </geometry>
      <origin rpy="0 0 0" xyz="0 0 0"/>
    </collision>
  </link>
  <joint name="WheelFR" type="continuous">
    <parent link="Tibia"/>
    <child link="WheelFR_link"/>
    <origin rpy="0 0 -1.07517" xyz="0.09 -0.155 -0.264"/>
    <axis xyz="1.0 0 0"/>
    <limit effort="3.25" lower="0" upper="0" velocity="6.28319"/>
  </joint>
  <joint name="base_link_fixedjoint" type="fixed">
    <parent link="base_link"/>
    <child link="Tibia"/>
    <origin rpy="0 0 0" xyz="0 0 0.334"/>
    <axis xyz="0 0 0"/>
  </joint>
  <!-- MACROS FOR DISABLE LINKS -->
  <!-- MACROS FOR MIMIC JOINTS -->
  <!-- Fingers -->
  <!-- Thumbs -->
  <!-- GAZEBO MATERIALS -->
  <gazebo reference="base_link">
    <turnGravityOff>false</turnGravityOff>
  </gazebo>
  <gazebo reference="torso">
    <mu1>0.5</mu1>
    <mu2>0.5</mu2>
    <selfCollide>false</selfCollide>
    <turnGravityOff>false</turnGravityOff>
  </gazebo>
  <gazebo reference="Neck">
    <mu1>0.5</mu1>
    <mu2>0.5</mu2>
    <selfCollide>false</selfCollide>
    <turnGravityOff>false</turnGravityOff>
  </gazebo>
  <gazebo reference="Head">
    <mu1>0.5</mu1>
    <mu2>0.5</mu2>
    <selfCollide>false</selfCollide>
    <turnGravityOff>false</turnGravityOff>
  </gazebo>
  <gazebo reference="gaze">
    <mu1>0.5</mu1>
    <mu2>0.5</mu2>
    <selfCollide>false</selfCollide>
    <turnGravityOff>false</turnGravityOff>
  </gazebo>
  <!-- ARMS -->
  <gazebo reference="LShoulder">
    <mu1>0.5</mu1>
    <mu2>0.5</mu2>
    <selfCollide>false</selfCollide>
    <turnGravityOff>false</turnGravityOff>
  </gazebo>
  <gazebo reference="LBicep">
    <mu1>0.5</mu1>
    <mu2>0.5</mu2>
    <selfCollide>false</selfCollide>
    <turnGravityOff>false</turnGravityOff>
  </gazebo>
  <gazebo reference="LElbow">
    <mu1>0.5</mu1>
    <mu2>0.5</mu2>
    <selfCollide>false</selfCollide>
    <turnGravityOff>false</turnGravityOff>
  </gazebo>
  <gazebo reference="LForeArm">
    <mu1>0.5</mu1>
    <mu2>0.5</mu2>
    <selfCollide>false</selfCollide>
    <turnGravityOff>false</turnGravityOff>
  </gazebo>
  <gazebo reference="l_wrist">
    <mu1>0.5</mu1>
    <mu2>0.5</mu2>
    <selfCollide>false</selfCollide>
    <turnGravityOff>false</turnGravityOff>
  </gazebo>
  <gazebo reference="l_gripper">
    <mu1>0.5</mu1>
    <mu2>0.5</mu2>
    <selfCollide>false</selfCollide>
    <turnGravityOff>false</turnGravityOff>
  </gazebo>
  <gazebo reference="RShoulder">
    <mu1>0.5</mu1>
    <mu2>0.5</mu2>
    <selfCollide>false</selfCollide>
    <turnGravityOff>false</turnGravityOff>
  </gazebo>
  <gazebo reference="RBicep">
    <mu1>0.5</mu1>
    <mu2>0.5</mu2>
    <selfCollide>false</selfCollide>
    <turnGravityOff>false</turnGravityOff>
  </gazebo>
  <gazebo reference="RElbow">
    <mu1>0.5</mu1>
    <mu2>0.5</mu2>
    <selfCollide>false</selfCollide>
    <turnGravityOff>false</turnGravityOff>
  </gazebo>
  <gazebo reference="RForeArm">
    <mu1>0.5</mu1>
    <mu2>0.5</mu2>
    <selfCollide>false</selfCollide>
    <turnGravityOff>false</turnGravityOff>
  </gazebo>
  <gazebo reference="r_wrist">
    <mu1>0.5</mu1>
    <mu2>0.5</mu2>
    <selfCollide>false</selfCollide>
    <turnGravityOff>false</turnGravityOff>
  </gazebo>
  <gazebo reference="r_gripper">
    <mu1>0.5</mu1>
    <mu2>0.5</mu2>
    <selfCollide>false</selfCollide>
    <turnGravityOff>false</turnGravityOff>
  </gazebo>
  <gazebo reference="LFinger11_link">
    <mu1>0.5</mu1>
    <mu2>0.5</mu2>
    <selfCollide>false</selfCollide>
    <turnGravityOff>false</turnGravityOff>
  </gazebo>
  <gazebo reference="LFinger12_link">
    <mu1>0.5</mu1>
    <mu2>0.5</mu2>
    <selfCollide>false</selfCollide>
    <turnGravityOff>false</turnGravityOff>
  </gazebo>
  <gazebo reference="LFinger13_link">
    <mu1>0.5</mu1>
    <mu2>0.5</mu2>
    <selfCollide>false</selfCollide>
    <turnGravityOff>false</turnGravityOff>
  </gazebo>
  <gazebo reference="LFinger21_link">
    <mu1>0.5</mu1>
    <mu2>0.5</mu2>
    <selfCollide>false</selfCollide>
    <turnGravityOff>false</turnGravityOff>
  </gazebo>
  <gazebo reference="LFinger22_link">
    <mu1>0.5</mu1>
    <mu2>0.5</mu2>
    <selfCollide>false</selfCollide>
    <turnGravityOff>false</turnGravityOff>
  </gazebo>
  <gazebo reference="LFinger23_link">
    <mu1>0.5</mu1>
    <mu2>0.5</mu2>
    <selfCollide>false</selfCollide>
    <turnGravityOff>false</turnGravityOff>
  </gazebo>
  <gazebo reference="LFinger31_link">
    <mu1>0.5</mu1>
    <mu2>0.5</mu2>
    <selfCollide>false</selfCollide>
    <turnGravityOff>false</turnGravityOff>
  </gazebo>
  <gazebo reference="LFinger32_link">
    <mu1>0.5</mu1>
    <mu2>0.5</mu2>
    <selfCollide>false</selfCollide>
    <turnGravityOff>false</turnGravityOff>
  </gazebo>
  <gazebo reference="LFinger33_link">
    <mu1>0.5</mu1>
    <mu2>0.5</mu2>
    <selfCollide>false</selfCollide>
    <turnGravityOff>false</turnGravityOff>
  </gazebo>
  <gazebo reference="LFinger41_link">
    <mu1>0.5</mu1>
    <mu2>0.5</mu2>
    <selfCollide>false</selfCollide>
    <turnGravityOff>false</turnGravityOff>
  </gazebo>
  <gazebo reference="LFinger42_link">
    <mu1>0.5</mu1>
    <mu2>0.5</mu2>
    <selfCollide>false</selfCollide>
    <turnGravityOff>false</turnGravityOff>
  </gazebo>
  <gazebo reference="LFinger43_link">
    <mu1>0.5</mu1>
    <mu2>0.5</mu2>
    <selfCollide>false</selfCollide>
    <turnGravityOff>false</turnGravityOff>
  </gazebo>
  <gazebo reference="LThumb1_link">
    <mu1>0.5</mu1>
    <mu2>0.5</mu2>
    <selfCollide>false</selfCollide>
    <turnGravityOff>false</turnGravityOff>
  </gazebo>
  <gazebo reference="LThumb2_link">
    <mu1>0.5</mu1>
    <mu2>0.5</mu2>
    <selfCollide>false</selfCollide>
    <turnGravityOff>false</turnGravityOff>
  </gazebo>
  <gazebo reference="Hip">
    <mu1>0.5</mu1>
    <mu2>0.5</mu2>
    <selfCollide>false</selfCollide>
    <turnGravityOff>false</turnGravityOff>
  </gazebo>
  <gazebo reference="Pelvis">
    <mu1>0.5</mu1>
    <mu2>0.5</mu2>
    <selfCollide>false</selfCollide>
    <turnGravityOff>false</turnGravityOff>
  </gazebo>
  <gazebo reference="Tibia">
    <mu1>0.5</mu1>
    <mu2>0.5</mu2>
    <selfCollide>false</selfCollide>
    <turnGravityOff>false</turnGravityOff>
  </gazebo>
  <gazebo reference="WheelFL_link">
    <mu1>1</mu1>
    <mu2>0</mu2>
    <kp value="10000000.0"/>
    <kd value="1.0"/>
    <fdir1 value="1 0 0"/>
    <minDepth>0.003</minDepth>
    <turnGravityOff>false</turnGravityOff>
  </gazebo>
  <gazebo reference="WheelB_link">
    <mu1>0.5</mu1>
    <mu2>0.5</mu2>
    <kp value="10000000.0"/>
    <kd value="1.0"/>
    <fdir1 value="1 0 0"/>
    <minDepth>0.003</minDepth>
    <turnGravityOff>false</turnGravityOff>
  </gazebo>
  <gazebo reference="WheelFR_link">
    <mu1>0</mu1>
    <mu2>1</mu2>
    <kp value="10000000.0"/>
    <kd value="1.0"/>
    <fdir1 value="0 1 0"/>
    <minDepth>0.003</minDepth>
    <turnGravityOff>false</turnGravityOff>
  </gazebo>
  <gazebo reference="RFinger11_link">
    <mu1>0.5</mu1>
    <mu2>0.5</mu2>
    <selfCollide>false</selfCollide>
    <turnGravityOff>false</turnGravityOff>
  </gazebo>
  <gazebo reference="RFinger12_link">
    <mu1>0.5</mu1>
    <mu2>0.5</mu2>
    <selfCollide>false</selfCollide>
    <turnGravityOff>false</turnGravityOff>
  </gazebo>
  <gazebo reference="RFinger13_link">
    <mu1>0.5</mu1>
    <mu2>0.5</mu2>
    <selfCollide>false</selfCollide>
    <turnGravityOff>false</turnGravityOff>
  </gazebo>
  <gazebo reference="RFinger21_link">
    <mu1>0.5</mu1>
    <mu2>0.5</mu2>
    <selfCollide>false</selfCollide>
    <turnGravityOff>false</turnGravityOff>
  </gazebo>
  <gazebo reference="RFinger22_link">
    <mu1>0.5</mu1>
    <mu2>0.5</mu2>
    <selfCollide>false</selfCollide>
    <turnGravityOff>false</turnGravityOff>
  </gazebo>
  <gazebo reference="RFinger23_link">
    <mu1>0.5</mu1>
    <mu2>0.5</mu2>
    <selfCollide>false</selfCollide>
    <turnGravityOff>false</turnGravityOff>
  </gazebo>
  <gazebo reference="RFinger31_link">
    <mu1>0.5</mu1>
    <mu2>0.5</mu2>
    <selfCollide>false</selfCollide>
    <turnGravityOff>false</turnGravityOff>
  </gazebo>
  <gazebo reference="RFinger32_link">
    <mu1>0.5</mu1>
    <mu2>0.5</mu2>
    <selfCollide>false</selfCollide>
    <turnGravityOff>false</turnGravityOff>
  </gazebo>
  <gazebo reference="RFinger33_link">
    <mu1>0.5</mu1>
    <mu2>0.5</mu2>
    <selfCollide>false</selfCollide>
    <turnGravityOff>false</turnGravityOff>
  </gazebo>
  <gazebo reference="RFinger41_link">
    <mu1>0.5</mu1>
    <mu2>0.5</mu2>
    <selfCollide>false</selfCollide>
    <turnGravityOff>false</turnGravityOff>
  </gazebo>
  <gazebo reference="RFinger42_link">
    <mu1>0.5</mu1>
    <mu2>0.5</mu2>
    <selfCollide>false</selfCollide>
    <turnGravityOff>false</turnGravityOff>
  </gazebo>
  <gazebo reference="RFinger43_link">
    <mu1>0.5</mu1>
    <mu2>0.5</mu2>
    <selfCollide>false</selfCollide>
    <turnGravityOff>false</turnGravityOff>
  </gazebo>
  <gazebo reference="RThumb1_link">
    <mu1>0.5</mu1>
    <mu2>0.5</mu2>
    <selfCollide>false</selfCollide>
    <turnGravityOff>false</turnGravityOff>
  </gazebo>
  <gazebo reference="RThumb2_link">
    <mu1>0.5</mu1>
    <mu2>0.5</mu2>
    <selfCollide>false</selfCollide>
    <turnGravityOff>false</turnGravityOff>
  </gazebo>
  <!--
        RGB CAMERAS
-->
  <gazebo reference="CameraTop_frame">
    <sensor name="CameraTop" type="camera">
      <update_rate>5.0</update_rate>
      <camera name="camera_top">
        <horizontal_fov>1.0</horizontal_fov>
        <image>
          <width>640</width>
          <height>480</height>
          <format>R8G8B8</format>
        </image>
        <clip>
          <near>0.3</near>
          <far>500</far>
        </clip>
        <noise>
          <type>gaussian</type>
          <mean>0.0</mean>
          <stddev>0.007</stddev>
        </noise>
      </camera>
    </sensor>
  </gazebo>
  <gazebo reference="CameraBottom_frame">
    <sensor name="CameraBottom" type="camera">
      <update_rate>5.0</update_rate>
      <camera name="camera_bottom">
        <horizontal_fov>1.0</horizontal_fov>
        <image>
          <width>640</width>
          <height>480</height>
          <format>R8G8B8</format>
        </image>
        <clip>
          <near>0.05</near>
          <far>500</far>
        </clip>
        <noise>
          <type>gaussian</type>
          <mean>0.0</mean>
          <stddev>0.007</stddev>
        </noise>
      </camera>
    </sensor>
  </gazebo>
  <gazebo reference="CameraDepth_frame">
    <sensor name="CameraDepth_frame_sensor" type="depth">
      <always_on>true</always_on>
      <update_rate>20.0</update_rate>
      <camera>
        <horizontal_fov>1.01229096616</horizontal_fov>
        <image>
          <format>B8G8R8</format>
          <width>320</width>
          <height>240</height>
        </image>
        <clip>
          <near>0.4</near>
          <far>8.0</far>
        </clip>
      </camera>
    </sensor>
  </gazebo>
  <!--
    BUMPERS
<gazebo reference="BumperB_frame">
  <mu1>0.5</mu1>
  <mu2>0.5</mu2>
  <selfCollide>false</selfCollide>
  <turnGravityOff>false</turnGravityOff>
  <fdir1>1 0 0</fdir1>
  <maxVel>0.1</maxVel>
  <minDepth>0.003</minDepth>
  <sensor name="BumperB" type="contact">
    <always_on>1</always_on>
    <update_rate>20</update_rate>
    <visualize>false</visualize>
    <contact>
      <collision>BumperB_frame_collision</collision>
    </contact>
  </sensor>
</gazebo>
<gazebo reference="BumperFL_frame">
  <mu1>0.5</mu1>
  <mu2>0.5</mu2>
  <selfCollide>false</selfCollide>
  <turnGravityOff>false</turnGravityOff>
  <fdir1>1 0 0</fdir1>
  <maxVel>0.1</maxVel>
  <minDepth>0.003</minDepth>
  <sensor name="BumperFL" type="contact">
    <always_on>1</always_on>
    <update_rate>20</update_rate>
    <visualize>false</visualize>
    <contact>
      <collision>BumperFL_frame_collision</collision>
    </contact>
  </sensor>
</gazebo>
<gazebo reference="BumperFR_frame">
  <mu1>0.5</mu1>
  <mu2>0.5</mu2>
  <selfCollide>false</selfCollide>
  <turnGravityOff>false</turnGravityOff>
  <fdir1>1 0 0</fdir1>
  <maxVel>0.1</maxVel>
  <minDepth>0.003</minDepth>
  <sensor name="BumperFR" type="contact">
    <always_on>1</always_on>
    <update_rate>20</update_rate>
    <visualize>false</visualize>
    <contact>
      <collision>BumperFR_frame_collision</collision>
    </contact>
  </sensor>
</gazebo>
-->
  <!--
    Sonars
-->
  <gazebo reference="SonarBack_frame">
    <sensor name="SonarBack" type="ray">
      <pose>0 0 0 0 0 0</pose>
      <update_rate>20</update_rate>
      <visualize>false</visualize>
      <ray>
        <scan>
          <horizontal>
            <samples>5</samples>
            <resolution>3</resolution>
            <min_angle>-0.52</min_angle>
            <max_angle>0.52</max_angle>
          </horizontal>
          <vertical>
            <samples>5</samples>
            <resolution>3</resolution>
            <min_angle>-0.52</min_angle>
            <max_angle>0.52</max_angle>
          </vertical>
        </scan>
        <range>
          <min>0.0</min>
          <max>5.0</max>
          <resolution>3</resolution>
        </range>
      </ray>
    </sensor>
  </gazebo>
  <gazebo reference="SonarFront_frame">
    <sensor name="SonarFront" type="ray">
      <pose>0 0 0 0 0 0</pose>
      <update_rate>20</update_rate>
      <visualize>false</visualize>
      <ray>
        <scan>
          <horizontal>
            <samples>5</samples>
            <resolution>3</resolution>
            <min_angle>-0.52</min_angle>
            <max_angle>0.52</max_angle>
          </horizontal>
          <vertical>
            <samples>5</samples>
            <resolution>3</resolution>
            <min_angle>-0.52</min_angle>
            <max_angle>0.52</max_angle>
          </vertical>
        </scan>
        <range>
          <min>0.0</min>
          <max>5.0</max>
          <resolution>3</resolution>
        </range>
      </ray>
    </sensor>
  </gazebo>
  <!-- Drive controller -->
<ros2_control name="pepper_robot_wheel_system" type="system">
    <hardware>
      <plugin>ign_ros2_control/IgnitionSystem</plugin>
    </hardware>
    <joint name="WheelFL">
      <param name="initial_position">0</param>
      <state_interface name="position"/>
      <state_interface name="velocity"/>
      <state_interface name="effort"/>
    </joint>
    <joint name="WheelB">
      <param name="initial_position">0</param>
      <state_interface name="position"/>
      <state_interface name="velocity"/>
      <state_interface name="effort"/>
    </joint>
    <joint name="WheelFR">
      <param name="initial_position">0</param>
      <state_interface name="position"/>
      <state_interface name="velocity"/>
      <state_interface name="effort"/>
    </joint>
  </ros2_control>
  <gazebo>
    <plugin filename="ignition-gazebo-diff-drive-system" name="ignition::gazebo::systems::DiffDrive">
    <left_joint>WheelFL</left_joint>
    <right_joint>WheelFR</right_joint>
    <back_joint>WheelB</back_joint>
    <wheel_separation>0.170</wheel_separation>
    <wheel_radius>0.07</wheel_radius>
    </plugin>
  </gazebo>

<!-- HEAD -->
  <transmission name="HeadYaw_Transmission">
    <type>transmission_interface/SimpleTransmission</type>
    <joint name="HeadYaw">
      <hardwareInterface>hardware_interface/PositionJointInterface</hardwareInterface>
    </joint>
    <actuator name="HeadYaw_Motor">
      <!-- Dummy Values -->
      <hardwareInterface>hardware_interface/PositionJointInterface</hardwareInterface>
      <mechanicalReduction>101.3</mechanicalReduction>
    </actuator>
  </transmission>
  <transmission name="HeadPitch_Transmission">
    <type>transmission_interface/SimpleTransmission</type>
    <joint name="HeadPitch">
      <hardwareInterface>hardware_interface/PositionJointInterface</hardwareInterface>
    </joint>
    <actuator name="HeadPitch_Motor">
      <!-- Dummy Values -->
      <hardwareInterface>hardware_interface/PositionJointInterface</hardwareInterface>
      <mechanicalReduction>118.1</mechanicalReduction>
    </actuator>
  </transmission>
  <!-- ARMS -->
  <!-- XACRO -->
  <transmission name="LShoulderPitch_Transmission">
    <type>transmission_interface/SimpleTransmission</type>
    <joint name="LShoulderPitch">
      <hardwareInterface>hardware_interface/EffortJointInterface</hardwareInterface>
    </joint>
    <actuator name="LShoulderPitch_Motor">
      <hardwareInterface>hardware_interface/EffortJointInterface</hardwareInterface>
      <mechanicalReduction>101.3</mechanicalReduction>
    </actuator>
  </transmission>
  <transmission name="LShoulderRoll_Transmission">
    <type>transmission_interface/SimpleTransmission</type>
    <joint name="LShoulderRoll">
      <hardwareInterface>hardware_interface/EffortJointInterface</hardwareInterface>
    </joint>
    <actuator name="LShoulderRoll_Motor">
      <hardwareInterface>hardware_interface/EffortJointInterface</hardwareInterface>
      <mechanicalReduction>118.1</mechanicalReduction>
    </actuator>
  </transmission>
  <transmission name="LElbowYaw_Transmission">
    <type>transmission_interface/SimpleTransmission</type>
    <joint name="LElbowYaw">
      <hardwareInterface>hardware_interface/EffortJointInterface</hardwareInterface>
    </joint>
    <actuator name="LElbowYaw_Motor">
      <hardwareInterface>hardware_interface/EffortJointInterface</hardwareInterface>
      <mechanicalReduction>101.3</mechanicalReduction>
    </actuator>
  </transmission>
  <transmission name="LElbowRoll_Transmission">
    <type>transmission_interface/SimpleTransmission</type>
    <joint name="LElbowRoll">
      <hardwareInterface>hardware_interface/EffortJointInterface</hardwareInterface>
    </joint>
    <actuator name="LElbowRoll_Motor">
      <hardwareInterface>hardware_interface/EffortJointInterface</hardwareInterface>
      <mechanicalReduction>118.1</mechanicalReduction>
    </actuator>
  </transmission>
  <transmission name="LWristYaw_Transmission">
    <type>transmission_interface/SimpleTransmission</type>
    <joint name="LWristYaw">
      <hardwareInterface>hardware_interface/EffortJointInterface</hardwareInterface>
    </joint>
    <actuator name="LWristYaw_Motor">
      <hardwareInterface>hardware_interface/EffortJointInterface</hardwareInterface>
      <mechanicalReduction>118.1</mechanicalReduction>
    </actuator>
  </transmission>
  <transmission name="LHand_Transmission">
    <type>transmission_interface/SimpleTransmission</type>
    <joint name="LHand">
      <hardwareInterface>hardware_interface/EffortJointInterface</hardwareInterface>
    </joint>
    <actuator name="LHand_Motor">
      <hardwareInterface>hardware_interface/EffortJointInterface</hardwareInterface>
      <mechanicalReduction>36.24</mechanicalReduction>
    </actuator>
  </transmission>
  <transmission name="RShoulderPitch_Transmission">
    <type>transmission_interface/SimpleTransmission</type>
    <joint name="RShoulderPitch">
      <hardwareInterface>hardware_interface/EffortJointInterface</hardwareInterface>
    </joint>
    <actuator name="RShoulderPitch_Motor">
      <hardwareInterface>hardware_interface/EffortJointInterface</hardwareInterface>
      <mechanicalReduction>101.3</mechanicalReduction>
    </actuator>
  </transmission>
  <transmission name="RShoulderRoll_Transmission">
    <type>transmission_interface/SimpleTransmission</type>
    <joint name="RShoulderRoll">
      <hardwareInterface>hardware_interface/EffortJointInterface</hardwareInterface>
    </joint>
    <actuator name="RShoulderRoll_Motor">
      <hardwareInterface>hardware_interface/EffortJointInterface</hardwareInterface>
      <mechanicalReduction>118.1</mechanicalReduction>
    </actuator>
  </transmission>
  <transmission name="RElbowYaw_Transmission">
    <type>transmission_interface/SimpleTransmission</type>
    <joint name="RElbowYaw">
      <hardwareInterface>hardware_interface/EffortJointInterface</hardwareInterface>
    </joint>
    <actuator name="RElbowYaw_Motor">
      <hardwareInterface>hardware_interface/EffortJointInterface</hardwareInterface>
      <mechanicalReduction>101.3</mechanicalReduction>
    </actuator>
  </transmission>
  <transmission name="RElbowRoll_Transmission">
    <type>transmission_interface/SimpleTransmission</type>
    <joint name="RElbowRoll">
      <hardwareInterface>hardware_interface/EffortJointInterface</hardwareInterface>
    </joint>
    <actuator name="RElbowRoll_Motor">
      <hardwareInterface>hardware_interface/EffortJointInterface</hardwareInterface>
      <mechanicalReduction>118.1</mechanicalReduction>
    </actuator>
  </transmission>
  <transmission name="RWristYaw_Transmission">
    <type>transmission_interface/SimpleTransmission</type>
    <joint name="RWristYaw">
      <hardwareInterface>hardware_interface/EffortJointInterface</hardwareInterface>
    </joint>
    <actuator name="RWristYaw_Motor">
      <hardwareInterface>hardware_interface/EffortJointInterface</hardwareInterface>
      <mechanicalReduction>118.1</mechanicalReduction>
    </actuator>
  </transmission>
  <transmission name="RHand_Transmission">
    <type>transmission_interface/SimpleTransmission</type>
    <joint name="RHand">
      <hardwareInterface>hardware_interface/EffortJointInterface</hardwareInterface>
    </joint>
    <actuator name="RHand_Motor">
      <hardwareInterface>hardware_interface/EffortJointInterface</hardwareInterface>
      <mechanicalReduction>36.24</mechanicalReduction>
    </actuator>
  </transmission>
  <!-- LEGS -->
  <transmission name="HipRoll_Transmission">
    <type>transmission_interface/SimpleTransmission</type>
    <joint name="HipRoll">
      <hardwareInterface>hardware_interface/EffortJointInterface</hardwareInterface>
    </joint>
    <actuator name="HipRoll_Motor">
      <!-- Dummy Values -->
      <hardwareInterface>hardware_interface/EffortJointInterface</hardwareInterface>
      <mechanicalReduction>108.33</mechanicalReduction>
    </actuator>
  </transmission>
  <transmission name="HipPitch_Transmission">
    <type>transmission_interface/SimpleTransmission</type>
    <joint name="HipPitch">
      <hardwareInterface>hardware_interface/EffortJointInterface</hardwareInterface>
    </joint>
    <actuator name="HipPitch_Motor">
      <!-- Dummy Values -->
      <hardwareInterface>hardware_interface/EffortJointInterface</hardwareInterface>
      <mechanicalReduction>108.33</mechanicalReduction>
    </actuator>
  </transmission>
  <transmission name="KneePitch_Transmission">
    <type>transmission_interface/SimpleTransmission</type>
    <joint name="KneePitch">
      <hardwareInterface>hardware_interface/EffortJointInterface</hardwareInterface>
    </joint>
    <actuator name="KneePitch_Motor">
      <!-- Dummy Values -->
      <hardwareInterface>hardware_interface/EffortJointInterface</hardwareInterface>
      <mechanicalReduction>108.33</mechanicalReduction>
    </actuator>
  </transmission>
  <!-- XACRO -->
  <transmission name="WheelFL_Transmission">
    <type>transmission_interface/SimpleTransmission</type>
    <joint name="WheelFL">
      <hardwareInterface>hardware_interface/VelocityJointInterface</hardwareInterface>
    </joint>
    <actuator name="WheelFL_Motor">
      <!-- Dummy Values -->
      <hardwareInterface>hardware_interface/VelocityJointInterface</hardwareInterface>
      <mechanicalReduction>25.0</mechanicalReduction>
    </actuator>
  </transmission>
  <transmission name="WheelB_Transmission">
    <type>transmission_interface/SimpleTransmission</type>
    <joint name="WheelB">
      <hardwareInterface>hardware_interface/VelocityJointInterface</hardwareInterface>
    </joint>
    <actuator name="WheelB_Motor">
      <!-- Dummy Values -->
      <hardwareInterface>hardware_interface/VelocityJointInterface</hardwareInterface>
      <mechanicalReduction>25.0</mechanicalReduction>
    </actuator>
  </transmission>
  <transmission name="WheelFR_Transmission">
    <type>transmission_interface/SimpleTransmission</type>
    <joint name="WheelFR">
      <hardwareInterface>hardware_interface/VelocityJointInterface</hardwareInterface>
    </joint>
    <actuator name="WheelFR_Motor">
      <!-- Dummy Values -->
      <hardwareInterface>hardware_interface/VelocityJointInterface</hardwareInterface>
      <mechanicalReduction>25.0</mechanicalReduction>
    </actuator>
  </transmission>
  <ros2_control name="pepper_robot_left_armSystem" type="system">
    <hardware>
      <plugin>ign_ros2_control/IgnitionSystem</plugin>
    </hardware>
    <joint name="LShoulderPitch">
      <param name="initial_position">0.0</param>
      <command_interface name="effort"/>
      <state_interface name="position"/>
      <state_interface name="velocity"/>
      <state_interface name="effort"/>
    </joint>
    <joint name="LShoulderRoll">
      <param name="initial_position">3.141592653589793</param>
      <command_interface name="effort"/>
      <state_interface name="position"/>
      <state_interface name="velocity"/>
      <state_interface name="effort"/>
    </joint>
    <joint name="LElbowYaw">
      <param name="initial_position">0.0</param>
      <command_interface name="effort"/>
      <state_interface name="position"/>
      <state_interface name="velocity"/>
      <state_interface name="effort"/>
    </joint>
    <joint name="LElbowRoll">
      <param name="initial_position">4.71238898038469</param>
      <command_interface name="effort"/>
      <state_interface name="position"/>
      <state_interface name="velocity"/>
      <state_interface name="effort"/>
    </joint>
    <joint name="LWristYaw">
      <param name="initial_position">0.0</param>
      <command_interface name="effort"/>
      <state_interface name="position"/>
      <state_interface name="velocity"/>
      <state_interface name="effort"/>
    </joint>
  </ros2_control>
  <ros2_control name="pepper_robot_right_armSystem" type="system">
    <hardware>
      <plugin>ign_ros2_control/IgnitionSystem</plugin>
    </hardware>
    <joint name="RShoulderPitch">
      <param name="initial_position">0.0</param>
      <command_interface name="effort"/>
      <state_interface name="position"/>
      <state_interface name="velocity"/>
      <state_interface name="effort"/>
    </joint>
    <joint name="RShoulderRoll">
      <param name="initial_position">3.141592653589793</param>
      <command_interface name="effort"/>
      <state_interface name="position"/>
      <state_interface name="velocity"/>
      <state_interface name="effort"/>
    </joint>
    <joint name="RElbowYaw">
      <param name="initial_position">0.0</param>
      <command_interface name="effort"/>
      <state_interface name="position"/>
      <state_interface name="velocity"/>
      <state_interface name="effort"/>
    </joint>
    <joint name="RElbowRoll">
      <param name="initial_position">4.71238898038469</param>
      <command_interface name="effort"/>
      <state_interface name="position"/>
      <state_interface name="velocity"/>
      <state_interface name="effort"/>
    </joint>
    <joint name="RWristYaw">
      <param name="initial_position">0.0</param>
      <command_interface name="effort"/>
      <state_interface name="position"/>
      <state_interface name="velocity"/>
      <state_interface name="effort"/>
    </joint>
  </ros2_control>
  <ros2_control name="pepper_robot_HeadSystem" type="system">
    <hardware>
      <plugin>ign_ros2_control/IgnitionSystem</plugin>
    </hardware>
    <joint name="HeadYaw">
      <param name="initial_position">0.0</param>
      <command_interface name="effort"/>
      <state_interface name="position"/>
      <state_interface name="velocity"/>
      <state_interface name="effort"/>
    </joint>
    <joint name="HeadPitch">
      <param name="initial_position">3.141592653589793</param>
      <command_interface name="effort"/>
      <state_interface name="position"/>
      <state_interface name="velocity"/>
      <state_interface name="effort"/>
    </joint>
  </ros2_control>
  <ros2_control name="pepper_robot_PelvisSystem" type="system">
    <hardware>
      <plugin>ign_ros2_control/IgnitionSystem</plugin>
    </hardware>
    <joint name="HipRoll">
      <param name="initial_position">0.0</param>
      <command_interface name="effort"/>
      <state_interface name="position"/>
      <state_interface name="velocity"/>
      <state_interface name="effort"/>
    </joint>
    <joint name="HipPitch">
      <param name="initial_position">3.141592653589793</param>
      <command_interface name="effort"/>
      <state_interface name="position"/>
      <state_interface name="velocity"/>
      <state_interface name="effort"/>
    </joint>
    <joint name="KneePitch">
      <param name="initial_position">3.141592653589793</param>
      <command_interface name="effort"/>
      <state_interface name="position"/>
      <state_interface name="velocity"/>
      <state_interface name="effort"/>
    </joint>
  </ros2_control>
  <ros2_control name="pepper_robot_LHandSystem" type="system">
    <hardware>
      <plugin>ign_ros2_control/IgnitionSystem</plugin>
    </hardware>
    <joint name="LHand">
      <param name="initial_position">0.0</param>
      <command_interface name="effort"/>
      <state_interface name="position"/>
      <state_interface name="velocity"/>
      <state_interface name="effort"/>
    </joint>
    <joint name="LFinger11">
      <param name="initial_position">0.2</param>
      <command_interface name="effort"/>
      <state_interface name="position"/>
      <state_interface name="velocity"/>
      <state_interface name="effort"/>
    </joint>
    <joint name="LFinger12">
      <param name="initial_position">0.2</param>
      <command_interface name="effort"/>
      <state_interface name="position"/>
      <state_interface name="velocity"/>
      <state_interface name="effort"/>
    </joint>
    <joint name="LFinger13">
      <param name="initial_position">0.2</param>
      <command_interface name="effort"/>
      <state_interface name="position"/>
      <state_interface name="velocity"/>
      <state_interface name="effort"/>
    </joint>
    <joint name="LFinger21">
      <param name="initial_position">0.2</param>
      <command_interface name="effort"/>
      <state_interface name="position"/>
      <state_interface name="velocity"/>
      <state_interface name="effort"/>
    </joint>
    <joint name="LFinger22">
      <param name="initial_position">0.2</param>
      <command_interface name="effort"/>
      <state_interface name="position"/>
      <state_interface name="velocity"/>
      <state_interface name="effort"/>
    </joint>
    <joint name="LFinger23">
      <param name="initial_position">0.2</param>
      <command_interface name="effort"/>
      <state_interface name="position"/>
      <state_interface name="velocity"/>
      <state_interface name="effort"/>
    </joint>
    <joint name="LFinger31">
      <param name="initial_position">0.2</param>
      <command_interface name="effort"/>
      <state_interface name="position"/>
      <state_interface name="velocity"/>
      <state_interface name="effort"/>
    </joint>
    <joint name="LFinger32">
      <param name="initial_position">0.2</param>
      <command_interface name="effort"/>
      <state_interface name="position"/>
      <state_interface name="velocity"/>
      <state_interface name="effort"/>
    </joint>
    <joint name="LFinger33">
      <param name="initial_position">0.2</param>
      <command_interface name="effort"/>
      <state_interface name="position"/>
      <state_interface name="velocity"/>
      <state_interface name="effort"/>
    </joint>
    <joint name="LFinger41">
      <param name="initial_position">0.2</param>
      <command_interface name="effort"/>
      <state_interface name="position"/>
      <state_interface name="velocity"/>
      <state_interface name="effort"/>
    </joint>
    <joint name="LFinger42">
      <param name="initial_position">0.2</param>
      <command_interface name="effort"/>
      <state_interface name="position"/>
      <state_interface name="velocity"/>
      <state_interface name="effort"/>
    </joint>
    <joint name="LFinger43">
      <param name="initial_position">0.2</param>
      <command_interface name="effort"/>
      <state_interface name="position"/>
      <state_interface name="velocity"/>
      <state_interface name="effort"/>
    </joint>
    <joint name="LThumb1">
      <param name="initial_position">0.2</param>
      <command_interface name="effort"/>
      <state_interface name="position"/>
      <state_interface name="velocity"/>
      <state_interface name="effort"/>
    </joint>
    <joint name="LThumb2">
      <param name="initial_position">0.2</param>
      <command_interface name="effort"/>
      <state_interface name="position"/>
      <state_interface name="velocity"/>
      <state_interface name="effort"/>
    </joint>
  </ros2_control>
  <ros2_control name="pepper_robot_RHandSystem" type="system">
    <hardware>
      <plugin>ign_ros2_control/IgnitionSystem</plugin>
    </hardware>
    <joint name="RHand">
      <param name="initial_position">0.0</param>
      <command_interface name="effort"/>
      <state_interface name="position"/>
      <state_interface name="velocity"/>
      <state_interface name="effort"/>
    </joint>
    <joint name="RFinger11">
      <param name="initial_position">0.2</param>
      <command_interface name="effort"/>
      <state_interface name="position"/>
      <state_interface name="velocity"/>
      <state_interface name="effort"/>
    </joint>
    <joint name="RFinger12">
      <param name="initial_position">0.2</param>
      <command_interface name="effort"/>
      <state_interface name="position"/>
      <state_interface name="velocity"/>
      <state_interface name="effort"/>
    </joint>
    <joint name="RFinger13">
      <param name="initial_position">0.2</param>
      <command_interface name="effort"/>
      <state_interface name="position"/>
      <state_interface name="velocity"/>
      <state_interface name="effort"/>
    </joint>
    <joint name="RFinger21">
      <param name="initial_position">0.2</param>
      <command_interface name="effort"/>
      <state_interface name="position"/>
      <state_interface name="velocity"/>
      <state_interface name="effort"/>
    </joint>
    <joint name="RFinger22">
      <param name="initial_position">0.2</param>
      <command_interface name="effort"/>
      <state_interface name="position"/>
      <state_interface name="velocity"/>
      <state_interface name="effort"/>
    </joint>
    <joint name="RFinger23">
      <param name="initial_position">0.2</param>
      <command_interface name="effort"/>
      <state_interface name="position"/>
      <state_interface name="velocity"/>
      <state_interface name="effort"/>
    </joint>
    <joint name="RFinger31">
      <param name="initial_position">0.2</param>
      <command_interface name="effort"/>
      <state_interface name="position"/>
      <state_interface name="velocity"/>
      <state_interface name="effort"/>
    </joint>
    <joint name="RFinger32">
      <param name="initial_position">0.2</param>
      <command_interface name="effort"/>
      <state_interface name="position"/>
      <state_interface name="velocity"/>
      <state_interface name="effort"/>
    </joint>
    <joint name="RFinger33">
      <param name="initial_position">0.2</param>
      <command_interface name="effort"/>
      <state_interface name="position"/>
      <state_interface name="velocity"/>
      <state_interface name="effort"/>
    </joint>
    <joint name="RFinger41">
      <param name="initial_position">0.2</param>
      <command_interface name="effort"/>
      <state_interface name="position"/>
      <state_interface name="velocity"/>
      <state_interface name="effort"/>
    </joint>
    <joint name="RFinger42">
      <param name="initial_position">0.2</param>
      <command_interface name="effort"/>
      <state_interface name="position"/>
      <state_interface name="velocity"/>
      <state_interface name="effort"/>
    </joint>
    <joint name="RFinger43">
      <param name="initial_position">0.2</param>
      <command_interface name="effort"/>
      <state_interface name="position"/>
      <state_interface name="velocity"/>
      <state_interface name="effort"/>
    </joint>
    <joint name="RThumb1">
      <param name="initial_position">0.2</param>
      <command_interface name="effort"/>
      <state_interface name="position"/>
      <state_interface name="velocity"/>
      <state_interface name="effort"/>
    </joint>
    <joint name="RThumb2">
      <param name="initial_position">0.2</param>
      <command_interface name="effort"/>
      <state_interface name="position"/>
      <state_interface name="velocity"/>
      <state_interface name="effort"/>
    </joint>
  </ros2_control>
   <gazebo>
    <plugin filename="ign_ros2_control-system" name="ign_ros2_control::IgnitionROS2ControlPlugin">
      <parameters>/root/ws/src/pepper_ign_moveit2/pepper_robot_moveit_config/config/controllers_effort.yaml</parameters>
    </plugin>
  </gazebo>
  <gazebo>
    <plugin filename="ignition-gazebo-pose-publisher-system" name="ignition::gazebo::systems::PosePublisher">
      <use_pose_vector_msg>true</use_pose_vector_msg>
      <publish_nested_model_pose>true</publish_nested_model_pose>
      <publish_link_pose>false</publish_link_pose>
      <publish_collision_pose>false</publish_collision_pose>
      <publish_visual_pose>false</publish_visual_pose>
    </plugin>
  </gazebo>
</robot>